package morethantrees.treegen;

import java.util.Random;

import net.minecraft.block.Block;
import net.minecraft.world.World;
import net.minecraft.world.gen.feature.WorldGenerator;

public class WorldGenGiantMushroomShroom extends WorldGenerator
{
    public boolean generate(World world, Random var2, int i, int j, int k)
    {
        while ((world.isAirBlock(i + 10, j, k + 12)) && (j > 2))
        {
            j--;
        }
        
        int var6 = world.getBlockId(i + 10, j, k + 12);
        
        if (var6 != Block.grass.blockID)
        {
            return false;
        }
        
        for (int var7 = -2; var7 <= 2; var7++)
        {
            for (int var8 = -2; var8 <= 2; var8++)
            {
                if ((world.isAirBlock(i + var7 + 10, j - 1, k + var8 + 12)) && (world.isAirBlock(i + var7 + 10, j - 2, k + var8 + 12)))
                {
                    return false;
                }
            }
        }
        world.setBlock(i + 8, j + 0, k + 8, 100, 0, 2);
        world.setBlock(i + 9, j + 0, k + 9, 100, 0, 2);
        world.setBlock(i + 9, j + 0, k + 8, 100, 0, 2);
        world.setBlock(i + 10, j + 0, k + 9, 100, 0, 2);
        world.setBlock(i + 10, j + 0, k + 8, 100, 0, 2);
        world.setBlock(i + 10, j + 0, k + 7, 100, 0, 2);
        world.setBlock(i + 11, j + 0, k + 10, 100, 0, 2);
        world.setBlock(i + 11, j + 0, k + 9, 100, 0, 2);
        world.setBlock(i + 11, j + 0, k + 8, 100, 0, 2);
        world.setBlock(i + 11, j + 0, k + 7, 100, 0, 2);
        world.setBlock(i + 12, j + 0, k + 9, 100, 0, 2);
        world.setBlock(i + 12, j + 0, k + 8, 100, 0, 2);
        world.setBlock(i + 9, j + 1, k + 8, 100, 0, 2);
        world.setBlock(i + 9, j + 1, k + 7, 100, 0, 2);
        world.setBlock(i + 10, j + 1, k + 9, 100, 0, 2);
        world.setBlock(i + 10, j + 1, k + 8, 100, 0, 2);
        world.setBlock(i + 11, j + 1, k + 9, 100, 0, 2);
        world.setBlock(i + 11, j + 1, k + 8, 100, 0, 2);
        world.setBlock(i + 9, j + 2, k + 8, 100, 0, 2);
        world.setBlock(i + 9, j + 2, k + 7, 100, 0, 2);
        world.setBlock(i + 10, j + 2, k + 8, 100, 0, 2);
        world.setBlock(i + 10, j + 2, k + 7, 100, 0, 2);
        world.setBlock(i + 10, j + 2, k + 6, 100, 0, 2);
        world.setBlock(i + 11, j + 2, k + 8, 100, 0, 2);
        world.setBlock(i + 11, j + 2, k + 7, 100, 0, 2);
        world.setBlock(i + 9, j + 3, k + 7, 100, 0, 2);
        world.setBlock(i + 10, j + 3, k + 8, 100, 0, 2);
        world.setBlock(i + 10, j + 3, k + 7, 100, 0, 2);
        world.setBlock(i + 10, j + 3, k + 6, 100, 0, 2);
        world.setBlock(i + 11, j + 3, k + 7, 100, 0, 2);
        world.setBlock(i + 11, j + 3, k + 6, 100, 0, 2);
        world.setBlock(i + 8, j + 4, k + 7, 100, 0, 2);
        world.setBlock(i + 8, j + 4, k + 6, 100, 0, 2);
        world.setBlock(i + 9, j + 4, k + 8, 100, 0, 2);
        world.setBlock(i + 9, j + 4, k + 7, 100, 0, 2);
        world.setBlock(i + 9, j + 4, k + 6, 100, 0, 2);
        world.setBlock(i + 9, j + 4, k + 5, 100, 0, 2);
        world.setBlock(i + 10, j + 4, k + 8, 100, 0, 2);
        world.setBlock(i + 10, j + 4, k + 7, 100, 0, 2);
        world.setBlock(i + 10, j + 4, k + 6, 100, 0, 2);
        world.setBlock(i + 8, j + 5, k + 8, 100, 0, 2);
        world.setBlock(i + 8, j + 5, k + 7, 100, 0, 2);
        world.setBlock(i + 8, j + 5, k + 6, 100, 0, 2);
        world.setBlock(i + 9, j + 5, k + 8, 100, 0, 2);
        world.setBlock(i + 9, j + 5, k + 7, 100, 0, 2);
        world.setBlock(i + 9, j + 5, k + 6, 100, 0, 2);
        world.setBlock(i + 10, j + 5, k + 7, 100, 0, 2);
        world.setBlock(i + 10, j + 5, k + 6, 100, 0, 2);
        world.setBlock(i + 8, j + 6, k + 6, 100, 0, 2);
        world.setBlock(i + 8, j + 6, k + 5, 100, 0, 2);
        world.setBlock(i + 9, j + 6, k + 7, 100, 0, 2);
        world.setBlock(i + 9, j + 6, k + 6, 100, 0, 2);
        world.setBlock(i + 9, j + 6, k + 5, 100, 0, 2);
        world.setBlock(i + 10, j + 6, k + 6, 100, 0, 2);
        world.setBlock(i + 10, j + 6, k + 5, 100, 0, 2);
        world.setBlock(i + 7, j + 7, k + 5, 100, 0, 2);
        world.setBlock(i + 8, j + 7, k + 7, 100, 0, 2);
        world.setBlock(i + 8, j + 7, k + 6, 100, 0, 2);
        world.setBlock(i + 8, j + 7, k + 5, 100, 0, 2);
        world.setBlock(i + 9, j + 7, k + 7, 100, 0, 2);
        world.setBlock(i + 9, j + 7, k + 6, 100, 0, 2);
        world.setBlock(i + 9, j + 7, k + 5, 100, 0, 2);
        world.setBlock(i + 9, j + 7, k + 4, 100, 0, 2);
        world.setBlock(i + 10, j + 7, k + 5, 100, 0, 2);
        world.setBlock(i + 7, j + 8, k + 7, 100, 0, 2);
        world.setBlock(i + 7, j + 8, k + 6, 100, 0, 2);
        world.setBlock(i + 8, j + 8, k + 7, 100, 0, 2);
        world.setBlock(i + 8, j + 8, k + 6, 100, 0, 2);
        world.setBlock(i + 8, j + 8, k + 5, 100, 0, 2);
        world.setBlock(i + 8, j + 8, k + 4, 100, 0, 2);
        world.setBlock(i + 9, j + 8, k + 6, 100, 0, 2);
        world.setBlock(i + 9, j + 8, k + 5, 100, 0, 2);
        world.setBlock(i + 6, j + 9, k + 7, 100, 0, 2);
        world.setBlock(i + 7, j + 9, k + 9, 100, 0, 2);
        world.setBlock(i + 7, j + 9, k + 8, 100, 0, 2);
        world.setBlock(i + 7, j + 9, k + 7, 100, 0, 2);
        world.setBlock(i + 7, j + 9, k + 6, 100, 0, 2);
        world.setBlock(i + 8, j + 9, k + 8, 100, 0, 2);
        world.setBlock(i + 8, j + 9, k + 7, 100, 0, 2);
        world.setBlock(i + 8, j + 9, k + 6, 100, 0, 2);
        world.setBlock(i + 9, j + 9, k + 7, 100, 0, 2);
        world.setBlock(i + 0, j + 10, k + 5, 100, 0, 2);
        world.setBlock(i + 0, j + 10, k + 4, 100, 0, 2);
        world.setBlock(i + 1, j + 10, k + 6, 100, 0, 2);
        world.setBlock(i + 1, j + 10, k + 5, 100, 0, 2);
        world.setBlock(i + 1, j + 10, k + 4, 100, 0, 2);
        world.setBlock(i + 1, j + 10, k + 3, 100, 0, 2);
        world.setBlock(i + 2, j + 10, k + 14, 100, 0, 2);
        world.setBlock(i + 2, j + 10, k + 13, 100, 0, 2);
        world.setBlock(i + 2, j + 10, k + 12, 100, 0, 2);
        world.setBlock(i + 2, j + 10, k + 11, 100, 0, 2);
        world.setBlock(i + 2, j + 10, k + 10, 100, 0, 2);
        world.setBlock(i + 2, j + 10, k + 7, 100, 0, 2);
        world.setBlock(i + 2, j + 10, k + 6, 100, 0, 2);
        world.setBlock(i + 2, j + 10, k + 5, 100, 0, 2);
        world.setBlock(i + 2, j + 10, k + 4, 100, 0, 2);
        world.setBlock(i + 2, j + 10, k + 3, 100, 0, 2);
        world.setBlock(i + 3, j + 10, k + 16, 100, 0, 2);
        world.setBlock(i + 3, j + 10, k + 15, 100, 0, 2);
        world.setBlock(i + 3, j + 10, k + 14, 100, 0, 2);
        world.setBlock(i + 3, j + 10, k + 13, 100, 0, 2);
        world.setBlock(i + 3, j + 10, k + 12, 100, 0, 2);
        world.setBlock(i + 3, j + 10, k + 11, 100, 0, 2);
        world.setBlock(i + 3, j + 10, k + 10, 100, 0, 2);
        world.setBlock(i + 3, j + 10, k + 9, 100, 0, 2);
        world.setBlock(i + 3, j + 10, k + 8, 100, 0, 2);
        world.setBlock(i + 3, j + 10, k + 7, 100, 0, 2);
        world.setBlock(i + 3, j + 10, k + 6, 100, 0, 2);
        world.setBlock(i + 3, j + 10, k + 5, 100, 0, 2);
        world.setBlock(i + 3, j + 10, k + 4, 100, 0, 2);
        world.setBlock(i + 3, j + 10, k + 3, 100, 0, 2);
        world.setBlock(i + 4, j + 10, k + 17, 100, 0, 2);
        world.setBlock(i + 4, j + 10, k + 16, 100, 0, 2);
        world.setBlock(i + 4, j + 10, k + 15, 100, 0, 2);
        world.setBlock(i + 4, j + 10, k + 14, 100, 0, 2);
        world.setBlock(i + 4, j + 10, k + 12, 100, 0, 2);
        world.setBlock(i + 4, j + 10, k + 10, 100, 0, 2);
        world.setBlock(i + 4, j + 10, k + 9, 100, 0, 2);
        world.setBlock(i + 4, j + 10, k + 8, 100, 0, 2);
        world.setBlock(i + 4, j + 10, k + 7, 100, 0, 2);
        world.setBlock(i + 4, j + 10, k + 4, 100, 0, 2);
        world.setBlock(i + 4, j + 10, k + 3, 100, 0, 2);
        world.setBlock(i + 4, j + 10, k + 2, 100, 0, 2);
        world.setBlock(i + 4, j + 10, k + 1, 100, 0, 2);
        world.setBlock(i + 5, j + 10, k + 17, 100, 0, 2);
        world.setBlock(i + 5, j + 10, k + 16, 100, 0, 2);
        world.setBlock(i + 5, j + 10, k + 3, 100, 0, 2);
        world.setBlock(i + 5, j + 10, k + 2, 100, 0, 2);
        world.setBlock(i + 5, j + 10, k + 1, 100, 0, 2);
        world.setBlock(i + 6, j + 10, k + 17, 100, 0, 2);
        world.setBlock(i + 6, j + 10, k + 16, 100, 0, 2);
        world.setBlock(i + 6, j + 10, k + 9, 100, 0, 2);
        world.setBlock(i + 6, j + 10, k + 3, 100, 0, 2);
        world.setBlock(i + 6, j + 10, k + 2, 100, 0, 2);
        world.setBlock(i + 6, j + 10, k + 1, 100, 0, 2);
        world.setBlock(i + 7, j + 10, k + 17, 100, 0, 2);
        world.setBlock(i + 7, j + 10, k + 16, 100, 0, 2);
        world.setBlock(i + 7, j + 10, k + 15, 100, 0, 2);
        world.setBlock(i + 7, j + 10, k + 10, 100, 0, 2);
        world.setBlock(i + 7, j + 10, k + 9, 100, 0, 2);
        world.setBlock(i + 7, j + 10, k + 8, 100, 0, 2);
        world.setBlock(i + 7, j + 10, k + 4, 100, 0, 2);
        world.setBlock(i + 7, j + 10, k + 3, 100, 0, 2);
        world.setBlock(i + 7, j + 10, k + 2, 100, 0, 2);
        world.setBlock(i + 7, j + 10, k + 1, 100, 0, 2);
        world.setBlock(i + 8, j + 10, k + 16, 100, 0, 2);
        world.setBlock(i + 8, j + 10, k + 15, 100, 0, 2);
        world.setBlock(i + 8, j + 10, k + 14, 100, 0, 2);
        world.setBlock(i + 8, j + 10, k + 10, 100, 0, 2);
        world.setBlock(i + 8, j + 10, k + 9, 100, 0, 2);
        world.setBlock(i + 8, j + 10, k + 8, 100, 0, 2);
        world.setBlock(i + 8, j + 10, k + 7, 100, 0, 2);
        world.setBlock(i + 8, j + 10, k + 4, 100, 0, 2);
        world.setBlock(i + 8, j + 10, k + 3, 100, 0, 2);
        world.setBlock(i + 8, j + 10, k + 2, 100, 0, 2);
        world.setBlock(i + 9, j + 10, k + 15, 100, 0, 2);
        world.setBlock(i + 9, j + 10, k + 14, 100, 0, 2);
        world.setBlock(i + 9, j + 10, k + 9, 100, 0, 2);
        world.setBlock(i + 9, j + 10, k + 8, 100, 0, 2);
        world.setBlock(i + 9, j + 10, k + 7, 100, 0, 2);
        world.setBlock(i + 9, j + 10, k + 5, 100, 0, 2);
        world.setBlock(i + 9, j + 10, k + 4, 100, 0, 2);
        world.setBlock(i + 9, j + 10, k + 3, 100, 0, 2);
        world.setBlock(i + 10, j + 10, k + 15, 100, 0, 2);
        world.setBlock(i + 10, j + 10, k + 14, 100, 0, 2);
        world.setBlock(i + 10, j + 10, k + 8, 100, 0, 2);
        world.setBlock(i + 10, j + 10, k + 7, 100, 0, 2);
        world.setBlock(i + 10, j + 10, k + 5, 100, 0, 2);
        world.setBlock(i + 10, j + 10, k + 4, 100, 0, 2);
        world.setBlock(i + 10, j + 10, k + 3, 100, 0, 2);
        world.setBlock(i + 11, j + 10, k + 16, 100, 0, 2);
        world.setBlock(i + 11, j + 10, k + 15, 100, 0, 2);
        world.setBlock(i + 11, j + 10, k + 4, 100, 0, 2);
        world.setBlock(i + 11, j + 10, k + 3, 100, 0, 2);
        world.setBlock(i + 11, j + 10, k + 2, 100, 0, 2);
        world.setBlock(i + 12, j + 10, k + 17, 100, 0, 2);
        world.setBlock(i + 12, j + 10, k + 16, 100, 0, 2);
        world.setBlock(i + 12, j + 10, k + 15, 100, 0, 2);
        world.setBlock(i + 12, j + 10, k + 3, 100, 0, 2);
        world.setBlock(i + 12, j + 10, k + 2, 100, 0, 2);
        world.setBlock(i + 13, j + 10, k + 17, 100, 0, 2);
        world.setBlock(i + 13, j + 10, k + 16, 100, 0, 2);
        world.setBlock(i + 13, j + 10, k + 4, 100, 0, 2);
        world.setBlock(i + 13, j + 10, k + 3, 100, 0, 2);
        world.setBlock(i + 13, j + 10, k + 2, 100, 0, 2);
        world.setBlock(i + 13, j + 10, k + 1, 100, 0, 2);
        world.setBlock(i + 14, j + 10, k + 17, 100, 0, 2);
        world.setBlock(i + 14, j + 10, k + 16, 100, 0, 2);
        world.setBlock(i + 14, j + 10, k + 15, 100, 0, 2);
        world.setBlock(i + 14, j + 10, k + 2, 100, 0, 2);
        world.setBlock(i + 14, j + 10, k + 1, 100, 0, 2);
        world.setBlock(i + 15, j + 10, k + 16, 100, 0, 2);
        world.setBlock(i + 15, j + 10, k + 15, 100, 0, 2);
        world.setBlock(i + 15, j + 10, k + 2, 100, 0, 2);
        world.setBlock(i + 15, j + 10, k + 1, 100, 0, 2);
        world.setBlock(i + 16, j + 10, k + 16, 100, 0, 2);
        world.setBlock(i + 16, j + 10, k + 15, 100, 0, 2);
        world.setBlock(i + 16, j + 10, k + 14, 100, 0, 2);
        world.setBlock(i + 16, j + 10, k + 2, 100, 0, 2);
        world.setBlock(i + 16, j + 10, k + 1, 100, 0, 2);
        world.setBlock(i + 16, j + 10, k + 0, 100, 0, 2);
        world.setBlock(i + 17, j + 10, k + 16, 100, 0, 2);
        world.setBlock(i + 17, j + 10, k + 15, 100, 0, 2);
        world.setBlock(i + 17, j + 10, k + 14, 100, 0, 2);
        world.setBlock(i + 17, j + 10, k + 13, 100, 0, 2);
        world.setBlock(i + 17, j + 10, k + 11, 100, 0, 2);
        world.setBlock(i + 17, j + 10, k + 10, 100, 0, 2);
        world.setBlock(i + 17, j + 10, k + 9, 100, 0, 2);
        world.setBlock(i + 17, j + 10, k + 8, 100, 0, 2);
        world.setBlock(i + 17, j + 10, k + 1, 100, 0, 2);
        world.setBlock(i + 17, j + 10, k + 0, 100, 0, 2);
        world.setBlock(i + 18, j + 10, k + 15, 100, 0, 2);
        world.setBlock(i + 18, j + 10, k + 14, 100, 0, 2);
        world.setBlock(i + 18, j + 10, k + 13, 100, 0, 2);
        world.setBlock(i + 18, j + 10, k + 12, 100, 0, 2);
        world.setBlock(i + 18, j + 10, k + 11, 100, 0, 2);
        world.setBlock(i + 18, j + 10, k + 10, 100, 0, 2);
        world.setBlock(i + 18, j + 10, k + 9, 100, 0, 2);
        world.setBlock(i + 18, j + 10, k + 8, 100, 0, 2);
        world.setBlock(i + 18, j + 10, k + 7, 100, 0, 2);
        world.setBlock(i + 18, j + 10, k + 6, 100, 0, 2);
        world.setBlock(i + 18, j + 10, k + 1, 100, 0, 2);
        world.setBlock(i + 18, j + 10, k + 0, 100, 0, 2);
        world.setBlock(i + 19, j + 10, k + 15, 100, 0, 2);
        world.setBlock(i + 19, j + 10, k + 14, 100, 0, 2);
        world.setBlock(i + 19, j + 10, k + 13, 100, 0, 2);
        world.setBlock(i + 19, j + 10, k + 12, 100, 0, 2);
        world.setBlock(i + 19, j + 10, k + 11, 100, 0, 2);
        world.setBlock(i + 19, j + 10, k + 8, 100, 0, 2);
        world.setBlock(i + 19, j + 10, k + 7, 100, 0, 2);
        world.setBlock(i + 19, j + 10, k + 6, 100, 0, 2);
        world.setBlock(i + 19, j + 10, k + 5, 100, 0, 2);
        world.setBlock(i + 19, j + 10, k + 4, 100, 0, 2);
        world.setBlock(i + 19, j + 10, k + 3, 100, 0, 2);
        world.setBlock(i + 19, j + 10, k + 2, 100, 0, 2);
        world.setBlock(i + 19, j + 10, k + 1, 100, 0, 2);
        world.setBlock(i + 19, j + 10, k + 0, 100, 0, 2);
        world.setBlock(i + 20, j + 10, k + 14, 100, 0, 2);
        world.setBlock(i + 20, j + 10, k + 13, 100, 0, 2);
        world.setBlock(i + 20, j + 10, k + 6, 100, 0, 2);
        world.setBlock(i + 20, j + 10, k + 5, 100, 0, 2);
        world.setBlock(i + 20, j + 10, k + 4, 100, 0, 2);
        world.setBlock(i + 20, j + 10, k + 3, 100, 0, 2);
        world.setBlock(i + 20, j + 10, k + 2, 100, 0, 2);
        world.setBlock(i + 20, j + 10, k + 1, 100, 0, 2);
        world.setBlock(i + 21, j + 10, k + 5, 100, 0, 2);
        world.setBlock(i + 21, j + 10, k + 4, 100, 0, 2);
        world.setBlock(i + 21, j + 10, k + 3, 100, 0, 2);
        world.setBlock(i + 21, j + 10, k + 2, 100, 0, 2);
        world.setBlock(i + 3, j + 11, k + 14, 100, 0, 2);
        world.setBlock(i + 3, j + 11, k + 13, 100, 0, 2);
        world.setBlock(i + 3, j + 11, k + 11, 100, 0, 2);
        world.setBlock(i + 3, j + 11, k + 10, 100, 0, 2);
        world.setBlock(i + 3, j + 11, k + 6, 100, 0, 2);
        world.setBlock(i + 3, j + 11, k + 5, 100, 0, 2);
        world.setBlock(i + 4, j + 11, k + 16, 100, 0, 2);
        world.setBlock(i + 4, j + 11, k + 15, 100, 0, 2);
        world.setBlock(i + 4, j + 11, k + 14, 100, 0, 2);
        world.setBlock(i + 4, j + 11, k + 13, 100, 0, 2);
        world.setBlock(i + 4, j + 11, k + 12, 100, 0, 2);
        world.setBlock(i + 4, j + 11, k + 11, 100, 0, 2);
        world.setBlock(i + 4, j + 11, k + 10, 100, 0, 2);
        world.setBlock(i + 4, j + 11, k + 9, 100, 0, 2);
        world.setBlock(i + 4, j + 11, k + 8, 100, 0, 2);
        world.setBlock(i + 4, j + 11, k + 7, 100, 0, 2);
        world.setBlock(i + 4, j + 11, k + 6, 100, 0, 2);
        world.setBlock(i + 4, j + 11, k + 5, 100, 0, 2);
        world.setBlock(i + 4, j + 11, k + 4, 100, 0, 2);
        world.setBlock(i + 5, j + 11, k + 16, 100, 0, 2);
        world.setBlock(i + 5, j + 11, k + 15, 100, 0, 2);
        world.setBlock(i + 5, j + 11, k + 14, 100, 0, 2);
        world.setBlock(i + 5, j + 11, k + 13, 100, 0, 2);
        world.setBlock(i + 5, j + 11, k + 12, 100, 0, 2);
        world.setBlock(i + 5, j + 11, k + 11, 100, 0, 2);
        world.setBlock(i + 5, j + 11, k + 10, 100, 0, 2);
        world.setBlock(i + 5, j + 11, k + 9, 100, 0, 2);
        world.setBlock(i + 5, j + 11, k + 8, 100, 0, 2);
        world.setBlock(i + 5, j + 11, k + 7, 100, 0, 2);
        world.setBlock(i + 5, j + 11, k + 6, 100, 0, 2);
        world.setBlock(i + 5, j + 11, k + 4, 100, 0, 2);
        world.setBlock(i + 5, j + 11, k + 3, 100, 0, 2);
        world.setBlock(i + 6, j + 11, k + 16, 100, 0, 2);
        world.setBlock(i + 6, j + 11, k + 15, 100, 0, 2);
        world.setBlock(i + 6, j + 11, k + 4, 100, 0, 2);
        world.setBlock(i + 6, j + 11, k + 3, 100, 0, 2);
        world.setBlock(i + 7, j + 11, k + 16, 100, 0, 2);
        world.setBlock(i + 7, j + 11, k + 15, 100, 0, 2);
        world.setBlock(i + 7, j + 11, k + 14, 100, 0, 2);
        world.setBlock(i + 7, j + 11, k + 13, 100, 0, 2);
        world.setBlock(i + 7, j + 11, k + 11, 100, 0, 2);
        world.setBlock(i + 7, j + 11, k + 10, 100, 0, 2);
        world.setBlock(i + 7, j + 11, k + 5, 100, 0, 2);
        world.setBlock(i + 7, j + 11, k + 4, 100, 0, 2);
        world.setBlock(i + 7, j + 11, k + 3, 100, 0, 2);
        world.setBlock(i + 8, j + 11, k + 15, 100, 0, 2);
        world.setBlock(i + 8, j + 11, k + 14, 100, 0, 2);
        world.setBlock(i + 8, j + 11, k + 13, 100, 0, 2);
        world.setBlock(i + 8, j + 11, k + 11, 100, 0, 2);
        world.setBlock(i + 8, j + 11, k + 10, 100, 0, 2);
        world.setBlock(i + 8, j + 11, k + 9, 100, 0, 2);
        world.setBlock(i + 8, j + 11, k + 5, 100, 0, 2);
        world.setBlock(i + 8, j + 11, k + 4, 100, 0, 2);
        world.setBlock(i + 9, j + 11, k + 14, 100, 0, 2);
        world.setBlock(i + 9, j + 11, k + 13, 100, 0, 2);
        world.setBlock(i + 9, j + 11, k + 10, 100, 0, 2);
        world.setBlock(i + 9, j + 11, k + 9, 100, 0, 2);
        world.setBlock(i + 9, j + 11, k + 6, 100, 0, 2);
        world.setBlock(i + 9, j + 11, k + 5, 100, 0, 2);
        world.setBlock(i + 9, j + 11, k + 4, 100, 0, 2);
        world.setBlock(i + 10, j + 11, k + 14, 100, 0, 2);
        world.setBlock(i + 10, j + 11, k + 13, 100, 0, 2);
        world.setBlock(i + 10, j + 11, k + 9, 100, 0, 2);
        world.setBlock(i + 10, j + 11, k + 6, 100, 0, 2);
        world.setBlock(i + 10, j + 11, k + 5, 100, 0, 2);
        world.setBlock(i + 11, j + 11, k + 15, 100, 0, 2);
        world.setBlock(i + 11, j + 11, k + 14, 100, 0, 2);
        world.setBlock(i + 11, j + 11, k + 13, 100, 0, 2);
        world.setBlock(i + 11, j + 11, k + 6, 100, 0, 2);
        world.setBlock(i + 11, j + 11, k + 5, 100, 0, 2);
        world.setBlock(i + 11, j + 11, k + 4, 100, 0, 2);
        world.setBlock(i + 12, j + 11, k + 16, 100, 0, 2);
        world.setBlock(i + 12, j + 11, k + 15, 100, 0, 2);
        world.setBlock(i + 12, j + 11, k + 14, 100, 0, 2);
        world.setBlock(i + 12, j + 11, k + 5, 100, 0, 2);
        world.setBlock(i + 12, j + 11, k + 4, 100, 0, 2);
        world.setBlock(i + 12, j + 11, k + 3, 100, 0, 2);
        world.setBlock(i + 13, j + 11, k + 16, 100, 0, 2);
        world.setBlock(i + 13, j + 11, k + 15, 100, 0, 2);
        world.setBlock(i + 13, j + 11, k + 14, 100, 0, 2);
        world.setBlock(i + 13, j + 11, k + 5, 100, 0, 2);
        world.setBlock(i + 13, j + 11, k + 4, 100, 0, 2);
        world.setBlock(i + 13, j + 11, k + 3, 100, 0, 2);
        world.setBlock(i + 14, j + 11, k + 16, 100, 0, 2);
        world.setBlock(i + 14, j + 11, k + 15, 100, 0, 2);
        world.setBlock(i + 14, j + 11, k + 14, 100, 0, 2);
        world.setBlock(i + 14, j + 11, k + 5, 100, 0, 2);
        world.setBlock(i + 14, j + 11, k + 4, 100, 0, 2);
        world.setBlock(i + 14, j + 11, k + 3, 100, 0, 2);
        world.setBlock(i + 14, j + 11, k + 2, 100, 0, 2);
        world.setBlock(i + 15, j + 11, k + 15, 100, 0, 2);
        world.setBlock(i + 15, j + 11, k + 14, 100, 0, 2);
        world.setBlock(i + 15, j + 11, k + 13, 100, 0, 2);
        world.setBlock(i + 15, j + 11, k + 3, 100, 0, 2);
        world.setBlock(i + 15, j + 11, k + 2, 100, 0, 2);
        world.setBlock(i + 16, j + 11, k + 15, 100, 0, 2);
        world.setBlock(i + 16, j + 11, k + 14, 100, 0, 2);
        world.setBlock(i + 16, j + 11, k + 13, 100, 0, 2);
        world.setBlock(i + 16, j + 11, k + 12, 100, 0, 2);
        world.setBlock(i + 16, j + 11, k + 11, 100, 0, 2);
        world.setBlock(i + 16, j + 11, k + 10, 100, 0, 2);
        world.setBlock(i + 16, j + 11, k + 9, 100, 0, 2);
        world.setBlock(i + 16, j + 11, k + 8, 100, 0, 2);
        world.setBlock(i + 16, j + 11, k + 7, 100, 0, 2);
        world.setBlock(i + 16, j + 11, k + 3, 100, 0, 2);
        world.setBlock(i + 16, j + 11, k + 2, 100, 0, 2);
        world.setBlock(i + 17, j + 11, k + 14, 100, 0, 2);
        world.setBlock(i + 17, j + 11, k + 13, 100, 0, 2);
        world.setBlock(i + 17, j + 11, k + 12, 100, 0, 2);
        world.setBlock(i + 17, j + 11, k + 11, 100, 0, 2);
        world.setBlock(i + 17, j + 11, k + 10, 100, 0, 2);
        world.setBlock(i + 17, j + 11, k + 9, 100, 0, 2);
        world.setBlock(i + 17, j + 11, k + 8, 100, 0, 2);
        world.setBlock(i + 17, j + 11, k + 7, 100, 0, 2);
        world.setBlock(i + 17, j + 11, k + 6, 100, 0, 2);
        world.setBlock(i + 17, j + 11, k + 5, 100, 0, 2);
        world.setBlock(i + 17, j + 11, k + 3, 100, 0, 2);
        world.setBlock(i + 17, j + 11, k + 2, 100, 0, 2);
        world.setBlock(i + 17, j + 11, k + 1, 100, 0, 2);
        world.setBlock(i + 18, j + 11, k + 13, 100, 0, 2);
        world.setBlock(i + 18, j + 11, k + 12, 100, 0, 2);
        world.setBlock(i + 18, j + 11, k + 7, 100, 0, 2);
        world.setBlock(i + 18, j + 11, k + 6, 100, 0, 2);
        world.setBlock(i + 18, j + 11, k + 5, 100, 0, 2);
        world.setBlock(i + 18, j + 11, k + 4, 100, 0, 2);
        world.setBlock(i + 18, j + 11, k + 3, 100, 0, 2);
        world.setBlock(i + 18, j + 11, k + 2, 100, 0, 2);
        world.setBlock(i + 18, j + 11, k + 1, 100, 0, 2);
        world.setBlock(i + 19, j + 11, k + 5, 100, 0, 2);
        world.setBlock(i + 19, j + 11, k + 4, 100, 0, 2);
        world.setBlock(i + 19, j + 11, k + 3, 100, 0, 2);
        world.setBlock(i + 19, j + 11, k + 2, 100, 0, 2);
        world.setBlock(i + 4, j + 12, k + 14, 100, 0, 2);
        world.setBlock(i + 4, j + 12, k + 13, 100, 0, 2);
        world.setBlock(i + 4, j + 12, k + 11, 100, 0, 2);
        world.setBlock(i + 4, j + 12, k + 10, 100, 0, 2);
        world.setBlock(i + 4, j + 12, k + 6, 100, 0, 2);
        world.setBlock(i + 4, j + 12, k + 5, 100, 0, 2);
        world.setBlock(i + 5, j + 12, k + 15, 100, 0, 2);
        world.setBlock(i + 5, j + 12, k + 14, 100, 0, 2);
        world.setBlock(i + 5, j + 12, k + 13, 100, 0, 2);
        world.setBlock(i + 5, j + 12, k + 12, 100, 0, 2);
        world.setBlock(i + 5, j + 12, k + 11, 100, 0, 2);
        world.setBlock(i + 5, j + 12, k + 10, 100, 0, 2);
        world.setBlock(i + 5, j + 12, k + 9, 100, 0, 2);
        world.setBlock(i + 5, j + 12, k + 8, 100, 0, 2);
        world.setBlock(i + 5, j + 12, k + 7, 100, 0, 2);
        world.setBlock(i + 5, j + 12, k + 6, 100, 0, 2);
        world.setBlock(i + 5, j + 12, k + 5, 100, 0, 2);
        world.setBlock(i + 5, j + 12, k + 4, 100, 0, 2);
        world.setBlock(i + 6, j + 12, k + 15, 100, 0, 2);
        world.setBlock(i + 6, j + 12, k + 14, 100, 0, 2);
        world.setBlock(i + 6, j + 12, k + 13, 100, 0, 2);
        world.setBlock(i + 6, j + 12, k + 12, 100, 0, 2);
        world.setBlock(i + 6, j + 12, k + 11, 100, 0, 2);
        world.setBlock(i + 6, j + 12, k + 10, 100, 0, 2);
        world.setBlock(i + 6, j + 12, k + 9, 100, 0, 2);
        world.setBlock(i + 6, j + 12, k + 8, 100, 0, 2);
        world.setBlock(i + 6, j + 12, k + 7, 100, 0, 2);
        world.setBlock(i + 6, j + 12, k + 6, 100, 0, 2);
        world.setBlock(i + 6, j + 12, k + 5, 100, 0, 2);
        world.setBlock(i + 6, j + 12, k + 4, 100, 0, 2);
        world.setBlock(i + 7, j + 12, k + 15, 100, 0, 2);
        world.setBlock(i + 7, j + 12, k + 14, 100, 0, 2);
        world.setBlock(i + 7, j + 12, k + 13, 100, 0, 2);
        world.setBlock(i + 7, j + 12, k + 12, 100, 0, 2);
        world.setBlock(i + 7, j + 12, k + 11, 100, 0, 2);
        world.setBlock(i + 7, j + 12, k + 10, 100, 0, 2);
        world.setBlock(i + 7, j + 12, k + 8, 100, 0, 2);
        world.setBlock(i + 7, j + 12, k + 7, 100, 0, 2);
        world.setBlock(i + 7, j + 12, k + 6, 100, 0, 2);
        world.setBlock(i + 7, j + 12, k + 5, 100, 0, 2);
        world.setBlock(i + 7, j + 12, k + 4, 100, 0, 2);
        world.setBlock(i + 8, j + 12, k + 14, 100, 0, 2);
        world.setBlock(i + 8, j + 12, k + 13, 100, 0, 2);
        world.setBlock(i + 8, j + 12, k + 12, 100, 0, 2);
        world.setBlock(i + 8, j + 12, k + 11, 100, 0, 2);
        world.setBlock(i + 8, j + 12, k + 10, 100, 0, 2);
        world.setBlock(i + 8, j + 12, k + 9, 100, 0, 2);
        world.setBlock(i + 8, j + 12, k + 8, 100, 0, 2);
        world.setBlock(i + 8, j + 12, k + 7, 100, 0, 2);
        world.setBlock(i + 8, j + 12, k + 6, 100, 0, 2);
        world.setBlock(i + 8, j + 12, k + 5, 100, 0, 2);
        world.setBlock(i + 9, j + 12, k + 13, 100, 0, 2);
        world.setBlock(i + 9, j + 12, k + 12, 100, 0, 2);
        world.setBlock(i + 9, j + 12, k + 11, 100, 0, 2);
        world.setBlock(i + 9, j + 12, k + 10, 100, 0, 2);
        world.setBlock(i + 9, j + 12, k + 9, 100, 0, 2);
        world.setBlock(i + 9, j + 12, k + 8, 100, 0, 2);
        world.setBlock(i + 9, j + 12, k + 7, 100, 0, 2);
        world.setBlock(i + 9, j + 12, k + 6, 100, 0, 2);
        world.setBlock(i + 9, j + 12, k + 5, 100, 0, 2);
        world.setBlock(i + 10, j + 12, k + 13, 100, 0, 2);
        world.setBlock(i + 10, j + 12, k + 12, 100, 0, 2);
        world.setBlock(i + 10, j + 12, k + 11, 100, 0, 2);
        world.setBlock(i + 10, j + 12, k + 10, 100, 0, 2);
        world.setBlock(i + 10, j + 12, k + 9, 100, 0, 2);
        world.setBlock(i + 10, j + 12, k + 8, 100, 0, 2);
        world.setBlock(i + 10, j + 12, k + 7, 100, 0, 2);
        world.setBlock(i + 10, j + 12, k + 6, 100, 0, 2);
        world.setBlock(i + 11, j + 12, k + 14, 100, 0, 2);
        world.setBlock(i + 11, j + 12, k + 13, 100, 0, 2);
        world.setBlock(i + 11, j + 12, k + 12, 100, 0, 2);
        world.setBlock(i + 11, j + 12, k + 10, 100, 0, 2);
        world.setBlock(i + 11, j + 12, k + 9, 100, 0, 2);
        world.setBlock(i + 11, j + 12, k + 8, 100, 0, 2);
        world.setBlock(i + 11, j + 12, k + 7, 100, 0, 2);
        world.setBlock(i + 11, j + 12, k + 6, 100, 0, 2);
        world.setBlock(i + 11, j + 12, k + 5, 100, 0, 2);
        world.setBlock(i + 12, j + 12, k + 15, 100, 0, 2);
        world.setBlock(i + 12, j + 12, k + 14, 100, 0, 2);
        world.setBlock(i + 12, j + 12, k + 13, 100, 0, 2);
        world.setBlock(i + 12, j + 12, k + 7, 100, 0, 2);
        world.setBlock(i + 12, j + 12, k + 6, 100, 0, 2);
        world.setBlock(i + 12, j + 12, k + 5, 100, 0, 2);
        world.setBlock(i + 12, j + 12, k + 4, 100, 0, 2);
        world.setBlock(i + 13, j + 12, k + 15, 100, 0, 2);
        world.setBlock(i + 13, j + 12, k + 14, 100, 0, 2);
        world.setBlock(i + 13, j + 12, k + 13, 100, 0, 2);
        world.setBlock(i + 13, j + 12, k + 7, 100, 0, 2);
        world.setBlock(i + 13, j + 12, k + 6, 100, 0, 2);
        world.setBlock(i + 13, j + 12, k + 5, 100, 0, 2);
        world.setBlock(i + 13, j + 12, k + 4, 100, 0, 2);
        world.setBlock(i + 14, j + 12, k + 15, 100, 0, 2);
        world.setBlock(i + 14, j + 12, k + 14, 100, 0, 2);
        world.setBlock(i + 14, j + 12, k + 13, 100, 0, 2);
        world.setBlock(i + 14, j + 12, k + 12, 100, 0, 2);
        world.setBlock(i + 14, j + 12, k + 7, 100, 0, 2);
        world.setBlock(i + 14, j + 12, k + 6, 100, 0, 2);
        world.setBlock(i + 14, j + 12, k + 5, 100, 0, 2);
        world.setBlock(i + 14, j + 12, k + 4, 100, 0, 2);
        world.setBlock(i + 14, j + 12, k + 3, 100, 0, 2);
        world.setBlock(i + 15, j + 12, k + 14, 100, 0, 2);
        world.setBlock(i + 15, j + 12, k + 13, 100, 0, 2);
        world.setBlock(i + 15, j + 12, k + 12, 100, 0, 2);
        world.setBlock(i + 15, j + 12, k + 11, 100, 0, 2);
        world.setBlock(i + 15, j + 12, k + 10, 100, 0, 2);
        world.setBlock(i + 15, j + 12, k + 9, 100, 0, 2);
        world.setBlock(i + 15, j + 12, k + 8, 100, 0, 2);
        world.setBlock(i + 15, j + 12, k + 7, 100, 0, 2);
        world.setBlock(i + 15, j + 12, k + 6, 100, 0, 2);
        world.setBlock(i + 15, j + 12, k + 5, 100, 0, 2);
        world.setBlock(i + 15, j + 12, k + 4, 100, 0, 2);
        world.setBlock(i + 15, j + 12, k + 3, 100, 0, 2);
        world.setBlock(i + 16, j + 12, k + 14, 100, 0, 2);
        world.setBlock(i + 16, j + 12, k + 13, 100, 0, 2);
        world.setBlock(i + 16, j + 12, k + 12, 100, 0, 2);
        world.setBlock(i + 16, j + 12, k + 11, 100, 0, 2);
        world.setBlock(i + 16, j + 12, k + 10, 100, 0, 2);
        world.setBlock(i + 16, j + 12, k + 9, 100, 0, 2);
        world.setBlock(i + 16, j + 12, k + 8, 100, 0, 2);
        world.setBlock(i + 16, j + 12, k + 7, 100, 0, 2);
        world.setBlock(i + 16, j + 12, k + 6, 100, 0, 2);
        world.setBlock(i + 16, j + 12, k + 5, 100, 0, 2);
        world.setBlock(i + 16, j + 12, k + 4, 100, 0, 2);
        world.setBlock(i + 16, j + 12, k + 3, 100, 0, 2);
        world.setBlock(i + 17, j + 12, k + 13, 100, 0, 2);
        world.setBlock(i + 17, j + 12, k + 12, 100, 0, 2);
        world.setBlock(i + 17, j + 12, k + 7, 100, 0, 2);
        world.setBlock(i + 17, j + 12, k + 6, 100, 0, 2);
        world.setBlock(i + 17, j + 12, k + 5, 100, 0, 2);
        world.setBlock(i + 17, j + 12, k + 4, 100, 0, 2);
        world.setBlock(i + 17, j + 12, k + 3, 100, 0, 2);
        world.setBlock(i + 18, j + 12, k + 5, 100, 0, 2);
        world.setBlock(i + 18, j + 12, k + 4, 100, 0, 2);
        world.setBlock(i + 18, j + 12, k + 3, 100, 0, 2);
        world.setBlock(i + 6, j + 13, k + 12, 100, 0, 2);
        world.setBlock(i + 6, j + 13, k + 11, 100, 0, 2);
        world.setBlock(i + 6, j + 13, k + 10, 100, 0, 2);
        world.setBlock(i + 6, j + 13, k + 9, 100, 0, 2);
        world.setBlock(i + 6, j + 13, k + 8, 100, 0, 2);
        world.setBlock(i + 6, j + 13, k + 7, 100, 0, 2);
        world.setBlock(i + 6, j + 13, k + 6, 100, 0, 2);
        world.setBlock(i + 7, j + 13, k + 12, 100, 0, 2);
        world.setBlock(i + 7, j + 13, k + 11, 100, 0, 2);
        world.setBlock(i + 7, j + 13, k + 9, 100, 0, 2);
        world.setBlock(i + 7, j + 13, k + 8, 100, 0, 2);
        world.setBlock(i + 7, j + 13, k + 7, 100, 0, 2);
        world.setBlock(i + 7, j + 13, k + 6, 100, 0, 2);
        world.setBlock(i + 8, j + 13, k + 12, 100, 0, 2);
        world.setBlock(i + 8, j + 13, k + 11, 100, 0, 2);
        world.setBlock(i + 8, j + 13, k + 8, 100, 0, 2);
        world.setBlock(i + 8, j + 13, k + 7, 100, 0, 2);
        world.setBlock(i + 8, j + 13, k + 6, 100, 0, 2);
        world.setBlock(i + 9, j + 13, k + 12, 100, 0, 2);
        world.setBlock(i + 9, j + 13, k + 11, 100, 0, 2);
        world.setBlock(i + 9, j + 13, k + 8, 100, 0, 2);
        world.setBlock(i + 9, j + 13, k + 7, 100, 0, 2);
        world.setBlock(i + 10, j + 13, k + 12, 100, 0, 2);
        world.setBlock(i + 10, j + 13, k + 11, 100, 0, 2);
        world.setBlock(i + 10, j + 13, k + 10, 100, 0, 2);
        world.setBlock(i + 10, j + 13, k + 9, 100, 0, 2);
        world.setBlock(i + 10, j + 13, k + 8, 100, 0, 2);
        world.setBlock(i + 10, j + 13, k + 7, 100, 0, 2);
        world.setBlock(i + 11, j + 13, k + 13, 100, 0, 2);
        world.setBlock(i + 11, j + 13, k + 12, 100, 0, 2);
        world.setBlock(i + 11, j + 13, k + 11, 100, 0, 2);
        world.setBlock(i + 11, j + 13, k + 9, 100, 0, 2);
        world.setBlock(i + 11, j + 13, k + 8, 100, 0, 2);
        world.setBlock(i + 11, j + 13, k + 7, 100, 0, 2);
        world.setBlock(i + 12, j + 13, k + 13, 100, 0, 2);
        world.setBlock(i + 12, j + 13, k + 12, 100, 0, 2);
        world.setBlock(i + 12, j + 13, k + 9, 100, 0, 2);
        world.setBlock(i + 12, j + 13, k + 8, 100, 0, 2);
        world.setBlock(i + 12, j + 13, k + 7, 100, 0, 2);
        world.setBlock(i + 12, j + 13, k + 6, 100, 0, 2);
        world.setBlock(i + 13, j + 13, k + 13, 100, 0, 2);
        world.setBlock(i + 13, j + 13, k + 12, 100, 0, 2);
        world.setBlock(i + 13, j + 13, k + 8, 100, 0, 2);
        world.setBlock(i + 13, j + 13, k + 7, 100, 0, 2);
        world.setBlock(i + 13, j + 13, k + 6, 100, 0, 2);
        world.setBlock(i + 14, j + 13, k + 13, 100, 0, 2);
        world.setBlock(i + 14, j + 13, k + 12, 100, 0, 2);
        world.setBlock(i + 14, j + 13, k + 11, 100, 0, 2);
        world.setBlock(i + 14, j + 13, k + 10, 100, 0, 2);
        world.setBlock(i + 14, j + 13, k + 9, 100, 0, 2);
        world.setBlock(i + 14, j + 13, k + 8, 100, 0, 2);
        world.setBlock(i + 14, j + 13, k + 7, 100, 0, 2);
        world.setBlock(i + 14, j + 13, k + 6, 100, 0, 2);
        world.setBlock(i + 15, j + 13, k + 12, 100, 0, 2);
        world.setBlock(i + 15, j + 13, k + 11, 100, 0, 2);
        world.setBlock(i + 15, j + 13, k + 10, 100, 0, 2);
        world.setBlock(i + 15, j + 13, k + 9, 100, 0, 2);
        world.setBlock(i + 15, j + 13, k + 8, 100, 0, 2);
        world.setBlock(i + 15, j + 13, k + 7, 100, 0, 2);
        world.setBlock(i + 15, j + 13, k + 6, 100, 0, 2);
        world.setBlock(i + 15, j + 13, k + 5, 100, 0, 2);
        world.setBlock(i + 15, j + 13, k + 4, 100, 0, 2);
        world.setBlock(i + 16, j + 13, k + 6, 100, 0, 2);
        world.setBlock(i + 16, j + 13, k + 5, 100, 0, 2);
        world.setBlock(i + 16, j + 13, k + 4, 100, 0, 2);
        world.setBlock(i + 7, j + 14, k + 11, 100, 0, 2);
        world.setBlock(i + 7, j + 14, k + 10, 100, 0, 2);
        world.setBlock(i + 7, j + 14, k + 9, 100, 0, 2);
        world.setBlock(i + 7, j + 14, k + 8, 100, 0, 2);
        world.setBlock(i + 8, j + 14, k + 11, 100, 0, 2);
        world.setBlock(i + 8, j + 14, k + 9, 100, 0, 2);
        world.setBlock(i + 8, j + 14, k + 8, 100, 0, 2);
        world.setBlock(i + 9, j + 14, k + 11, 100, 0, 2);
        world.setBlock(i + 9, j + 14, k + 10, 100, 0, 2);
        world.setBlock(i + 9, j + 14, k + 9, 100, 0, 2);
        world.setBlock(i + 9, j + 14, k + 8, 100, 0, 2);
        world.setBlock(i + 10, j + 14, k + 11, 100, 0, 2);
        world.setBlock(i + 10, j + 14, k + 10, 100, 0, 2);
        world.setBlock(i + 10, j + 14, k + 9, 100, 0, 2);
        world.setBlock(i + 10, j + 14, k + 8, 100, 0, 2);
        world.setBlock(i + 11, j + 14, k + 11, 100, 0, 2);
        world.setBlock(i + 11, j + 14, k + 10, 100, 0, 2);
        world.setBlock(i + 11, j + 14, k + 9, 100, 0, 2);
        world.setBlock(i + 11, j + 14, k + 8, 100, 0, 2);
        world.setBlock(i + 12, j + 14, k + 12, 100, 0, 2);
        world.setBlock(i + 12, j + 14, k + 11, 100, 0, 2);
        world.setBlock(i + 12, j + 14, k + 10, 100, 0, 2);
        world.setBlock(i + 12, j + 14, k + 9, 100, 0, 2);
        world.setBlock(i + 12, j + 14, k + 8, 100, 0, 2);
        world.setBlock(i + 13, j + 14, k + 12, 100, 0, 2);
        world.setBlock(i + 13, j + 14, k + 11, 100, 0, 2);
        world.setBlock(i + 13, j + 14, k + 10, 100, 0, 2);
        world.setBlock(i + 13, j + 14, k + 9, 100, 0, 2);
        world.setBlock(i + 13, j + 14, k + 8, 100, 0, 2);
        world.setBlock(i + 14, j + 14, k + 11, 100, 0, 2);
        world.setBlock(i + 14, j + 14, k + 10, 100, 0, 2);
        world.setBlock(i + 14, j + 14, k + 9, 100, 0, 2);
        world.setBlock(i + 14, j + 14, k + 8, 100, 0, 2);
        world.setBlock(i + 8, j + 15, k + 10, 100, 0, 2);
        world.setBlock(i + 8, j + 15, k + 9, 100, 0, 2);
        world.setBlock(i + 9, j + 15, k + 10, 100, 0, 2);
        world.setBlock(i + 9, j + 15, k + 9, 100, 0, 2);
        world.setBlock(i + 10, j + 15, k + 10, 100, 0, 2);
        world.setBlock(i + 10, j + 15, k + 9, 100, 0, 2);
        world.setBlock(i + 11, j + 15, k + 10, 100, 0, 2);
        world.setBlock(i + 11, j + 15, k + 9, 100, 0, 2);
        world.setBlock(i + 12, j + 15, k + 11, 100, 0, 2);
        world.setBlock(i + 12, j + 15, k + 10, 100, 0, 2);
        world.setBlock(i + 12, j + 15, k + 9, 100, 0, 2);
        world.setBlock(i + 13, j + 15, k + 11, 100, 0, 2);
        world.setBlock(i + 13, j + 15, k + 10, 100, 0, 2);
        world.setBlock(i + 13, j + 15, k + 9, 100, 0, 2);
        
        return true;
    }
}
