package morethantrees.treegen;

import java.util.Random;

import net.minecraft.block.Block;
import net.minecraft.world.World;
import net.minecraft.world.gen.feature.WorldGenerator;

public class WorldGenDouglasFirXLargeTree extends WorldGenerator
{
    public boolean generate(World world, Random var2, int i, int j, int k)
    {
        while ((world.isAirBlock(i + 10, j, k + 12)) && (j > 2))
        {
            j--;
        }
        
        int var6 = world.getBlockId(i + 10, j, k + 12);
        
        if (var6 != Block.grass.blockID)
        {
            return false;
        }
        
        for (int var7 = -2; var7 <= 2; var7++)
        {
            for (int var8 = -2; var8 <= 2; var8++)
            {
                if ((world.isAirBlock(i + var7 + 10, j - 1, k + var8 + 12)) && (world.isAirBlock(i + var7 + 10, j - 2, k + var8 + 12)))
                {
                    return false;
                }
            }
        }
        world.setBlock(i + 9, j + 0, k + 10, 17, 1, 2);
        world.setBlock(i + 9, j + 0, k + 8, 17, 1, 2);
        world.setBlock(i + 10, j + 0, k + 9, 17, 1, 2);
        world.setBlock(i + 10, j + 0, k + 8, 17, 1, 2);
        world.setBlock(i + 10, j + 0, k + 7, 17, 1, 2);
        world.setBlock(i + 11, j + 0, k + 10, 17, 1, 2);
        world.setBlock(i + 11, j + 0, k + 9, 17, 1, 2);
        world.setBlock(i + 11, j + 0, k + 8, 17, 1, 2);
        world.setBlock(i + 12, j + 0, k + 11, 17, 1, 2);
        world.setBlock(i + 12, j + 0, k + 10, 17, 1, 2);
        world.setBlock(i + 12, j + 0, k + 8, 17, 1, 2);
        world.setBlock(i + 12, j + 0, k + 7, 17, 1, 2);
        world.setBlock(i + 9, j + 1, k + 8, 17, 1, 2);
        world.setBlock(i + 10, j + 1, k + 9, 17, 1, 2);
        world.setBlock(i + 10, j + 1, k + 8, 17, 1, 2);
        world.setBlock(i + 11, j + 1, k + 9, 17, 1, 2);
        world.setBlock(i + 11, j + 1, k + 8, 17, 1, 2);
        world.setBlock(i + 10, j + 2, k + 9, 17, 1, 2);
        world.setBlock(i + 10, j + 2, k + 8, 17, 1, 2);
        world.setBlock(i + 11, j + 2, k + 9, 17, 1, 2);
        world.setBlock(i + 11, j + 2, k + 8, 17, 1, 2);
        world.setBlock(i + 10, j + 3, k + 9, 17, 1, 2);
        world.setBlock(i + 10, j + 3, k + 8, 17, 1, 2);
        world.setBlock(i + 11, j + 3, k + 9, 17, 1, 2);
        world.setBlock(i + 11, j + 3, k + 8, 17, 1, 2);
        world.setBlock(i + 10, j + 4, k + 9, 17, 1, 2);
        world.setBlock(i + 10, j + 4, k + 8, 17, 1, 2);
        world.setBlock(i + 11, j + 4, k + 9, 17, 1, 2);
        world.setBlock(i + 11, j + 4, k + 8, 17, 1, 2);
        world.setBlock(i + 10, j + 5, k + 9, 17, 1, 2);
        world.setBlock(i + 10, j + 5, k + 8, 17, 1, 2);
        world.setBlock(i + 11, j + 5, k + 9, 17, 1, 2);
        world.setBlock(i + 11, j + 5, k + 8, 17, 1, 2);
        world.setBlock(i + 10, j + 6, k + 9, 17, 1, 2);
        world.setBlock(i + 10, j + 6, k + 8, 17, 1, 2);
        world.setBlock(i + 11, j + 6, k + 9, 17, 1, 2);
        world.setBlock(i + 11, j + 6, k + 8, 17, 1, 2);
        world.setBlock(i + 10, j + 7, k + 9, 17, 1, 2);
        world.setBlock(i + 10, j + 7, k + 8, 17, 1, 2);
        world.setBlock(i + 11, j + 7, k + 9, 17, 1, 2);
        world.setBlock(i + 11, j + 7, k + 8, 17, 1, 2);
        world.setBlock(i + 10, j + 8, k + 9, 17, 1, 2);
        world.setBlock(i + 10, j + 8, k + 8, 17, 1, 2);
        world.setBlock(i + 11, j + 8, k + 9, 17, 1, 2);
        world.setBlock(i + 11, j + 8, k + 8, 17, 1, 2);
        world.setBlock(i + 10, j + 9, k + 9, 17, 1, 2);
        world.setBlock(i + 10, j + 9, k + 8, 17, 1, 2);
        world.setBlock(i + 11, j + 9, k + 9, 17, 1, 2);
        world.setBlock(i + 11, j + 9, k + 8, 17, 1, 2);
        world.setBlock(i + 10, j + 10, k + 9, 17, 1, 2);
        world.setBlock(i + 10, j + 10, k + 8, 17, 1, 2);
        world.setBlock(i + 11, j + 10, k + 9, 17, 1, 2);
        world.setBlock(i + 11, j + 10, k + 8, 17, 1, 2);
        world.setBlock(i + 8, j + 11, k + 13, 18, 1, 2);
        world.setBlock(i + 8, j + 11, k + 10, 18, 1, 2);
        world.setBlock(i + 9, j + 11, k + 15, 18, 1, 2);
        world.setBlock(i + 9, j + 11, k + 14, 18, 1, 2);
        world.setBlock(i + 9, j + 11, k + 13, 18, 1, 2);
        world.setBlock(i + 9, j + 11, k + 12, 18, 1, 2);
        world.setBlock(i + 10, j + 11, k + 16, 18, 1, 2);
        world.setBlock(i + 10, j + 11, k + 10, 18, 1, 2);
        world.setBlock(i + 10, j + 11, k + 9, 17, 1, 2);
        world.setBlock(i + 10, j + 11, k + 8, 17, 1, 2);
        world.setBlock(i + 11, j + 11, k + 15, 18, 1, 2);
        world.setBlock(i + 11, j + 11, k + 14, 18, 1, 2);
        world.setBlock(i + 11, j + 11, k + 13, 18, 1, 2);
        world.setBlock(i + 11, j + 11, k + 10, 17, 1, 2);
        world.setBlock(i + 11, j + 11, k + 9, 17, 1, 2);
        world.setBlock(i + 11, j + 11, k + 8, 17, 1, 2);
        world.setBlock(i + 12, j + 11, k + 14, 18, 1, 2);
        world.setBlock(i + 12, j + 11, k + 12, 17, 1, 2);
        world.setBlock(i + 12, j + 11, k + 11, 17, 1, 2);
        world.setBlock(i + 12, j + 11, k + 10, 18, 1, 2);
        world.setBlock(i + 12, j + 11, k + 9, 18, 1, 2);
        world.setBlock(i + 13, j + 11, k + 12, 18, 1, 2);
        world.setBlock(i + 14, j + 11, k + 9, 18, 1, 2);
        world.setBlock(i + 14, j + 11, k + 8, 18, 1, 2);
        world.setBlock(i + 15, j + 11, k + 12, 18, 1, 2);
        world.setBlock(i + 15, j + 11, k + 10, 18, 1, 2);
        world.setBlock(i + 16, j + 11, k + 10, 18, 1, 2);
        world.setBlock(i + 0, j + 12, k + 12, 18, 1, 2);
        world.setBlock(i + 0, j + 12, k + 11, 18, 1, 2);
        world.setBlock(i + 0, j + 12, k + 10, 18, 1, 2);
        world.setBlock(i + 0, j + 12, k + 9, 18, 1, 2);
        world.setBlock(i + 1, j + 12, k + 11, 18, 1, 2);
        world.setBlock(i + 1, j + 12, k + 8, 18, 1, 2);
        world.setBlock(i + 2, j + 12, k + 13, 18, 1, 2);
        world.setBlock(i + 2, j + 12, k + 12, 18, 1, 2);
        world.setBlock(i + 2, j + 12, k + 10, 18, 1, 2);
        world.setBlock(i + 2, j + 12, k + 8, 18, 1, 2);
        world.setBlock(i + 2, j + 12, k + 6, 18, 1, 2);
        world.setBlock(i + 2, j + 12, k + 5, 18, 1, 2);
        world.setBlock(i + 3, j + 12, k + 12, 18, 1, 2);
        world.setBlock(i + 3, j + 12, k + 11, 18, 1, 2);
        world.setBlock(i + 3, j + 12, k + 10, 18, 1, 2);
        world.setBlock(i + 3, j + 12, k + 7, 18, 1, 2);
        world.setBlock(i + 4, j + 12, k + 12, 18, 1, 2);
        world.setBlock(i + 4, j + 12, k + 11, 17, 1, 2);
        world.setBlock(i + 4, j + 12, k + 10, 18, 1, 2);
        world.setBlock(i + 4, j + 12, k + 9, 18, 1, 2);
        world.setBlock(i + 4, j + 12, k + 8, 18, 1, 2);
        world.setBlock(i + 4, j + 12, k + 5, 18, 1, 2);
        world.setBlock(i + 5, j + 12, k + 14, 18, 1, 2);
        world.setBlock(i + 5, j + 12, k + 13, 18, 1, 2);
        world.setBlock(i + 5, j + 12, k + 11, 17, 1, 2);
        world.setBlock(i + 5, j + 12, k + 9, 18, 1, 2);
        world.setBlock(i + 5, j + 12, k + 7, 18, 1, 2);
        world.setBlock(i + 5, j + 12, k + 3, 18, 1, 2);
        world.setBlock(i + 6, j + 12, k + 15, 18, 1, 2);
        world.setBlock(i + 6, j + 12, k + 11, 18, 1, 2);
        world.setBlock(i + 6, j + 12, k + 10, 17, 1, 2);
        world.setBlock(i + 6, j + 12, k + 9, 18, 1, 2);
        world.setBlock(i + 6, j + 12, k + 8, 18, 1, 2);
        world.setBlock(i + 6, j + 12, k + 7, 17, 1, 2);
        world.setBlock(i + 6, j + 12, k + 6, 18, 1, 2);
        world.setBlock(i + 6, j + 12, k + 5, 18, 1, 2);
        world.setBlock(i + 6, j + 12, k + 3, 18, 1, 2);
        world.setBlock(i + 7, j + 12, k + 12, 18, 1, 2);
        world.setBlock(i + 7, j + 12, k + 11, 18, 1, 2);
        world.setBlock(i + 7, j + 12, k + 10, 17, 1, 2);
        world.setBlock(i + 7, j + 12, k + 8, 17, 1, 2);
        world.setBlock(i + 7, j + 12, k + 7, 18, 1, 2);
        world.setBlock(i + 7, j + 12, k + 5, 18, 1, 2);
        world.setBlock(i + 7, j + 12, k + 3, 18, 1, 2);
        world.setBlock(i + 8, j + 12, k + 13, 18, 1, 2);
        world.setBlock(i + 8, j + 12, k + 12, 18, 1, 2);
        world.setBlock(i + 8, j + 12, k + 11, 18, 1, 2);
        world.setBlock(i + 8, j + 12, k + 10, 18, 1, 2);
        world.setBlock(i + 8, j + 12, k + 9, 17, 1, 2);
        world.setBlock(i + 8, j + 12, k + 8, 18, 1, 2);
        world.setBlock(i + 8, j + 12, k + 7, 18, 1, 2);
        world.setBlock(i + 8, j + 12, k + 3, 18, 1, 2);
        world.setBlock(i + 9, j + 12, k + 9, 17, 1, 2);
        world.setBlock(i + 9, j + 12, k + 7, 18, 1, 2);
        world.setBlock(i + 10, j + 12, k + 9, 17, 1, 2);
        world.setBlock(i + 10, j + 12, k + 8, 17, 1, 2);
        world.setBlock(i + 10, j + 12, k + 7, 18, 1, 2);
        world.setBlock(i + 11, j + 12, k + 9, 17, 1, 2);
        world.setBlock(i + 11, j + 12, k + 8, 17, 1, 2);
        world.setBlock(i + 6, j + 13, k + 7, 18, 1, 2);
        world.setBlock(i + 7, j + 13, k + 8, 18, 1, 2);
        world.setBlock(i + 7, j + 13, k + 7, 18, 1, 2);
        world.setBlock(i + 8, j + 13, k + 11, 18, 1, 2);
        world.setBlock(i + 8, j + 13, k + 6, 18, 1, 2);
        world.setBlock(i + 8, j + 13, k + 5, 18, 1, 2);
        world.setBlock(i + 9, j + 13, k + 11, 18, 1, 2);
        world.setBlock(i + 9, j + 13, k + 10, 18, 1, 2);
        world.setBlock(i + 9, j + 13, k + 9, 18, 1, 2);
        world.setBlock(i + 10, j + 13, k + 13, 18, 1, 2);
        world.setBlock(i + 10, j + 13, k + 11, 18, 1, 2);
        world.setBlock(i + 10, j + 13, k + 10, 18, 1, 2);
        world.setBlock(i + 10, j + 13, k + 9, 17, 1, 2);
        world.setBlock(i + 10, j + 13, k + 8, 17, 1, 2);
        world.setBlock(i + 10, j + 13, k + 6, 18, 1, 2);
        world.setBlock(i + 11, j + 13, k + 11, 18, 1, 2);
        world.setBlock(i + 11, j + 13, k + 9, 17, 1, 2);
        world.setBlock(i + 11, j + 13, k + 8, 17, 1, 2);
        world.setBlock(i + 12, j + 13, k + 12, 18, 1, 2);
        world.setBlock(i + 12, j + 13, k + 9, 18, 1, 2);
        world.setBlock(i + 13, j + 13, k + 7, 18, 1, 2);
        world.setBlock(i + 10, j + 14, k + 9, 17, 1, 2);
        world.setBlock(i + 10, j + 14, k + 8, 17, 1, 2);
        world.setBlock(i + 11, j + 14, k + 9, 17, 1, 2);
        world.setBlock(i + 11, j + 14, k + 8, 17, 1, 2);
        world.setBlock(i + 5, j + 15, k + 13, 18, 1, 2);
        world.setBlock(i + 5, j + 15, k + 6, 18, 1, 2);
        world.setBlock(i + 5, j + 15, k + 5, 18, 1, 2);
        world.setBlock(i + 6, j + 15, k + 13, 18, 1, 2);
        world.setBlock(i + 6, j + 15, k + 12, 18, 1, 2);
        world.setBlock(i + 6, j + 15, k + 11, 18, 1, 2);
        world.setBlock(i + 6, j + 15, k + 5, 18, 1, 2);
        world.setBlock(i + 6, j + 15, k + 4, 18, 1, 2);
        world.setBlock(i + 6, j + 15, k + 3, 18, 1, 2);
        world.setBlock(i + 6, j + 15, k + 2, 18, 1, 2);
        world.setBlock(i + 7, j + 15, k + 12, 18, 1, 2);
        world.setBlock(i + 7, j + 15, k + 11, 18, 1, 2);
        world.setBlock(i + 7, j + 15, k + 8, 18, 1, 2);
        world.setBlock(i + 7, j + 15, k + 6, 18, 1, 2);
        world.setBlock(i + 7, j + 15, k + 3, 18, 1, 2);
        world.setBlock(i + 8, j + 15, k + 11, 18, 1, 2);
        world.setBlock(i + 8, j + 15, k + 8, 18, 1, 2);
        world.setBlock(i + 8, j + 15, k + 1, 18, 1, 2);
        world.setBlock(i + 9, j + 15, k + 15, 18, 1, 2);
        world.setBlock(i + 9, j + 15, k + 14, 18, 1, 2);
        world.setBlock(i + 9, j + 15, k + 11, 17, 1, 2);
        world.setBlock(i + 9, j + 15, k + 10, 18, 1, 2);
        world.setBlock(i + 9, j + 15, k + 9, 18, 1, 2);
        world.setBlock(i + 9, j + 15, k + 8, 18, 1, 2);
        world.setBlock(i + 9, j + 15, k + 7, 18, 1, 2);
        world.setBlock(i + 9, j + 15, k + 5, 17, 1, 2);
        world.setBlock(i + 9, j + 15, k + 4, 18, 1, 2);
        world.setBlock(i + 9, j + 15, k + 3, 18, 1, 2);
        world.setBlock(i + 9, j + 15, k + 2, 18, 1, 2);
        world.setBlock(i + 9, j + 15, k + 1, 18, 1, 2);
        world.setBlock(i + 10, j + 15, k + 13, 18, 1, 2);
        world.setBlock(i + 10, j + 15, k + 10, 17, 1, 2);
        world.setBlock(i + 10, j + 15, k + 9, 17, 1, 2);
        world.setBlock(i + 10, j + 15, k + 8, 17, 1, 2);
        world.setBlock(i + 10, j + 15, k + 7, 17, 1, 2);
        world.setBlock(i + 10, j + 15, k + 6, 17, 1, 2);
        world.setBlock(i + 10, j + 15, k + 5, 18, 1, 2);
        world.setBlock(i + 10, j + 15, k + 4, 18, 1, 2);
        world.setBlock(i + 10, j + 15, k + 3, 18, 1, 2);
        world.setBlock(i + 11, j + 15, k + 14, 18, 1, 2);
        world.setBlock(i + 11, j + 15, k + 9, 17, 1, 2);
        world.setBlock(i + 11, j + 15, k + 8, 17, 1, 2);
        world.setBlock(i + 11, j + 15, k + 6, 18, 1, 2);
        world.setBlock(i + 11, j + 15, k + 5, 18, 1, 2);
        world.setBlock(i + 11, j + 15, k + 4, 18, 1, 2);
        world.setBlock(i + 11, j + 15, k + 3, 18, 1, 2);
        world.setBlock(i + 11, j + 15, k + 1, 18, 1, 2);
        world.setBlock(i + 12, j + 15, k + 12, 18, 1, 2);
        world.setBlock(i + 12, j + 15, k + 10, 18, 1, 2);
        world.setBlock(i + 12, j + 15, k + 8, 18, 1, 2);
        world.setBlock(i + 12, j + 15, k + 6, 18, 1, 2);
        world.setBlock(i + 12, j + 15, k + 4, 18, 1, 2);
        world.setBlock(i + 12, j + 15, k + 2, 18, 1, 2);
        world.setBlock(i + 13, j + 15, k + 12, 18, 1, 2);
        world.setBlock(i + 13, j + 15, k + 9, 18, 1, 2);
        world.setBlock(i + 13, j + 15, k + 7, 18, 1, 2);
        world.setBlock(i + 6, j + 16, k + 11, 18, 1, 2);
        world.setBlock(i + 6, j + 16, k + 9, 18, 1, 2);
        world.setBlock(i + 6, j + 16, k + 8, 18, 1, 2);
        world.setBlock(i + 7, j + 16, k + 10, 18, 1, 2);
        world.setBlock(i + 7, j + 16, k + 6, 18, 1, 2);
        world.setBlock(i + 8, j + 16, k + 11, 18, 1, 2);
        world.setBlock(i + 9, j + 16, k + 10, 18, 1, 2);
        world.setBlock(i + 10, j + 16, k + 13, 18, 1, 2);
        world.setBlock(i + 10, j + 16, k + 12, 18, 1, 2);
        world.setBlock(i + 10, j + 16, k + 11, 18, 1, 2);
        world.setBlock(i + 10, j + 16, k + 10, 18, 1, 2);
        world.setBlock(i + 10, j + 16, k + 9, 17, 1, 2);
        world.setBlock(i + 10, j + 16, k + 8, 17, 1, 2);
        world.setBlock(i + 10, j + 16, k + 7, 18, 1, 2);
        world.setBlock(i + 10, j + 16, k + 6, 18, 1, 2);
        world.setBlock(i + 10, j + 16, k + 5, 18, 1, 2);
        world.setBlock(i + 11, j + 16, k + 9, 17, 1, 2);
        world.setBlock(i + 11, j + 16, k + 8, 17, 1, 2);
        world.setBlock(i + 12, j + 16, k + 13, 18, 1, 2);
        world.setBlock(i + 12, j + 16, k + 9, 18, 1, 2);
        world.setBlock(i + 13, j + 16, k + 12, 18, 1, 2);
        world.setBlock(i + 13, j + 16, k + 9, 18, 1, 2);
        world.setBlock(i + 13, j + 16, k + 6, 18, 1, 2);
        world.setBlock(i + 14, j + 16, k + 9, 18, 1, 2);
        world.setBlock(i + 14, j + 16, k + 8, 18, 1, 2);
        world.setBlock(i + 14, j + 16, k + 7, 18, 1, 2);
        world.setBlock(i + 10, j + 17, k + 9, 17, 1, 2);
        world.setBlock(i + 10, j + 17, k + 8, 18, 1, 2);
        world.setBlock(i + 10, j + 17, k + 7, 18, 1, 2);
        world.setBlock(i + 10, j + 17, k + 5, 18, 1, 2);
        world.setBlock(i + 11, j + 17, k + 9, 17, 1, 2);
        world.setBlock(i + 11, j + 17, k + 8, 17, 1, 2);
        world.setBlock(i + 12, j + 17, k + 10, 18, 1, 2);
        world.setBlock(i + 12, j + 17, k + 8, 17, 1, 2);
        world.setBlock(i + 12, j + 17, k + 7, 18, 1, 2);
        world.setBlock(i + 12, j + 17, k + 4, 18, 1, 2);
        world.setBlock(i + 13, j + 17, k + 11, 18, 1, 2);
        world.setBlock(i + 13, j + 17, k + 8, 17, 1, 2);
        world.setBlock(i + 13, j + 17, k + 7, 18, 1, 2);
        world.setBlock(i + 13, j + 17, k + 4, 18, 1, 2);
        world.setBlock(i + 14, j + 17, k + 12, 18, 1, 2);
        world.setBlock(i + 14, j + 17, k + 11, 18, 1, 2);
        world.setBlock(i + 14, j + 17, k + 7, 17, 1, 2);
        world.setBlock(i + 14, j + 17, k + 6, 17, 1, 2);
        world.setBlock(i + 14, j + 17, k + 4, 18, 1, 2);
        world.setBlock(i + 15, j + 17, k + 11, 18, 1, 2);
        world.setBlock(i + 15, j + 17, k + 9, 18, 1, 2);
        world.setBlock(i + 15, j + 17, k + 7, 17, 1, 2);
        world.setBlock(i + 15, j + 17, k + 5, 17, 1, 2);
        world.setBlock(i + 15, j + 17, k + 4, 18, 1, 2);
        world.setBlock(i + 15, j + 17, k + 3, 18, 1, 2);
        world.setBlock(i + 15, j + 17, k + 2, 18, 1, 2);
        world.setBlock(i + 15, j + 17, k + 1, 18, 1, 2);
        world.setBlock(i + 16, j + 17, k + 13, 18, 1, 2);
        world.setBlock(i + 16, j + 17, k + 9, 18, 1, 2);
        world.setBlock(i + 16, j + 17, k + 8, 17, 1, 2);
        world.setBlock(i + 16, j + 17, k + 6, 18, 1, 2);
        world.setBlock(i + 16, j + 17, k + 5, 18, 1, 2);
        world.setBlock(i + 16, j + 17, k + 4, 17, 1, 2);
        world.setBlock(i + 16, j + 17, k + 3, 18, 1, 2);
        world.setBlock(i + 16, j + 17, k + 2, 18, 1, 2);
        world.setBlock(i + 16, j + 17, k + 1, 18, 1, 2);
        world.setBlock(i + 17, j + 17, k + 10, 18, 1, 2);
        world.setBlock(i + 17, j + 17, k + 9, 17, 1, 2);
        world.setBlock(i + 17, j + 17, k + 7, 18, 1, 2);
        world.setBlock(i + 17, j + 17, k + 6, 18, 1, 2);
        world.setBlock(i + 17, j + 17, k + 4, 18, 1, 2);
        world.setBlock(i + 18, j + 17, k + 13, 18, 1, 2);
        world.setBlock(i + 18, j + 17, k + 7, 18, 1, 2);
        world.setBlock(i + 18, j + 17, k + 5, 18, 1, 2);
        world.setBlock(i + 18, j + 17, k + 4, 18, 1, 2);
        world.setBlock(i + 19, j + 17, k + 13, 18, 1, 2);
        world.setBlock(i + 19, j + 17, k + 11, 18, 1, 2);
        world.setBlock(i + 19, j + 17, k + 9, 18, 1, 2);
        world.setBlock(i + 19, j + 17, k + 6, 18, 1, 2);
        world.setBlock(i + 19, j + 17, k + 5, 18, 1, 2);
        world.setBlock(i + 20, j + 17, k + 10, 18, 1, 2);
        world.setBlock(i + 20, j + 17, k + 6, 18, 1, 2);
        world.setBlock(i + 20, j + 17, k + 4, 18, 1, 2);
        world.setBlock(i + 20, j + 17, k + 3, 18, 1, 2);
        world.setBlock(i + 21, j + 17, k + 8, 18, 1, 2);
        world.setBlock(i + 21, j + 17, k + 7, 18, 1, 2);
        world.setBlock(i + 6, j + 18, k + 12, 18, 1, 2);
        world.setBlock(i + 6, j + 18, k + 10, 18, 1, 2);
        world.setBlock(i + 7, j + 18, k + 13, 18, 1, 2);
        world.setBlock(i + 7, j + 18, k + 11, 18, 1, 2);
        world.setBlock(i + 7, j + 18, k + 10, 18, 1, 2);
        world.setBlock(i + 8, j + 18, k + 13, 18, 1, 2);
        world.setBlock(i + 8, j + 18, k + 12, 18, 1, 2);
        world.setBlock(i + 8, j + 18, k + 11, 18, 1, 2);
        world.setBlock(i + 9, j + 18, k + 16, 18, 1, 2);
        world.setBlock(i + 9, j + 18, k + 13, 18, 1, 2);
        world.setBlock(i + 9, j + 18, k + 12, 17, 1, 2);
        world.setBlock(i + 9, j + 18, k + 10, 18, 1, 2);
        world.setBlock(i + 9, j + 18, k + 9, 18, 1, 2);
        world.setBlock(i + 10, j + 18, k + 16, 18, 1, 2);
        world.setBlock(i + 10, j + 18, k + 12, 18, 1, 2);
        world.setBlock(i + 10, j + 18, k + 11, 17, 1, 2);
        world.setBlock(i + 10, j + 18, k + 10, 17, 1, 2);
        world.setBlock(i + 10, j + 18, k + 9, 17, 1, 2);
        world.setBlock(i + 11, j + 18, k + 16, 18, 1, 2);
        world.setBlock(i + 11, j + 18, k + 11, 18, 1, 2);
        world.setBlock(i + 11, j + 18, k + 10, 18, 1, 2);
        world.setBlock(i + 11, j + 18, k + 9, 17, 1, 2);
        world.setBlock(i + 11, j + 18, k + 8, 17, 1, 2);
        world.setBlock(i + 7, j + 19, k + 9, 18, 1, 2);
        world.setBlock(i + 8, j + 19, k + 13, 18, 1, 2);
        world.setBlock(i + 8, j + 19, k + 12, 18, 1, 2);
        world.setBlock(i + 8, j + 19, k + 8, 18, 1, 2);
        world.setBlock(i + 8, j + 19, k + 7, 18, 1, 2);
        world.setBlock(i + 9, j + 19, k + 12, 18, 1, 2);
        world.setBlock(i + 9, j + 19, k + 11, 18, 1, 2);
        world.setBlock(i + 9, j + 19, k + 9, 18, 1, 2);
        world.setBlock(i + 9, j + 19, k + 8, 18, 1, 2);
        world.setBlock(i + 10, j + 19, k + 9, 17, 1, 2);
        world.setBlock(i + 10, j + 19, k + 5, 18, 1, 2);
        world.setBlock(i + 11, j + 19, k + 10, 18, 1, 2);
        world.setBlock(i + 11, j + 19, k + 9, 17, 1, 2);
        world.setBlock(i + 11, j + 19, k + 8, 17, 1, 2);
        world.setBlock(i + 11, j + 19, k + 5, 18, 1, 2);
        world.setBlock(i + 12, j + 19, k + 13, 18, 1, 2);
        world.setBlock(i + 12, j + 19, k + 11, 18, 1, 2);
        world.setBlock(i + 12, j + 19, k + 9, 18, 1, 2);
        world.setBlock(i + 12, j + 19, k + 7, 18, 1, 2);
        world.setBlock(i + 13, j + 19, k + 10, 18, 1, 2);
        world.setBlock(i + 14, j + 19, k + 11, 18, 1, 2);
        world.setBlock(i + 14, j + 19, k + 9, 18, 1, 2);
        world.setBlock(i + 14, j + 19, k + 7, 18, 1, 2);
        world.setBlock(i + 10, j + 20, k + 9, 17, 1, 2);
        world.setBlock(i + 11, j + 20, k + 9, 17, 1, 2);
        world.setBlock(i + 11, j + 20, k + 8, 17, 1, 2);
        world.setBlock(i + 4, j + 21, k + 7, 18, 1, 2);
        world.setBlock(i + 4, j + 21, k + 5, 18, 1, 2);
        world.setBlock(i + 5, j + 21, k + 8, 18, 1, 2);
        world.setBlock(i + 5, j + 21, k + 7, 18, 1, 2);
        world.setBlock(i + 5, j + 21, k + 6, 18, 1, 2);
        world.setBlock(i + 6, j + 21, k + 10, 18, 1, 2);
        world.setBlock(i + 6, j + 21, k + 3, 18, 1, 2);
        world.setBlock(i + 7, j + 21, k + 13, 18, 1, 2);
        world.setBlock(i + 7, j + 21, k + 11, 18, 1, 2);
        world.setBlock(i + 7, j + 21, k + 10, 18, 1, 2);
        world.setBlock(i + 7, j + 21, k + 9, 18, 1, 2);
        world.setBlock(i + 7, j + 21, k + 7, 18, 1, 2);
        world.setBlock(i + 7, j + 21, k + 6, 18, 1, 2);
        world.setBlock(i + 8, j + 21, k + 11, 18, 1, 2);
        world.setBlock(i + 8, j + 21, k + 10, 18, 1, 2);
        world.setBlock(i + 8, j + 21, k + 8, 18, 1, 2);
        world.setBlock(i + 8, j + 21, k + 7, 18, 1, 2);
        world.setBlock(i + 8, j + 21, k + 4, 18, 1, 2);
        world.setBlock(i + 9, j + 21, k + 17, 18, 1, 2);
        world.setBlock(i + 9, j + 21, k + 15, 18, 1, 2);
        world.setBlock(i + 9, j + 21, k + 13, 18, 1, 2);
        world.setBlock(i + 9, j + 21, k + 12, 18, 1, 2);
        world.setBlock(i + 9, j + 21, k + 10, 18, 1, 2);
        world.setBlock(i + 9, j + 21, k + 8, 18, 1, 2);
        world.setBlock(i + 9, j + 21, k + 6, 18, 1, 2);
        world.setBlock(i + 10, j + 21, k + 16, 18, 1, 2);
        world.setBlock(i + 10, j + 21, k + 12, 18, 1, 2);
        world.setBlock(i + 10, j + 21, k + 11, 18, 1, 2);
        world.setBlock(i + 10, j + 21, k + 10, 18, 1, 2);
        world.setBlock(i + 10, j + 21, k + 9, 17, 1, 2);
        world.setBlock(i + 10, j + 21, k + 8, 18, 1, 2);
        world.setBlock(i + 10, j + 21, k + 7, 18, 1, 2);
        world.setBlock(i + 10, j + 21, k + 6, 18, 1, 2);
        world.setBlock(i + 10, j + 21, k + 5, 18, 1, 2);
        world.setBlock(i + 10, j + 21, k + 4, 18, 1, 2);
        world.setBlock(i + 10, j + 21, k + 3, 18, 1, 2);
        world.setBlock(i + 11, j + 21, k + 17, 18, 1, 2);
        world.setBlock(i + 11, j + 21, k + 16, 18, 1, 2);
        world.setBlock(i + 11, j + 21, k + 15, 18, 1, 2);
        world.setBlock(i + 11, j + 21, k + 14, 18, 1, 2);
        world.setBlock(i + 11, j + 21, k + 13, 18, 1, 2);
        world.setBlock(i + 11, j + 21, k + 11, 18, 1, 2);
        world.setBlock(i + 11, j + 21, k + 9, 17, 1, 2);
        world.setBlock(i + 11, j + 21, k + 8, 17, 1, 2);
        world.setBlock(i + 11, j + 21, k + 5, 18, 1, 2);
        world.setBlock(i + 12, j + 21, k + 17, 18, 1, 2);
        world.setBlock(i + 12, j + 21, k + 13, 18, 1, 2);
        world.setBlock(i + 12, j + 21, k + 11, 18, 1, 2);
        world.setBlock(i + 12, j + 21, k + 9, 18, 1, 2);
        world.setBlock(i + 12, j + 21, k + 8, 18, 1, 2);
        world.setBlock(i + 12, j + 21, k + 7, 18, 1, 2);
        world.setBlock(i + 13, j + 21, k + 11, 18, 1, 2);
        world.setBlock(i + 13, j + 21, k + 9, 18, 1, 2);
        world.setBlock(i + 14, j + 21, k + 12, 18, 1, 2);
        world.setBlock(i + 14, j + 21, k + 9, 18, 1, 2);
        world.setBlock(i + 14, j + 21, k + 8, 18, 1, 2);
        world.setBlock(i + 14, j + 21, k + 6, 18, 1, 2);
        world.setBlock(i + 14, j + 21, k + 5, 18, 1, 2);
        world.setBlock(i + 14, j + 21, k + 4, 18, 1, 2);
        world.setBlock(i + 14, j + 21, k + 2, 18, 1, 2);
        world.setBlock(i + 15, j + 21, k + 11, 18, 1, 2);
        world.setBlock(i + 15, j + 21, k + 8, 18, 1, 2);
        world.setBlock(i + 15, j + 21, k + 2, 18, 1, 2);
        world.setBlock(i + 16, j + 21, k + 8, 18, 1, 2);
        world.setBlock(i + 16, j + 21, k + 3, 18, 1, 2);
        world.setBlock(i + 16, j + 21, k + 2, 18, 1, 2);
        world.setBlock(i + 17, j + 21, k + 8, 18, 1, 2);
        world.setBlock(i + 17, j + 21, k + 6, 18, 1, 2);
        world.setBlock(i + 17, j + 21, k + 5, 18, 1, 2);
        world.setBlock(i + 17, j + 21, k + 3, 18, 1, 2);
        world.setBlock(i + 18, j + 21, k + 6, 18, 1, 2);
        world.setBlock(i + 6, j + 22, k + 7, 18, 1, 2);
        world.setBlock(i + 7, j + 22, k + 6, 18, 1, 2);
        world.setBlock(i + 8, j + 22, k + 10, 18, 1, 2);
        world.setBlock(i + 8, j + 22, k + 6, 18, 1, 2);
        world.setBlock(i + 10, j + 22, k + 13, 18, 1, 2);
        world.setBlock(i + 10, j + 22, k + 11, 18, 1, 2);
        world.setBlock(i + 10, j + 22, k + 9, 17, 1, 2);
        world.setBlock(i + 10, j + 22, k + 7, 18, 1, 2);
        world.setBlock(i + 11, j + 22, k + 10, 18, 1, 2);
        world.setBlock(i + 11, j + 22, k + 9, 17, 1, 2);
        world.setBlock(i + 11, j + 22, k + 8, 17, 1, 2);
        world.setBlock(i + 11, j + 22, k + 6, 18, 1, 2);
        world.setBlock(i + 12, j + 22, k + 9, 18, 1, 2);
        world.setBlock(i + 12, j + 22, k + 5, 18, 1, 2);
        world.setBlock(i + 13, j + 22, k + 9, 18, 1, 2);
        world.setBlock(i + 13, j + 22, k + 6, 18, 1, 2);
        world.setBlock(i + 14, j + 22, k + 11, 18, 1, 2);
        world.setBlock(i + 14, j + 22, k + 10, 18, 1, 2);
        world.setBlock(i + 14, j + 22, k + 9, 18, 1, 2);
        world.setBlock(i + 5, j + 23, k + 4, 18, 1, 2);
        world.setBlock(i + 6, j + 23, k + 4, 18, 1, 2);
        world.setBlock(i + 6, j + 23, k + 1, 18, 1, 2);
        world.setBlock(i + 7, j + 23, k + 7, 18, 1, 2);
        world.setBlock(i + 7, j + 23, k + 6, 18, 1, 2);
        world.setBlock(i + 7, j + 23, k + 3, 18, 1, 2);
        world.setBlock(i + 8, j + 23, k + 8, 18, 1, 2);
        world.setBlock(i + 8, j + 23, k + 7, 18, 1, 2);
        world.setBlock(i + 8, j + 23, k + 5, 18, 1, 2);
        world.setBlock(i + 8, j + 23, k + 2, 18, 1, 2);
        world.setBlock(i + 8, j + 23, k + 1, 18, 1, 2);
        world.setBlock(i + 8, j + 23, k + 0, 18, 1, 2);
        world.setBlock(i + 9, j + 23, k + 8, 18, 1, 2);
        world.setBlock(i + 9, j + 23, k + 7, 18, 1, 2);
        world.setBlock(i + 9, j + 23, k + 6, 18, 1, 2);
        world.setBlock(i + 9, j + 23, k + 5, 18, 1, 2);
        world.setBlock(i + 9, j + 23, k + 4, 17, 1, 2);
        world.setBlock(i + 9, j + 23, k + 1, 18, 1, 2);
        world.setBlock(i + 9, j + 23, k + 0, 18, 1, 2);
        world.setBlock(i + 10, j + 23, k + 9, 17, 1, 2);
        world.setBlock(i + 10, j + 23, k + 8, 18, 1, 2);
        world.setBlock(i + 10, j + 23, k + 7, 18, 1, 2);
        world.setBlock(i + 10, j + 23, k + 6, 17, 1, 2);
        world.setBlock(i + 10, j + 23, k + 5, 17, 1, 2);
        world.setBlock(i + 10, j + 23, k + 4, 18, 1, 2);
        world.setBlock(i + 10, j + 23, k + 1, 18, 1, 2);
        world.setBlock(i + 11, j + 23, k + 9, 17, 1, 2);
        world.setBlock(i + 11, j + 23, k + 8, 17, 1, 2);
        world.setBlock(i + 11, j + 23, k + 7, 17, 1, 2);
        world.setBlock(i + 11, j + 23, k + 6, 18, 1, 2);
        world.setBlock(i + 11, j + 23, k + 5, 18, 1, 2);
        world.setBlock(i + 11, j + 23, k + 4, 18, 1, 2);
        world.setBlock(i + 11, j + 23, k + 3, 18, 1, 2);
        world.setBlock(i + 11, j + 23, k + 0, 18, 1, 2);
        world.setBlock(i + 12, j + 23, k + 4, 18, 1, 2);
        world.setBlock(i + 12, j + 23, k + 3, 18, 1, 2);
        world.setBlock(i + 13, j + 23, k + 8, 18, 1, 2);
        world.setBlock(i + 13, j + 23, k + 4, 18, 1, 2);
        world.setBlock(i + 14, j + 23, k + 5, 18, 1, 2);
        world.setBlock(i + 14, j + 23, k + 4, 18, 1, 2);
        world.setBlock(i + 7, j + 24, k + 9, 18, 1, 2);
        world.setBlock(i + 7, j + 24, k + 7, 18, 1, 2);
        world.setBlock(i + 7, j + 24, k + 5, 18, 1, 2);
        world.setBlock(i + 8, j + 24, k + 9, 18, 1, 2);
        world.setBlock(i + 8, j + 24, k + 7, 18, 1, 2);
        world.setBlock(i + 8, j + 24, k + 6, 18, 1, 2);
        world.setBlock(i + 9, j + 24, k + 9, 18, 1, 2);
        world.setBlock(i + 9, j + 24, k + 4, 18, 1, 2);
        world.setBlock(i + 9, j + 24, k + 3, 18, 1, 2);
        world.setBlock(i + 10, j + 24, k + 12, 18, 1, 2);
        world.setBlock(i + 10, j + 24, k + 10, 18, 1, 2);
        world.setBlock(i + 10, j + 24, k + 9, 17, 1, 2);
        world.setBlock(i + 10, j + 24, k + 8, 18, 1, 2);
        world.setBlock(i + 10, j + 24, k + 7, 18, 1, 2);
        world.setBlock(i + 10, j + 24, k + 5, 18, 1, 2);
        world.setBlock(i + 11, j + 24, k + 10, 18, 1, 2);
        world.setBlock(i + 11, j + 24, k + 9, 17, 1, 2);
        world.setBlock(i + 11, j + 24, k + 8, 17, 1, 2);
        world.setBlock(i + 11, j + 24, k + 7, 18, 1, 2);
        world.setBlock(i + 11, j + 24, k + 5, 18, 1, 2);
        world.setBlock(i + 11, j + 24, k + 3, 18, 1, 2);
        world.setBlock(i + 11, j + 24, k + 1, 18, 1, 2);
        world.setBlock(i + 12, j + 24, k + 13, 18, 1, 2);
        world.setBlock(i + 12, j + 24, k + 12, 18, 1, 2);
        world.setBlock(i + 12, j + 24, k + 9, 18, 1, 2);
        world.setBlock(i + 12, j + 24, k + 8, 18, 1, 2);
        world.setBlock(i + 12, j + 24, k + 7, 18, 1, 2);
        world.setBlock(i + 12, j + 24, k + 5, 18, 1, 2);
        world.setBlock(i + 13, j + 24, k + 12, 18, 1, 2);
        world.setBlock(i + 13, j + 24, k + 11, 18, 1, 2);
        world.setBlock(i + 13, j + 24, k + 9, 18, 1, 2);
        world.setBlock(i + 13, j + 24, k + 8, 18, 1, 2);
        world.setBlock(i + 13, j + 24, k + 7, 18, 1, 2);
        world.setBlock(i + 13, j + 24, k + 5, 18, 1, 2);
        world.setBlock(i + 13, j + 24, k + 4, 18, 1, 2);
        world.setBlock(i + 13, j + 24, k + 3, 18, 1, 2);
        world.setBlock(i + 14, j + 24, k + 9, 18, 1, 2);
        world.setBlock(i + 14, j + 24, k + 8, 18, 1, 2);
        world.setBlock(i + 14, j + 24, k + 5, 18, 1, 2);
        world.setBlock(i + 14, j + 24, k + 4, 18, 1, 2);
        world.setBlock(i + 15, j + 24, k + 8, 18, 1, 2);
        world.setBlock(i + 15, j + 24, k + 7, 18, 1, 2);
        world.setBlock(i + 15, j + 24, k + 4, 18, 1, 2);
        world.setBlock(i + 16, j + 24, k + 8, 18, 1, 2);
        world.setBlock(i + 17, j + 24, k + 9, 18, 1, 2);
        world.setBlock(i + 10, j + 25, k + 9, 17, 1, 2);
        world.setBlock(i + 11, j + 25, k + 9, 17, 1, 2);
        world.setBlock(i + 11, j + 25, k + 8, 17, 1, 2);
        world.setBlock(i + 10, j + 26, k + 9, 17, 1, 2);
        world.setBlock(i + 11, j + 26, k + 9, 17, 1, 2);
        world.setBlock(i + 11, j + 26, k + 8, 17, 1, 2);
        world.setBlock(i + 11, j + 26, k + 6, 18, 1, 2);
        world.setBlock(i + 11, j + 26, k + 4, 18, 1, 2);
        world.setBlock(i + 12, j + 26, k + 8, 17, 1, 2);
        world.setBlock(i + 12, j + 26, k + 7, 18, 1, 2);
        world.setBlock(i + 12, j + 26, k + 6, 18, 1, 2);
        world.setBlock(i + 12, j + 26, k + 4, 18, 1, 2);
        world.setBlock(i + 13, j + 26, k + 10, 18, 1, 2);
        world.setBlock(i + 13, j + 26, k + 8, 17, 1, 2);
        world.setBlock(i + 13, j + 26, k + 3, 18, 1, 2);
        world.setBlock(i + 13, j + 26, k + 2, 18, 1, 2);
        world.setBlock(i + 14, j + 26, k + 10, 18, 1, 2);
        world.setBlock(i + 14, j + 26, k + 7, 17, 1, 2);
        world.setBlock(i + 14, j + 26, k + 6, 18, 1, 2);
        world.setBlock(i + 14, j + 26, k + 5, 18, 1, 2);
        world.setBlock(i + 14, j + 26, k + 4, 18, 1, 2);
        world.setBlock(i + 14, j + 26, k + 2, 18, 1, 2);
        world.setBlock(i + 15, j + 26, k + 8, 18, 1, 2);
        world.setBlock(i + 15, j + 26, k + 7, 18, 1, 2);
        world.setBlock(i + 15, j + 26, k + 6, 17, 1, 2);
        world.setBlock(i + 15, j + 26, k + 4, 18, 1, 2);
        world.setBlock(i + 15, j + 26, k + 3, 18, 1, 2);
        world.setBlock(i + 15, j + 26, k + 2, 18, 1, 2);
        world.setBlock(i + 17, j + 26, k + 10, 18, 1, 2);
        world.setBlock(i + 17, j + 26, k + 7, 18, 1, 2);
        world.setBlock(i + 17, j + 26, k + 5, 18, 1, 2);
        world.setBlock(i + 18, j + 26, k + 6, 18, 1, 2);
        world.setBlock(i + 18, j + 26, k + 3, 18, 1, 2);
        world.setBlock(i + 2, j + 27, k + 7, 18, 1, 2);
        world.setBlock(i + 2, j + 27, k + 5, 18, 1, 2);
        world.setBlock(i + 3, j + 27, k + 10, 18, 1, 2);
        world.setBlock(i + 3, j + 27, k + 7, 18, 1, 2);
        world.setBlock(i + 4, j + 27, k + 11, 18, 1, 2);
        world.setBlock(i + 4, j + 27, k + 7, 18, 1, 2);
        world.setBlock(i + 4, j + 27, k + 4, 18, 1, 2);
        world.setBlock(i + 4, j + 27, k + 3, 18, 1, 2);
        world.setBlock(i + 5, j + 27, k + 15, 18, 1, 2);
        world.setBlock(i + 5, j + 27, k + 13, 18, 1, 2);
        world.setBlock(i + 5, j + 27, k + 11, 18, 1, 2);
        world.setBlock(i + 5, j + 27, k + 9, 18, 1, 2);
        world.setBlock(i + 5, j + 27, k + 6, 18, 1, 2);
        world.setBlock(i + 5, j + 27, k + 3, 18, 1, 2);
        world.setBlock(i + 6, j + 27, k + 14, 18, 1, 2);
        world.setBlock(i + 6, j + 27, k + 10, 18, 1, 2);
        world.setBlock(i + 6, j + 27, k + 9, 18, 1, 2);
        world.setBlock(i + 6, j + 27, k + 8, 18, 1, 2);
        world.setBlock(i + 6, j + 27, k + 7, 17, 1, 2);
        world.setBlock(i + 6, j + 27, k + 3, 18, 1, 2);
        world.setBlock(i + 7, j + 27, k + 17, 18, 1, 2);
        world.setBlock(i + 7, j + 27, k + 16, 18, 1, 2);
        world.setBlock(i + 7, j + 27, k + 15, 18, 1, 2);
        world.setBlock(i + 7, j + 27, k + 12, 18, 1, 2);
        world.setBlock(i + 7, j + 27, k + 10, 18, 1, 2);
        world.setBlock(i + 7, j + 27, k + 9, 18, 1, 2);
        world.setBlock(i + 7, j + 27, k + 8, 17, 1, 2);
        world.setBlock(i + 8, j + 27, k + 15, 18, 1, 2);
        world.setBlock(i + 8, j + 27, k + 13, 18, 1, 2);
        world.setBlock(i + 8, j + 27, k + 9, 17, 1, 2);
        world.setBlock(i + 8, j + 27, k + 7, 18, 1, 2);
        world.setBlock(i + 9, j + 27, k + 16, 18, 1, 2);
        world.setBlock(i + 9, j + 27, k + 15, 18, 1, 2);
        world.setBlock(i + 9, j + 27, k + 13, 17, 1, 2);
        world.setBlock(i + 9, j + 27, k + 12, 18, 1, 2);
        world.setBlock(i + 9, j + 27, k + 9, 17, 1, 2);
        world.setBlock(i + 9, j + 27, k + 7, 18, 1, 2);
        world.setBlock(i + 10, j + 27, k + 17, 18, 1, 2);
        world.setBlock(i + 10, j + 27, k + 13, 18, 1, 2);
        world.setBlock(i + 10, j + 27, k + 12, 17, 1, 2);
        world.setBlock(i + 10, j + 27, k + 11, 18, 1, 2);
        world.setBlock(i + 10, j + 27, k + 9, 17, 1, 2);
        world.setBlock(i + 10, j + 27, k + 6, 18, 1, 2);
        world.setBlock(i + 11, j + 27, k + 17, 18, 1, 2);
        world.setBlock(i + 11, j + 27, k + 11, 17, 1, 2);
        world.setBlock(i + 11, j + 27, k + 10, 17, 1, 2);
        world.setBlock(i + 11, j + 27, k + 9, 17, 1, 2);
        world.setBlock(i + 12, j + 27, k + 15, 18, 1, 2);
        world.setBlock(i + 12, j + 27, k + 14, 18, 1, 2);
        world.setBlock(i + 13, j + 27, k + 15, 18, 1, 2);
        world.setBlock(i + 13, j + 27, k + 13, 18, 1, 2);
        world.setBlock(i + 13, j + 27, k + 12, 18, 1, 2);
        world.setBlock(i + 13, j + 27, k + 11, 18, 1, 2);
        world.setBlock(i + 3, j + 28, k + 10, 18, 1, 2);
        world.setBlock(i + 5, j + 28, k + 13, 18, 1, 2);
        world.setBlock(i + 6, j + 28, k + 13, 18, 1, 2);
        world.setBlock(i + 6, j + 28, k + 9, 18, 1, 2);
        world.setBlock(i + 6, j + 28, k + 8, 18, 1, 2);
        world.setBlock(i + 6, j + 28, k + 6, 18, 1, 2);
        world.setBlock(i + 7, j + 28, k + 13, 18, 1, 2);
        world.setBlock(i + 7, j + 28, k + 12, 18, 1, 2);
        world.setBlock(i + 7, j + 28, k + 10, 18, 1, 2);
        world.setBlock(i + 7, j + 28, k + 9, 18, 1, 2);
        world.setBlock(i + 7, j + 28, k + 7, 18, 1, 2);
        world.setBlock(i + 7, j + 28, k + 5, 18, 1, 2);
        world.setBlock(i + 8, j + 28, k + 13, 18, 1, 2);
        world.setBlock(i + 8, j + 28, k + 9, 18, 1, 2);
        world.setBlock(i + 8, j + 28, k + 8, 18, 1, 2);
        world.setBlock(i + 8, j + 28, k + 6, 18, 1, 2);
        world.setBlock(i + 9, j + 28, k + 13, 18, 1, 2);
        world.setBlock(i + 9, j + 28, k + 12, 18, 1, 2);
        world.setBlock(i + 9, j + 28, k + 11, 18, 1, 2);
        world.setBlock(i + 9, j + 28, k + 8, 18, 1, 2);
        world.setBlock(i + 9, j + 28, k + 7, 18, 1, 2);
        world.setBlock(i + 9, j + 28, k + 6, 18, 1, 2);
        world.setBlock(i + 10, j + 28, k + 11, 18, 1, 2);
        world.setBlock(i + 10, j + 28, k + 9, 17, 1, 2);
        world.setBlock(i + 10, j + 28, k + 7, 18, 1, 2);
        world.setBlock(i + 11, j + 28, k + 11, 18, 1, 2);
        world.setBlock(i + 11, j + 28, k + 10, 18, 1, 2);
        world.setBlock(i + 11, j + 28, k + 9, 17, 1, 2);
        world.setBlock(i + 11, j + 28, k + 7, 18, 1, 2);
        world.setBlock(i + 12, j + 28, k + 9, 18, 1, 2);
        world.setBlock(i + 12, j + 28, k + 8, 18, 1, 2);
        world.setBlock(i + 12, j + 28, k + 6, 18, 1, 2);
        world.setBlock(i + 12, j + 28, k + 5, 18, 1, 2);
        world.setBlock(i + 13, j + 28, k + 11, 18, 1, 2);
        world.setBlock(i + 13, j + 28, k + 9, 18, 1, 2);
        world.setBlock(i + 14, j + 28, k + 11, 18, 1, 2);
        world.setBlock(i + 15, j + 28, k + 10, 18, 1, 2);
        world.setBlock(i + 10, j + 29, k + 9, 17, 1, 2);
        world.setBlock(i + 11, j + 29, k + 9, 17, 1, 2);
        world.setBlock(i + 5, j + 30, k + 14, 18, 1, 2);
        world.setBlock(i + 5, j + 30, k + 12, 18, 1, 2);
        world.setBlock(i + 5, j + 30, k + 11, 18, 1, 2);
        world.setBlock(i + 6, j + 30, k + 10, 18, 1, 2);
        world.setBlock(i + 7, j + 30, k + 15, 18, 1, 2);
        world.setBlock(i + 7, j + 30, k + 14, 18, 1, 2);
        world.setBlock(i + 7, j + 30, k + 12, 18, 1, 2);
        world.setBlock(i + 8, j + 30, k + 14, 18, 1, 2);
        world.setBlock(i + 8, j + 30, k + 12, 18, 1, 2);
        world.setBlock(i + 8, j + 30, k + 11, 18, 1, 2);
        world.setBlock(i + 9, j + 30, k + 12, 17, 1, 2);
        world.setBlock(i + 10, j + 30, k + 13, 18, 1, 2);
        world.setBlock(i + 10, j + 30, k + 11, 17, 1, 2);
        world.setBlock(i + 10, j + 30, k + 10, 17, 1, 2);
        world.setBlock(i + 10, j + 30, k + 9, 17, 1, 2);
        world.setBlock(i + 11, j + 30, k + 12, 18, 1, 2);
        world.setBlock(i + 11, j + 30, k + 9, 17, 1, 2);
        world.setBlock(i + 12, j + 30, k + 12, 18, 1, 2);
        world.setBlock(i + 12, j + 30, k + 11, 18, 1, 2);
        world.setBlock(i + 13, j + 30, k + 13, 18, 1, 2);
        world.setBlock(i + 13, j + 30, k + 12, 18, 1, 2);
        world.setBlock(i + 7, j + 31, k + 8, 18, 1, 2);
        world.setBlock(i + 8, j + 31, k + 11, 18, 1, 2);
        world.setBlock(i + 8, j + 31, k + 10, 18, 1, 2);
        world.setBlock(i + 8, j + 31, k + 9, 18, 1, 2);
        world.setBlock(i + 8, j + 31, k + 8, 18, 1, 2);
        world.setBlock(i + 8, j + 31, k + 7, 18, 1, 2);
        world.setBlock(i + 9, j + 31, k + 8, 18, 1, 2);
        world.setBlock(i + 10, j + 31, k + 10, 18, 1, 2);
        world.setBlock(i + 10, j + 31, k + 9, 17, 1, 2);
        world.setBlock(i + 10, j + 31, k + 8, 18, 1, 2);
        world.setBlock(i + 10, j + 31, k + 7, 18, 1, 2);
        world.setBlock(i + 11, j + 31, k + 12, 18, 1, 2);
        world.setBlock(i + 11, j + 31, k + 9, 17, 1, 2);
        world.setBlock(i + 11, j + 31, k + 8, 18, 1, 2);
        world.setBlock(i + 12, j + 31, k + 8, 18, 1, 2);
        world.setBlock(i + 12, j + 31, k + 5, 18, 1, 2);
        world.setBlock(i + 13, j + 31, k + 10, 18, 1, 2);
        world.setBlock(i + 13, j + 31, k + 8, 18, 1, 2);
        world.setBlock(i + 14, j + 31, k + 8, 18, 1, 2);
        world.setBlock(i + 15, j + 31, k + 10, 18, 1, 2);
        world.setBlock(i + 15, j + 31, k + 7, 18, 1, 2);
        world.setBlock(i + 6, j + 32, k + 7, 18, 1, 2);
        world.setBlock(i + 7, j + 32, k + 11, 18, 1, 2);
        world.setBlock(i + 7, j + 32, k + 6, 18, 1, 2);
        world.setBlock(i + 8, j + 32, k + 11, 18, 1, 2);
        world.setBlock(i + 8, j + 32, k + 8, 18, 1, 2);
        world.setBlock(i + 8, j + 32, k + 7, 18, 1, 2);
        world.setBlock(i + 8, j + 32, k + 5, 18, 1, 2);
        world.setBlock(i + 8, j + 32, k + 4, 18, 1, 2);
        world.setBlock(i + 9, j + 32, k + 12, 18, 1, 2);
        world.setBlock(i + 9, j + 32, k + 10, 18, 1, 2);
        world.setBlock(i + 9, j + 32, k + 7, 18, 1, 2);
        world.setBlock(i + 9, j + 32, k + 6, 17, 1, 2);
        world.setBlock(i + 9, j + 32, k + 4, 18, 1, 2);
        world.setBlock(i + 10, j + 32, k + 11, 18, 1, 2);
        world.setBlock(i + 10, j + 32, k + 9, 17, 1, 2);
        world.setBlock(i + 10, j + 32, k + 8, 17, 1, 2);
        world.setBlock(i + 10, j + 32, k + 7, 17, 1, 2);
        world.setBlock(i + 10, j + 32, k + 6, 18, 1, 2);
        world.setBlock(i + 11, j + 32, k + 12, 18, 1, 2);
        world.setBlock(i + 11, j + 32, k + 11, 18, 1, 2);
        world.setBlock(i + 11, j + 32, k + 9, 17, 1, 2);
        world.setBlock(i + 11, j + 32, k + 8, 18, 1, 2);
        world.setBlock(i + 11, j + 32, k + 7, 18, 1, 2);
        world.setBlock(i + 11, j + 32, k + 5, 18, 1, 2);
        world.setBlock(i + 11, j + 32, k + 4, 18, 1, 2);
        world.setBlock(i + 12, j + 32, k + 7, 18, 1, 2);
        world.setBlock(i + 12, j + 32, k + 6, 18, 1, 2);
        world.setBlock(i + 13, j + 32, k + 11, 18, 1, 2);
        world.setBlock(i + 13, j + 32, k + 9, 18, 1, 2);
        world.setBlock(i + 13, j + 32, k + 8, 18, 1, 2);
        world.setBlock(i + 14, j + 32, k + 10, 18, 1, 2);
        world.setBlock(i + 14, j + 32, k + 7, 18, 1, 2);
        world.setBlock(i + 14, j + 32, k + 6, 18, 1, 2);
        world.setBlock(i + 10, j + 33, k + 9, 17, 1, 2);
        world.setBlock(i + 11, j + 33, k + 9, 17, 1, 2);
        world.setBlock(i + 6, j + 34, k + 11, 18, 1, 2);
        world.setBlock(i + 6, j + 34, k + 10, 18, 1, 2);
        world.setBlock(i + 6, j + 34, k + 9, 18, 1, 2);
        world.setBlock(i + 7, j + 34, k + 9, 18, 1, 2);
        world.setBlock(i + 8, j + 34, k + 10, 18, 1, 2);
        world.setBlock(i + 8, j + 34, k + 8, 18, 1, 2);
        world.setBlock(i + 8, j + 34, k + 6, 18, 1, 2);
        world.setBlock(i + 8, j + 34, k + 5, 18, 1, 2);
        world.setBlock(i + 9, j + 34, k + 12, 18, 1, 2);
        world.setBlock(i + 9, j + 34, k + 7, 18, 1, 2);
        world.setBlock(i + 9, j + 34, k + 5, 18, 1, 2);
        world.setBlock(i + 10, j + 34, k + 11, 18, 1, 2);
        world.setBlock(i + 10, j + 34, k + 10, 18, 1, 2);
        world.setBlock(i + 10, j + 34, k + 9, 17, 1, 2);
        world.setBlock(i + 10, j + 34, k + 8, 18, 1, 2);
        world.setBlock(i + 11, j + 34, k + 10, 18, 1, 2);
        world.setBlock(i + 11, j + 34, k + 9, 17, 1, 2);
        world.setBlock(i + 11, j + 34, k + 6, 18, 1, 2);
        world.setBlock(i + 12, j + 34, k + 12, 18, 1, 2);
        world.setBlock(i + 12, j + 34, k + 11, 18, 1, 2);
        world.setBlock(i + 12, j + 34, k + 9, 18, 1, 2);
        world.setBlock(i + 12, j + 34, k + 8, 18, 1, 2);
        world.setBlock(i + 13, j + 34, k + 11, 18, 1, 2);
        world.setBlock(i + 13, j + 34, k + 7, 18, 1, 2);
        world.setBlock(i + 9, j + 35, k + 7, 18, 1, 2);
        world.setBlock(i + 10, j + 35, k + 10, 18, 1, 2);
        world.setBlock(i + 10, j + 35, k + 9, 17, 1, 2);
        world.setBlock(i + 10, j + 35, k + 8, 18, 1, 2);
        world.setBlock(i + 11, j + 35, k + 13, 18, 1, 2);
        world.setBlock(i + 11, j + 35, k + 9, 17, 1, 2);
        world.setBlock(i + 11, j + 35, k + 7, 18, 1, 2);
        world.setBlock(i + 11, j + 35, k + 5, 18, 1, 2);
        world.setBlock(i + 12, j + 35, k + 9, 17, 1, 2);
        world.setBlock(i + 13, j + 35, k + 10, 18, 1, 2);
        world.setBlock(i + 13, j + 35, k + 9, 17, 1, 2);
        world.setBlock(i + 13, j + 35, k + 8, 18, 1, 2);
        world.setBlock(i + 13, j + 35, k + 6, 18, 1, 2);
        world.setBlock(i + 14, j + 35, k + 12, 18, 1, 2);
        world.setBlock(i + 14, j + 35, k + 6, 18, 1, 2);
        world.setBlock(i + 15, j + 35, k + 7, 18, 1, 2);
        world.setBlock(i + 15, j + 35, k + 5, 18, 1, 2);
        world.setBlock(i + 16, j + 35, k + 9, 18, 1, 2);
        world.setBlock(i + 16, j + 35, k + 7, 18, 1, 2);
        world.setBlock(i + 16, j + 35, k + 6, 18, 1, 2);
        world.setBlock(i + 17, j + 35, k + 7, 18, 1, 2);
        world.setBlock(i + 10, j + 36, k + 9, 17, 1, 2);
        world.setBlock(i + 6, j + 37, k + 10, 18, 1, 2);
        world.setBlock(i + 6, j + 37, k + 8, 18, 1, 2);
        world.setBlock(i + 7, j + 37, k + 11, 18, 1, 2);
        world.setBlock(i + 7, j + 37, k + 7, 18, 1, 2);
        world.setBlock(i + 8, j + 37, k + 12, 18, 1, 2);
        world.setBlock(i + 8, j + 37, k + 9, 18, 1, 2);
        world.setBlock(i + 8, j + 37, k + 6, 18, 1, 2);
        world.setBlock(i + 9, j + 37, k + 13, 18, 1, 2);
        world.setBlock(i + 9, j + 37, k + 7, 18, 1, 2);
        world.setBlock(i + 9, j + 37, k + 6, 18, 1, 2);
        world.setBlock(i + 10, j + 37, k + 11, 18, 1, 2);
        world.setBlock(i + 10, j + 37, k + 10, 18, 1, 2);
        world.setBlock(i + 10, j + 37, k + 9, 17, 1, 2);
        world.setBlock(i + 10, j + 37, k + 8, 18, 1, 2);
        world.setBlock(i + 10, j + 37, k + 6, 18, 1, 2);
        world.setBlock(i + 10, j + 37, k + 5, 18, 1, 2);
        world.setBlock(i + 11, j + 37, k + 11, 18, 1, 2);
        world.setBlock(i + 11, j + 37, k + 9, 18, 1, 2);
        world.setBlock(i + 11, j + 37, k + 5, 18, 1, 2);
        world.setBlock(i + 12, j + 37, k + 9, 18, 1, 2);
        world.setBlock(i + 12, j + 37, k + 7, 18, 1, 2);
        world.setBlock(i + 13, j + 37, k + 10, 18, 1, 2);
        world.setBlock(i + 13, j + 37, k + 8, 18, 1, 2);
        world.setBlock(i + 14, j + 37, k + 8, 18, 1, 2);
        world.setBlock(i + 6, j + 38, k + 11, 18, 1, 2);
        world.setBlock(i + 6, j + 38, k + 10, 18, 1, 2);
        world.setBlock(i + 7, j + 38, k + 13, 18, 1, 2);
        world.setBlock(i + 7, j + 38, k + 12, 18, 1, 2);
        world.setBlock(i + 7, j + 38, k + 8, 18, 1, 2);
        world.setBlock(i + 8, j + 38, k + 14, 18, 1, 2);
        world.setBlock(i + 8, j + 38, k + 12, 18, 1, 2);
        world.setBlock(i + 9, j + 38, k + 15, 18, 1, 2);
        world.setBlock(i + 9, j + 38, k + 14, 18, 1, 2);
        world.setBlock(i + 9, j + 38, k + 12, 18, 1, 2);
        world.setBlock(i + 9, j + 38, k + 11, 18, 1, 2);
        world.setBlock(i + 10, j + 38, k + 13, 18, 1, 2);
        world.setBlock(i + 10, j + 38, k + 12, 17, 1, 2);
        world.setBlock(i + 10, j + 38, k + 11, 17, 1, 2);
        world.setBlock(i + 10, j + 38, k + 10, 17, 1, 2);
        world.setBlock(i + 10, j + 38, k + 9, 17, 1, 2);
        world.setBlock(i + 10, j + 38, k + 7, 18, 1, 2);
        world.setBlock(i + 11, j + 38, k + 15, 18, 1, 2);
        world.setBlock(i + 11, j + 38, k + 13, 18, 1, 2);
        world.setBlock(i + 11, j + 38, k + 11, 18, 1, 2);
        world.setBlock(i + 11, j + 38, k + 10, 18, 1, 2);
        world.setBlock(i + 11, j + 38, k + 7, 18, 1, 2);
        world.setBlock(i + 12, j + 38, k + 8, 18, 1, 2);
        world.setBlock(i + 13, j + 38, k + 13, 18, 1, 2);
        world.setBlock(i + 13, j + 38, k + 12, 18, 1, 2);
        world.setBlock(i + 13, j + 38, k + 11, 18, 1, 2);
        world.setBlock(i + 13, j + 38, k + 8, 18, 1, 2);
        world.setBlock(i + 10, j + 39, k + 9, 17, 1, 2);
        world.setBlock(i + 5, j + 40, k + 10, 18, 1, 2);
        world.setBlock(i + 5, j + 40, k + 8, 18, 1, 2);
        world.setBlock(i + 5, j + 40, k + 7, 18, 1, 2);
        world.setBlock(i + 6, j + 40, k + 11, 18, 1, 2);
        world.setBlock(i + 7, j + 40, k + 12, 18, 1, 2);
        world.setBlock(i + 8, j + 40, k + 7, 17, 1, 2);
        world.setBlock(i + 9, j + 40, k + 9, 18, 1, 2);
        world.setBlock(i + 9, j + 40, k + 8, 17, 1, 2);
        world.setBlock(i + 9, j + 40, k + 6, 18, 1, 2);
        world.setBlock(i + 10, j + 40, k + 12, 18, 1, 2);
        world.setBlock(i + 10, j + 40, k + 9, 17, 1, 2);
        world.setBlock(i + 10, j + 40, k + 8, 18, 1, 2);
        world.setBlock(i + 10, j + 40, k + 7, 18, 1, 2);
        world.setBlock(i + 10, j + 40, k + 6, 18, 1, 2);
        world.setBlock(i + 10, j + 40, k + 4, 18, 1, 2);
        world.setBlock(i + 11, j + 40, k + 8, 18, 1, 2);
        world.setBlock(i + 11, j + 40, k + 6, 18, 1, 2);
        world.setBlock(i + 12, j + 40, k + 7, 18, 1, 2);
        world.setBlock(i + 10, j + 41, k + 9, 17, 1, 2);
        world.setBlock(i + 6, j + 42, k + 10, 18, 1, 2);
        world.setBlock(i + 6, j + 42, k + 9, 18, 1, 2);
        world.setBlock(i + 7, j + 42, k + 12, 18, 1, 2);
        world.setBlock(i + 7, j + 42, k + 10, 18, 1, 2);
        world.setBlock(i + 7, j + 42, k + 7, 18, 1, 2);
        world.setBlock(i + 8, j + 42, k + 12, 18, 1, 2);
        world.setBlock(i + 8, j + 42, k + 11, 18, 1, 2);
        world.setBlock(i + 8, j + 42, k + 9, 18, 1, 2);
        world.setBlock(i + 9, j + 42, k + 12, 18, 1, 2);
        world.setBlock(i + 9, j + 42, k + 9, 18, 1, 2);
        world.setBlock(i + 9, j + 42, k + 8, 18, 1, 2);
        world.setBlock(i + 9, j + 42, k + 5, 18, 1, 2);
        world.setBlock(i + 10, j + 42, k + 12, 18, 1, 2);
        world.setBlock(i + 10, j + 42, k + 10, 18, 1, 2);
        world.setBlock(i + 10, j + 42, k + 9, 17, 1, 2);
        world.setBlock(i + 10, j + 42, k + 8, 18, 1, 2);
        world.setBlock(i + 10, j + 42, k + 6, 18, 1, 2);
        world.setBlock(i + 11, j + 42, k + 11, 18, 1, 2);
        world.setBlock(i + 11, j + 42, k + 10, 18, 1, 2);
        world.setBlock(i + 11, j + 42, k + 7, 18, 1, 2);
        world.setBlock(i + 12, j + 42, k + 13, 18, 1, 2);
        world.setBlock(i + 12, j + 42, k + 5, 18, 1, 2);
        world.setBlock(i + 13, j + 42, k + 11, 18, 1, 2);
        world.setBlock(i + 13, j + 42, k + 10, 18, 1, 2);
        world.setBlock(i + 13, j + 42, k + 6, 18, 1, 2);
        world.setBlock(i + 14, j + 42, k + 9, 18, 1, 2);
        world.setBlock(i + 14, j + 42, k + 7, 18, 1, 2);
        world.setBlock(i + 7, j + 43, k + 10, 18, 1, 2);
        world.setBlock(i + 7, j + 43, k + 9, 18, 1, 2);
        world.setBlock(i + 8, j + 43, k + 9, 18, 1, 2);
        world.setBlock(i + 8, j + 43, k + 7, 18, 1, 2);
        world.setBlock(i + 9, j + 43, k + 9, 18, 1, 2);
        world.setBlock(i + 9, j + 43, k + 8, 18, 1, 2);
        world.setBlock(i + 10, j + 43, k + 11, 18, 1, 2);
        world.setBlock(i + 10, j + 43, k + 9, 17, 1, 2);
        world.setBlock(i + 10, j + 43, k + 7, 18, 1, 2);
        world.setBlock(i + 11, j + 43, k + 12, 18, 1, 2);
        world.setBlock(i + 11, j + 43, k + 7, 18, 1, 2);
        world.setBlock(i + 12, j + 43, k + 11, 18, 1, 2);
        world.setBlock(i + 12, j + 43, k + 9, 18, 1, 2);
        world.setBlock(i + 12, j + 43, k + 7, 18, 1, 2);
        world.setBlock(i + 13, j + 43, k + 9, 18, 1, 2);
        world.setBlock(i + 7, j + 44, k + 10, 18, 1, 2);
        world.setBlock(i + 7, j + 44, k + 8, 18, 1, 2);
        world.setBlock(i + 9, j + 44, k + 10, 18, 1, 2);
        world.setBlock(i + 9, j + 44, k + 6, 18, 1, 2);
        world.setBlock(i + 10, j + 44, k + 9, 17, 1, 2);
        world.setBlock(i + 12, j + 44, k + 9, 18, 1, 2);
        world.setBlock(i + 13, j + 44, k + 9, 18, 1, 2);
        world.setBlock(i + 10, j + 45, k + 9, 17, 1, 2);
        world.setBlock(i + 9, j + 46, k + 11, 18, 1, 2);
        world.setBlock(i + 9, j + 46, k + 9, 18, 1, 2);
        world.setBlock(i + 10, j + 46, k + 10, 18, 1, 2);
        world.setBlock(i + 10, j + 46, k + 9, 17, 1, 2);
        world.setBlock(i + 10, j + 46, k + 8, 18, 1, 2);
        world.setBlock(i + 11, j + 46, k + 7, 18, 1, 2);
        world.setBlock(i + 9, j + 47, k + 9, 18, 1, 2);
        world.setBlock(i + 10, j + 47, k + 9, 17, 1, 2);
        world.setBlock(i + 10, j + 47, k + 7, 18, 1, 2);
        world.setBlock(i + 12, j + 47, k + 10, 18, 1, 2);
        world.setBlock(i + 12, j + 47, k + 9, 18, 1, 2);
        world.setBlock(i + 12, j + 47, k + 8, 18, 1, 2);
        world.setBlock(i + 10, j + 48, k + 9, 17, 1, 2);
        world.setBlock(i + 9, j + 49, k + 11, 18, 1, 2);
        world.setBlock(i + 9, j + 49, k + 10, 18, 1, 2);
        world.setBlock(i + 10, j + 49, k + 11, 18, 1, 2);
        world.setBlock(i + 10, j + 49, k + 9, 17, 1, 2);
        world.setBlock(i + 10, j + 49, k + 7, 18, 1, 2);
        world.setBlock(i + 11, j + 49, k + 10, 18, 1, 2);
        world.setBlock(i + 12, j + 49, k + 9, 18, 1, 2);
        world.setBlock(i + 8, j + 50, k + 10, 18, 1, 2);
        world.setBlock(i + 8, j + 50, k + 9, 18, 1, 2);
        world.setBlock(i + 9, j + 50, k + 7, 18, 1, 2);
        world.setBlock(i + 10, j + 50, k + 9, 17, 1, 2);
        world.setBlock(i + 11, j + 50, k + 11, 18, 1, 2);
        world.setBlock(i + 12, j + 50, k + 8, 18, 1, 2);
        world.setBlock(i + 10, j + 51, k + 9, 17, 1, 2);
        world.setBlock(i + 9, j + 52, k + 9, 18, 1, 2);
        world.setBlock(i + 9, j + 52, k + 8, 18, 1, 2);
        world.setBlock(i + 10, j + 52, k + 9, 17, 1, 2);
        world.setBlock(i + 11, j + 52, k + 9, 18, 1, 2);
        world.setBlock(i + 10, j + 53, k + 9, 17, 1, 2);
        world.setBlock(i + 10, j + 53, k + 8, 18, 1, 2);
        world.setBlock(i + 11, j + 53, k + 10, 18, 1, 2);
        world.setBlock(i + 10, j + 54, k + 10, 18, 1, 2);
        world.setBlock(i + 10, j + 54, k + 9, 17, 1, 2);
        world.setBlock(i + 11, j + 54, k + 10, 18, 1, 2);
        
        return true;
    }
}
