package morethantrees.treegen;

import java.util.Random;

import morethantrees.MTJT;
import net.minecraft.block.Block;
import net.minecraft.world.World;
import net.minecraft.world.gen.feature.WorldGenerator;

public class WorldGenRubberTrees extends WorldGenerator
{
    public boolean generate(World world, Random var2, int i, int j, int k)
    {
        while ((world.isAirBlock(i + 10, j, k + 12)) && (j > 2))
        {
            j--;
        }
        
        int var6 = world.getBlockId(i + 10, j, k + 12);
        
        if (var6 != Block.grass.blockID && var6 != Block.dirt.blockID)
        {
            return false;
        }
        
        for (int var7 = -2; var7 <= 2; var7++)
        {
            for (int var8 = -2; var8 <= 2; var8++)
            {
                if ((world.isAirBlock(i + var7 + 10, j - 1, k + var8 + 12)) && (world.isAirBlock(i + var7 + 10, j - 2, k + var8 + 12)))
                {
                    return false;
                }
            }
        }
        world.setBlock(i + 9, j + 0, k + 12, MTJT.rubberLog.blockID, 0, 2);
        world.setBlock(i + 10, j + 0, k + 12, MTJT.rubberLog.blockID, 0, 2);
        world.setBlock(i + 10, j + 0, k + 11, MTJT.rubberLog.blockID, 0, 2);
        world.setBlock(i + 11, j + 0, k + 13, MTJT.rubberLog.blockID, 0, 2);
        world.setBlock(i + 11, j + 0, k + 12, MTJT.rubberLog.blockID, 0, 2);
        world.setBlock(i + 11, j + 0, k + 10, MTJT.rubberLog.blockID, 0, 2);
        world.setBlock(i + 10, j + 1, k + 11, MTJT.rubberLog.blockID, 0, 2);
        world.setBlock(i + 11, j + 1, k + 12, MTJT.rubberLog.blockID, 0, 2);
        world.setBlock(i + 10, j + 2, k + 11, MTJT.rubberLog.blockID, 0, 2);
        world.setBlock(i + 11, j + 2, k + 12, MTJT.rubberLog.blockID, 0, 2);
        world.setBlock(i + 10, j + 3, k + 11, MTJT.rubberLog.blockID, 0, 2);
        world.setBlock(i + 11, j + 3, k + 12, MTJT.rubberLog.blockID, 0, 2);
        world.setBlock(i + 8, j + 4, k + 16, MTJT.rubberLeaves.blockID, 0, 2);
        world.setBlock(i + 10, j + 4, k + 11, MTJT.rubberLog.blockID, 0, 2);
        world.setBlock(i + 11, j + 4, k + 12, MTJT.rubberLog.blockID, 0, 2);
        world.setBlock(i + 11, j + 4, k + 11, MTJT.rubberLeaves.blockID, 0, 2);
        world.setBlock(i + 6, j + 5, k + 15, MTJT.rubberLeaves.blockID, 0, 2);
        world.setBlock(i + 8, j + 5, k + 10, MTJT.rubberLeaves.blockID, 0, 2);
        world.setBlock(i + 8, j + 5, k + 9, MTJT.rubberLeaves.blockID, 0, 2);
        world.setBlock(i + 9, j + 5, k + 15, MTJT.rubberLeaves.blockID, 0, 2);
        world.setBlock(i + 9, j + 5, k + 11, MTJT.rubberLog.blockID, 0, 2);
        world.setBlock(i + 10, j + 5, k + 12, MTJT.rubberLeaves.blockID, 0, 2);
        world.setBlock(i + 10, j + 5, k + 11, MTJT.rubberLog.blockID, 0, 2);
        world.setBlock(i + 11, j + 5, k + 12, MTJT.rubberLog.blockID, 0, 2);
        world.setBlock(i + 11, j + 5, k + 10, MTJT.rubberLog.blockID, 0, 2);
        world.setBlock(i + 4, j + 6, k + 13, MTJT.rubberLeaves.blockID, 0, 2);
        world.setBlock(i + 4, j + 6, k + 10, MTJT.rubberLeaves.blockID, 0, 2);
        world.setBlock(i + 6, j + 6, k + 8, MTJT.rubberLeaves.blockID, 0, 2);
        world.setBlock(i + 8, j + 6, k + 12, MTJT.rubberLog.blockID, 0, 2);
        world.setBlock(i + 8, j + 6, k + 8, MTJT.rubberLeaves.blockID, 0, 2);
        world.setBlock(i + 10, j + 6, k + 15, MTJT.rubberLeaves.blockID, 0, 2);
        world.setBlock(i + 10, j + 6, k + 14, MTJT.rubberLeaves.blockID, 0, 2);
        world.setBlock(i + 10, j + 6, k + 11, MTJT.rubberLog.blockID, 0, 2);
        world.setBlock(i + 11, j + 6, k + 13, MTJT.rubberLog.blockID, 0, 2);
        world.setBlock(i + 11, j + 6, k + 9, MTJT.rubberLog.blockID, 0, 2);
        world.setBlock(i + 12, j + 6, k + 12, MTJT.rubberLeaves.blockID, 0, 2);
        world.setBlock(i + 16, j + 6, k + 18, MTJT.rubberLeaves.blockID, 0, 2);
        world.setBlock(i + 17, j + 6, k + 18, MTJT.rubberLeaves.blockID, 0, 2);
        world.setBlock(i + 4, j + 7, k + 13, MTJT.rubberLeaves.blockID, 0, 2);
        world.setBlock(i + 6, j + 7, k + 5, MTJT.rubberLeaves.blockID, 0, 2);
        world.setBlock(i + 7, j + 7, k + 16, MTJT.rubberLeaves.blockID, 0, 2);
        world.setBlock(i + 7, j + 7, k + 12, MTJT.rubberLeaves.blockID, 0, 2);
        world.setBlock(i + 7, j + 7, k + 9, MTJT.rubberLeaves.blockID, 0, 2);
        world.setBlock(i + 7, j + 7, k + 4, MTJT.rubberLeaves.blockID, 0, 2);
        world.setBlock(i + 8, j + 7, k + 12, MTJT.rubberLeaves.blockID, 0, 2);
        world.setBlock(i + 9, j + 7, k + 12, MTJT.rubberLeaves.blockID, 0, 2);
        world.setBlock(i + 10, j + 7, k + 11, MTJT.rubberLog.blockID, 0, 2);
        world.setBlock(i + 10, j + 7, k + 8, MTJT.rubberLog.blockID, 0, 2);
        world.setBlock(i + 11, j + 7, k + 13, MTJT.rubberLog.blockID, 0, 2);
        world.setBlock(i + 11, j + 7, k + 11, MTJT.rubberLog.blockID, 0, 2);
        world.setBlock(i + 11, j + 7, k + 2, MTJT.rubberLeaves.blockID, 0, 2);
        world.setBlock(i + 12, j + 7, k + 9, MTJT.rubberLog.blockID, 0, 2);
        world.setBlock(i + 15, j + 7, k + 19, MTJT.rubberLeaves.blockID, 0, 2);
        world.setBlock(i + 16, j + 7, k + 19, MTJT.rubberLeaves.blockID, 0, 2);
        world.setBlock(i + 4, j + 8, k + 12, MTJT.rubberLeaves.blockID, 0, 2);
        world.setBlock(i + 5, j + 8, k + 5, MTJT.rubberLeaves.blockID, 0, 2);
        world.setBlock(i + 8, j + 8, k + 13, MTJT.rubberLeaves.blockID, 0, 2);
        world.setBlock(i + 8, j + 8, k + 5, MTJT.rubberLeaves.blockID, 0, 2);
        world.setBlock(i + 9, j + 8, k + 15, MTJT.rubberLeaves.blockID, 0, 2);
        world.setBlock(i + 10, j + 8, k + 11, MTJT.rubberLog.blockID, 0, 2);
        world.setBlock(i + 10, j + 8, k + 7, MTJT.rubberLog.blockID, 0, 2);
        world.setBlock(i + 10, j + 8, k + 3, MTJT.rubberLeaves.blockID, 0, 2);
        world.setBlock(i + 10, j + 8, k + 0, MTJT.rubberLeaves.blockID, 0, 2);
        world.setBlock(i + 11, j + 8, k + 14, MTJT.rubberLog.blockID, 0, 2);
        world.setBlock(i + 12, j + 8, k + 11, MTJT.rubberLog.blockID, 0, 2);
        world.setBlock(i + 12, j + 8, k + 9, MTJT.rubberLog.blockID, 0, 2);
        world.setBlock(i + 12, j + 8, k + 4, MTJT.rubberLeaves.blockID, 0, 2);
        world.setBlock(i + 15, j + 8, k + 23, MTJT.rubberLeaves.blockID, 0, 2);
        world.setBlock(i + 16, j + 8, k + 20, MTJT.rubberLeaves.blockID, 0, 2);
        world.setBlock(i + 16, j + 8, k + 11, MTJT.rubberLeaves.blockID, 0, 2);
        world.setBlock(i + 17, j + 8, k + 19, MTJT.rubberLeaves.blockID, 0, 2);
        world.setBlock(i + 17, j + 8, k + 10, MTJT.rubberLeaves.blockID, 0, 2);
        world.setBlock(i + 1, j + 9, k + 12, MTJT.rubberLeaves.blockID, 0, 2);
        world.setBlock(i + 4, j + 9, k + 13, MTJT.rubberLeaves.blockID, 0, 2);
        world.setBlock(i + 4, j + 9, k + 12, MTJT.rubberLeaves.blockID, 0, 2);
        world.setBlock(i + 6, j + 9, k + 13, MTJT.rubberLeaves.blockID, 0, 2);
        world.setBlock(i + 8, j + 9, k + 12, MTJT.rubberLeaves.blockID, 0, 2);
        world.setBlock(i + 8, j + 9, k + 11, MTJT.rubberLeaves.blockID, 0, 2);
        world.setBlock(i + 8, j + 9, k + 6, MTJT.rubberLeaves.blockID, 0, 2);
        world.setBlock(i + 8, j + 9, k + 3, MTJT.rubberLeaves.blockID, 0, 2);
        world.setBlock(i + 9, j + 9, k + 12, MTJT.rubberLog.blockID, 0, 2);
        world.setBlock(i + 9, j + 9, k + 6, MTJT.rubberLog.blockID, 0, 2);
        world.setBlock(i + 10, j + 9, k + 19, MTJT.rubberLeaves.blockID, 0, 2);
        world.setBlock(i + 10, j + 9, k + 16, MTJT.rubberLog.blockID, 0, 2);
        world.setBlock(i + 10, j + 9, k + 12, MTJT.rubberLeaves.blockID, 0, 2);
        world.setBlock(i + 10, j + 9, k + 11, MTJT.rubberLog.blockID, 0, 2);
        world.setBlock(i + 10, j + 9, k + 10, MTJT.rubberLog.blockID, 0, 2);
        world.setBlock(i + 10, j + 9, k + 6, MTJT.rubberLeaves.blockID, 0, 2);
        world.setBlock(i + 10, j + 9, k + 4, MTJT.rubberLeaves.blockID, 0, 2);
        world.setBlock(i + 11, j + 9, k + 15, MTJT.rubberLog.blockID, 0, 2);
        world.setBlock(i + 12, j + 9, k + 23, MTJT.rubberLeaves.blockID, 0, 2);
        world.setBlock(i + 12, j + 9, k + 22, MTJT.rubberLeaves.blockID, 0, 2);
        world.setBlock(i + 12, j + 9, k + 16, MTJT.rubberLog.blockID, 0, 2);
        world.setBlock(i + 12, j + 9, k + 8, MTJT.rubberLog.blockID, 0, 2);
        world.setBlock(i + 13, j + 9, k + 11, MTJT.rubberLog.blockID, 0, 2);
        world.setBlock(i + 13, j + 9, k + 10, MTJT.rubberLeaves.blockID, 0, 2);
        world.setBlock(i + 14, j + 9, k + 19, MTJT.rubberLeaves.blockID, 0, 2);
        world.setBlock(i + 15, j + 9, k + 20, MTJT.rubberLog.blockID, 0, 2);
        world.setBlock(i + 16, j + 9, k + 17, MTJT.rubberLeaves.blockID, 0, 2);
        world.setBlock(i + 16, j + 9, k + 12, MTJT.rubberLeaves.blockID, 0, 2);
        world.setBlock(i + 16, j + 9, k + 9, MTJT.rubberLeaves.blockID, 0, 2);
        world.setBlock(i + 17, j + 9, k + 21, MTJT.rubberLeaves.blockID, 0, 2);
        world.setBlock(i + 17, j + 9, k + 20, MTJT.rubberLeaves.blockID, 0, 2);
        world.setBlock(i + 18, j + 9, k + 18, MTJT.rubberLeaves.blockID, 0, 2);
        world.setBlock(i + 18, j + 9, k + 8, MTJT.rubberLeaves.blockID, 0, 2);
        world.setBlock(i + 19, j + 9, k + 20, MTJT.rubberLeaves.blockID, 0, 2);
        world.setBlock(i + 19, j + 9, k + 11, MTJT.rubberLeaves.blockID, 0, 2);
        world.setBlock(i + 0, j + 10, k + 12, MTJT.rubberLeaves.blockID, 0, 2);
        world.setBlock(i + 3, j + 10, k + 14, MTJT.rubberLeaves.blockID, 0, 2);
        world.setBlock(i + 4, j + 10, k + 14, MTJT.rubberLeaves.blockID, 0, 2);
        world.setBlock(i + 4, j + 10, k + 12, MTJT.rubberLeaves.blockID, 0, 2);
        world.setBlock(i + 4, j + 10, k + 11, MTJT.rubberLeaves.blockID, 0, 2);
        world.setBlock(i + 5, j + 10, k + 15, MTJT.rubberLeaves.blockID, 0, 2);
        world.setBlock(i + 5, j + 10, k + 8, MTJT.rubberLeaves.blockID, 0, 2);
        world.setBlock(i + 5, j + 10, k + 6, MTJT.rubberLeaves.blockID, 0, 2);
        world.setBlock(i + 6, j + 10, k + 12, MTJT.rubberLeaves.blockID, 0, 2);
        world.setBlock(i + 6, j + 10, k + 4, MTJT.rubberLeaves.blockID, 0, 2);
        world.setBlock(i + 7, j + 10, k + 15, MTJT.rubberLeaves.blockID, 0, 2);
        world.setBlock(i + 7, j + 10, k + 1, MTJT.rubberLeaves.blockID, 0, 2);
        world.setBlock(i + 8, j + 10, k + 17, MTJT.rubberLeaves.blockID, 0, 2);
        world.setBlock(i + 8, j + 10, k + 12, MTJT.rubberLog.blockID, 0, 2);
        world.setBlock(i + 8, j + 10, k + 6, MTJT.rubberLog.blockID, 0, 2);
        world.setBlock(i + 9, j + 10, k + 22, MTJT.rubberLeaves.blockID, 0, 2);
        world.setBlock(i + 9, j + 10, k + 21, MTJT.rubberLeaves.blockID, 0, 2);
        world.setBlock(i + 9, j + 10, k + 20, MTJT.rubberLeaves.blockID, 0, 2);
        world.setBlock(i + 9, j + 10, k + 16, MTJT.rubberLog.blockID, 0, 2);
        world.setBlock(i + 9, j + 10, k + 12, MTJT.rubberLeaves.blockID, 0, 2);
        world.setBlock(i + 9, j + 10, k + 9, MTJT.rubberLog.blockID, 0, 2);
        world.setBlock(i + 9, j + 10, k + 8, MTJT.rubberLeaves.blockID, 0, 2);
        world.setBlock(i + 10, j + 10, k + 19, MTJT.rubberLeaves.blockID, 0, 2);
        world.setBlock(i + 10, j + 10, k + 11, MTJT.rubberLog.blockID, 0, 2);
        world.setBlock(i + 10, j + 10, k + 5, MTJT.rubberLog.blockID, 0, 2);
        world.setBlock(i + 10, j + 10, k + 4, MTJT.rubberLog.blockID, 0, 2);
        world.setBlock(i + 12, j + 10, k + 17, MTJT.rubberLog.blockID, 0, 2);
        world.setBlock(i + 12, j + 10, k + 8, MTJT.rubberLog.blockID, 0, 2);
        world.setBlock(i + 12, j + 10, k + 3, MTJT.rubberLeaves.blockID, 0, 2);
        world.setBlock(i + 13, j + 10, k + 18, MTJT.rubberLog.blockID, 0, 2);
        world.setBlock(i + 13, j + 10, k + 12, MTJT.rubberLog.blockID, 0, 2);
        world.setBlock(i + 13, j + 10, k + 10, MTJT.rubberLeaves.blockID, 0, 2);
        world.setBlock(i + 13, j + 10, k + 6, MTJT.rubberLeaves.blockID, 0, 2);
        world.setBlock(i + 13, j + 10, k + 3, MTJT.rubberLeaves.blockID, 0, 2);
        world.setBlock(i + 14, j + 10, k + 20, MTJT.rubberLeaves.blockID, 0, 2);
        world.setBlock(i + 14, j + 10, k + 19, MTJT.rubberLog.blockID, 0, 2);
        world.setBlock(i + 14, j + 10, k + 10, MTJT.rubberLog.blockID, 0, 2);
        world.setBlock(i + 15, j + 10, k + 19, MTJT.rubberLeaves.blockID, 0, 2);
        world.setBlock(i + 15, j + 10, k + 11, MTJT.rubberLeaves.blockID, 0, 2);
        world.setBlock(i + 15, j + 10, k + 10, MTJT.rubberLog.blockID, 0, 2);
        world.setBlock(i + 15, j + 10, k + 8, MTJT.rubberLeaves.blockID, 0, 2);
        world.setBlock(i + 15, j + 10, k + 7, MTJT.rubberLeaves.blockID, 0, 2);
        world.setBlock(i + 16, j + 10, k + 9, MTJT.rubberLeaves.blockID, 0, 2);
        world.setBlock(i + 17, j + 10, k + 15, MTJT.rubberLeaves.blockID, 0, 2);
        world.setBlock(i + 2, j + 11, k + 14, MTJT.rubberLeaves.blockID, 0, 2);
        world.setBlock(i + 2, j + 11, k + 11, MTJT.rubberLeaves.blockID, 0, 2);
        world.setBlock(i + 3, j + 11, k + 7, MTJT.rubberLeaves.blockID, 0, 2);
        world.setBlock(i + 3, j + 11, k + 5, MTJT.rubberLeaves.blockID, 0, 2);
        world.setBlock(i + 3, j + 11, k + 4, MTJT.rubberLeaves.blockID, 0, 2);
        world.setBlock(i + 4, j + 11, k + 16, MTJT.rubberLeaves.blockID, 0, 2);
        world.setBlock(i + 4, j + 11, k + 14, MTJT.rubberLeaves.blockID, 0, 2);
        world.setBlock(i + 4, j + 11, k + 8, MTJT.rubberLeaves.blockID, 0, 2);
        world.setBlock(i + 5, j + 11, k + 17, MTJT.rubberLeaves.blockID, 0, 2);
        world.setBlock(i + 5, j + 11, k + 5, MTJT.rubberLeaves.blockID, 0, 2);
        world.setBlock(i + 6, j + 11, k + 20, MTJT.rubberLeaves.blockID, 0, 2);
        world.setBlock(i + 6, j + 11, k + 19, MTJT.rubberLeaves.blockID, 0, 2);
        world.setBlock(i + 6, j + 11, k + 18, MTJT.rubberLeaves.blockID, 0, 2);
        world.setBlock(i + 6, j + 11, k + 15, MTJT.rubberLeaves.blockID, 0, 2);
        world.setBlock(i + 6, j + 11, k + 13, MTJT.rubberLog.blockID, 0, 2);
        world.setBlock(i + 6, j + 11, k + 10, MTJT.rubberLeaves.blockID, 0, 2);
        world.setBlock(i + 6, j + 11, k + 8, MTJT.rubberLeaves.blockID, 0, 2);
        world.setBlock(i + 7, j + 11, k + 16, MTJT.rubberLeaves.blockID, 0, 2);
        world.setBlock(i + 7, j + 11, k + 15, MTJT.rubberLeaves.blockID, 0, 2);
        world.setBlock(i + 7, j + 11, k + 12, MTJT.rubberLog.blockID, 0, 2);
        world.setBlock(i + 7, j + 11, k + 6, MTJT.rubberLeaves.blockID, 0, 2);
        world.setBlock(i + 7, j + 11, k + 5, MTJT.rubberLog.blockID, 0, 2);
        world.setBlock(i + 7, j + 11, k + 2, MTJT.rubberLeaves.blockID, 0, 2);
        world.setBlock(i + 8, j + 11, k + 17, MTJT.rubberLog.blockID, 0, 2);
        world.setBlock(i + 8, j + 11, k + 9, MTJT.rubberLog.blockID, 0, 2);
        world.setBlock(i + 9, j + 11, k + 20, MTJT.rubberLeaves.blockID, 0, 2);
        world.setBlock(i + 9, j + 11, k + 18, MTJT.rubberLeaves.blockID, 0, 2);
        world.setBlock(i + 10, j + 11, k + 20, MTJT.rubberLeaves.blockID, 0, 2);
        world.setBlock(i + 10, j + 11, k + 11, MTJT.rubberLog.blockID, 0, 2);
        world.setBlock(i + 10, j + 11, k + 5, MTJT.rubberLeaves.blockID, 0, 2);
        world.setBlock(i + 10, j + 11, k + 4, MTJT.rubberLeaves.blockID, 0, 2);
        world.setBlock(i + 10, j + 11, k + 3, MTJT.rubberLog.blockID, 0, 2);
        world.setBlock(i + 10, j + 11, k + 1, MTJT.rubberLeaves.blockID, 0, 2);
        world.setBlock(i + 11, j + 11, k + 7, MTJT.rubberLog.blockID, 0, 2);
        world.setBlock(i + 11, j + 11, k + 5, MTJT.rubberLeaves.blockID, 0, 2);
        world.setBlock(i + 11, j + 11, k + 4, MTJT.rubberLeaves.blockID, 0, 2);
        world.setBlock(i + 11, j + 11, k + 2, MTJT.rubberLeaves.blockID, 0, 2);
        world.setBlock(i + 11, j + 11, k + 0, MTJT.rubberLeaves.blockID, 0, 2);
        world.setBlock(i + 12, j + 11, k + 8, MTJT.rubberLeaves.blockID, 0, 2);
        world.setBlock(i + 12, j + 11, k + 6, MTJT.rubberLeaves.blockID, 0, 2);
        world.setBlock(i + 12, j + 11, k + 5, MTJT.rubberLeaves.blockID, 0, 2);
        world.setBlock(i + 12, j + 11, k + 4, MTJT.rubberLeaves.blockID, 0, 2);
        world.setBlock(i + 12, j + 11, k + 3, MTJT.rubberLeaves.blockID, 0, 2);
        world.setBlock(i + 13, j + 11, k + 18, MTJT.rubberLeaves.blockID, 0, 2);
        world.setBlock(i + 13, j + 11, k + 9, MTJT.rubberLeaves.blockID, 0, 2);
        world.setBlock(i + 13, j + 11, k + 7, MTJT.rubberLog.blockID, 0, 2);
        world.setBlock(i + 13, j + 11, k + 4, MTJT.rubberLeaves.blockID, 0, 2);
        world.setBlock(i + 14, j + 11, k + 21, MTJT.rubberLeaves.blockID, 0, 2);
        world.setBlock(i + 14, j + 11, k + 13, MTJT.rubberLog.blockID, 0, 2);
        world.setBlock(i + 14, j + 11, k + 3, MTJT.rubberLeaves.blockID, 0, 2);
        world.setBlock(i + 14, j + 11, k + 1, MTJT.rubberLeaves.blockID, 0, 2);
        world.setBlock(i + 15, j + 11, k + 21, MTJT.rubberLeaves.blockID, 0, 2);
        world.setBlock(i + 15, j + 11, k + 13, MTJT.rubberLog.blockID, 0, 2);
        world.setBlock(i + 15, j + 11, k + 10, MTJT.rubberLeaves.blockID, 0, 2);
        world.setBlock(i + 15, j + 11, k + 9, MTJT.rubberLog.blockID, 0, 2);
        world.setBlock(i + 16, j + 11, k + 23, MTJT.rubberLeaves.blockID, 0, 2);
        world.setBlock(i + 16, j + 11, k + 18, MTJT.rubberLeaves.blockID, 0, 2);
        world.setBlock(i + 16, j + 11, k + 15, MTJT.rubberLeaves.blockID, 0, 2);
        world.setBlock(i + 16, j + 11, k + 14, MTJT.rubberLeaves.blockID, 0, 2);
        world.setBlock(i + 16, j + 11, k + 11, MTJT.rubberLog.blockID, 0, 2);
        world.setBlock(i + 16, j + 11, k + 5, MTJT.rubberLeaves.blockID, 0, 2);
        world.setBlock(i + 17, j + 11, k + 14, MTJT.rubberLeaves.blockID, 0, 2);
        world.setBlock(i + 18, j + 11, k + 8, MTJT.rubberLeaves.blockID, 0, 2);
        world.setBlock(i + 19, j + 11, k + 11, MTJT.rubberLeaves.blockID, 0, 2);
        world.setBlock(i + 19, j + 11, k + 7, MTJT.rubberLeaves.blockID, 0, 2);
        world.setBlock(i + 20, j + 11, k + 11, MTJT.rubberLeaves.blockID, 0, 2);
        world.setBlock(i + 0, j + 12, k + 14, MTJT.rubberLeaves.blockID, 0, 2);
        world.setBlock(i + 1, j + 12, k + 13, MTJT.rubberLeaves.blockID, 0, 2);
        world.setBlock(i + 1, j + 12, k + 12, MTJT.rubberLeaves.blockID, 0, 2);
        world.setBlock(i + 2, j + 12, k + 12, MTJT.rubberLeaves.blockID, 0, 2);
        world.setBlock(i + 2, j + 12, k + 9, MTJT.rubberLeaves.blockID, 0, 2);
        world.setBlock(i + 3, j + 12, k + 9, MTJT.rubberLeaves.blockID, 0, 2);
        world.setBlock(i + 3, j + 12, k + 8, MTJT.rubberLeaves.blockID, 0, 2);
        world.setBlock(i + 3, j + 12, k + 7, MTJT.rubberLeaves.blockID, 0, 2);
        world.setBlock(i + 3, j + 12, k + 6, MTJT.rubberLeaves.blockID, 0, 2);
        world.setBlock(i + 4, j + 12, k + 15, MTJT.rubberLeaves.blockID, 0, 2);
        world.setBlock(i + 4, j + 12, k + 14, MTJT.rubberLeaves.blockID, 0, 2);
        world.setBlock(i + 4, j + 12, k + 12, MTJT.rubberLog.blockID, 0, 2);
        world.setBlock(i + 4, j + 12, k + 8, MTJT.rubberLeaves.blockID, 0, 2);
        world.setBlock(i + 5, j + 12, k + 18, MTJT.rubberLeaves.blockID, 0, 2);
        world.setBlock(i + 5, j + 12, k + 13, MTJT.rubberLog.blockID, 0, 2);
        world.setBlock(i + 5, j + 12, k + 11, MTJT.rubberLeaves.blockID, 0, 2);
        world.setBlock(i + 5, j + 12, k + 9, MTJT.rubberLeaves.blockID, 0, 2);
        world.setBlock(i + 5, j + 12, k + 8, MTJT.rubberLeaves.blockID, 0, 2);
        world.setBlock(i + 6, j + 12, k + 20, MTJT.rubberLeaves.blockID, 0, 2);
        world.setBlock(i + 6, j + 12, k + 13, MTJT.rubberLeaves.blockID, 0, 2);
        world.setBlock(i + 6, j + 12, k + 12, MTJT.rubberLeaves.blockID, 0, 2);
        world.setBlock(i + 6, j + 12, k + 9, MTJT.rubberLeaves.blockID, 0, 2);
        world.setBlock(i + 6, j + 12, k + 7, MTJT.rubberLeaves.blockID, 0, 2);
        world.setBlock(i + 7, j + 12, k + 17, MTJT.rubberLeaves.blockID, 0, 2);
        world.setBlock(i + 7, j + 12, k + 16, MTJT.rubberLog.blockID, 0, 2);
        world.setBlock(i + 7, j + 12, k + 9, MTJT.rubberLog.blockID, 0, 2);
        world.setBlock(i + 7, j + 12, k + 6, MTJT.rubberLeaves.blockID, 0, 2);
        world.setBlock(i + 7, j + 12, k + 3, MTJT.rubberLeaves.blockID, 0, 2);
        world.setBlock(i + 8, j + 12, k + 17, MTJT.rubberLeaves.blockID, 0, 2);
        world.setBlock(i + 8, j + 12, k + 10, MTJT.rubberLeaves.blockID, 0, 2);
        world.setBlock(i + 9, j + 12, k + 18, MTJT.rubberLog.blockID, 0, 2);
        world.setBlock(i + 10, j + 12, k + 19, MTJT.rubberLeaves.blockID, 0, 2);
        world.setBlock(i + 10, j + 12, k + 10, MTJT.rubberLog.blockID, 0, 2);
        world.setBlock(i + 10, j + 12, k + 6, MTJT.rubberLog.blockID, 0, 2);
        world.setBlock(i + 11, j + 12, k + 17, MTJT.rubberLeaves.blockID, 0, 2);
        world.setBlock(i + 11, j + 12, k + 12, MTJT.rubberLog.blockID, 0, 2);
        world.setBlock(i + 11, j + 12, k + 5, MTJT.rubberLeaves.blockID, 0, 2);
        world.setBlock(i + 12, j + 12, k + 16, MTJT.rubberLeaves.blockID, 0, 2);
        world.setBlock(i + 12, j + 12, k + 15, MTJT.rubberLeaves.blockID, 0, 2);
        world.setBlock(i + 12, j + 12, k + 7, MTJT.rubberLeaves.blockID, 0, 2);
        world.setBlock(i + 13, j + 12, k + 18, MTJT.rubberLeaves.blockID, 0, 2);
        world.setBlock(i + 13, j + 12, k + 1, MTJT.rubberLeaves.blockID, 0, 2);
        world.setBlock(i + 14, j + 12, k + 17, MTJT.rubberLeaves.blockID, 0, 2);
        world.setBlock(i + 14, j + 12, k + 15, MTJT.rubberLeaves.blockID, 0, 2);
        world.setBlock(i + 15, j + 12, k + 19, MTJT.rubberLeaves.blockID, 0, 2);
        world.setBlock(i + 15, j + 12, k + 14, MTJT.rubberLog.blockID, 0, 2);
        world.setBlock(i + 15, j + 12, k + 11, MTJT.rubberLeaves.blockID, 0, 2);
        world.setBlock(i + 15, j + 12, k + 9, MTJT.rubberLog.blockID, 0, 2);
        world.setBlock(i + 15, j + 12, k + 3, MTJT.rubberLeaves.blockID, 0, 2);
        world.setBlock(i + 16, j + 12, k + 15, MTJT.rubberLeaves.blockID, 0, 2);
        world.setBlock(i + 16, j + 12, k + 14, MTJT.rubberLeaves.blockID, 0, 2);
        world.setBlock(i + 16, j + 12, k + 11, MTJT.rubberLog.blockID, 0, 2);
        world.setBlock(i + 16, j + 12, k + 8, MTJT.rubberLeaves.blockID, 0, 2);
        world.setBlock(i + 16, j + 12, k + 6, MTJT.rubberLeaves.blockID, 0, 2);
        world.setBlock(i + 19, j + 12, k + 10, MTJT.rubberLeaves.blockID, 0, 2);
        world.setBlock(i + 19, j + 12, k + 6, MTJT.rubberLeaves.blockID, 0, 2);
        world.setBlock(i + 20, j + 12, k + 13, MTJT.rubberLeaves.blockID, 0, 2);
        world.setBlock(i + 0, j + 13, k + 14, MTJT.rubberLeaves.blockID, 0, 2);
        world.setBlock(i + 1, j + 13, k + 17, MTJT.rubberLeaves.blockID, 0, 2);
        world.setBlock(i + 1, j + 13, k + 15, MTJT.rubberLeaves.blockID, 0, 2);
        world.setBlock(i + 1, j + 13, k + 14, MTJT.rubberLeaves.blockID, 0, 2);
        world.setBlock(i + 2, j + 13, k + 15, MTJT.rubberLeaves.blockID, 0, 2);
        world.setBlock(i + 2, j + 13, k + 14, MTJT.rubberLeaves.blockID, 0, 2);
        world.setBlock(i + 2, j + 13, k + 12, MTJT.rubberLeaves.blockID, 0, 2);
        world.setBlock(i + 2, j + 13, k + 9, MTJT.rubberLeaves.blockID, 0, 2);
        world.setBlock(i + 2, j + 13, k + 5, MTJT.rubberLeaves.blockID, 0, 2);
        world.setBlock(i + 3, j + 13, k + 14, MTJT.rubberLeaves.blockID, 0, 2);
        world.setBlock(i + 3, j + 13, k + 12, MTJT.rubberLeaves.blockID, 0, 2);
        world.setBlock(i + 4, j + 13, k + 18, MTJT.rubberLeaves.blockID, 0, 2);
        world.setBlock(i + 4, j + 13, k + 17, MTJT.rubberLeaves.blockID, 0, 2);
        world.setBlock(i + 4, j + 13, k + 14, MTJT.rubberLog.blockID, 0, 2);
        world.setBlock(i + 4, j + 13, k + 12, MTJT.rubberLeaves.blockID, 0, 2);
        world.setBlock(i + 4, j + 13, k + 10, MTJT.rubberLeaves.blockID, 0, 2);
        world.setBlock(i + 5, j + 13, k + 17, MTJT.rubberLeaves.blockID, 0, 2);
        world.setBlock(i + 5, j + 13, k + 16, MTJT.rubberLeaves.blockID, 0, 2);
        world.setBlock(i + 5, j + 13, k + 14, MTJT.rubberLeaves.blockID, 0, 2);
        world.setBlock(i + 5, j + 13, k + 8, MTJT.rubberLeaves.blockID, 0, 2);
        world.setBlock(i + 6, j + 13, k + 16, MTJT.rubberLeaves.blockID, 0, 2);
        world.setBlock(i + 6, j + 13, k + 12, MTJT.rubberLeaves.blockID, 0, 2);
        world.setBlock(i + 6, j + 13, k + 11, MTJT.rubberLeaves.blockID, 0, 2);
        world.setBlock(i + 6, j + 13, k + 9, MTJT.rubberLeaves.blockID, 0, 2);
        world.setBlock(i + 6, j + 13, k + 8, MTJT.rubberLog.blockID, 0, 2);
        world.setBlock(i + 6, j + 13, k + 7, MTJT.rubberLeaves.blockID, 0, 2);
        world.setBlock(i + 6, j + 13, k + 3, MTJT.rubberLeaves.blockID, 0, 2);
        world.setBlock(i + 7, j + 13, k + 17, MTJT.rubberLeaves.blockID, 0, 2);
        world.setBlock(i + 7, j + 13, k + 16, MTJT.rubberLog.blockID, 0, 2);
        world.setBlock(i + 7, j + 13, k + 7, MTJT.rubberLeaves.blockID, 0, 2);
        world.setBlock(i + 7, j + 13, k + 4, MTJT.rubberLeaves.blockID, 0, 2);
        world.setBlock(i + 8, j + 13, k + 15, MTJT.rubberLeaves.blockID, 0, 2);
        world.setBlock(i + 8, j + 13, k + 14, MTJT.rubberLeaves.blockID, 0, 2);
        world.setBlock(i + 8, j + 13, k + 13, MTJT.rubberLeaves.blockID, 0, 2);
        world.setBlock(i + 8, j + 13, k + 2, MTJT.rubberLeaves.blockID, 0, 2);
        world.setBlock(i + 9, j + 13, k + 11, MTJT.rubberLeaves.blockID, 0, 2);
        world.setBlock(i + 9, j + 13, k + 6, MTJT.rubberLog.blockID, 0, 2);
        world.setBlock(i + 9, j + 13, k + 3, MTJT.rubberLeaves.blockID, 0, 2);
        world.setBlock(i + 9, j + 13, k + 2, MTJT.rubberLeaves.blockID, 0, 2);
        world.setBlock(i + 10, j + 13, k + 17, MTJT.rubberLeaves.blockID, 0, 2);
        world.setBlock(i + 10, j + 13, k + 10, MTJT.rubberLog.blockID, 0, 2);
        world.setBlock(i + 10, j + 13, k + 6, MTJT.rubberLeaves.blockID, 0, 2);
        world.setBlock(i + 10, j + 13, k + 2, MTJT.rubberLeaves.blockID, 0, 2);
        world.setBlock(i + 11, j + 13, k + 12, MTJT.rubberLog.blockID, 0, 2);
        world.setBlock(i + 11, j + 13, k + 5, MTJT.rubberLog.blockID, 0, 2);
        world.setBlock(i + 12, j + 13, k + 21, MTJT.rubberLeaves.blockID, 0, 2);
        world.setBlock(i + 12, j + 13, k + 16, MTJT.rubberLeaves.blockID, 0, 2);
        world.setBlock(i + 12, j + 13, k + 14, MTJT.rubberLeaves.blockID, 0, 2);
        world.setBlock(i + 12, j + 13, k + 8, MTJT.rubberLeaves.blockID, 0, 2);
        world.setBlock(i + 12, j + 13, k + 4, MTJT.rubberLeaves.blockID, 0, 2);
        world.setBlock(i + 13, j + 13, k + 8, MTJT.rubberLeaves.blockID, 0, 2);
        world.setBlock(i + 13, j + 13, k + 4, MTJT.rubberLeaves.blockID, 0, 2);
        world.setBlock(i + 14, j + 13, k + 14, MTJT.rubberLeaves.blockID, 0, 2);
        world.setBlock(i + 14, j + 13, k + 4, MTJT.rubberLeaves.blockID, 0, 2);
        world.setBlock(i + 14, j + 13, k + 3, MTJT.rubberLeaves.blockID, 0, 2);
        world.setBlock(i + 15, j + 13, k + 21, MTJT.rubberLeaves.blockID, 0, 2);
        world.setBlock(i + 15, j + 13, k + 14, MTJT.rubberLeaves.blockID, 0, 2);
        world.setBlock(i + 15, j + 13, k + 8, MTJT.rubberLeaves.blockID, 0, 2);
        world.setBlock(i + 16, j + 13, k + 14, MTJT.rubberLog.blockID, 0, 2);
        world.setBlock(i + 16, j + 13, k + 11, MTJT.rubberLeaves.blockID, 0, 2);
        world.setBlock(i + 16, j + 13, k + 8, MTJT.rubberLog.blockID, 0, 2);
        world.setBlock(i + 18, j + 13, k + 15, MTJT.rubberLeaves.blockID, 0, 2);
        world.setBlock(i + 18, j + 13, k + 13, MTJT.rubberLeaves.blockID, 0, 2);
        world.setBlock(i + 19, j + 13, k + 12, MTJT.rubberLeaves.blockID, 0, 2);
        world.setBlock(i + 19, j + 13, k + 8, MTJT.rubberLeaves.blockID, 0, 2);
        world.setBlock(i + 1, j + 14, k + 13, MTJT.rubberLeaves.blockID, 0, 2);
        world.setBlock(i + 2, j + 14, k + 10, MTJT.rubberLeaves.blockID, 0, 2);
        world.setBlock(i + 4, j + 14, k + 17, MTJT.rubberLeaves.blockID, 0, 2);
        world.setBlock(i + 4, j + 14, k + 15, MTJT.rubberLeaves.blockID, 0, 2);
        world.setBlock(i + 4, j + 14, k + 13, MTJT.rubberLeaves.blockID, 0, 2);
        world.setBlock(i + 4, j + 14, k + 11, MTJT.rubberLeaves.blockID, 0, 2);
        world.setBlock(i + 5, j + 14, k + 18, MTJT.rubberLeaves.blockID, 0, 2);
        world.setBlock(i + 5, j + 14, k + 16, MTJT.rubberLeaves.blockID, 0, 2);
        world.setBlock(i + 5, j + 14, k + 13, MTJT.rubberLeaves.blockID, 0, 2);
        world.setBlock(i + 5, j + 14, k + 8, MTJT.rubberLog.blockID, 0, 2);
        world.setBlock(i + 6, j + 14, k + 18, MTJT.rubberLeaves.blockID, 0, 2);
        world.setBlock(i + 6, j + 14, k + 17, MTJT.rubberLog.blockID, 0, 2);
        world.setBlock(i + 6, j + 14, k + 16, MTJT.rubberLeaves.blockID, 0, 2);
        world.setBlock(i + 6, j + 14, k + 14, MTJT.rubberLeaves.blockID, 0, 2);
        world.setBlock(i + 6, j + 14, k + 13, MTJT.rubberLeaves.blockID, 0, 2);
        world.setBlock(i + 6, j + 14, k + 5, MTJT.rubberLeaves.blockID, 0, 2);
        world.setBlock(i + 6, j + 14, k + 3, MTJT.rubberLeaves.blockID, 0, 2);
        world.setBlock(i + 7, j + 14, k + 21, MTJT.rubberLeaves.blockID, 0, 2);
        world.setBlock(i + 7, j + 14, k + 8, MTJT.rubberLeaves.blockID, 0, 2);
        world.setBlock(i + 7, j + 14, k + 5, MTJT.rubberLeaves.blockID, 0, 2);
        world.setBlock(i + 8, j + 14, k + 7, MTJT.rubberLog.blockID, 0, 2);
        world.setBlock(i + 9, j + 14, k + 18, MTJT.rubberLeaves.blockID, 0, 2);
        world.setBlock(i + 9, j + 14, k + 17, MTJT.rubberLeaves.blockID, 0, 2);
        world.setBlock(i + 9, j + 14, k + 14, MTJT.rubberLeaves.blockID, 0, 2);
        world.setBlock(i + 9, j + 14, k + 13, MTJT.rubberLeaves.blockID, 0, 2);
        world.setBlock(i + 9, j + 14, k + 10, MTJT.rubberLeaves.blockID, 0, 2);
        world.setBlock(i + 9, j + 14, k + 8, MTJT.rubberLeaves.blockID, 0, 2);
        world.setBlock(i + 9, j + 14, k + 5, MTJT.rubberLog.blockID, 0, 2);
        world.setBlock(i + 10, j + 14, k + 16, MTJT.rubberLeaves.blockID, 0, 2);
        world.setBlock(i + 10, j + 14, k + 13, MTJT.rubberLog.blockID, 0, 2);
        world.setBlock(i + 10, j + 14, k + 2, MTJT.rubberLeaves.blockID, 0, 2);
        world.setBlock(i + 11, j + 14, k + 10, MTJT.rubberLog.blockID, 0, 2);
        world.setBlock(i + 11, j + 14, k + 1, MTJT.rubberLeaves.blockID, 0, 2);
        world.setBlock(i + 12, j + 14, k + 18, MTJT.rubberLeaves.blockID, 0, 2);
        world.setBlock(i + 12, j + 14, k + 14, MTJT.rubberLeaves.blockID, 0, 2);
        world.setBlock(i + 12, j + 14, k + 12, MTJT.rubberLeaves.blockID, 0, 2);
        world.setBlock(i + 12, j + 14, k + 6, MTJT.rubberLeaves.blockID, 0, 2);
        world.setBlock(i + 12, j + 14, k + 5, MTJT.rubberLog.blockID, 0, 2);
        world.setBlock(i + 12, j + 14, k + 3, MTJT.rubberLeaves.blockID, 0, 2);
        world.setBlock(i + 13, j + 14, k + 18, MTJT.rubberLeaves.blockID, 0, 2);
        world.setBlock(i + 13, j + 14, k + 15, MTJT.rubberLeaves.blockID, 0, 2);
        world.setBlock(i + 13, j + 14, k + 6, MTJT.rubberLeaves.blockID, 0, 2);
        world.setBlock(i + 13, j + 14, k + 4, MTJT.rubberLeaves.blockID, 0, 2);
        world.setBlock(i + 13, j + 14, k + 3, MTJT.rubberLeaves.blockID, 0, 2);
        world.setBlock(i + 14, j + 14, k + 15, MTJT.rubberLeaves.blockID, 0, 2);
        world.setBlock(i + 14, j + 14, k + 14, MTJT.rubberLeaves.blockID, 0, 2);
        world.setBlock(i + 15, j + 14, k + 9, MTJT.rubberLeaves.blockID, 0, 2);
        world.setBlock(i + 16, j + 14, k + 15, MTJT.rubberLog.blockID, 0, 2);
        world.setBlock(i + 16, j + 14, k + 11, MTJT.rubberLeaves.blockID, 0, 2);
        world.setBlock(i + 16, j + 14, k + 10, MTJT.rubberLeaves.blockID, 0, 2);
        world.setBlock(i + 16, j + 14, k + 8, MTJT.rubberLeaves.blockID, 0, 2);
        world.setBlock(i + 17, j + 14, k + 12, MTJT.rubberLeaves.blockID, 0, 2);
        world.setBlock(i + 19, j + 14, k + 8, MTJT.rubberLeaves.blockID, 0, 2);
        world.setBlock(i + 20, j + 14, k + 14, MTJT.rubberLeaves.blockID, 0, 2);
        world.setBlock(i + 20, j + 14, k + 13, MTJT.rubberLeaves.blockID, 0, 2);
        world.setBlock(i + 1, j + 15, k + 16, MTJT.rubberLeaves.blockID, 0, 2);
        world.setBlock(i + 1, j + 15, k + 12, MTJT.rubberLeaves.blockID, 0, 2);
        world.setBlock(i + 1, j + 15, k + 9, MTJT.rubberLeaves.blockID, 0, 2);
        world.setBlock(i + 2, j + 15, k + 17, MTJT.rubberLeaves.blockID, 0, 2);
        world.setBlock(i + 2, j + 15, k + 14, MTJT.rubberLeaves.blockID, 0, 2);
        world.setBlock(i + 3, j + 15, k + 16, MTJT.rubberLeaves.blockID, 0, 2);
        world.setBlock(i + 4, j + 15, k + 17, MTJT.rubberLeaves.blockID, 0, 2);
        world.setBlock(i + 5, j + 15, k + 17, MTJT.rubberLeaves.blockID, 0, 2);
        world.setBlock(i + 5, j + 15, k + 13, MTJT.rubberLeaves.blockID, 0, 2);
        world.setBlock(i + 6, j + 15, k + 13, MTJT.rubberLeaves.blockID, 0, 2);
        world.setBlock(i + 6, j + 15, k + 11, MTJT.rubberLeaves.blockID, 0, 2);
        world.setBlock(i + 6, j + 15, k + 8, MTJT.rubberLeaves.blockID, 0, 2);
        world.setBlock(i + 7, j + 15, k + 21, MTJT.rubberLeaves.blockID, 0, 2);
        world.setBlock(i + 7, j + 15, k + 20, MTJT.rubberLeaves.blockID, 0, 2);
        world.setBlock(i + 7, j + 15, k + 6, MTJT.rubberLeaves.blockID, 0, 2);
        world.setBlock(i + 8, j + 15, k + 21, MTJT.rubberLeaves.blockID, 0, 2);
        world.setBlock(i + 8, j + 15, k + 18, MTJT.rubberLeaves.blockID, 0, 2);
        world.setBlock(i + 8, j + 15, k + 15, MTJT.rubberLeaves.blockID, 0, 2);
        world.setBlock(i + 8, j + 15, k + 5, MTJT.rubberLeaves.blockID, 0, 2);
        world.setBlock(i + 8, j + 15, k + 4, MTJT.rubberLeaves.blockID, 0, 2);
        world.setBlock(i + 9, j + 15, k + 7, MTJT.rubberLeaves.blockID, 0, 2);
        world.setBlock(i + 9, j + 15, k + 4, MTJT.rubberLeaves.blockID, 0, 2);
        world.setBlock(i + 10, j + 15, k + 13, MTJT.rubberLog.blockID, 0, 2);
        world.setBlock(i + 11, j + 15, k + 15, MTJT.rubberLeaves.blockID, 0, 2);
        world.setBlock(i + 11, j + 15, k + 9, MTJT.rubberLog.blockID, 0, 2);
        world.setBlock(i + 12, j + 15, k + 17, MTJT.rubberLeaves.blockID, 0, 2);
        world.setBlock(i + 12, j + 15, k + 12, MTJT.rubberLeaves.blockID, 0, 2);
        world.setBlock(i + 12, j + 15, k + 4, MTJT.rubberLog.blockID, 0, 2);
        world.setBlock(i + 13, j + 15, k + 8, MTJT.rubberLeaves.blockID, 0, 2);
        world.setBlock(i + 13, j + 15, k + 7, MTJT.rubberLeaves.blockID, 0, 2);
        world.setBlock(i + 13, j + 15, k + 2, MTJT.rubberLeaves.blockID, 0, 2);
        world.setBlock(i + 14, j + 15, k + 10, MTJT.rubberLeaves.blockID, 0, 2);
        world.setBlock(i + 14, j + 15, k + 8, MTJT.rubberLeaves.blockID, 0, 2);
        world.setBlock(i + 14, j + 15, k + 6, MTJT.rubberLeaves.blockID, 0, 2);
        world.setBlock(i + 16, j + 15, k + 16, MTJT.rubberLeaves.blockID, 0, 2);
        world.setBlock(i + 16, j + 15, k + 8, MTJT.rubberLeaves.blockID, 0, 2);
        world.setBlock(i + 17, j + 15, k + 9, MTJT.rubberLeaves.blockID, 0, 2);
        world.setBlock(i + 18, j + 15, k + 10, MTJT.rubberLeaves.blockID, 0, 2);
        world.setBlock(i + 2, j + 16, k + 12, MTJT.rubberLeaves.blockID, 0, 2);
        world.setBlock(i + 3, j + 16, k + 17, MTJT.rubberLeaves.blockID, 0, 2);
        world.setBlock(i + 3, j + 16, k + 8, MTJT.rubberLeaves.blockID, 0, 2);
        world.setBlock(i + 4, j + 16, k + 17, MTJT.rubberLeaves.blockID, 0, 2);
        world.setBlock(i + 4, j + 16, k + 16, MTJT.rubberLeaves.blockID, 0, 2);
        world.setBlock(i + 4, j + 16, k + 14, MTJT.rubberLeaves.blockID, 0, 2);
        world.setBlock(i + 4, j + 16, k + 10, MTJT.rubberLeaves.blockID, 0, 2);
        world.setBlock(i + 4, j + 16, k + 7, MTJT.rubberLeaves.blockID, 0, 2);
        world.setBlock(i + 5, j + 16, k + 15, MTJT.rubberLeaves.blockID, 0, 2);
        world.setBlock(i + 5, j + 16, k + 11, MTJT.rubberLeaves.blockID, 0, 2);
        world.setBlock(i + 5, j + 16, k + 8, MTJT.rubberLeaves.blockID, 0, 2);
        world.setBlock(i + 5, j + 16, k + 6, MTJT.rubberLeaves.blockID, 0, 2);
        world.setBlock(i + 6, j + 16, k + 8, MTJT.rubberLeaves.blockID, 0, 2);
        world.setBlock(i + 8, j + 16, k + 14, MTJT.rubberLeaves.blockID, 0, 2);
        world.setBlock(i + 8, j + 16, k + 12, MTJT.rubberLeaves.blockID, 0, 2);
        world.setBlock(i + 8, j + 16, k + 3, MTJT.rubberLeaves.blockID, 0, 2);
        world.setBlock(i + 9, j + 16, k + 18, MTJT.rubberLeaves.blockID, 0, 2);
        world.setBlock(i + 9, j + 16, k + 13, MTJT.rubberLog.blockID, 0, 2);
        world.setBlock(i + 9, j + 16, k + 12, MTJT.rubberLeaves.blockID, 0, 2);
        world.setBlock(i + 10, j + 16, k + 17, MTJT.rubberLeaves.blockID, 0, 2);
        world.setBlock(i + 10, j + 16, k + 10, MTJT.rubberLeaves.blockID, 0, 2);
        world.setBlock(i + 11, j + 16, k + 18, MTJT.rubberLeaves.blockID, 0, 2);
        world.setBlock(i + 11, j + 16, k + 14, MTJT.rubberLog.blockID, 0, 2);
        world.setBlock(i + 11, j + 16, k + 12, MTJT.rubberLeaves.blockID, 0, 2);
        world.setBlock(i + 12, j + 16, k + 18, MTJT.rubberLeaves.blockID, 0, 2);
        world.setBlock(i + 12, j + 16, k + 15, MTJT.rubberLeaves.blockID, 0, 2);
        world.setBlock(i + 12, j + 16, k + 9, MTJT.rubberLog.blockID, 0, 2);
        world.setBlock(i + 12, j + 16, k + 5, MTJT.rubberLeaves.blockID, 0, 2);
        world.setBlock(i + 12, j + 16, k + 3, MTJT.rubberLeaves.blockID, 0, 2);
        world.setBlock(i + 13, j + 16, k + 15, MTJT.rubberLeaves.blockID, 0, 2);
        world.setBlock(i + 13, j + 16, k + 8, MTJT.rubberLeaves.blockID, 0, 2);
        world.setBlock(i + 14, j + 16, k + 18, MTJT.rubberLeaves.blockID, 0, 2);
        world.setBlock(i + 14, j + 16, k + 17, MTJT.rubberLeaves.blockID, 0, 2);
        world.setBlock(i + 14, j + 16, k + 10, MTJT.rubberLeaves.blockID, 0, 2);
        world.setBlock(i + 14, j + 16, k + 6, MTJT.rubberLeaves.blockID, 0, 2);
        world.setBlock(i + 15, j + 16, k + 16, MTJT.rubberLeaves.blockID, 0, 2);
        world.setBlock(i + 15, j + 16, k + 15, MTJT.rubberLeaves.blockID, 0, 2);
        world.setBlock(i + 15, j + 16, k + 11, MTJT.rubberLeaves.blockID, 0, 2);
        world.setBlock(i + 15, j + 16, k + 8, MTJT.rubberLeaves.blockID, 0, 2);
        world.setBlock(i + 16, j + 16, k + 17, MTJT.rubberLeaves.blockID, 0, 2);
        world.setBlock(i + 16, j + 16, k + 11, MTJT.rubberLeaves.blockID, 0, 2);
        world.setBlock(i + 16, j + 16, k + 8, MTJT.rubberLeaves.blockID, 0, 2);
        world.setBlock(i + 16, j + 16, k + 7, MTJT.rubberLeaves.blockID, 0, 2);
        world.setBlock(i + 17, j + 16, k + 11, MTJT.rubberLeaves.blockID, 0, 2);
        world.setBlock(i + 17, j + 16, k + 8, MTJT.rubberLeaves.blockID, 0, 2);
        world.setBlock(i + 18, j + 16, k + 9, MTJT.rubberLeaves.blockID, 0, 2);
        world.setBlock(i + 18, j + 16, k + 8, MTJT.rubberLeaves.blockID, 0, 2);
        world.setBlock(i + 19, j + 16, k + 9, MTJT.rubberLeaves.blockID, 0, 2);
        world.setBlock(i + 3, j + 17, k + 17, MTJT.rubberLeaves.blockID, 0, 2);
        world.setBlock(i + 4, j + 17, k + 15, MTJT.rubberLeaves.blockID, 0, 2);
        world.setBlock(i + 5, j + 17, k + 14, MTJT.rubberLeaves.blockID, 0, 2);
        world.setBlock(i + 6, j + 17, k + 13, MTJT.rubberLeaves.blockID, 0, 2);
        world.setBlock(i + 6, j + 17, k + 12, MTJT.rubberLeaves.blockID, 0, 2);
        world.setBlock(i + 7, j + 17, k + 17, MTJT.rubberLeaves.blockID, 0, 2);
        world.setBlock(i + 7, j + 17, k + 14, MTJT.rubberLeaves.blockID, 0, 2);
        world.setBlock(i + 8, j + 17, k + 15, MTJT.rubberLeaves.blockID, 0, 2);
        world.setBlock(i + 8, j + 17, k + 14, MTJT.rubberLeaves.blockID, 0, 2);
        world.setBlock(i + 8, j + 17, k + 10, MTJT.rubberLeaves.blockID, 0, 2);
        world.setBlock(i + 8, j + 17, k + 9, MTJT.rubberLeaves.blockID, 0, 2);
        world.setBlock(i + 9, j + 17, k + 13, MTJT.rubberLog.blockID, 0, 2);
        world.setBlock(i + 9, j + 17, k + 11, MTJT.rubberLeaves.blockID, 0, 2);
        world.setBlock(i + 9, j + 17, k + 8, MTJT.rubberLeaves.blockID, 0, 2);
        world.setBlock(i + 10, j + 17, k + 13, MTJT.rubberLeaves.blockID, 0, 2);
        world.setBlock(i + 10, j + 17, k + 12, MTJT.rubberLeaves.blockID, 0, 2);
        world.setBlock(i + 10, j + 17, k + 2, MTJT.rubberLeaves.blockID, 0, 2);
        world.setBlock(i + 11, j + 17, k + 15, MTJT.rubberLeaves.blockID, 0, 2);
        world.setBlock(i + 11, j + 17, k + 14, MTJT.rubberLeaves.blockID, 0, 2);
        world.setBlock(i + 11, j + 17, k + 11, MTJT.rubberLeaves.blockID, 0, 2);
        world.setBlock(i + 11, j + 17, k + 9, MTJT.rubberLeaves.blockID, 0, 2);
        world.setBlock(i + 12, j + 17, k + 15, MTJT.rubberLog.blockID, 0, 2);
        world.setBlock(i + 12, j + 17, k + 14, MTJT.rubberLeaves.blockID, 0, 2);
        world.setBlock(i + 12, j + 17, k + 9, MTJT.rubberLog.blockID, 0, 2);
        world.setBlock(i + 13, j + 17, k + 17, MTJT.rubberLeaves.blockID, 0, 2);
        world.setBlock(i + 13, j + 17, k + 15, MTJT.rubberLeaves.blockID, 0, 2);
        world.setBlock(i + 13, j + 17, k + 12, MTJT.rubberLeaves.blockID, 0, 2);
        world.setBlock(i + 14, j + 17, k + 11, MTJT.rubberLeaves.blockID, 0, 2);
        world.setBlock(i + 15, j + 17, k + 15, MTJT.rubberLeaves.blockID, 0, 2);
        world.setBlock(i + 15, j + 17, k + 7, MTJT.rubberLeaves.blockID, 0, 2);
        world.setBlock(i + 16, j + 17, k + 15, MTJT.rubberLeaves.blockID, 0, 2);
        world.setBlock(i + 16, j + 17, k + 8, MTJT.rubberLeaves.blockID, 0, 2);
        world.setBlock(i + 17, j + 17, k + 8, MTJT.rubberLeaves.blockID, 0, 2);
        world.setBlock(i + 18, j + 17, k + 16, MTJT.rubberLeaves.blockID, 0, 2);
        world.setBlock(i + 5, j + 18, k + 13, MTJT.rubberLeaves.blockID, 0, 2);
        world.setBlock(i + 6, j + 18, k + 16, MTJT.rubberLeaves.blockID, 0, 2);
        world.setBlock(i + 7, j + 18, k + 8, MTJT.rubberLeaves.blockID, 0, 2);
        world.setBlock(i + 8, j + 18, k + 15, MTJT.rubberLeaves.blockID, 0, 2);
        world.setBlock(i + 8, j + 18, k + 10, MTJT.rubberLeaves.blockID, 0, 2);
        world.setBlock(i + 9, j + 18, k + 17, MTJT.rubberLeaves.blockID, 0, 2);
        world.setBlock(i + 9, j + 18, k + 16, MTJT.rubberLeaves.blockID, 0, 2);
        world.setBlock(i + 9, j + 18, k + 15, MTJT.rubberLeaves.blockID, 0, 2);
        world.setBlock(i + 10, j + 18, k + 14, MTJT.rubberLeaves.blockID, 0, 2);
        world.setBlock(i + 10, j + 18, k + 10, MTJT.rubberLeaves.blockID, 0, 2);
        world.setBlock(i + 11, j + 18, k + 12, MTJT.rubberLeaves.blockID, 0, 2);
        world.setBlock(i + 11, j + 18, k + 7, MTJT.rubberLeaves.blockID, 0, 2);
        world.setBlock(i + 12, j + 18, k + 12, MTJT.rubberLeaves.blockID, 0, 2);
        world.setBlock(i + 12, j + 18, k + 10, MTJT.rubberLog.blockID, 0, 2);
        world.setBlock(i + 12, j + 18, k + 8, MTJT.rubberLeaves.blockID, 0, 2);
        world.setBlock(i + 13, j + 18, k + 19, MTJT.rubberLeaves.blockID, 0, 2);
        world.setBlock(i + 13, j + 18, k + 8, MTJT.rubberLog.blockID, 0, 2);
        world.setBlock(i + 13, j + 18, k + 4, MTJT.rubberLeaves.blockID, 0, 2);
        world.setBlock(i + 13, j + 18, k + 1, MTJT.rubberLeaves.blockID, 0, 2);
        world.setBlock(i + 14, j + 18, k + 13, MTJT.rubberLeaves.blockID, 0, 2);
        world.setBlock(i + 14, j + 18, k + 9, MTJT.rubberLeaves.blockID, 0, 2);
        world.setBlock(i + 15, j + 18, k + 14, MTJT.rubberLeaves.blockID, 0, 2);
        world.setBlock(i + 15, j + 18, k + 5, MTJT.rubberLeaves.blockID, 0, 2);
        world.setBlock(i + 17, j + 18, k + 15, MTJT.rubberLeaves.blockID, 0, 2);
        world.setBlock(i + 8, j + 19, k + 15, MTJT.rubberLeaves.blockID, 0, 2);
        world.setBlock(i + 9, j + 19, k + 16, MTJT.rubberLeaves.blockID, 0, 2);
        world.setBlock(i + 9, j + 19, k + 14, MTJT.rubberLeaves.blockID, 0, 2);
        world.setBlock(i + 9, j + 19, k + 9, MTJT.rubberLeaves.blockID, 0, 2);
        world.setBlock(i + 10, j + 19, k + 13, MTJT.rubberLeaves.blockID, 0, 2);
        world.setBlock(i + 10, j + 19, k + 7, MTJT.rubberLeaves.blockID, 0, 2);
        world.setBlock(i + 10, j + 19, k + 6, MTJT.rubberLeaves.blockID, 0, 2);
        world.setBlock(i + 11, j + 19, k + 13, MTJT.rubberLeaves.blockID, 0, 2);
        world.setBlock(i + 11, j + 19, k + 12, MTJT.rubberLeaves.blockID, 0, 2);
        world.setBlock(i + 11, j + 19, k + 10, MTJT.rubberLeaves.blockID, 0, 2);
        world.setBlock(i + 12, j + 19, k + 18, MTJT.rubberLeaves.blockID, 0, 2);
        world.setBlock(i + 12, j + 19, k + 17, MTJT.rubberLeaves.blockID, 0, 2);
        world.setBlock(i + 12, j + 19, k + 15, MTJT.rubberLeaves.blockID, 0, 2);
        world.setBlock(i + 12, j + 19, k + 13, MTJT.rubberLeaves.blockID, 0, 2);
        world.setBlock(i + 12, j + 19, k + 12, MTJT.rubberLeaves.blockID, 0, 2);
        world.setBlock(i + 12, j + 19, k + 10, MTJT.rubberLog.blockID, 0, 2);
        world.setBlock(i + 12, j + 19, k + 5, MTJT.rubberLeaves.blockID, 0, 2);
        world.setBlock(i + 12, j + 19, k + 4, MTJT.rubberLeaves.blockID, 0, 2);
        world.setBlock(i + 13, j + 19, k + 15, MTJT.rubberLeaves.blockID, 0, 2);
        world.setBlock(i + 13, j + 19, k + 14, MTJT.rubberLeaves.blockID, 0, 2);
        world.setBlock(i + 13, j + 19, k + 8, MTJT.rubberLeaves.blockID, 0, 2);
        world.setBlock(i + 13, j + 19, k + 4, MTJT.rubberLeaves.blockID, 0, 2);
        world.setBlock(i + 14, j + 19, k + 8, MTJT.rubberLog.blockID, 0, 2);
        world.setBlock(i + 15, j + 19, k + 9, MTJT.rubberLeaves.blockID, 0, 2);
        world.setBlock(i + 16, j + 19, k + 12, MTJT.rubberLeaves.blockID, 0, 2);
        world.setBlock(i + 16, j + 19, k + 8, MTJT.rubberLeaves.blockID, 0, 2);
        world.setBlock(i + 18, j + 19, k + 9, MTJT.rubberLeaves.blockID, 0, 2);
        world.setBlock(i + 7, j + 20, k + 10, MTJT.rubberLeaves.blockID, 0, 2);
        world.setBlock(i + 8, j + 20, k + 10, MTJT.rubberLeaves.blockID, 0, 2);
        world.setBlock(i + 9, j + 20, k + 14, MTJT.rubberLeaves.blockID, 0, 2);
        world.setBlock(i + 11, j + 20, k + 16, MTJT.rubberLeaves.blockID, 0, 2);
        world.setBlock(i + 11, j + 20, k + 10, MTJT.rubberLog.blockID, 0, 2);
        world.setBlock(i + 11, j + 20, k + 9, MTJT.rubberLeaves.blockID, 0, 2);
        world.setBlock(i + 11, j + 20, k + 6, MTJT.rubberLeaves.blockID, 0, 2);
        world.setBlock(i + 12, j + 20, k + 16, MTJT.rubberLeaves.blockID, 0, 2);
        world.setBlock(i + 14, j + 20, k + 12, MTJT.rubberLeaves.blockID, 0, 2);
        world.setBlock(i + 14, j + 20, k + 10, MTJT.rubberLeaves.blockID, 0, 2);
        world.setBlock(i + 14, j + 20, k + 8, MTJT.rubberLeaves.blockID, 0, 2);
        world.setBlock(i + 14, j + 20, k + 7, MTJT.rubberLeaves.blockID, 0, 2);
        world.setBlock(i + 17, j + 20, k + 9, MTJT.rubberLeaves.blockID, 0, 2);
        world.setBlock(i + 10, j + 21, k + 15, MTJT.rubberLeaves.blockID, 0, 2);
        world.setBlock(i + 10, j + 21, k + 7, MTJT.rubberLeaves.blockID, 0, 2);
        world.setBlock(i + 11, j + 21, k + 10, MTJT.rubberLeaves.blockID, 0, 2);
        world.setBlock(i + 12, j + 21, k + 14, MTJT.rubberLeaves.blockID, 0, 2);
        world.setBlock(i + 13, j + 21, k + 6, MTJT.rubberLeaves.blockID, 0, 2);
        world.setBlock(i + 14, j + 21, k + 13, MTJT.rubberLeaves.blockID, 0, 2);
        world.setBlock(i + 14, j + 21, k + 6, MTJT.rubberLeaves.blockID, 0, 2);
        world.setBlock(i + 13, j + 22, k + 10, MTJT.rubberLeaves.blockID, 0, 2);
        world.setBlock(i + 14, j + 22, k + 9, MTJT.rubberLeaves.blockID, 0, 2);
        world.setBlock(i + 17, j + 22, k + 7, MTJT.rubberLeaves.blockID, 0, 2);
        world.setBlock(i + 11, j + 23, k + 12, MTJT.rubberLeaves.blockID, 0, 2);
        world.setBlock(i + 11, j + 23, k + 9, MTJT.rubberLeaves.blockID, 0, 2);
        world.setBlock(i + 12, j + 23, k + 11, MTJT.rubberLeaves.blockID, 0, 2);
        world.setBlock(i + 12, j + 23, k + 9, MTJT.rubberLeaves.blockID, 0, 2);
        world.setBlock(i + 9, j + 24, k + 10, MTJT.rubberLeaves.blockID, 0, 2);
        world.setBlock(i + 12, j + 24, k + 11, MTJT.rubberLeaves.blockID, 0, 2);
        
        return true;
    }
}
