package morethantrees.treegen;

import java.util.Random;

import net.minecraft.block.Block;
import net.minecraft.world.World;
import net.minecraft.world.gen.feature.WorldGenerator;

public class WorldGenNorwaySpruceLargeTree extends WorldGenerator
{
	public boolean generate(World world, Random var2, int i, int j, int k)
	  {
	    while ((world.isAirBlock(i + 10, j, k + 12)) && (j > 2))
	    {
	      j--;
	    }

	    int var6 = world.getBlockId(i + 10, j, k + 12);

	    if (var6 != Block.grass.blockID)
	    {
	      return false;
	    }

	    for (int var7 = -2; var7 <= 2; var7++)
	    {
	      for (int var8 = -2; var8 <= 2; var8++)
	      {
	        if ((world.isAirBlock(i + var7 + 10, j - 1, k + var8 + 12)) && (world.isAirBlock(i + var7 + 10, j - 2, k + var8 + 12)))
	        {
	          return false;
	        }
	      }
	    }  	
    	world.setBlock(i + 8, j + 0, k + 6, 17, 1, 2);
        world.setBlock(i + 3, j + 1, k + 7, 18, 1, 2);
        world.setBlock(i + 3, j + 1, k + 6, 18, 1, 2);
        world.setBlock(i + 4, j + 1, k + 6, 18, 1, 2);
        world.setBlock(i + 5, j + 1, k + 10, 18, 1, 2);
        world.setBlock(i + 5, j + 1, k + 2, 18, 1, 2);
        world.setBlock(i + 6, j + 1, k + 9, 18, 1, 2);
        world.setBlock(i + 6, j + 1, k + 8, 18, 1, 2);
        world.setBlock(i + 6, j + 1, k + 7, 18, 1, 2);
        world.setBlock(i + 6, j + 1, k + 6, 18, 1, 2);
        world.setBlock(i + 6, j + 1, k + 2, 18, 1, 2);
        world.setBlock(i + 7, j + 1, k + 9, 18, 1, 2);
        world.setBlock(i + 7, j + 1, k + 4, 18, 1, 2);
        world.setBlock(i + 7, j + 1, k + 3, 18, 1, 2);
        world.setBlock(i + 7, j + 1, k + 1, 18, 1, 2);
        world.setBlock(i + 8, j + 1, k + 11, 18, 1, 2);
        world.setBlock(i + 8, j + 1, k + 10, 18, 1, 2);
        world.setBlock(i + 8, j + 1, k + 6, 17, 1, 2);
        world.setBlock(i + 8, j + 1, k + 5, 18, 1, 2);
        world.setBlock(i + 8, j + 1, k + 4, 18, 1, 2);
        world.setBlock(i + 8, j + 1, k + 3, 18, 1, 2);
        world.setBlock(i + 8, j + 1, k + 2, 18, 1, 2);
        world.setBlock(i + 8, j + 1, k + 1, 18, 1, 2);
        world.setBlock(i + 9, j + 1, k + 8, 18, 1, 2);
        world.setBlock(i + 9, j + 1, k + 6, 18, 1, 2);
        world.setBlock(i + 9, j + 1, k + 3, 18, 1, 2);
        world.setBlock(i + 9, j + 1, k + 2, 18, 1, 2);
        world.setBlock(i + 10, j + 1, k + 11, 18, 1, 2);
        world.setBlock(i + 10, j + 1, k + 10, 18, 1, 2);
        world.setBlock(i + 11, j + 1, k + 9, 18, 1, 2);
        world.setBlock(i + 13, j + 1, k + 7, 18, 1, 2);
        world.setBlock(i + 13, j + 1, k + 6, 18, 1, 2);
        world.setBlock(i + 3, j + 2, k + 6, 18, 1, 2);
        world.setBlock(i + 3, j + 2, k + 5, 18, 1, 2);
        world.setBlock(i + 4, j + 2, k + 8, 18, 1, 2);
        world.setBlock(i + 4, j + 2, k + 6, 18, 1, 2);
        world.setBlock(i + 5, j + 2, k + 10, 18, 1, 2);
        world.setBlock(i + 5, j + 2, k + 8, 18, 1, 2);
        world.setBlock(i + 5, j + 2, k + 4, 18, 1, 2);
        world.setBlock(i + 6, j + 2, k + 9, 18, 1, 2);
        world.setBlock(i + 6, j + 2, k + 6, 18, 1, 2);
        world.setBlock(i + 6, j + 2, k + 2, 18, 1, 2);
        world.setBlock(i + 6, j + 2, k + 1, 18, 1, 2);
        world.setBlock(i + 7, j + 2, k + 11, 18, 1, 2);
        world.setBlock(i + 7, j + 2, k + 10, 18, 1, 2);
        world.setBlock(i + 7, j + 2, k + 8, 18, 1, 2);
        world.setBlock(i + 7, j + 2, k + 1, 18, 1, 2);
        world.setBlock(i + 8, j + 2, k + 11, 18, 1, 2);
        world.setBlock(i + 8, j + 2, k + 9, 18, 1, 2);
        world.setBlock(i + 8, j + 2, k + 8, 18, 1, 2);
        world.setBlock(i + 8, j + 2, k + 6, 17, 1, 2);
        world.setBlock(i + 8, j + 2, k + 4, 18, 1, 2);
        world.setBlock(i + 9, j + 2, k + 10, 18, 1, 2);
        world.setBlock(i + 9, j + 2, k + 9, 18, 1, 2);
        world.setBlock(i + 11, j + 2, k + 8, 18, 1, 2);
        world.setBlock(i + 11, j + 2, k + 5, 18, 1, 2);
        world.setBlock(i + 11, j + 2, k + 2, 18, 1, 2);
        world.setBlock(i + 12, j + 2, k + 9, 18, 1, 2);
        world.setBlock(i + 12, j + 2, k + 6, 18, 1, 2);
        world.setBlock(i + 12, j + 2, k + 3, 18, 1, 2);
        world.setBlock(i + 13, j + 2, k + 8, 18, 1, 2);
        world.setBlock(i + 4, j + 3, k + 7, 18, 1, 2);
        world.setBlock(i + 4, j + 3, k + 6, 18, 1, 2);
        world.setBlock(i + 4, j + 3, k + 4, 18, 1, 2);
        world.setBlock(i + 5, j + 3, k + 8, 18, 1, 2);
        world.setBlock(i + 6, j + 3, k + 7, 18, 1, 2);
        world.setBlock(i + 8, j + 3, k + 7, 18, 1, 2);
        world.setBlock(i + 8, j + 3, k + 6, 17, 1, 2);
        world.setBlock(i + 8, j + 3, k + 5, 18, 1, 2);
        world.setBlock(i + 8, j + 3, k + 4, 18, 1, 2);
        world.setBlock(i + 8, j + 3, k + 2, 18, 1, 2);
        world.setBlock(i + 9, j + 3, k + 7, 18, 1, 2);
        world.setBlock(i + 9, j + 3, k + 5, 18, 1, 2);
        world.setBlock(i + 9, j + 3, k + 2, 18, 1, 2);
        world.setBlock(i + 10, j + 3, k + 6, 18, 1, 2);
        world.setBlock(i + 10, j + 3, k + 4, 18, 1, 2);
        world.setBlock(i + 11, j + 3, k + 7, 18, 1, 2);
        world.setBlock(i + 12, j + 3, k + 5, 18, 1, 2);
        world.setBlock(i + 4, j + 4, k + 4, 18, 1, 2);
        world.setBlock(i + 5, j + 4, k + 9, 18, 1, 2);
        world.setBlock(i + 5, j + 4, k + 7, 18, 1, 2);
        world.setBlock(i + 5, j + 4, k + 6, 18, 1, 2);
        world.setBlock(i + 6, j + 4, k + 8, 18, 1, 2);
        world.setBlock(i + 7, j + 4, k + 4, 18, 1, 2);
        world.setBlock(i + 7, j + 4, k + 2, 18, 1, 2);
        world.setBlock(i + 8, j + 4, k + 8, 18, 1, 2);
        world.setBlock(i + 8, j + 4, k + 6, 17, 1, 2);
        world.setBlock(i + 8, j + 4, k + 5, 18, 1, 2);
        world.setBlock(i + 8, j + 4, k + 3, 18, 1, 2);
        world.setBlock(i + 9, j + 4, k + 6, 18, 1, 2);
        world.setBlock(i + 9, j + 4, k + 2, 18, 1, 2);
        world.setBlock(i + 10, j + 4, k + 10, 18, 1, 2);
        world.setBlock(i + 10, j + 4, k + 5, 18, 1, 2);
        world.setBlock(i + 10, j + 4, k + 3, 18, 1, 2);
        world.setBlock(i + 10, j + 4, k + 2, 18, 1, 2);
        world.setBlock(i + 11, j + 4, k + 6, 18, 1, 2);
        world.setBlock(i + 11, j + 4, k + 3, 18, 1, 2);
        world.setBlock(i + 12, j + 4, k + 8, 18, 1, 2);
        world.setBlock(i + 12, j + 4, k + 6, 18, 1, 2);
        world.setBlock(i + 4, j + 5, k + 8, 18, 1, 2);
        world.setBlock(i + 4, j + 5, k + 7, 18, 1, 2);
        world.setBlock(i + 4, j + 5, k + 6, 18, 1, 2);
        world.setBlock(i + 5, j + 5, k + 9, 18, 1, 2);
        world.setBlock(i + 6, j + 5, k + 8, 18, 1, 2);
        world.setBlock(i + 6, j + 5, k + 7, 18, 1, 2);
        world.setBlock(i + 7, j + 5, k + 8, 18, 1, 2);
        world.setBlock(i + 7, j + 5, k + 4, 18, 1, 2);
        world.setBlock(i + 7, j + 5, k + 3, 18, 1, 2);
        world.setBlock(i + 8, j + 5, k + 8, 18, 1, 2);
        world.setBlock(i + 8, j + 5, k + 7, 18, 1, 2);
        world.setBlock(i + 8, j + 5, k + 6, 17, 1, 2);
        world.setBlock(i + 8, j + 5, k + 5, 18, 1, 2);
        world.setBlock(i + 8, j + 5, k + 2, 18, 1, 2);
        world.setBlock(i + 9, j + 5, k + 9, 18, 1, 2);
        world.setBlock(i + 10, j + 5, k + 10, 18, 1, 2);
        world.setBlock(i + 10, j + 5, k + 9, 18, 1, 2);
        world.setBlock(i + 10, j + 5, k + 3, 18, 1, 2);
        world.setBlock(i + 11, j + 5, k + 6, 18, 1, 2);
        world.setBlock(i + 11, j + 5, k + 5, 18, 1, 2);
        world.setBlock(i + 12, j + 5, k + 7, 18, 1, 2);
        world.setBlock(i + 4, j + 6, k + 4, 18, 1, 2);
        world.setBlock(i + 5, j + 6, k + 6, 18, 1, 2);
        world.setBlock(i + 5, j + 6, k + 5, 18, 1, 2);
        world.setBlock(i + 5, j + 6, k + 4, 18, 1, 2);
        world.setBlock(i + 7, j + 6, k + 9, 18, 1, 2);
        world.setBlock(i + 7, j + 6, k + 7, 18, 1, 2);
        world.setBlock(i + 7, j + 6, k + 3, 18, 1, 2);
        world.setBlock(i + 8, j + 6, k + 10, 18, 1, 2);
        world.setBlock(i + 8, j + 6, k + 9, 18, 1, 2);
        world.setBlock(i + 8, j + 6, k + 8, 18, 1, 2);
        world.setBlock(i + 8, j + 6, k + 7, 18, 1, 2);
        world.setBlock(i + 8, j + 6, k + 6, 17, 1, 2);
        world.setBlock(i + 8, j + 6, k + 2, 18, 1, 2);
        world.setBlock(i + 9, j + 6, k + 6, 18, 1, 2);
        world.setBlock(i + 9, j + 6, k + 5, 18, 1, 2);
        world.setBlock(i + 10, j + 6, k + 9, 18, 1, 2);
        world.setBlock(i + 10, j + 6, k + 8, 18, 1, 2);
        world.setBlock(i + 10, j + 6, k + 3, 18, 1, 2);
        world.setBlock(i + 11, j + 6, k + 9, 18, 1, 2);
        world.setBlock(i + 11, j + 6, k + 4, 18, 1, 2);
        world.setBlock(i + 12, j + 6, k + 8, 18, 1, 2);
        world.setBlock(i + 12, j + 6, k + 6, 18, 1, 2);
        world.setBlock(i + 6, j + 7, k + 8, 18, 1, 2);
        world.setBlock(i + 6, j + 7, k + 4, 18, 1, 2);
        world.setBlock(i + 8, j + 7, k + 9, 18, 1, 2);
        world.setBlock(i + 8, j + 7, k + 7, 18, 1, 2);
        world.setBlock(i + 8, j + 7, k + 6, 17, 1, 2);
        world.setBlock(i + 8, j + 7, k + 5, 18, 1, 2);
        world.setBlock(i + 8, j + 7, k + 4, 18, 1, 2);
        world.setBlock(i + 8, j + 7, k + 3, 18, 1, 2);
        world.setBlock(i + 10, j + 7, k + 5, 18, 1, 2);
        world.setBlock(i + 10, j + 7, k + 4, 18, 1, 2);
        world.setBlock(i + 11, j + 7, k + 6, 18, 1, 2);
        world.setBlock(i + 11, j + 7, k + 5, 18, 1, 2);
        world.setBlock(i + 5, j + 8, k + 7, 18, 1, 2);
        world.setBlock(i + 6, j + 8, k + 6, 18, 1, 2);
        world.setBlock(i + 7, j + 8, k + 9, 18, 1, 2);
        world.setBlock(i + 7, j + 8, k + 6, 18, 1, 2);
        world.setBlock(i + 8, j + 8, k + 9, 18, 1, 2);
        world.setBlock(i + 8, j + 8, k + 7, 18, 1, 2);
        world.setBlock(i + 8, j + 8, k + 6, 17, 1, 2);
        world.setBlock(i + 8, j + 8, k + 5, 18, 1, 2);
        world.setBlock(i + 8, j + 8, k + 4, 18, 1, 2);
        world.setBlock(i + 9, j + 8, k + 8, 18, 1, 2);
        world.setBlock(i + 9, j + 8, k + 7, 18, 1, 2);
        world.setBlock(i + 9, j + 8, k + 4, 18, 1, 2);
        world.setBlock(i + 9, j + 8, k + 3, 18, 1, 2);
        world.setBlock(i + 10, j + 8, k + 4, 18, 1, 2);
        world.setBlock(i + 11, j + 8, k + 7, 18, 1, 2);
        world.setBlock(i + 5, j + 9, k + 7, 18, 1, 2);
        world.setBlock(i + 6, j + 9, k + 7, 18, 1, 2);
        world.setBlock(i + 7, j + 9, k + 8, 18, 1, 2);
        world.setBlock(i + 7, j + 9, k + 7, 18, 1, 2);
        world.setBlock(i + 7, j + 9, k + 6, 18, 1, 2);
        world.setBlock(i + 7, j + 9, k + 3, 18, 1, 2);
        world.setBlock(i + 8, j + 9, k + 8, 18, 1, 2);
        world.setBlock(i + 8, j + 9, k + 6, 17, 1, 2);
        world.setBlock(i + 11, j + 9, k + 6, 18, 1, 2);
        world.setBlock(i + 5, j + 10, k + 6, 18, 1, 2);
        world.setBlock(i + 5, j + 10, k + 5, 18, 1, 2);
        world.setBlock(i + 7, j + 10, k + 9, 18, 1, 2);
        world.setBlock(i + 7, j + 10, k + 3, 18, 1, 2);
        world.setBlock(i + 8, j + 10, k + 9, 18, 1, 2);
        world.setBlock(i + 8, j + 10, k + 6, 17, 1, 2);
        world.setBlock(i + 8, j + 10, k + 4, 18, 1, 2);
        world.setBlock(i + 10, j + 10, k + 8, 18, 1, 2);
        world.setBlock(i + 10, j + 10, k + 6, 18, 1, 2);
        world.setBlock(i + 11, j + 10, k + 6, 18, 1, 2);
        world.setBlock(i + 11, j + 10, k + 5, 18, 1, 2);
        world.setBlock(i + 5, j + 11, k + 5, 18, 1, 2);
        world.setBlock(i + 7, j + 11, k + 7, 18, 1, 2);
        world.setBlock(i + 7, j + 11, k + 6, 18, 1, 2);
        world.setBlock(i + 7, j + 11, k + 3, 18, 1, 2);
        world.setBlock(i + 8, j + 11, k + 9, 18, 1, 2);
        world.setBlock(i + 8, j + 11, k + 8, 18, 1, 2);
        world.setBlock(i + 8, j + 11, k + 7, 18, 1, 2);
        world.setBlock(i + 8, j + 11, k + 6, 17, 1, 2);
        world.setBlock(i + 8, j + 11, k + 5, 18, 1, 2);
        world.setBlock(i + 8, j + 11, k + 4, 18, 1, 2);
        world.setBlock(i + 9, j + 11, k + 8, 18, 1, 2);
        world.setBlock(i + 9, j + 11, k + 7, 18, 1, 2);
        world.setBlock(i + 10, j + 11, k + 8, 18, 1, 2);
        world.setBlock(i + 10, j + 11, k + 6, 18, 1, 2);
        world.setBlock(i + 11, j + 11, k + 6, 18, 1, 2);
        world.setBlock(i + 5, j + 12, k + 7, 18, 1, 2);
        world.setBlock(i + 6, j + 12, k + 5, 18, 1, 2);
        world.setBlock(i + 7, j + 12, k + 7, 18, 1, 2);
        world.setBlock(i + 7, j + 12, k + 4, 18, 1, 2);
        world.setBlock(i + 8, j + 12, k + 9, 18, 1, 2);
        world.setBlock(i + 8, j + 12, k + 8, 18, 1, 2);
        world.setBlock(i + 8, j + 12, k + 6, 17, 1, 2);
        world.setBlock(i + 8, j + 12, k + 5, 18, 1, 2);
        world.setBlock(i + 8, j + 12, k + 3, 18, 1, 2);
        world.setBlock(i + 9, j + 12, k + 6, 18, 1, 2);
        world.setBlock(i + 9, j + 12, k + 4, 18, 1, 2);
        world.setBlock(i + 11, j + 12, k + 5, 18, 1, 2);
        world.setBlock(i + 6, j + 13, k + 6, 18, 1, 2);
        world.setBlock(i + 7, j + 13, k + 6, 18, 1, 2);
        world.setBlock(i + 7, j + 13, k + 4, 18, 1, 2);
        world.setBlock(i + 8, j + 13, k + 8, 18, 1, 2);
        world.setBlock(i + 8, j + 13, k + 7, 18, 1, 2);
        world.setBlock(i + 8, j + 13, k + 6, 17, 1, 2);
        world.setBlock(i + 8, j + 13, k + 4, 18, 1, 2);
        world.setBlock(i + 9, j + 13, k + 7, 18, 1, 2);
        world.setBlock(i + 7, j + 14, k + 5, 18, 1, 2);
        world.setBlock(i + 8, j + 14, k + 7, 18, 1, 2);
        world.setBlock(i + 8, j + 14, k + 6, 17, 1, 2);
        world.setBlock(i + 8, j + 14, k + 5, 18, 1, 2);
        world.setBlock(i + 6, j + 15, k + 7, 18, 1, 2);
        world.setBlock(i + 6, j + 15, k + 5, 18, 1, 2);
        world.setBlock(i + 7, j + 15, k + 7, 18, 1, 2);
        world.setBlock(i + 8, j + 15, k + 7, 18, 1, 2);
        world.setBlock(i + 8, j + 15, k + 6, 17, 1, 2);
        world.setBlock(i + 8, j + 15, k + 5, 18, 1, 2);
        world.setBlock(i + 8, j + 15, k + 4, 18, 1, 2);
        world.setBlock(i + 9, j + 15, k + 6, 18, 1, 2);
        world.setBlock(i + 9, j + 15, k + 5, 18, 1, 2);
        world.setBlock(i + 7, j + 16, k + 5, 18, 1, 2);
        world.setBlock(i + 8, j + 16, k + 7, 18, 1, 2);
        world.setBlock(i + 8, j + 16, k + 6, 17, 1, 2);
        world.setBlock(i + 8, j + 16, k + 5, 18, 1, 2);
        world.setBlock(i + 9, j + 16, k + 8, 18, 1, 2);
        world.setBlock(i + 10, j + 16, k + 6, 18, 1, 2);
        world.setBlock(i + 7, j + 17, k + 6, 18, 1, 2);
        world.setBlock(i + 8, j + 17, k + 6, 17, 1, 2);
        world.setBlock(i + 8, j + 17, k + 5, 18, 1, 2);
        world.setBlock(i + 9, j + 17, k + 6, 18, 1, 2);
        world.setBlock(i + 7, j + 18, k + 6, 18, 1, 2);
        world.setBlock(i + 8, j + 18, k + 6, 17, 1, 2);
        world.setBlock(i + 8, j + 18, k + 5, 18, 1, 2);
        world.setBlock(i + 9, j + 18, k + 7, 18, 1, 2);
        world.setBlock(i + 8, j + 19, k + 6, 18, 1, 2);

return true;
}
}
