package morethantrees.treegen;

import java.util.Random;

import net.minecraft.block.Block;
import net.minecraft.world.World;
import net.minecraft.world.gen.feature.WorldGenerator;

public class WorldGenJungleTrees extends WorldGenerator
{
    public boolean generate(World world, Random rand, int i, int j, int k)
    {
        while ((world.isAirBlock(i + 10, j, k + 12)) && (j > 2))
        {
            j--;
        }
        
        int var6 = world.getBlockId(i + 10, j, k + 12);
        
        if (var6 != Block.grass.blockID)
        {
            return false;
        }
        
        for (int var7 = -2; var7 <= 2; var7++)
        {
            for (int var8 = -2; var8 <= 2; var8++)
            {
                if ((world.isAirBlock(i + var7 + 10, j - 1, k + var8 + 12)) && (world.isAirBlock(i + var7 + 10, j - 2, k + var8 + 12)))
                {
                    return false;
                }
            }
        }
        world.setBlock(i + 7, j + 0, k + 8, 17, 3, 2);
        world.setBlock(i + 8, j + 0, k + 25, 17, 3, 2);
        world.setBlock(i + 8, j + 0, k + 24, 17, 3, 2);
        world.setBlock(i + 8, j + 0, k + 23, 17, 3, 2);
        world.setBlock(i + 8, j + 0, k + 22, 17, 3, 2);
        world.setBlock(i + 8, j + 0, k + 21, 17, 3, 2);
        world.setBlock(i + 8, j + 0, k + 9, 17, 3, 2);
        world.setBlock(i + 8, j + 0, k + 8, 17, 3, 2);
        world.setBlock(i + 9, j + 0, k + 24, 17, 3, 2);
        world.setBlock(i + 9, j + 0, k + 23, 17, 3, 2);
        world.setBlock(i + 9, j + 0, k + 22, 17, 3, 2);
        world.setBlock(i + 9, j + 0, k + 21, 17, 3, 2);
        world.setBlock(i + 9, j + 0, k + 12, 17, 3, 2);
        world.setBlock(i + 9, j + 0, k + 11, 17, 3, 2);
        world.setBlock(i + 9, j + 0, k + 10, 17, 3, 2);
        world.setBlock(i + 9, j + 0, k + 9, 17, 3, 2);
        world.setBlock(i + 10, j + 0, k + 21, 17, 3, 2);
        world.setBlock(i + 10, j + 0, k + 20, 17, 3, 2);
        world.setBlock(i + 10, j + 0, k + 19, 17, 3, 2);
        world.setBlock(i + 10, j + 0, k + 16, 17, 3, 2);
        world.setBlock(i + 10, j + 0, k + 15, 17, 3, 2);
        world.setBlock(i + 10, j + 0, k + 14, 17, 3, 2);
        world.setBlock(i + 10, j + 0, k + 13, 17, 3, 2);
        world.setBlock(i + 10, j + 0, k + 12, 17, 3, 2);
        world.setBlock(i + 10, j + 0, k + 11, 17, 3, 2);
        world.setBlock(i + 10, j + 0, k + 10, 17, 3, 2);
        world.setBlock(i + 11, j + 0, k + 21, 17, 3, 2);
        world.setBlock(i + 11, j + 0, k + 20, 17, 3, 2);
        world.setBlock(i + 11, j + 0, k + 19, 17, 3, 2);
        world.setBlock(i + 11, j + 0, k + 18, 17, 3, 2);
        world.setBlock(i + 11, j + 0, k + 17, 17, 3, 2);
        world.setBlock(i + 11, j + 0, k + 16, 17, 3, 2);
        world.setBlock(i + 11, j + 0, k + 15, 17, 3, 2);
        world.setBlock(i + 11, j + 0, k + 14, 17, 3, 2);
        world.setBlock(i + 11, j + 0, k + 13, 17, 3, 2);
        world.setBlock(i + 11, j + 0, k + 4, 17, 3, 2);
        world.setBlock(i + 11, j + 0, k + 3, 17, 3, 2);
        world.setBlock(i + 12, j + 0, k + 20, 17, 3, 2);
        world.setBlock(i + 12, j + 0, k + 19, 17, 3, 2);
        world.setBlock(i + 12, j + 0, k + 18, 17, 3, 2);
        world.setBlock(i + 12, j + 0, k + 14, 17, 3, 2);
        world.setBlock(i + 12, j + 0, k + 5, 17, 3, 2);
        world.setBlock(i + 12, j + 0, k + 4, 17, 3, 2);
        world.setBlock(i + 13, j + 0, k + 21, 17, 3, 2);
        world.setBlock(i + 13, j + 0, k + 20, 17, 3, 2);
        world.setBlock(i + 13, j + 0, k + 7, 17, 3, 2);
        world.setBlock(i + 13, j + 0, k + 6, 17, 3, 2);
        world.setBlock(i + 14, j + 0, k + 33, 17, 3, 2);
        world.setBlock(i + 14, j + 0, k + 32, 17, 3, 2);
        world.setBlock(i + 14, j + 0, k + 23, 17, 3, 2);
        world.setBlock(i + 14, j + 0, k + 22, 17, 3, 2);
        world.setBlock(i + 14, j + 0, k + 21, 17, 3, 2);
        world.setBlock(i + 14, j + 0, k + 12, 17, 3, 2);
        world.setBlock(i + 14, j + 0, k + 8, 17, 3, 2);
        world.setBlock(i + 14, j + 0, k + 7, 17, 3, 2);
        world.setBlock(i + 14, j + 0, k + 6, 17, 3, 2);
        world.setBlock(i + 15, j + 0, k + 32, 17, 3, 2);
        world.setBlock(i + 15, j + 0, k + 31, 17, 3, 2);
        world.setBlock(i + 15, j + 0, k + 30, 17, 3, 2);
        world.setBlock(i + 15, j + 0, k + 29, 17, 3, 2);
        world.setBlock(i + 15, j + 0, k + 28, 17, 3, 2);
        world.setBlock(i + 15, j + 0, k + 27, 17, 3, 2);
        world.setBlock(i + 15, j + 0, k + 26, 17, 3, 2);
        world.setBlock(i + 15, j + 0, k + 25, 17, 3, 2);
        world.setBlock(i + 15, j + 0, k + 24, 17, 3, 2);
        world.setBlock(i + 15, j + 0, k + 23, 17, 3, 2);
        world.setBlock(i + 15, j + 0, k + 22, 17, 3, 2);
        world.setBlock(i + 15, j + 0, k + 7, 17, 3, 2);
        world.setBlock(i + 15, j + 0, k + 6, 17, 3, 2);
        world.setBlock(i + 15, j + 0, k + 5, 17, 3, 2);
        world.setBlock(i + 15, j + 0, k + 4, 17, 3, 2);
        world.setBlock(i + 15, j + 0, k + 3, 17, 3, 2);
        world.setBlock(i + 15, j + 0, k + 2, 17, 3, 2);
        world.setBlock(i + 16, j + 0, k + 28, 17, 3, 2);
        world.setBlock(i + 16, j + 0, k + 27, 17, 3, 2);
        world.setBlock(i + 16, j + 0, k + 22, 17, 3, 2);
        world.setBlock(i + 16, j + 0, k + 18, 17, 3, 2);
        world.setBlock(i + 16, j + 0, k + 6, 17, 3, 2);
        world.setBlock(i + 16, j + 0, k + 5, 17, 3, 2);
        world.setBlock(i + 16, j + 0, k + 4, 17, 3, 2);
        world.setBlock(i + 17, j + 0, k + 29, 17, 3, 2);
        world.setBlock(i + 17, j + 0, k + 28, 17, 3, 2);
        world.setBlock(i + 17, j + 0, k + 27, 17, 3, 2);
        world.setBlock(i + 17, j + 0, k + 26, 17, 3, 2);
        world.setBlock(i + 17, j + 0, k + 25, 17, 3, 2);
        world.setBlock(i + 17, j + 0, k + 22, 17, 3, 2);
        world.setBlock(i + 17, j + 0, k + 6, 17, 3, 2);
        world.setBlock(i + 17, j + 0, k + 3, 17, 3, 2);
        world.setBlock(i + 17, j + 0, k + 2, 17, 3, 2);
        world.setBlock(i + 17, j + 0, k + 1, 17, 3, 2);
        world.setBlock(i + 18, j + 0, k + 31, 17, 3, 2);
        world.setBlock(i + 18, j + 0, k + 30, 17, 3, 2);
        world.setBlock(i + 18, j + 0, k + 29, 17, 3, 2);
        world.setBlock(i + 18, j + 0, k + 21, 17, 3, 2);
        world.setBlock(i + 18, j + 0, k + 7, 17, 3, 2);
        world.setBlock(i + 18, j + 0, k + 6, 17, 3, 2);
        world.setBlock(i + 18, j + 0, k + 0, 17, 3, 2);
        world.setBlock(i + 19, j + 0, k + 33, 17, 3, 2);
        world.setBlock(i + 19, j + 0, k + 32, 17, 3, 2);
        world.setBlock(i + 19, j + 0, k + 31, 17, 3, 2);
        world.setBlock(i + 19, j + 0, k + 28, 17, 3, 2);
        world.setBlock(i + 19, j + 0, k + 27, 17, 3, 2);
        world.setBlock(i + 19, j + 0, k + 26, 17, 3, 2);
        world.setBlock(i + 19, j + 0, k + 25, 17, 3, 2);
        world.setBlock(i + 19, j + 0, k + 24, 17, 3, 2);
        world.setBlock(i + 19, j + 0, k + 23, 17, 3, 2);
        world.setBlock(i + 19, j + 0, k + 22, 17, 3, 2);
        world.setBlock(i + 19, j + 0, k + 21, 17, 3, 2);
        world.setBlock(i + 19, j + 0, k + 20, 17, 3, 2);
        world.setBlock(i + 19, j + 0, k + 7, 17, 3, 2);
        world.setBlock(i + 19, j + 0, k + 5, 17, 3, 2);
        world.setBlock(i + 20, j + 0, k + 28, 17, 3, 2);
        world.setBlock(i + 20, j + 0, k + 22, 17, 3, 2);
        world.setBlock(i + 20, j + 0, k + 21, 17, 3, 2);
        world.setBlock(i + 20, j + 0, k + 12, 17, 3, 2);
        world.setBlock(i + 20, j + 0, k + 11, 17, 3, 2);
        world.setBlock(i + 20, j + 0, k + 10, 17, 3, 2);
        world.setBlock(i + 20, j + 0, k + 9, 17, 3, 2);
        world.setBlock(i + 20, j + 0, k + 8, 17, 3, 2);
        world.setBlock(i + 20, j + 0, k + 4, 17, 3, 2);
        world.setBlock(i + 20, j + 0, k + 3, 17, 3, 2);
        world.setBlock(i + 21, j + 0, k + 28, 17, 3, 2);
        world.setBlock(i + 21, j + 0, k + 23, 17, 3, 2);
        world.setBlock(i + 21, j + 0, k + 22, 17, 3, 2);
        world.setBlock(i + 21, j + 0, k + 21, 17, 3, 2);
        world.setBlock(i + 21, j + 0, k + 13, 17, 3, 2);
        world.setBlock(i + 21, j + 0, k + 9, 17, 3, 2);
        world.setBlock(i + 21, j + 0, k + 8, 17, 3, 2);
        world.setBlock(i + 22, j + 0, k + 28, 17, 3, 2);
        world.setBlock(i + 22, j + 0, k + 22, 17, 3, 2);
        world.setBlock(i + 22, j + 0, k + 21, 17, 3, 2);
        world.setBlock(i + 22, j + 0, k + 15, 17, 3, 2);
        world.setBlock(i + 22, j + 0, k + 13, 17, 3, 2);
        world.setBlock(i + 22, j + 0, k + 9, 17, 3, 2);
        world.setBlock(i + 22, j + 0, k + 8, 17, 3, 2);
        world.setBlock(i + 22, j + 0, k + 7, 17, 3, 2);
        world.setBlock(i + 23, j + 0, k + 28, 17, 3, 2);
        world.setBlock(i + 23, j + 0, k + 21, 17, 3, 2);
        world.setBlock(i + 23, j + 0, k + 15, 17, 3, 2);
        world.setBlock(i + 23, j + 0, k + 12, 17, 3, 2);
        world.setBlock(i + 23, j + 0, k + 6, 17, 3, 2);
        world.setBlock(i + 24, j + 0, k + 28, 17, 3, 2);
        world.setBlock(i + 24, j + 0, k + 22, 17, 3, 2);
        world.setBlock(i + 24, j + 0, k + 17, 17, 3, 2);
        world.setBlock(i + 24, j + 0, k + 15, 17, 3, 2);
        world.setBlock(i + 24, j + 0, k + 12, 17, 3, 2);
        world.setBlock(i + 25, j + 0, k + 29, 17, 3, 2);
        world.setBlock(i + 25, j + 0, k + 22, 17, 3, 2);
        world.setBlock(i + 25, j + 0, k + 17, 17, 3, 2);
        world.setBlock(i + 25, j + 0, k + 16, 17, 3, 2);
        world.setBlock(i + 25, j + 0, k + 15, 17, 3, 2);
        world.setBlock(i + 26, j + 0, k + 30, 17, 3, 2);
        world.setBlock(i + 26, j + 0, k + 23, 17, 3, 2);
        world.setBlock(i + 26, j + 0, k + 17, 17, 3, 2);
        world.setBlock(i + 26, j + 0, k + 15, 17, 3, 2);
        world.setBlock(i + 27, j + 0, k + 17, 17, 3, 2);
        world.setBlock(i + 27, j + 0, k + 15, 17, 3, 2);
        world.setBlock(i + 27, j + 0, k + 14, 17, 3, 2);
        world.setBlock(i + 28, j + 0, k + 18, 17, 3, 2);
        world.setBlock(i + 12, j + 1, k + 17, 17, 3, 2);
        world.setBlock(i + 12, j + 1, k + 16, 17, 3, 2);
        world.setBlock(i + 12, j + 1, k + 15, 17, 3, 2);
        world.setBlock(i + 13, j + 1, k + 20, 17, 3, 2);
        world.setBlock(i + 13, j + 1, k + 19, 17, 3, 2);
        world.setBlock(i + 13, j + 1, k + 18, 17, 3, 2);
        world.setBlock(i + 13, j + 1, k + 17, 17, 3, 2);
        world.setBlock(i + 13, j + 1, k + 16, 17, 3, 2);
        world.setBlock(i + 13, j + 1, k + 14, 17, 3, 2);
        world.setBlock(i + 14, j + 1, k + 21, 17, 3, 2);
        world.setBlock(i + 14, j + 1, k + 20, 17, 3, 2);
        world.setBlock(i + 14, j + 1, k + 19, 17, 3, 2);
        world.setBlock(i + 14, j + 1, k + 18, 17, 3, 2);
        world.setBlock(i + 14, j + 1, k + 17, 17, 3, 2);
        world.setBlock(i + 14, j + 1, k + 16, 17, 3, 2);
        world.setBlock(i + 14, j + 1, k + 13, 17, 3, 2);
        world.setBlock(i + 14, j + 1, k + 11, 17, 3, 2);
        world.setBlock(i + 14, j + 1, k + 10, 17, 3, 2);
        world.setBlock(i + 14, j + 1, k + 9, 17, 3, 2);
        world.setBlock(i + 15, j + 1, k + 22, 17, 3, 2);
        world.setBlock(i + 15, j + 1, k + 21, 17, 3, 2);
        world.setBlock(i + 15, j + 1, k + 20, 17, 3, 2);
        world.setBlock(i + 15, j + 1, k + 19, 17, 3, 2);
        world.setBlock(i + 15, j + 1, k + 18, 17, 3, 2);
        world.setBlock(i + 15, j + 1, k + 17, 17, 3, 2);
        world.setBlock(i + 15, j + 1, k + 16, 17, 3, 2);
        world.setBlock(i + 15, j + 1, k + 12, 17, 3, 2);
        world.setBlock(i + 15, j + 1, k + 10, 17, 3, 2);
        world.setBlock(i + 15, j + 1, k + 9, 17, 3, 2);
        world.setBlock(i + 15, j + 1, k + 8, 17, 3, 2);
        world.setBlock(i + 16, j + 1, k + 26, 17, 3, 2);
        world.setBlock(i + 16, j + 1, k + 25, 17, 3, 2);
        world.setBlock(i + 16, j + 1, k + 24, 17, 3, 2);
        world.setBlock(i + 16, j + 1, k + 23, 17, 3, 2);
        world.setBlock(i + 16, j + 1, k + 22, 17, 3, 2);
        world.setBlock(i + 16, j + 1, k + 21, 17, 3, 2);
        world.setBlock(i + 16, j + 1, k + 20, 17, 3, 2);
        world.setBlock(i + 16, j + 1, k + 19, 17, 3, 2);
        world.setBlock(i + 16, j + 1, k + 18, 17, 3, 2);
        world.setBlock(i + 16, j + 1, k + 17, 17, 3, 2);
        world.setBlock(i + 16, j + 1, k + 16, 17, 3, 2);
        world.setBlock(i + 16, j + 1, k + 10, 17, 3, 2);
        world.setBlock(i + 16, j + 1, k + 9, 17, 3, 2);
        world.setBlock(i + 16, j + 1, k + 8, 17, 3, 2);
        world.setBlock(i + 16, j + 1, k + 7, 17, 3, 2);
        world.setBlock(i + 17, j + 1, k + 24, 17, 3, 2);
        world.setBlock(i + 17, j + 1, k + 22, 17, 3, 2);
        world.setBlock(i + 17, j + 1, k + 21, 17, 3, 2);
        world.setBlock(i + 17, j + 1, k + 20, 17, 3, 2);
        world.setBlock(i + 17, j + 1, k + 19, 17, 3, 2);
        world.setBlock(i + 17, j + 1, k + 18, 17, 3, 2);
        world.setBlock(i + 17, j + 1, k + 17, 17, 3, 2);
        world.setBlock(i + 17, j + 1, k + 16, 17, 3, 2);
        world.setBlock(i + 17, j + 1, k + 8, 17, 3, 2);
        world.setBlock(i + 17, j + 1, k + 7, 17, 3, 2);
        world.setBlock(i + 18, j + 1, k + 28, 17, 3, 2);
        world.setBlock(i + 18, j + 1, k + 27, 17, 3, 2);
        world.setBlock(i + 18, j + 1, k + 26, 17, 3, 2);
        world.setBlock(i + 18, j + 1, k + 25, 17, 3, 2);
        world.setBlock(i + 18, j + 1, k + 24, 17, 3, 2);
        world.setBlock(i + 18, j + 1, k + 23, 17, 3, 2);
        world.setBlock(i + 18, j + 1, k + 22, 17, 3, 2);
        world.setBlock(i + 18, j + 1, k + 21, 17, 3, 2);
        world.setBlock(i + 18, j + 1, k + 20, 17, 3, 2);
        world.setBlock(i + 18, j + 1, k + 19, 17, 3, 2);
        world.setBlock(i + 18, j + 1, k + 18, 17, 3, 2);
        world.setBlock(i + 18, j + 1, k + 17, 17, 3, 2);
        world.setBlock(i + 18, j + 1, k + 16, 17, 3, 2);
        world.setBlock(i + 18, j + 1, k + 8, 17, 3, 2);
        world.setBlock(i + 19, j + 1, k + 20, 17, 3, 2);
        world.setBlock(i + 19, j + 1, k + 19, 17, 3, 2);
        world.setBlock(i + 19, j + 1, k + 18, 17, 3, 2);
        world.setBlock(i + 19, j + 1, k + 17, 17, 3, 2);
        world.setBlock(i + 19, j + 1, k + 16, 17, 3, 2);
        world.setBlock(i + 19, j + 1, k + 12, 17, 3, 2);
        world.setBlock(i + 19, j + 1, k + 11, 17, 3, 2);
        world.setBlock(i + 19, j + 1, k + 10, 17, 3, 2);
        world.setBlock(i + 19, j + 1, k + 9, 17, 3, 2);
        world.setBlock(i + 19, j + 1, k + 8, 17, 3, 2);
        world.setBlock(i + 20, j + 1, k + 19, 17, 3, 2);
        world.setBlock(i + 20, j + 1, k + 18, 17, 3, 2);
        world.setBlock(i + 20, j + 1, k + 17, 17, 3, 2);
        world.setBlock(i + 20, j + 1, k + 16, 17, 3, 2);
        world.setBlock(i + 20, j + 1, k + 14, 17, 3, 2);
        world.setBlock(i + 20, j + 1, k + 13, 17, 3, 2);
        world.setBlock(i + 21, j + 1, k + 19, 17, 3, 2);
        world.setBlock(i + 21, j + 1, k + 18, 17, 3, 2);
        world.setBlock(i + 21, j + 1, k + 17, 17, 3, 2);
        world.setBlock(i + 21, j + 1, k + 16, 17, 3, 2);
        world.setBlock(i + 21, j + 1, k + 15, 17, 3, 2);
        world.setBlock(i + 21, j + 1, k + 14, 17, 3, 2);
        world.setBlock(i + 22, j + 1, k + 16, 17, 3, 2);
        world.setBlock(i + 23, j + 1, k + 16, 17, 3, 2);
        world.setBlock(i + 24, j + 1, k + 16, 17, 3, 2);
        world.setBlock(i + 13, j + 2, k + 20, 17, 3, 2);
        world.setBlock(i + 13, j + 2, k + 19, 17, 3, 2);
        world.setBlock(i + 13, j + 2, k + 18, 17, 3, 2);
        world.setBlock(i + 13, j + 2, k + 17, 17, 3, 2);
        world.setBlock(i + 13, j + 2, k + 16, 17, 3, 2);
        world.setBlock(i + 13, j + 2, k + 15, 17, 3, 2);
        world.setBlock(i + 14, j + 2, k + 21, 17, 3, 2);
        world.setBlock(i + 14, j + 2, k + 20, 17, 3, 2);
        world.setBlock(i + 14, j + 2, k + 19, 17, 3, 2);
        world.setBlock(i + 14, j + 2, k + 18, 17, 3, 2);
        world.setBlock(i + 14, j + 2, k + 17, 17, 3, 2);
        world.setBlock(i + 14, j + 2, k + 16, 17, 3, 2);
        world.setBlock(i + 14, j + 2, k + 14, 17, 3, 2);
        world.setBlock(i + 15, j + 2, k + 22, 17, 3, 2);
        world.setBlock(i + 15, j + 2, k + 21, 17, 3, 2);
        world.setBlock(i + 15, j + 2, k + 20, 17, 3, 2);
        world.setBlock(i + 15, j + 2, k + 19, 17, 3, 2);
        world.setBlock(i + 15, j + 2, k + 18, 17, 3, 2);
        world.setBlock(i + 15, j + 2, k + 17, 17, 3, 2);
        world.setBlock(i + 15, j + 2, k + 16, 17, 3, 2);
        world.setBlock(i + 15, j + 2, k + 13, 17, 3, 2);
        world.setBlock(i + 15, j + 2, k + 12, 17, 3, 2);
        world.setBlock(i + 15, j + 2, k + 11, 17, 3, 2);
        world.setBlock(i + 16, j + 2, k + 23, 17, 3, 2);
        world.setBlock(i + 16, j + 2, k + 22, 17, 3, 2);
        world.setBlock(i + 16, j + 2, k + 21, 17, 3, 2);
        world.setBlock(i + 16, j + 2, k + 20, 17, 3, 2);
        world.setBlock(i + 16, j + 2, k + 19, 17, 3, 2);
        world.setBlock(i + 16, j + 2, k + 18, 17, 3, 2);
        world.setBlock(i + 16, j + 2, k + 17, 17, 3, 2);
        world.setBlock(i + 16, j + 2, k + 16, 17, 3, 2);
        world.setBlock(i + 16, j + 2, k + 13, 17, 3, 2);
        world.setBlock(i + 16, j + 2, k + 12, 17, 3, 2);
        world.setBlock(i + 16, j + 2, k + 11, 17, 3, 2);
        world.setBlock(i + 17, j + 2, k + 22, 17, 3, 2);
        world.setBlock(i + 17, j + 2, k + 21, 17, 3, 2);
        world.setBlock(i + 17, j + 2, k + 20, 17, 3, 2);
        world.setBlock(i + 17, j + 2, k + 19, 17, 3, 2);
        world.setBlock(i + 17, j + 2, k + 18, 17, 3, 2);
        world.setBlock(i + 17, j + 2, k + 17, 17, 3, 2);
        world.setBlock(i + 17, j + 2, k + 16, 17, 3, 2);
        world.setBlock(i + 17, j + 2, k + 13, 17, 3, 2);
        world.setBlock(i + 17, j + 2, k + 12, 17, 3, 2);
        world.setBlock(i + 17, j + 2, k + 11, 17, 3, 2);
        world.setBlock(i + 17, j + 2, k + 10, 17, 3, 2);
        world.setBlock(i + 17, j + 2, k + 9, 17, 3, 2);
        world.setBlock(i + 18, j + 2, k + 22, 17, 3, 2);
        world.setBlock(i + 18, j + 2, k + 21, 17, 3, 2);
        world.setBlock(i + 18, j + 2, k + 20, 17, 3, 2);
        world.setBlock(i + 18, j + 2, k + 19, 17, 3, 2);
        world.setBlock(i + 18, j + 2, k + 18, 17, 3, 2);
        world.setBlock(i + 18, j + 2, k + 17, 17, 3, 2);
        world.setBlock(i + 18, j + 2, k + 16, 17, 3, 2);
        world.setBlock(i + 18, j + 2, k + 13, 17, 3, 2);
        world.setBlock(i + 18, j + 2, k + 12, 17, 3, 2);
        world.setBlock(i + 18, j + 2, k + 11, 17, 3, 2);
        world.setBlock(i + 18, j + 2, k + 10, 17, 3, 2);
        world.setBlock(i + 18, j + 2, k + 9, 17, 3, 2);
        world.setBlock(i + 19, j + 2, k + 20, 17, 3, 2);
        world.setBlock(i + 19, j + 2, k + 19, 17, 3, 2);
        world.setBlock(i + 19, j + 2, k + 18, 17, 3, 2);
        world.setBlock(i + 19, j + 2, k + 17, 17, 3, 2);
        world.setBlock(i + 19, j + 2, k + 16, 17, 3, 2);
        world.setBlock(i + 19, j + 2, k + 14, 17, 3, 2);
        world.setBlock(i + 19, j + 2, k + 13, 17, 3, 2);
        world.setBlock(i + 20, j + 2, k + 19, 17, 3, 2);
        world.setBlock(i + 20, j + 2, k + 18, 17, 3, 2);
        world.setBlock(i + 20, j + 2, k + 17, 17, 3, 2);
        world.setBlock(i + 20, j + 2, k + 16, 17, 3, 2);
        world.setBlock(i + 20, j + 2, k + 15, 17, 3, 2);
        world.setBlock(i + 13, j + 3, k + 20, 17, 3, 2);
        world.setBlock(i + 13, j + 3, k + 19, 17, 3, 2);
        
        generate2(world, rand, i, j, k);
        return true;
    }
    
    public boolean generate2(World world, Random rand, int i, int j, int k)
    {
        world.setBlock(i + 13, j + 3, k + 18, 17, 3, 2);
        world.setBlock(i + 13, j + 3, k + 17, 17, 3, 2);
        world.setBlock(i + 13, j + 3, k + 16, 17, 3, 2);
        world.setBlock(i + 14, j + 3, k + 21, 17, 3, 2);
        world.setBlock(i + 14, j + 3, k + 20, 17, 3, 2);
        world.setBlock(i + 14, j + 3, k + 19, 17, 3, 2);
        world.setBlock(i + 14, j + 3, k + 18, 17, 3, 2);
        world.setBlock(i + 14, j + 3, k + 17, 17, 3, 2);
        world.setBlock(i + 14, j + 3, k + 16, 17, 3, 2);
        world.setBlock(i + 14, j + 3, k + 15, 17, 3, 2);
        world.setBlock(i + 14, j + 3, k + 14, 17, 3, 2);
        world.setBlock(i + 15, j + 3, k + 22, 17, 3, 2);
        world.setBlock(i + 15, j + 3, k + 21, 17, 3, 2);
        world.setBlock(i + 15, j + 3, k + 20, 17, 3, 2);
        world.setBlock(i + 15, j + 3, k + 19, 17, 3, 2);
        world.setBlock(i + 15, j + 3, k + 18, 17, 3, 2);
        world.setBlock(i + 15, j + 3, k + 17, 17, 3, 2);
        world.setBlock(i + 15, j + 3, k + 16, 17, 3, 2);
        world.setBlock(i + 15, j + 3, k + 14, 17, 3, 2);
        world.setBlock(i + 16, j + 3, k + 22, 17, 3, 2);
        world.setBlock(i + 16, j + 3, k + 21, 17, 3, 2);
        world.setBlock(i + 16, j + 3, k + 20, 17, 3, 2);
        world.setBlock(i + 16, j + 3, k + 19, 17, 3, 2);
        world.setBlock(i + 16, j + 3, k + 18, 17, 3, 2);
        world.setBlock(i + 16, j + 3, k + 17, 17, 3, 2);
        world.setBlock(i + 16, j + 3, k + 16, 17, 3, 2);
        world.setBlock(i + 16, j + 3, k + 14, 17, 3, 2);
        world.setBlock(i + 17, j + 3, k + 22, 17, 3, 2);
        world.setBlock(i + 17, j + 3, k + 21, 17, 3, 2);
        world.setBlock(i + 17, j + 3, k + 20, 17, 3, 2);
        world.setBlock(i + 17, j + 3, k + 19, 17, 3, 2);
        world.setBlock(i + 17, j + 3, k + 18, 17, 3, 2);
        world.setBlock(i + 17, j + 3, k + 17, 17, 3, 2);
        world.setBlock(i + 17, j + 3, k + 16, 17, 3, 2);
        world.setBlock(i + 17, j + 3, k + 14, 17, 3, 2);
        world.setBlock(i + 18, j + 3, k + 21, 17, 3, 2);
        world.setBlock(i + 18, j + 3, k + 20, 17, 3, 2);
        world.setBlock(i + 18, j + 3, k + 19, 17, 3, 2);
        world.setBlock(i + 18, j + 3, k + 18, 17, 3, 2);
        world.setBlock(i + 18, j + 3, k + 17, 17, 3, 2);
        world.setBlock(i + 18, j + 3, k + 16, 17, 3, 2);
        world.setBlock(i + 18, j + 3, k + 14, 17, 3, 2);
        world.setBlock(i + 19, j + 3, k + 20, 17, 3, 2);
        world.setBlock(i + 19, j + 3, k + 19, 17, 3, 2);
        world.setBlock(i + 19, j + 3, k + 18, 17, 3, 2);
        world.setBlock(i + 19, j + 3, k + 17, 17, 3, 2);
        world.setBlock(i + 19, j + 3, k + 16, 17, 3, 2);
        world.setBlock(i + 19, j + 3, k + 15, 17, 3, 2);
        world.setBlock(i + 19, j + 3, k + 14, 17, 3, 2);
        world.setBlock(i + 13, j + 4, k + 20, 17, 3, 2);
        world.setBlock(i + 13, j + 4, k + 19, 17, 3, 2);
        world.setBlock(i + 13, j + 4, k + 18, 17, 3, 2);
        world.setBlock(i + 13, j + 4, k + 17, 17, 3, 2);
        world.setBlock(i + 14, j + 4, k + 21, 17, 3, 2);
        world.setBlock(i + 14, j + 4, k + 20, 17, 3, 2);
        world.setBlock(i + 14, j + 4, k + 19, 17, 3, 2);
        world.setBlock(i + 14, j + 4, k + 18, 17, 3, 2);
        world.setBlock(i + 14, j + 4, k + 17, 17, 3, 2);
        world.setBlock(i + 14, j + 4, k + 16, 17, 3, 2);
        world.setBlock(i + 14, j + 4, k + 15, 17, 3, 2);
        world.setBlock(i + 15, j + 4, k + 22, 17, 3, 2);
        world.setBlock(i + 15, j + 4, k + 21, 17, 3, 2);
        world.setBlock(i + 15, j + 4, k + 20, 17, 3, 2);
        world.setBlock(i + 15, j + 4, k + 19, 17, 3, 2);
        world.setBlock(i + 15, j + 4, k + 18, 17, 3, 2);
        world.setBlock(i + 15, j + 4, k + 17, 17, 3, 2);
        world.setBlock(i + 15, j + 4, k + 16, 17, 3, 2);
        world.setBlock(i + 15, j + 4, k + 15, 17, 3, 2);
        world.setBlock(i + 16, j + 4, k + 22, 17, 3, 2);
        world.setBlock(i + 16, j + 4, k + 21, 17, 3, 2);
        world.setBlock(i + 16, j + 4, k + 20, 17, 3, 2);
        world.setBlock(i + 16, j + 4, k + 19, 17, 3, 2);
        world.setBlock(i + 16, j + 4, k + 18, 17, 3, 2);
        world.setBlock(i + 16, j + 4, k + 17, 17, 3, 2);
        world.setBlock(i + 16, j + 4, k + 16, 17, 3, 2);
        world.setBlock(i + 16, j + 4, k + 15, 17, 3, 2);
        world.setBlock(i + 17, j + 4, k + 22, 17, 3, 2);
        world.setBlock(i + 17, j + 4, k + 21, 17, 3, 2);
        world.setBlock(i + 17, j + 4, k + 20, 17, 3, 2);
        world.setBlock(i + 17, j + 4, k + 19, 17, 3, 2);
        world.setBlock(i + 17, j + 4, k + 18, 17, 3, 2);
        world.setBlock(i + 17, j + 4, k + 17, 17, 3, 2);
        world.setBlock(i + 17, j + 4, k + 16, 17, 3, 2);
        world.setBlock(i + 17, j + 4, k + 15, 17, 3, 2);
        world.setBlock(i + 18, j + 4, k + 21, 17, 3, 2);
        world.setBlock(i + 18, j + 4, k + 20, 17, 3, 2);
        world.setBlock(i + 18, j + 4, k + 19, 17, 3, 2);
        world.setBlock(i + 18, j + 4, k + 18, 17, 3, 2);
        world.setBlock(i + 18, j + 4, k + 17, 17, 3, 2);
        world.setBlock(i + 18, j + 4, k + 16, 17, 3, 2);
        world.setBlock(i + 18, j + 4, k + 15, 17, 3, 2);
        world.setBlock(i + 19, j + 4, k + 20, 17, 3, 2);
        world.setBlock(i + 19, j + 4, k + 19, 17, 3, 2);
        world.setBlock(i + 19, j + 4, k + 18, 17, 3, 2);
        world.setBlock(i + 19, j + 4, k + 17, 17, 3, 2);
        world.setBlock(i + 19, j + 4, k + 16, 17, 3, 2);
        world.setBlock(i + 19, j + 4, k + 15, 17, 3, 2);
        world.setBlock(i + 13, j + 5, k + 20, 17, 3, 2);
        world.setBlock(i + 13, j + 5, k + 19, 17, 3, 2);
        world.setBlock(i + 13, j + 5, k + 18, 17, 3, 2);
        world.setBlock(i + 13, j + 5, k + 17, 17, 3, 2);
        world.setBlock(i + 14, j + 5, k + 21, 17, 3, 2);
        world.setBlock(i + 14, j + 5, k + 20, 17, 3, 2);
        world.setBlock(i + 14, j + 5, k + 19, 17, 3, 2);
        world.setBlock(i + 14, j + 5, k + 18, 17, 3, 2);
        world.setBlock(i + 14, j + 5, k + 17, 17, 3, 2);
        world.setBlock(i + 14, j + 5, k + 16, 17, 3, 2);
        world.setBlock(i + 15, j + 5, k + 22, 17, 3, 2);
        world.setBlock(i + 15, j + 5, k + 21, 17, 3, 2);
        world.setBlock(i + 15, j + 5, k + 20, 17, 3, 2);
        world.setBlock(i + 15, j + 5, k + 19, 17, 3, 2);
        world.setBlock(i + 15, j + 5, k + 18, 17, 3, 2);
        world.setBlock(i + 15, j + 5, k + 17, 17, 3, 2);
        world.setBlock(i + 15, j + 5, k + 16, 17, 3, 2);
        world.setBlock(i + 15, j + 5, k + 15, 17, 3, 2);
        world.setBlock(i + 16, j + 5, k + 22, 17, 3, 2);
        world.setBlock(i + 16, j + 5, k + 21, 17, 3, 2);
        world.setBlock(i + 16, j + 5, k + 20, 17, 3, 2);
        world.setBlock(i + 16, j + 5, k + 19, 17, 3, 2);
        world.setBlock(i + 16, j + 5, k + 18, 17, 3, 2);
        world.setBlock(i + 16, j + 5, k + 17, 17, 3, 2);
        world.setBlock(i + 16, j + 5, k + 16, 17, 3, 2);
        world.setBlock(i + 16, j + 5, k + 15, 17, 3, 2);
        world.setBlock(i + 17, j + 5, k + 22, 17, 3, 2);
        world.setBlock(i + 17, j + 5, k + 21, 17, 3, 2);
        world.setBlock(i + 17, j + 5, k + 20, 17, 3, 2);
        world.setBlock(i + 17, j + 5, k + 19, 17, 3, 2);
        world.setBlock(i + 17, j + 5, k + 18, 17, 3, 2);
        world.setBlock(i + 17, j + 5, k + 17, 17, 3, 2);
        world.setBlock(i + 17, j + 5, k + 16, 17, 3, 2);
        world.setBlock(i + 17, j + 5, k + 15, 17, 3, 2);
        world.setBlock(i + 18, j + 5, k + 21, 17, 3, 2);
        world.setBlock(i + 18, j + 5, k + 20, 17, 3, 2);
        world.setBlock(i + 18, j + 5, k + 19, 17, 3, 2);
        world.setBlock(i + 18, j + 5, k + 18, 17, 3, 2);
        world.setBlock(i + 18, j + 5, k + 17, 17, 3, 2);
        world.setBlock(i + 18, j + 5, k + 16, 17, 3, 2);
        world.setBlock(i + 18, j + 5, k + 15, 17, 3, 2);
        world.setBlock(i + 19, j + 5, k + 20, 17, 3, 2);
        world.setBlock(i + 19, j + 5, k + 19, 17, 3, 2);
        world.setBlock(i + 19, j + 5, k + 18, 17, 3, 2);
        world.setBlock(i + 19, j + 5, k + 17, 17, 3, 2);
        world.setBlock(i + 19, j + 5, k + 16, 17, 3, 2);
        world.setBlock(i + 13, j + 6, k + 20, 17, 3, 2);
        world.setBlock(i + 13, j + 6, k + 19, 17, 3, 2);
        world.setBlock(i + 13, j + 6, k + 18, 17, 3, 2);
        world.setBlock(i + 13, j + 6, k + 17, 17, 3, 2);
        world.setBlock(i + 14, j + 6, k + 21, 17, 3, 2);
        world.setBlock(i + 14, j + 6, k + 20, 17, 3, 2);
        world.setBlock(i + 14, j + 6, k + 19, 17, 3, 2);
        world.setBlock(i + 14, j + 6, k + 18, 17, 3, 2);
        world.setBlock(i + 14, j + 6, k + 17, 17, 3, 2);
        world.setBlock(i + 14, j + 6, k + 16, 17, 3, 2);
        world.setBlock(i + 15, j + 6, k + 22, 17, 3, 2);
        world.setBlock(i + 15, j + 6, k + 21, 17, 3, 2);
        world.setBlock(i + 15, j + 6, k + 20, 17, 3, 2);
        world.setBlock(i + 15, j + 6, k + 19, 17, 3, 2);
        world.setBlock(i + 15, j + 6, k + 18, 17, 3, 2);
        world.setBlock(i + 15, j + 6, k + 17, 17, 3, 2);
        world.setBlock(i + 15, j + 6, k + 16, 17, 3, 2);
        world.setBlock(i + 16, j + 6, k + 22, 17, 3, 2);
        world.setBlock(i + 16, j + 6, k + 21, 17, 3, 2);
        world.setBlock(i + 16, j + 6, k + 20, 17, 3, 2);
        world.setBlock(i + 16, j + 6, k + 19, 17, 3, 2);
        world.setBlock(i + 16, j + 6, k + 18, 17, 3, 2);
        world.setBlock(i + 16, j + 6, k + 17, 17, 3, 2);
        world.setBlock(i + 16, j + 6, k + 16, 17, 3, 2);
        world.setBlock(i + 17, j + 6, k + 22, 17, 3, 2);
        world.setBlock(i + 17, j + 6, k + 21, 17, 3, 2);
        world.setBlock(i + 17, j + 6, k + 20, 17, 3, 2);
        world.setBlock(i + 17, j + 6, k + 19, 17, 3, 2);
        world.setBlock(i + 17, j + 6, k + 18, 17, 3, 2);
        world.setBlock(i + 17, j + 6, k + 17, 17, 3, 2);
        world.setBlock(i + 17, j + 6, k + 16, 17, 3, 2);
        world.setBlock(i + 18, j + 6, k + 21, 17, 3, 2);
        world.setBlock(i + 18, j + 6, k + 20, 17, 3, 2);
        world.setBlock(i + 18, j + 6, k + 19, 17, 3, 2);
        world.setBlock(i + 18, j + 6, k + 18, 17, 3, 2);
        world.setBlock(i + 18, j + 6, k + 17, 17, 3, 2);
        world.setBlock(i + 18, j + 6, k + 16, 17, 3, 2);
        world.setBlock(i + 19, j + 6, k + 20, 17, 3, 2);
        world.setBlock(i + 19, j + 6, k + 19, 17, 3, 2);
        world.setBlock(i + 19, j + 6, k + 18, 17, 3, 2);
        world.setBlock(i + 19, j + 6, k + 17, 17, 3, 2);
        world.setBlock(i + 19, j + 6, k + 16, 17, 3, 2);
        world.setBlock(i + 13, j + 7, k + 20, 17, 3, 2);
        world.setBlock(i + 13, j + 7, k + 19, 17, 3, 2);
        world.setBlock(i + 13, j + 7, k + 18, 17, 3, 2);
        world.setBlock(i + 13, j + 7, k + 17, 17, 3, 2);
        world.setBlock(i + 14, j + 7, k + 21, 17, 3, 2);
        world.setBlock(i + 14, j + 7, k + 20, 17, 3, 2);
        world.setBlock(i + 14, j + 7, k + 19, 17, 3, 2);
        world.setBlock(i + 14, j + 7, k + 18, 17, 3, 2);
        world.setBlock(i + 14, j + 7, k + 17, 17, 3, 2);
        world.setBlock(i + 14, j + 7, k + 16, 17, 3, 2);
        world.setBlock(i + 15, j + 7, k + 22, 17, 3, 2);
        world.setBlock(i + 15, j + 7, k + 21, 17, 3, 2);
        world.setBlock(i + 15, j + 7, k + 20, 17, 3, 2);
        world.setBlock(i + 15, j + 7, k + 19, 17, 3, 2);
        world.setBlock(i + 15, j + 7, k + 18, 17, 3, 2);
        world.setBlock(i + 15, j + 7, k + 17, 17, 3, 2);
        world.setBlock(i + 15, j + 7, k + 16, 17, 3, 2);
        world.setBlock(i + 16, j + 7, k + 22, 17, 3, 2);
        world.setBlock(i + 16, j + 7, k + 21, 17, 3, 2);
        world.setBlock(i + 16, j + 7, k + 20, 17, 3, 2);
        world.setBlock(i + 16, j + 7, k + 19, 17, 3, 2);
        world.setBlock(i + 16, j + 7, k + 18, 17, 3, 2);
        world.setBlock(i + 16, j + 7, k + 17, 17, 3, 2);
        world.setBlock(i + 16, j + 7, k + 16, 17, 3, 2);
        world.setBlock(i + 17, j + 7, k + 22, 17, 3, 2);
        world.setBlock(i + 17, j + 7, k + 21, 17, 3, 2);
        world.setBlock(i + 17, j + 7, k + 20, 17, 3, 2);
        world.setBlock(i + 17, j + 7, k + 19, 17, 3, 2);
        world.setBlock(i + 17, j + 7, k + 18, 17, 3, 2);
        world.setBlock(i + 17, j + 7, k + 17, 17, 3, 2);
        world.setBlock(i + 17, j + 7, k + 16, 17, 3, 2);
        world.setBlock(i + 18, j + 7, k + 21, 17, 3, 2);
        world.setBlock(i + 18, j + 7, k + 20, 17, 3, 2);
        world.setBlock(i + 18, j + 7, k + 19, 17, 3, 2);
        world.setBlock(i + 18, j + 7, k + 18, 17, 3, 2);
        world.setBlock(i + 18, j + 7, k + 17, 17, 3, 2);
        world.setBlock(i + 18, j + 7, k + 16, 17, 3, 2);
        world.setBlock(i + 19, j + 7, k + 20, 17, 3, 2);
        world.setBlock(i + 19, j + 7, k + 19, 17, 3, 2);
        world.setBlock(i + 19, j + 7, k + 18, 17, 3, 2);
        world.setBlock(i + 19, j + 7, k + 17, 17, 3, 2);
        world.setBlock(i + 19, j + 7, k + 16, 17, 3, 2);
        world.setBlock(i + 13, j + 8, k + 20, 17, 3, 2);
        world.setBlock(i + 13, j + 8, k + 19, 17, 3, 2);
        world.setBlock(i + 13, j + 8, k + 18, 17, 3, 2);
        world.setBlock(i + 13, j + 8, k + 17, 17, 3, 2);
        world.setBlock(i + 14, j + 8, k + 21, 17, 3, 2);
        world.setBlock(i + 14, j + 8, k + 20, 17, 3, 2);
        world.setBlock(i + 14, j + 8, k + 19, 17, 3, 2);
        world.setBlock(i + 14, j + 8, k + 18, 17, 3, 2);
        world.setBlock(i + 14, j + 8, k + 17, 17, 3, 2);
        world.setBlock(i + 14, j + 8, k + 16, 17, 3, 2);
        world.setBlock(i + 15, j + 8, k + 22, 17, 3, 2);
        world.setBlock(i + 15, j + 8, k + 21, 17, 3, 2);
        world.setBlock(i + 15, j + 8, k + 20, 17, 3, 2);
        world.setBlock(i + 15, j + 8, k + 19, 17, 3, 2);
        world.setBlock(i + 15, j + 8, k + 18, 17, 3, 2);
        world.setBlock(i + 15, j + 8, k + 17, 17, 3, 2);
        world.setBlock(i + 15, j + 8, k + 16, 17, 3, 2);
        world.setBlock(i + 16, j + 8, k + 22, 17, 3, 2);
        world.setBlock(i + 16, j + 8, k + 21, 17, 3, 2);
        world.setBlock(i + 16, j + 8, k + 20, 17, 3, 2);
        world.setBlock(i + 16, j + 8, k + 19, 17, 3, 2);
        world.setBlock(i + 16, j + 8, k + 18, 17, 3, 2);
        world.setBlock(i + 16, j + 8, k + 17, 17, 3, 2);
        world.setBlock(i + 16, j + 8, k + 16, 17, 3, 2);
        world.setBlock(i + 17, j + 8, k + 22, 17, 3, 2);
        world.setBlock(i + 17, j + 8, k + 21, 17, 3, 2);
        world.setBlock(i + 17, j + 8, k + 20, 17, 3, 2);
        world.setBlock(i + 17, j + 8, k + 19, 17, 3, 2);
        world.setBlock(i + 17, j + 8, k + 18, 17, 3, 2);
        world.setBlock(i + 17, j + 8, k + 17, 17, 3, 2);
        world.setBlock(i + 17, j + 8, k + 16, 17, 3, 2);
        world.setBlock(i + 18, j + 8, k + 21, 17, 3, 2);
        world.setBlock(i + 18, j + 8, k + 20, 17, 3, 2);
        world.setBlock(i + 18, j + 8, k + 19, 17, 3, 2);
        world.setBlock(i + 18, j + 8, k + 18, 17, 3, 2);
        world.setBlock(i + 18, j + 8, k + 17, 17, 3, 2);
        world.setBlock(i + 18, j + 8, k + 16, 17, 3, 2);
        world.setBlock(i + 19, j + 8, k + 20, 17, 3, 2);
        world.setBlock(i + 19, j + 8, k + 19, 17, 3, 2);
        world.setBlock(i + 19, j + 8, k + 18, 17, 3, 2);
        world.setBlock(i + 19, j + 8, k + 17, 17, 3, 2);
        world.setBlock(i + 19, j + 8, k + 16, 17, 3, 2);
        world.setBlock(i + 13, j + 9, k + 20, 17, 3, 2);
        world.setBlock(i + 13, j + 9, k + 19, 17, 3, 2);
        world.setBlock(i + 13, j + 9, k + 18, 17, 3, 2);
        world.setBlock(i + 13, j + 9, k + 17, 17, 3, 2);
        world.setBlock(i + 14, j + 9, k + 21, 17, 3, 2);
        world.setBlock(i + 14, j + 9, k + 20, 17, 3, 2);
        world.setBlock(i + 14, j + 9, k + 19, 17, 3, 2);
        world.setBlock(i + 14, j + 9, k + 18, 17, 3, 2);
        world.setBlock(i + 14, j + 9, k + 17, 17, 3, 2);
        world.setBlock(i + 14, j + 9, k + 16, 17, 3, 2);
        world.setBlock(i + 15, j + 9, k + 22, 17, 3, 2);
        world.setBlock(i + 15, j + 9, k + 21, 17, 3, 2);
        world.setBlock(i + 15, j + 9, k + 20, 17, 3, 2);
        world.setBlock(i + 15, j + 9, k + 19, 17, 3, 2);
        world.setBlock(i + 15, j + 9, k + 18, 17, 3, 2);
        world.setBlock(i + 15, j + 9, k + 17, 17, 3, 2);
        world.setBlock(i + 15, j + 9, k + 16, 17, 3, 2);
        world.setBlock(i + 16, j + 9, k + 22, 17, 3, 2);
        world.setBlock(i + 16, j + 9, k + 21, 17, 3, 2);
        world.setBlock(i + 16, j + 9, k + 20, 17, 3, 2);
        world.setBlock(i + 16, j + 9, k + 19, 17, 3, 2);
        world.setBlock(i + 16, j + 9, k + 18, 17, 3, 2);
        world.setBlock(i + 16, j + 9, k + 17, 17, 3, 2);
        world.setBlock(i + 16, j + 9, k + 16, 17, 3, 2);
        world.setBlock(i + 17, j + 9, k + 22, 17, 3, 2);
        world.setBlock(i + 17, j + 9, k + 21, 17, 3, 2);
        world.setBlock(i + 17, j + 9, k + 20, 17, 3, 2);
        world.setBlock(i + 17, j + 9, k + 19, 17, 3, 2);
        world.setBlock(i + 17, j + 9, k + 18, 17, 3, 2);
        world.setBlock(i + 17, j + 9, k + 17, 17, 3, 2);
        world.setBlock(i + 17, j + 9, k + 16, 17, 3, 2);
        world.setBlock(i + 18, j + 9, k + 21, 17, 3, 2);
        world.setBlock(i + 18, j + 9, k + 20, 17, 3, 2);
        world.setBlock(i + 18, j + 9, k + 19, 17, 3, 2);
        world.setBlock(i + 18, j + 9, k + 18, 17, 3, 2);
        world.setBlock(i + 18, j + 9, k + 17, 17, 3, 2);
        world.setBlock(i + 18, j + 9, k + 16, 17, 3, 2);
        world.setBlock(i + 19, j + 9, k + 20, 17, 3, 2);
        world.setBlock(i + 19, j + 9, k + 19, 17, 3, 2);
        world.setBlock(i + 19, j + 9, k + 18, 17, 3, 2);
        world.setBlock(i + 19, j + 9, k + 17, 17, 3, 2);
        world.setBlock(i + 13, j + 10, k + 20, 17, 3, 2);
        world.setBlock(i + 13, j + 10, k + 19, 17, 3, 2);
        world.setBlock(i + 13, j + 10, k + 18, 17, 3, 2);
        world.setBlock(i + 13, j + 10, k + 17, 17, 3, 2);
        world.setBlock(i + 14, j + 10, k + 21, 17, 3, 2);
        world.setBlock(i + 14, j + 10, k + 20, 17, 3, 2);
        world.setBlock(i + 14, j + 10, k + 19, 17, 3, 2);
        world.setBlock(i + 14, j + 10, k + 18, 17, 3, 2);
        world.setBlock(i + 14, j + 10, k + 17, 17, 3, 2);
        world.setBlock(i + 14, j + 10, k + 16, 17, 3, 2);
        world.setBlock(i + 15, j + 10, k + 22, 17, 3, 2);
        world.setBlock(i + 15, j + 10, k + 21, 17, 3, 2);
        world.setBlock(i + 15, j + 10, k + 20, 17, 3, 2);
        world.setBlock(i + 15, j + 10, k + 19, 17, 3, 2);
        world.setBlock(i + 15, j + 10, k + 18, 17, 3, 2);
        world.setBlock(i + 15, j + 10, k + 17, 17, 3, 2);
        world.setBlock(i + 15, j + 10, k + 16, 17, 3, 2);
        world.setBlock(i + 16, j + 10, k + 22, 17, 3, 2);
        world.setBlock(i + 16, j + 10, k + 21, 17, 3, 2);
        world.setBlock(i + 16, j + 10, k + 20, 17, 3, 2);
        world.setBlock(i + 16, j + 10, k + 19, 17, 3, 2);
        world.setBlock(i + 16, j + 10, k + 18, 17, 3, 2);
        world.setBlock(i + 16, j + 10, k + 17, 17, 3, 2);
        world.setBlock(i + 16, j + 10, k + 16, 17, 3, 2);
        world.setBlock(i + 17, j + 10, k + 22, 17, 3, 2);
        world.setBlock(i + 17, j + 10, k + 21, 17, 3, 2);
        world.setBlock(i + 17, j + 10, k + 20, 17, 3, 2);
        world.setBlock(i + 17, j + 10, k + 19, 17, 3, 2);
        world.setBlock(i + 17, j + 10, k + 18, 17, 3, 2);
        world.setBlock(i + 17, j + 10, k + 17, 17, 3, 2);
        world.setBlock(i + 17, j + 10, k + 16, 17, 3, 2);
        world.setBlock(i + 18, j + 10, k + 21, 17, 3, 2);
        world.setBlock(i + 18, j + 10, k + 20, 17, 3, 2);
        world.setBlock(i + 18, j + 10, k + 19, 17, 3, 2);
        world.setBlock(i + 18, j + 10, k + 18, 17, 3, 2);
        world.setBlock(i + 18, j + 10, k + 17, 17, 3, 2);
        world.setBlock(i + 18, j + 10, k + 16, 17, 3, 2);
        world.setBlock(i + 19, j + 10, k + 20, 17, 3, 2);
        world.setBlock(i + 19, j + 10, k + 19, 17, 3, 2);
        world.setBlock(i + 19, j + 10, k + 18, 17, 3, 2);
        world.setBlock(i + 19, j + 10, k + 17, 17, 3, 2);
        world.setBlock(i + 13, j + 11, k + 20, 17, 3, 2);
        world.setBlock(i + 13, j + 11, k + 19, 17, 3, 2);
        world.setBlock(i + 13, j + 11, k + 18, 17, 3, 2);
        world.setBlock(i + 13, j + 11, k + 17, 17, 3, 2);
        world.setBlock(i + 14, j + 11, k + 21, 17, 3, 2);
        world.setBlock(i + 14, j + 11, k + 20, 17, 3, 2);
        world.setBlock(i + 14, j + 11, k + 19, 17, 3, 2);
        world.setBlock(i + 14, j + 11, k + 18, 17, 3, 2);
        world.setBlock(i + 14, j + 11, k + 17, 17, 3, 2);
        world.setBlock(i + 14, j + 11, k + 16, 17, 3, 2);
        world.setBlock(i + 15, j + 11, k + 22, 17, 3, 2);
        world.setBlock(i + 15, j + 11, k + 21, 17, 3, 2);
        world.setBlock(i + 15, j + 11, k + 20, 17, 3, 2);
        world.setBlock(i + 15, j + 11, k + 19, 17, 3, 2);
        world.setBlock(i + 15, j + 11, k + 18, 17, 3, 2);
        world.setBlock(i + 15, j + 11, k + 17, 17, 3, 2);
        world.setBlock(i + 15, j + 11, k + 16, 17, 3, 2);
        world.setBlock(i + 16, j + 11, k + 22, 17, 3, 2);
        world.setBlock(i + 16, j + 11, k + 21, 17, 3, 2);
        world.setBlock(i + 16, j + 11, k + 20, 17, 3, 2);
        world.setBlock(i + 16, j + 11, k + 19, 17, 3, 2);
        world.setBlock(i + 16, j + 11, k + 18, 17, 3, 2);
        world.setBlock(i + 16, j + 11, k + 17, 17, 3, 2);
        world.setBlock(i + 16, j + 11, k + 16, 17, 3, 2);
        world.setBlock(i + 17, j + 11, k + 22, 17, 3, 2);
        world.setBlock(i + 17, j + 11, k + 21, 17, 3, 2);
        world.setBlock(i + 17, j + 11, k + 20, 17, 3, 2);
        world.setBlock(i + 17, j + 11, k + 19, 17, 3, 2);
        world.setBlock(i + 17, j + 11, k + 18, 17, 3, 2);
        world.setBlock(i + 17, j + 11, k + 17, 17, 3, 2);
        world.setBlock(i + 17, j + 11, k + 16, 17, 3, 2);
        world.setBlock(i + 18, j + 11, k + 21, 17, 3, 2);
        world.setBlock(i + 18, j + 11, k + 20, 17, 3, 2);
        world.setBlock(i + 18, j + 11, k + 19, 17, 3, 2);
        world.setBlock(i + 18, j + 11, k + 18, 17, 3, 2);
        world.setBlock(i + 18, j + 11, k + 17, 17, 3, 2);
        world.setBlock(i + 18, j + 11, k + 16, 17, 3, 2);
        world.setBlock(i + 19, j + 11, k + 20, 17, 3, 2);
        world.setBlock(i + 19, j + 11, k + 19, 17, 3, 2);
        world.setBlock(i + 19, j + 11, k + 18, 17, 3, 2);
        world.setBlock(i + 19, j + 11, k + 17, 17, 3, 2);
        world.setBlock(i + 13, j + 12, k + 20, 17, 3, 2);
        world.setBlock(i + 13, j + 12, k + 19, 17, 3, 2);
        world.setBlock(i + 13, j + 12, k + 18, 17, 3, 2);
        world.setBlock(i + 13, j + 12, k + 17, 17, 3, 2);
        world.setBlock(i + 14, j + 12, k + 21, 17, 3, 2);
        world.setBlock(i + 14, j + 12, k + 20, 17, 3, 2);
        world.setBlock(i + 14, j + 12, k + 19, 17, 3, 2);
        world.setBlock(i + 14, j + 12, k + 18, 17, 3, 2);
        world.setBlock(i + 14, j + 12, k + 17, 17, 3, 2);
        world.setBlock(i + 14, j + 12, k + 16, 17, 3, 2);
        world.setBlock(i + 15, j + 12, k + 22, 17, 3, 2);
        world.setBlock(i + 15, j + 12, k + 21, 17, 3, 2);
        world.setBlock(i + 15, j + 12, k + 20, 17, 3, 2);
        world.setBlock(i + 15, j + 12, k + 19, 17, 3, 2);
        world.setBlock(i + 15, j + 12, k + 18, 17, 3, 2);
        world.setBlock(i + 15, j + 12, k + 17, 17, 3, 2);
        world.setBlock(i + 15, j + 12, k + 16, 17, 3, 2);
        world.setBlock(i + 16, j + 12, k + 22, 17, 3, 2);
        world.setBlock(i + 16, j + 12, k + 21, 17, 3, 2);
        world.setBlock(i + 16, j + 12, k + 20, 17, 3, 2);
        world.setBlock(i + 16, j + 12, k + 19, 17, 3, 2);
        world.setBlock(i + 16, j + 12, k + 18, 17, 3, 2);
        world.setBlock(i + 16, j + 12, k + 17, 17, 3, 2);
        world.setBlock(i + 16, j + 12, k + 16, 17, 3, 2);
        world.setBlock(i + 17, j + 12, k + 22, 17, 3, 2);
        world.setBlock(i + 17, j + 12, k + 21, 17, 3, 2);
        world.setBlock(i + 17, j + 12, k + 20, 17, 3, 2);
        world.setBlock(i + 17, j + 12, k + 19, 17, 3, 2);
        world.setBlock(i + 17, j + 12, k + 18, 17, 3, 2);
        world.setBlock(i + 17, j + 12, k + 17, 17, 3, 2);
        world.setBlock(i + 17, j + 12, k + 16, 17, 3, 2);
        world.setBlock(i + 18, j + 12, k + 21, 17, 3, 2);
        world.setBlock(i + 18, j + 12, k + 20, 17, 3, 2);
        world.setBlock(i + 18, j + 12, k + 19, 17, 3, 2);
        world.setBlock(i + 18, j + 12, k + 18, 17, 3, 2);
        world.setBlock(i + 18, j + 12, k + 17, 17, 3, 2);
        world.setBlock(i + 18, j + 12, k + 16, 17, 3, 2);
        world.setBlock(i + 19, j + 12, k + 20, 17, 3, 2);
        world.setBlock(i + 19, j + 12, k + 19, 17, 3, 2);
        world.setBlock(i + 19, j + 12, k + 18, 17, 3, 2);
        world.setBlock(i + 19, j + 12, k + 17, 17, 3, 2);
        world.setBlock(i + 13, j + 13, k + 20, 17, 3, 2);
        world.setBlock(i + 13, j + 13, k + 19, 17, 3, 2);
        world.setBlock(i + 13, j + 13, k + 18, 17, 3, 2);
        world.setBlock(i + 13, j + 13, k + 17, 17, 3, 2);
        world.setBlock(i + 14, j + 13, k + 21, 17, 3, 2);
        world.setBlock(i + 14, j + 13, k + 20, 17, 3, 2);
        world.setBlock(i + 14, j + 13, k + 19, 17, 3, 2);
        world.setBlock(i + 14, j + 13, k + 18, 17, 3, 2);
        world.setBlock(i + 14, j + 13, k + 17, 17, 3, 2);
        world.setBlock(i + 14, j + 13, k + 16, 17, 3, 2);
        world.setBlock(i + 15, j + 13, k + 22, 17, 3, 2);
        world.setBlock(i + 15, j + 13, k + 21, 17, 3, 2);
        world.setBlock(i + 15, j + 13, k + 20, 17, 3, 2);
        world.setBlock(i + 15, j + 13, k + 19, 17, 3, 2);
        world.setBlock(i + 15, j + 13, k + 18, 17, 3, 2);
        world.setBlock(i + 15, j + 13, k + 17, 17, 3, 2);
        world.setBlock(i + 15, j + 13, k + 16, 17, 3, 2);
        world.setBlock(i + 16, j + 13, k + 22, 17, 3, 2);
        world.setBlock(i + 16, j + 13, k + 21, 17, 3, 2);
        world.setBlock(i + 16, j + 13, k + 20, 17, 3, 2);
        world.setBlock(i + 16, j + 13, k + 19, 17, 3, 2);
        world.setBlock(i + 16, j + 13, k + 18, 17, 3, 2);
        world.setBlock(i + 16, j + 13, k + 17, 17, 3, 2);
        world.setBlock(i + 16, j + 13, k + 16, 17, 3, 2);
        world.setBlock(i + 17, j + 13, k + 22, 17, 3, 2);
        world.setBlock(i + 17, j + 13, k + 21, 17, 3, 2);
        world.setBlock(i + 17, j + 13, k + 20, 17, 3, 2);
        world.setBlock(i + 17, j + 13, k + 19, 17, 3, 2);
        world.setBlock(i + 17, j + 13, k + 18, 17, 3, 2);
        world.setBlock(i + 17, j + 13, k + 17, 17, 3, 2);
        world.setBlock(i + 17, j + 13, k + 16, 17, 3, 2);
        world.setBlock(i + 18, j + 13, k + 21, 17, 3, 2);
        world.setBlock(i + 18, j + 13, k + 20, 17, 3, 2);
        world.setBlock(i + 18, j + 13, k + 19, 17, 3, 2);
        world.setBlock(i + 18, j + 13, k + 18, 17, 3, 2);
        world.setBlock(i + 18, j + 13, k + 17, 17, 3, 2);
        world.setBlock(i + 18, j + 13, k + 16, 17, 3, 2);
        world.setBlock(i + 19, j + 13, k + 20, 17, 3, 2);
        world.setBlock(i + 19, j + 13, k + 19, 17, 3, 2);
        world.setBlock(i + 19, j + 13, k + 18, 17, 3, 2);
        world.setBlock(i + 19, j + 13, k + 17, 17, 3, 2);
        world.setBlock(i + 13, j + 14, k + 20, 17, 3, 2);
        world.setBlock(i + 13, j + 14, k + 19, 17, 3, 2);
        world.setBlock(i + 13, j + 14, k + 18, 17, 3, 2);
        world.setBlock(i + 13, j + 14, k + 17, 17, 3, 2);
        world.setBlock(i + 14, j + 14, k + 21, 17, 3, 2);
        world.setBlock(i + 14, j + 14, k + 20, 17, 3, 2);
        world.setBlock(i + 14, j + 14, k + 19, 17, 3, 2);
        world.setBlock(i + 14, j + 14, k + 18, 17, 3, 2);
        world.setBlock(i + 14, j + 14, k + 17, 17, 3, 2);
        world.setBlock(i + 14, j + 14, k + 16, 17, 3, 2);
        world.setBlock(i + 15, j + 14, k + 22, 17, 3, 2);
        world.setBlock(i + 15, j + 14, k + 21, 17, 3, 2);
        world.setBlock(i + 15, j + 14, k + 20, 17, 3, 2);
        world.setBlock(i + 15, j + 14, k + 19, 17, 3, 2);
        world.setBlock(i + 15, j + 14, k + 18, 17, 3, 2);
        world.setBlock(i + 15, j + 14, k + 17, 17, 3, 2);
        world.setBlock(i + 15, j + 14, k + 16, 17, 3, 2);
        world.setBlock(i + 16, j + 14, k + 22, 17, 3, 2);
        world.setBlock(i + 16, j + 14, k + 21, 17, 3, 2);
        world.setBlock(i + 16, j + 14, k + 20, 17, 3, 2);
        world.setBlock(i + 16, j + 14, k + 19, 17, 3, 2);
        world.setBlock(i + 16, j + 14, k + 18, 17, 3, 2);
        world.setBlock(i + 16, j + 14, k + 17, 17, 3, 2);
        world.setBlock(i + 16, j + 14, k + 16, 17, 3, 2);
        world.setBlock(i + 17, j + 14, k + 22, 17, 3, 2);
        world.setBlock(i + 17, j + 14, k + 21, 17, 3, 2);
        world.setBlock(i + 17, j + 14, k + 20, 17, 3, 2);
        world.setBlock(i + 17, j + 14, k + 19, 17, 3, 2);
        world.setBlock(i + 17, j + 14, k + 18, 17, 3, 2);
        world.setBlock(i + 17, j + 14, k + 17, 17, 3, 2);
        world.setBlock(i + 17, j + 14, k + 16, 17, 3, 2);
        world.setBlock(i + 18, j + 14, k + 21, 17, 3, 2);
        world.setBlock(i + 18, j + 14, k + 20, 17, 3, 2);
        world.setBlock(i + 18, j + 14, k + 19, 17, 3, 2);
        world.setBlock(i + 18, j + 14, k + 18, 17, 3, 2);
        world.setBlock(i + 18, j + 14, k + 17, 17, 3, 2);
        world.setBlock(i + 18, j + 14, k + 16, 17, 3, 2);
        world.setBlock(i + 19, j + 14, k + 20, 17, 3, 2);
        world.setBlock(i + 19, j + 14, k + 19, 17, 3, 2);
        world.setBlock(i + 19, j + 14, k + 18, 17, 3, 2);
        world.setBlock(i + 19, j + 14, k + 17, 17, 3, 2);
        world.setBlock(i + 13, j + 15, k + 20, 17, 3, 2);
        world.setBlock(i + 13, j + 15, k + 19, 17, 3, 2);
        world.setBlock(i + 13, j + 15, k + 18, 17, 3, 2);
        world.setBlock(i + 14, j + 15, k + 21, 17, 3, 2);
        world.setBlock(i + 14, j + 15, k + 20, 17, 3, 2);
        world.setBlock(i + 14, j + 15, k + 19, 17, 3, 2);
        world.setBlock(i + 14, j + 15, k + 18, 17, 3, 2);
        world.setBlock(i + 15, j + 15, k + 22, 17, 3, 2);
        world.setBlock(i + 15, j + 15, k + 21, 17, 3, 2);
        world.setBlock(i + 15, j + 15, k + 20, 17, 3, 2);
        world.setBlock(i + 15, j + 15, k + 19, 17, 3, 2);
        world.setBlock(i + 15, j + 15, k + 18, 17, 3, 2);
        world.setBlock(i + 15, j + 15, k + 17, 17, 3, 2);
        world.setBlock(i + 16, j + 15, k + 22, 17, 3, 2);
        world.setBlock(i + 16, j + 15, k + 21, 17, 3, 2);
        world.setBlock(i + 16, j + 15, k + 20, 17, 3, 2);
        world.setBlock(i + 16, j + 15, k + 19, 17, 3, 2);
        world.setBlock(i + 16, j + 15, k + 18, 17, 3, 2);
        world.setBlock(i + 16, j + 15, k + 17, 17, 3, 2);
        world.setBlock(i + 16, j + 15, k + 16, 17, 3, 2);
        world.setBlock(i + 17, j + 15, k + 22, 17, 3, 2);
        world.setBlock(i + 17, j + 15, k + 21, 17, 3, 2);
        world.setBlock(i + 17, j + 15, k + 20, 17, 3, 2);
        world.setBlock(i + 17, j + 15, k + 19, 17, 3, 2);
        world.setBlock(i + 17, j + 15, k + 18, 17, 3, 2);
        world.setBlock(i + 17, j + 15, k + 17, 17, 3, 2);
        world.setBlock(i + 17, j + 15, k + 16, 17, 3, 2);
        world.setBlock(i + 18, j + 15, k + 21, 17, 3, 2);
        world.setBlock(i + 18, j + 15, k + 20, 17, 3, 2);
        world.setBlock(i + 18, j + 15, k + 19, 17, 3, 2);
        world.setBlock(i + 18, j + 15, k + 18, 17, 3, 2);
        world.setBlock(i + 18, j + 15, k + 17, 17, 3, 2);
        world.setBlock(i + 19, j + 15, k + 20, 17, 3, 2);
        world.setBlock(i + 19, j + 15, k + 19, 17, 3, 2);
        world.setBlock(i + 19, j + 15, k + 18, 17, 3, 2);
        world.setBlock(i + 13, j + 16, k + 20, 17, 3, 2);
        world.setBlock(i + 13, j + 16, k + 19, 17, 3, 2);
        world.setBlock(i + 13, j + 16, k + 18, 17, 3, 2);
        world.setBlock(i + 14, j + 16, k + 21, 17, 3, 2);
        world.setBlock(i + 14, j + 16, k + 20, 17, 3, 2);
        world.setBlock(i + 14, j + 16, k + 19, 17, 3, 2);
        world.setBlock(i + 14, j + 16, k + 18, 17, 3, 2);
        world.setBlock(i + 15, j + 16, k + 22, 17, 3, 2);
        world.setBlock(i + 15, j + 16, k + 21, 17, 3, 2);
        world.setBlock(i + 15, j + 16, k + 20, 17, 3, 2);
        world.setBlock(i + 15, j + 16, k + 19, 17, 3, 2);
        world.setBlock(i + 15, j + 16, k + 18, 17, 3, 2);
        world.setBlock(i + 15, j + 16, k + 17, 17, 3, 2);
        world.setBlock(i + 16, j + 16, k + 22, 17, 3, 2);
        world.setBlock(i + 16, j + 16, k + 21, 17, 3, 2);
        world.setBlock(i + 16, j + 16, k + 20, 17, 3, 2);
        world.setBlock(i + 16, j + 16, k + 19, 17, 3, 2);
        world.setBlock(i + 16, j + 16, k + 18, 17, 3, 2);
        world.setBlock(i + 16, j + 16, k + 17, 17, 3, 2);
        world.setBlock(i + 17, j + 16, k + 22, 17, 3, 2);
        world.setBlock(i + 17, j + 16, k + 21, 17, 3, 2);
        world.setBlock(i + 17, j + 16, k + 20, 17, 3, 2);
        world.setBlock(i + 17, j + 16, k + 19, 17, 3, 2);
        world.setBlock(i + 17, j + 16, k + 18, 17, 3, 2);
        world.setBlock(i + 17, j + 16, k + 17, 17, 3, 2);
        world.setBlock(i + 17, j + 16, k + 16, 17, 3, 2);
        world.setBlock(i + 18, j + 16, k + 21, 17, 3, 2);
        world.setBlock(i + 18, j + 16, k + 20, 17, 3, 2);
        world.setBlock(i + 18, j + 16, k + 19, 17, 3, 2);
        world.setBlock(i + 18, j + 16, k + 18, 17, 3, 2);
        world.setBlock(i + 18, j + 16, k + 17, 17, 3, 2);
        world.setBlock(i + 19, j + 16, k + 20, 17, 3, 2);
        world.setBlock(i + 19, j + 16, k + 19, 17, 3, 2);
        world.setBlock(i + 19, j + 16, k + 18, 17, 3, 2);
        world.setBlock(i + 13, j + 17, k + 20, 17, 3, 2);
        world.setBlock(i + 13, j + 17, k + 19, 17, 3, 2);
        world.setBlock(i + 13, j + 17, k + 18, 17, 3, 2);
        world.setBlock(i + 14, j + 17, k + 21, 17, 3, 2);
        world.setBlock(i + 14, j + 17, k + 20, 17, 3, 2);
        world.setBlock(i + 14, j + 17, k + 19, 17, 3, 2);
        world.setBlock(i + 14, j + 17, k + 18, 17, 3, 2);
        world.setBlock(i + 15, j + 17, k + 22, 17, 3, 2);
        world.setBlock(i + 15, j + 17, k + 21, 17, 3, 2);
        world.setBlock(i + 15, j + 17, k + 20, 17, 3, 2);
        world.setBlock(i + 15, j + 17, k + 19, 17, 3, 2);
        world.setBlock(i + 15, j + 17, k + 18, 17, 3, 2);
        world.setBlock(i + 15, j + 17, k + 17, 17, 3, 2);
        world.setBlock(i + 16, j + 17, k + 22, 17, 3, 2);
        world.setBlock(i + 16, j + 17, k + 21, 17, 3, 2);
        world.setBlock(i + 16, j + 17, k + 20, 17, 3, 2);
        world.setBlock(i + 16, j + 17, k + 19, 17, 3, 2);
        world.setBlock(i + 16, j + 17, k + 18, 17, 3, 2);
        world.setBlock(i + 16, j + 17, k + 17, 17, 3, 2);
        world.setBlock(i + 17, j + 17, k + 22, 17, 3, 2);
        world.setBlock(i + 17, j + 17, k + 21, 17, 3, 2);
        world.setBlock(i + 17, j + 17, k + 20, 17, 3, 2);
        world.setBlock(i + 17, j + 17, k + 19, 17, 3, 2);
        world.setBlock(i + 17, j + 17, k + 18, 17, 3, 2);
        world.setBlock(i + 17, j + 17, k + 17, 17, 3, 2);
        world.setBlock(i + 18, j + 17, k + 21, 17, 3, 2);
        world.setBlock(i + 18, j + 17, k + 20, 17, 3, 2);
        world.setBlock(i + 18, j + 17, k + 19, 17, 3, 2);
        world.setBlock(i + 18, j + 17, k + 18, 17, 3, 2);
        world.setBlock(i + 18, j + 17, k + 17, 17, 3, 2);
        world.setBlock(i + 19, j + 17, k + 20, 17, 3, 2);
        world.setBlock(i + 19, j + 17, k + 19, 17, 3, 2);
        world.setBlock(i + 19, j + 17, k + 18, 17, 3, 2);
        world.setBlock(i + 13, j + 18, k + 20, 17, 3, 2);
        world.setBlock(i + 13, j + 18, k + 19, 17, 3, 2);
        world.setBlock(i + 13, j + 18, k + 18, 17, 3, 2);
        world.setBlock(i + 14, j + 18, k + 21, 17, 3, 2);
        world.setBlock(i + 14, j + 18, k + 20, 17, 3, 2);
        world.setBlock(i + 14, j + 18, k + 19, 17, 3, 2);
        world.setBlock(i + 14, j + 18, k + 18, 17, 3, 2);
        world.setBlock(i + 15, j + 18, k + 22, 17, 3, 2);
        world.setBlock(i + 15, j + 18, k + 21, 17, 3, 2);
        world.setBlock(i + 15, j + 18, k + 20, 17, 3, 2);
        world.setBlock(i + 15, j + 18, k + 19, 17, 3, 2);
        world.setBlock(i + 15, j + 18, k + 18, 17, 3, 2);
        world.setBlock(i + 15, j + 18, k + 17, 17, 3, 2);
        world.setBlock(i + 16, j + 18, k + 22, 17, 3, 2);
        world.setBlock(i + 16, j + 18, k + 21, 17, 3, 2);
        world.setBlock(i + 16, j + 18, k + 20, 17, 3, 2);
        world.setBlock(i + 16, j + 18, k + 19, 17, 3, 2);
        world.setBlock(i + 16, j + 18, k + 18, 17, 3, 2);
        world.setBlock(i + 16, j + 18, k + 17, 17, 3, 2);
        world.setBlock(i + 17, j + 18, k + 22, 17, 3, 2);
        world.setBlock(i + 17, j + 18, k + 21, 17, 3, 2);
        world.setBlock(i + 17, j + 18, k + 20, 17, 3, 2);
        world.setBlock(i + 17, j + 18, k + 19, 17, 3, 2);
        world.setBlock(i + 17, j + 18, k + 18, 17, 3, 2);
        world.setBlock(i + 17, j + 18, k + 17, 17, 3, 2);
        world.setBlock(i + 18, j + 18, k + 21, 17, 3, 2);
        world.setBlock(i + 18, j + 18, k + 20, 17, 3, 2);
        world.setBlock(i + 18, j + 18, k + 19, 17, 3, 2);
        world.setBlock(i + 18, j + 18, k + 18, 17, 3, 2);
        world.setBlock(i + 18, j + 18, k + 17, 17, 3, 2);
        world.setBlock(i + 19, j + 18, k + 20, 17, 3, 2);
        world.setBlock(i + 19, j + 18, k + 19, 17, 3, 2);
        world.setBlock(i + 19, j + 18, k + 18, 17, 3, 2);
        world.setBlock(i + 13, j + 19, k + 20, 17, 3, 2);
        world.setBlock(i + 13, j + 19, k + 19, 17, 3, 2);
        world.setBlock(i + 13, j + 19, k + 18, 17, 3, 2);
        world.setBlock(i + 14, j + 19, k + 20, 17, 3, 2);
        world.setBlock(i + 14, j + 19, k + 19, 17, 3, 2);
        world.setBlock(i + 14, j + 19, k + 18, 17, 3, 2);
        world.setBlock(i + 15, j + 19, k + 22, 17, 3, 2);
        world.setBlock(i + 15, j + 19, k + 21, 17, 3, 2);
        world.setBlock(i + 15, j + 19, k + 20, 17, 3, 2);
        world.setBlock(i + 15, j + 19, k + 19, 17, 3, 2);
        world.setBlock(i + 15, j + 19, k + 18, 17, 3, 2);
        world.setBlock(i + 15, j + 19, k + 17, 17, 3, 2);
        world.setBlock(i + 16, j + 19, k + 22, 17, 3, 2);
        world.setBlock(i + 16, j + 19, k + 21, 17, 3, 2);
        world.setBlock(i + 16, j + 19, k + 20, 17, 3, 2);
        world.setBlock(i + 16, j + 19, k + 19, 17, 3, 2);
        world.setBlock(i + 16, j + 19, k + 18, 17, 3, 2);
        world.setBlock(i + 16, j + 19, k + 17, 17, 3, 2);
        world.setBlock(i + 17, j + 19, k + 22, 17, 3, 2);
        world.setBlock(i + 17, j + 19, k + 21, 17, 3, 2);
        world.setBlock(i + 17, j + 19, k + 20, 17, 3, 2);
        world.setBlock(i + 17, j + 19, k + 19, 17, 3, 2);
        world.setBlock(i + 17, j + 19, k + 18, 17, 3, 2);
        world.setBlock(i + 17, j + 19, k + 17, 17, 3, 2);
        world.setBlock(i + 18, j + 19, k + 21, 17, 3, 2);
        world.setBlock(i + 18, j + 19, k + 20, 17, 3, 2);
        world.setBlock(i + 18, j + 19, k + 19, 17, 3, 2);
        world.setBlock(i + 18, j + 19, k + 18, 17, 3, 2);
        world.setBlock(i + 18, j + 19, k + 17, 17, 3, 2);
        world.setBlock(i + 19, j + 19, k + 20, 17, 3, 2);
        world.setBlock(i + 19, j + 19, k + 19, 17, 3, 2);
        world.setBlock(i + 19, j + 19, k + 18, 17, 3, 2);
        world.setBlock(i + 13, j + 20, k + 20, 17, 3, 2);
        world.setBlock(i + 13, j + 20, k + 19, 17, 3, 2);
        world.setBlock(i + 13, j + 20, k + 18, 17, 3, 2);
        world.setBlock(i + 14, j + 20, k + 20, 17, 3, 2);
        world.setBlock(i + 14, j + 20, k + 19, 17, 3, 2);
        world.setBlock(i + 14, j + 20, k + 18, 17, 3, 2);
        world.setBlock(i + 15, j + 20, k + 21, 17, 3, 2);
        world.setBlock(i + 15, j + 20, k + 20, 17, 3, 2);
        world.setBlock(i + 15, j + 20, k + 19, 17, 3, 2);
        world.setBlock(i + 15, j + 20, k + 18, 17, 3, 2);
        world.setBlock(i + 15, j + 20, k + 17, 17, 3, 2);
        world.setBlock(i + 16, j + 20, k + 22, 17, 3, 2);
        world.setBlock(i + 16, j + 20, k + 21, 17, 3, 2);
        world.setBlock(i + 16, j + 20, k + 20, 17, 3, 2);
        world.setBlock(i + 16, j + 20, k + 19, 17, 3, 2);
        world.setBlock(i + 16, j + 20, k + 18, 17, 3, 2);
        world.setBlock(i + 16, j + 20, k + 17, 17, 3, 2);
        world.setBlock(i + 17, j + 20, k + 22, 17, 3, 2);
        world.setBlock(i + 17, j + 20, k + 21, 17, 3, 2);
        world.setBlock(i + 17, j + 20, k + 20, 17, 3, 2);
        world.setBlock(i + 17, j + 20, k + 19, 17, 3, 2);
        world.setBlock(i + 17, j + 20, k + 18, 17, 3, 2);
        world.setBlock(i + 17, j + 20, k + 17, 17, 3, 2);
        world.setBlock(i + 18, j + 20, k + 21, 17, 3, 2);
        world.setBlock(i + 18, j + 20, k + 20, 17, 3, 2);
        world.setBlock(i + 18, j + 20, k + 19, 17, 3, 2);
        world.setBlock(i + 18, j + 20, k + 18, 17, 3, 2);
        world.setBlock(i + 18, j + 20, k + 17, 17, 3, 2);
        world.setBlock(i + 19, j + 20, k + 20, 17, 3, 2);
        world.setBlock(i + 19, j + 20, k + 19, 17, 3, 2);
        world.setBlock(i + 19, j + 20, k + 18, 17, 3, 2);
        world.setBlock(i + 13, j + 21, k + 19, 17, 3, 2);
        world.setBlock(i + 13, j + 21, k + 18, 17, 3, 2);
        world.setBlock(i + 14, j + 21, k + 20, 17, 3, 2);
        world.setBlock(i + 14, j + 21, k + 19, 17, 3, 2);
        world.setBlock(i + 14, j + 21, k + 18, 17, 3, 2);
        world.setBlock(i + 15, j + 21, k + 21, 17, 3, 2);
        world.setBlock(i + 15, j + 21, k + 20, 17, 3, 2);
        world.setBlock(i + 15, j + 21, k + 19, 17, 3, 2);
        world.setBlock(i + 15, j + 21, k + 18, 17, 3, 2);
        world.setBlock(i + 15, j + 21, k + 17, 17, 3, 2);
        world.setBlock(i + 16, j + 21, k + 21, 17, 3, 2);
        world.setBlock(i + 16, j + 21, k + 20, 17, 3, 2);
        world.setBlock(i + 16, j + 21, k + 19, 17, 3, 2);
        world.setBlock(i + 16, j + 21, k + 18, 17, 3, 2);
        world.setBlock(i + 16, j + 21, k + 17, 17, 3, 2);
        world.setBlock(i + 17, j + 21, k + 22, 17, 3, 2);
        world.setBlock(i + 17, j + 21, k + 21, 17, 3, 2);
        world.setBlock(i + 17, j + 21, k + 20, 17, 3, 2);
        world.setBlock(i + 17, j + 21, k + 19, 17, 3, 2);
        world.setBlock(i + 17, j + 21, k + 18, 17, 3, 2);
        world.setBlock(i + 17, j + 21, k + 17, 17, 3, 2);
        world.setBlock(i + 18, j + 21, k + 21, 17, 3, 2);
        world.setBlock(i + 18, j + 21, k + 20, 17, 3, 2);
        world.setBlock(i + 18, j + 21, k + 19, 17, 3, 2);
        world.setBlock(i + 18, j + 21, k + 18, 17, 3, 2);
        world.setBlock(i + 18, j + 21, k + 17, 17, 3, 2);
        world.setBlock(i + 19, j + 21, k + 20, 17, 3, 2);
        world.setBlock(i + 19, j + 21, k + 19, 17, 3, 2);
        world.setBlock(i + 13, j + 22, k + 18, 17, 3, 2);
        world.setBlock(i + 14, j + 22, k + 20, 17, 3, 2);
        world.setBlock(i + 14, j + 22, k + 19, 17, 3, 2);
        world.setBlock(i + 14, j + 22, k + 18, 17, 3, 2);
        world.setBlock(i + 15, j + 22, k + 21, 17, 3, 2);
        world.setBlock(i + 15, j + 22, k + 20, 17, 3, 2);
        world.setBlock(i + 15, j + 22, k + 19, 17, 3, 2);
        world.setBlock(i + 15, j + 22, k + 18, 17, 3, 2);
        world.setBlock(i + 15, j + 22, k + 17, 17, 3, 2);
        world.setBlock(i + 16, j + 22, k + 21, 17, 3, 2);
        world.setBlock(i + 16, j + 22, k + 20, 17, 3, 2);
        world.setBlock(i + 16, j + 22, k + 19, 17, 3, 2);
        world.setBlock(i + 16, j + 22, k + 18, 17, 3, 2);
        world.setBlock(i + 16, j + 22, k + 17, 17, 3, 2);
        world.setBlock(i + 17, j + 22, k + 22, 17, 3, 2);
        world.setBlock(i + 17, j + 22, k + 21, 17, 3, 2);
        world.setBlock(i + 17, j + 22, k + 20, 17, 3, 2);
        world.setBlock(i + 17, j + 22, k + 19, 17, 3, 2);
        world.setBlock(i + 17, j + 22, k + 18, 17, 3, 2);
        world.setBlock(i + 17, j + 22, k + 17, 17, 3, 2);
        world.setBlock(i + 18, j + 22, k + 21, 17, 3, 2);
        world.setBlock(i + 18, j + 22, k + 20, 17, 3, 2);
        world.setBlock(i + 18, j + 22, k + 19, 17, 3, 2);
        world.setBlock(i + 18, j + 22, k + 18, 17, 3, 2);
        world.setBlock(i + 19, j + 22, k + 20, 17, 3, 2);
        world.setBlock(i + 14, j + 23, k + 20, 17, 3, 2);
        world.setBlock(i + 14, j + 23, k + 19, 17, 3, 2);
        world.setBlock(i + 14, j + 23, k + 18, 17, 3, 2);
        world.setBlock(i + 15, j + 23, k + 20, 17, 3, 2);
        world.setBlock(i + 15, j + 23, k + 19, 17, 3, 2);
        world.setBlock(i + 15, j + 23, k + 18, 17, 3, 2);
        world.setBlock(i + 16, j + 23, k + 21, 17, 3, 2);
        world.setBlock(i + 16, j + 23, k + 20, 17, 3, 2);
        world.setBlock(i + 16, j + 23, k + 19, 17, 3, 2);
        world.setBlock(i + 16, j + 23, k + 18, 17, 3, 2);
        world.setBlock(i + 16, j + 23, k + 17, 17, 3, 2);
        world.setBlock(i + 17, j + 23, k + 21, 17, 3, 2);
        world.setBlock(i + 17, j + 23, k + 20, 17, 3, 2);
        world.setBlock(i + 17, j + 23, k + 19, 17, 3, 2);
        world.setBlock(i + 17, j + 23, k + 18, 17, 3, 2);
        world.setBlock(i + 17, j + 23, k + 17, 17, 3, 2);
        world.setBlock(i + 18, j + 23, k + 21, 17, 3, 2);
        world.setBlock(i + 18, j + 23, k + 20, 17, 3, 2);
        world.setBlock(i + 18, j + 23, k + 19, 17, 3, 2);
        world.setBlock(i + 18, j + 23, k + 18, 17, 3, 2);
        world.setBlock(i + 19, j + 23, k + 20, 17, 3, 2);
        world.setBlock(i + 14, j + 24, k + 20, 17, 3, 2);
        world.setBlock(i + 14, j + 24, k + 19, 17, 3, 2);
        world.setBlock(i + 14, j + 24, k + 18, 17, 3, 2);
        world.setBlock(i + 15, j + 24, k + 20, 17, 3, 2);
        world.setBlock(i + 15, j + 24, k + 19, 17, 3, 2);
        world.setBlock(i + 15, j + 24, k + 18, 17, 3, 2);
        world.setBlock(i + 16, j + 24, k + 20, 17, 3, 2);
        world.setBlock(i + 16, j + 24, k + 19, 17, 3, 2);
        world.setBlock(i + 16, j + 24, k + 18, 17, 3, 2);
        world.setBlock(i + 17, j + 24, k + 21, 17, 3, 2);
        world.setBlock(i + 17, j + 24, k + 20, 17, 3, 2);
        world.setBlock(i + 17, j + 24, k + 19, 17, 3, 2);
        world.setBlock(i + 17, j + 24, k + 18, 17, 3, 2);
        world.setBlock(i + 17, j + 24, k + 17, 17, 3, 2);
        world.setBlock(i + 18, j + 24, k + 20, 17, 3, 2);
        world.setBlock(i + 18, j + 24, k + 19, 17, 3, 2);
        world.setBlock(i + 18, j + 24, k + 18, 17, 3, 2);
        world.setBlock(i + 14, j + 25, k + 19, 17, 3, 2);
        world.setBlock(i + 14, j + 25, k + 18, 17, 3, 2);
        world.setBlock(i + 15, j + 25, k + 20, 17, 3, 2);
        world.setBlock(i + 15, j + 25, k + 19, 17, 3, 2);
        world.setBlock(i + 15, j + 25, k + 18, 17, 3, 2);
        world.setBlock(i + 16, j + 25, k + 20, 17, 3, 2);
        world.setBlock(i + 16, j + 25, k + 19, 17, 3, 2);
        world.setBlock(i + 16, j + 25, k + 18, 17, 3, 2);
        world.setBlock(i + 17, j + 25, k + 20, 17, 3, 2);
        world.setBlock(i + 17, j + 25, k + 19, 17, 3, 2);
        world.setBlock(i + 17, j + 25, k + 18, 17, 3, 2);
        world.setBlock(i + 18, j + 25, k + 20, 17, 3, 2);
        world.setBlock(i + 18, j + 25, k + 19, 17, 3, 2);
        world.setBlock(i + 18, j + 25, k + 18, 17, 3, 2);
        world.setBlock(i + 14, j + 26, k + 19, 17, 3, 2);
        world.setBlock(i + 14, j + 26, k + 18, 17, 3, 2);
        world.setBlock(i + 15, j + 26, k + 20, 17, 3, 2);
        world.setBlock(i + 15, j + 26, k + 19, 17, 3, 2);
        world.setBlock(i + 15, j + 26, k + 18, 17, 3, 2);
        world.setBlock(i + 16, j + 26, k + 20, 17, 3, 2);
        world.setBlock(i + 16, j + 26, k + 19, 17, 3, 2);
        world.setBlock(i + 16, j + 26, k + 18, 17, 3, 2);
        world.setBlock(i + 17, j + 26, k + 20, 17, 3, 2);
        world.setBlock(i + 17, j + 26, k + 19, 17, 3, 2);
        world.setBlock(i + 17, j + 26, k + 18, 17, 3, 2);
        world.setBlock(i + 18, j + 26, k + 20, 17, 3, 2);
        world.setBlock(i + 18, j + 26, k + 19, 17, 3, 2);
        world.setBlock(i + 14, j + 27, k + 19, 17, 3, 2);
        world.setBlock(i + 14, j + 27, k + 18, 17, 3, 2);
        world.setBlock(i + 15, j + 27, k + 20, 17, 3, 2);
        world.setBlock(i + 15, j + 27, k + 19, 17, 3, 2);
        world.setBlock(i + 15, j + 27, k + 18, 17, 3, 2);
        world.setBlock(i + 16, j + 27, k + 20, 17, 3, 2);
        world.setBlock(i + 16, j + 27, k + 19, 17, 3, 2);
        world.setBlock(i + 16, j + 27, k + 18, 17, 3, 2);
        world.setBlock(i + 16, j + 27, k + 17, 17, 3, 2);
        world.setBlock(i + 16, j + 27, k + 16, 17, 3, 2);
        world.setBlock(i + 17, j + 27, k + 20, 17, 3, 2);
        world.setBlock(i + 17, j + 27, k + 19, 17, 3, 2);
        world.setBlock(i + 17, j + 27, k + 18, 17, 3, 2);
        world.setBlock(i + 18, j + 27, k + 20, 17, 3, 2);
        world.setBlock(i + 18, j + 27, k + 19, 17, 3, 2);
        world.setBlock(i + 14, j + 28, k + 19, 17, 3, 2);
        world.setBlock(i + 14, j + 28, k + 18, 17, 3, 2);
        world.setBlock(i + 15, j + 28, k + 20, 17, 3, 2);
        world.setBlock(i + 15, j + 28, k + 19, 17, 3, 2);
        world.setBlock(i + 15, j + 28, k + 18, 17, 3, 2);
        world.setBlock(i + 16, j + 28, k + 20, 17, 3, 2);
        world.setBlock(i + 16, j + 28, k + 19, 17, 3, 2);
        world.setBlock(i + 16, j + 28, k + 18, 17, 3, 2);
        world.setBlock(i + 16, j + 28, k + 17, 17, 3, 2);
        world.setBlock(i + 16, j + 28, k + 16, 17, 3, 2);
        world.setBlock(i + 16, j + 28, k + 15, 17, 3, 2);
        world.setBlock(i + 17, j + 28, k + 20, 17, 3, 2);
        world.setBlock(i + 17, j + 28, k + 19, 17, 3, 2);
        world.setBlock(i + 17, j + 28, k + 18, 17, 3, 2);
        world.setBlock(i + 18, j + 28, k + 20, 17, 3, 2);
        world.setBlock(i + 18, j + 28, k + 19, 17, 3, 2);
        world.setBlock(i + 14, j + 29, k + 19, 17, 3, 2);
        world.setBlock(i + 14, j + 29, k + 18, 17, 3, 2);
        world.setBlock(i + 15, j + 29, k + 20, 17, 3, 2);
        world.setBlock(i + 15, j + 29, k + 19, 17, 3, 2);
        world.setBlock(i + 15, j + 29, k + 18, 17, 3, 2);
        world.setBlock(i + 16, j + 29, k + 20, 17, 3, 2);
        world.setBlock(i + 16, j + 29, k + 19, 17, 3, 2);
        world.setBlock(i + 16, j + 29, k + 18, 17, 3, 2);
        world.setBlock(i + 16, j + 29, k + 17, 17, 3, 2);
        world.setBlock(i + 16, j + 29, k + 16, 17, 3, 2);
        world.setBlock(i + 16, j + 29, k + 15, 17, 3, 2);
        world.setBlock(i + 16, j + 29, k + 14, 17, 3, 2);
        world.setBlock(i + 17, j + 29, k + 20, 17, 3, 2);
        world.setBlock(i + 17, j + 29, k + 19, 17, 3, 2);
        world.setBlock(i + 17, j + 29, k + 18, 17, 3, 2);
        world.setBlock(i + 18, j + 29, k + 20, 17, 3, 2);
        world.setBlock(i + 18, j + 29, k + 19, 17, 3, 2);
        world.setBlock(i + 14, j + 30, k + 19, 17, 3, 2);
        world.setBlock(i + 15, j + 30, k + 21, 17, 3, 2);
        world.setBlock(i + 15, j + 30, k + 20, 17, 3, 2);
        world.setBlock(i + 15, j + 30, k + 19, 17, 3, 2);
        world.setBlock(i + 15, j + 30, k + 18, 17, 3, 2);
        world.setBlock(i + 16, j + 30, k + 21, 17, 3, 2);
        world.setBlock(i + 16, j + 30, k + 20, 17, 3, 2);
        world.setBlock(i + 16, j + 30, k + 19, 17, 3, 2);
        world.setBlock(i + 16, j + 30, k + 18, 17, 3, 2);
        world.setBlock(i + 16, j + 30, k + 16, 17, 3, 2);
        world.setBlock(i + 16, j + 30, k + 15, 17, 3, 2);
        world.setBlock(i + 16, j + 30, k + 14, 17, 3, 2);
        world.setBlock(i + 16, j + 30, k + 13, 17, 3, 2);
        world.setBlock(i + 17, j + 30, k + 21, 17, 3, 2);
        world.setBlock(i + 17, j + 30, k + 20, 17, 3, 2);
        world.setBlock(i + 17, j + 30, k + 19, 17, 3, 2);
        world.setBlock(i + 17, j + 30, k + 18, 17, 3, 2);
        world.setBlock(i + 18, j + 30, k + 21, 17, 3, 2);
        world.setBlock(i + 18, j + 30, k + 20, 17, 3, 2);
        world.setBlock(i + 18, j + 30, k + 19, 17, 3, 2);
        world.setBlock(i + 14, j + 31, k + 19, 17, 3, 2);
        world.setBlock(i + 15, j + 31, k + 21, 17, 3, 2);
        world.setBlock(i + 15, j + 31, k + 20, 17, 3, 2);
        world.setBlock(i + 15, j + 31, k + 19, 17, 3, 2);
        world.setBlock(i + 15, j + 31, k + 18, 17, 3, 2);
        world.setBlock(i + 16, j + 31, k + 21, 17, 3, 2);
        world.setBlock(i + 16, j + 31, k + 20, 17, 3, 2);
        world.setBlock(i + 16, j + 31, k + 19, 17, 3, 2);
        world.setBlock(i + 16, j + 31, k + 18, 17, 3, 2);
        world.setBlock(i + 16, j + 31, k + 13, 17, 3, 2);
        world.setBlock(i + 16, j + 31, k + 12, 17, 3, 2);
        world.setBlock(i + 16, j + 31, k + 11, 17, 3, 2);
        world.setBlock(i + 16, j + 31, k + 10, 17, 3, 2);
        world.setBlock(i + 17, j + 31, k + 21, 17, 3, 2);
        world.setBlock(i + 17, j + 31, k + 20, 17, 3, 2);
        world.setBlock(i + 17, j + 31, k + 19, 17, 3, 2);
        world.setBlock(i + 17, j + 31, k + 18, 17, 3, 2);
        world.setBlock(i + 18, j + 31, k + 20, 17, 3, 2);
        world.setBlock(i + 18, j + 31, k + 19, 17, 3, 2);
        world.setBlock(i + 15, j + 32, k + 21, 17, 3, 2);
        world.setBlock(i + 15, j + 32, k + 20, 17, 3, 2);
        world.setBlock(i + 15, j + 32, k + 19, 17, 3, 2);
        world.setBlock(i + 15, j + 32, k + 18, 17, 3, 2);
        world.setBlock(i + 16, j + 32, k + 21, 17, 3, 2);
        world.setBlock(i + 16, j + 32, k + 20, 17, 3, 2);
        world.setBlock(i + 16, j + 32, k + 19, 17, 3, 2);
        world.setBlock(i + 16, j + 32, k + 18, 17, 3, 2);
        world.setBlock(i + 16, j + 32, k + 11, 17, 3, 2);
        world.setBlock(i + 16, j + 32, k + 10, 17, 3, 2);
        world.setBlock(i + 16, j + 32, k + 9, 17, 3, 2);
        world.setBlock(i + 16, j + 32, k + 8, 17, 3, 2);
        world.setBlock(i + 17, j + 32, k + 21, 17, 3, 2);
        world.setBlock(i + 17, j + 32, k + 20, 17, 3, 2);
        world.setBlock(i + 17, j + 32, k + 19, 17, 3, 2);
        world.setBlock(i + 17, j + 32, k + 18, 17, 3, 2);
        world.setBlock(i + 18, j + 32, k + 20, 17, 3, 2);
        world.setBlock(i + 18, j + 32, k + 19, 17, 3, 2);
        world.setBlock(i + 11, j + 33, k + 10, 18, 3, 2);
        world.setBlock(i + 11, j + 33, k + 9, 18, 3, 2);
        world.setBlock(i + 11, j + 33, k + 8, 18, 3, 2);
        world.setBlock(i + 11, j + 33, k + 7, 18, 3, 2);
        world.setBlock(i + 11, j + 33, k + 6, 18, 3, 2);
        world.setBlock(i + 12, j + 33, k + 11, 18, 3, 2);
        world.setBlock(i + 12, j + 33, k + 10, 18, 3, 2);
        world.setBlock(i + 12, j + 33, k + 9, 18, 3, 2);
        world.setBlock(i + 12, j + 33, k + 8, 18, 3, 2);
        world.setBlock(i + 12, j + 33, k + 7, 18, 3, 2);
        world.setBlock(i + 12, j + 33, k + 6, 18, 3, 2);
        world.setBlock(i + 12, j + 33, k + 5, 18, 3, 2);
        world.setBlock(i + 13, j + 33, k + 12, 18, 3, 2);
        world.setBlock(i + 13, j + 33, k + 11, 18, 3, 2);
        world.setBlock(i + 13, j + 33, k + 10, 18, 3, 2);
        world.setBlock(i + 13, j + 33, k + 8, 17, 3, 2);
        world.setBlock(i + 13, j + 33, k + 6, 18, 3, 2);
        world.setBlock(i + 13, j + 33, k + 5, 18, 3, 2);
        world.setBlock(i + 13, j + 33, k + 4, 18, 3, 2);
        world.setBlock(i + 14, j + 33, k + 13, 18, 3, 2);
        world.setBlock(i + 14, j + 33, k + 12, 18, 3, 2);
        world.setBlock(i + 14, j + 33, k + 11, 18, 3, 2);
        world.setBlock(i + 14, j + 33, k + 8, 17, 3, 2);
        world.setBlock(i + 14, j + 33, k + 5, 18, 3, 2);
        world.setBlock(i + 14, j + 33, k + 4, 18, 3, 2);
        world.setBlock(i + 14, j + 33, k + 3, 18, 3, 2);
        world.setBlock(i + 15, j + 33, k + 21, 17, 3, 2);
        world.setBlock(i + 15, j + 33, k + 20, 17, 3, 2);
        world.setBlock(i + 15, j + 33, k + 19, 17, 3, 2);
        world.setBlock(i + 15, j + 33, k + 13, 18, 3, 2);
        world.setBlock(i + 15, j + 33, k + 12, 18, 3, 2);
        world.setBlock(i + 15, j + 33, k + 8, 17, 3, 2);
        world.setBlock(i + 15, j + 33, k + 4, 18, 3, 2);
        world.setBlock(i + 15, j + 33, k + 3, 18, 3, 2);
        world.setBlock(i + 16, j + 33, k + 22, 17, 3, 2);
        world.setBlock(i + 16, j + 33, k + 21, 17, 3, 2);
        world.setBlock(i + 16, j + 33, k + 20, 17, 3, 2);
        world.setBlock(i + 16, j + 33, k + 19, 17, 3, 2);
        world.setBlock(i + 16, j + 33, k + 13, 18, 3, 2);
        world.setBlock(i + 16, j + 33, k + 12, 18, 3, 2);
        world.setBlock(i + 16, j + 33, k + 11, 17, 3, 2);
        world.setBlock(i + 16, j + 33, k + 7, 17, 3, 2);
        world.setBlock(i + 16, j + 33, k + 6, 17, 3, 2);
        world.setBlock(i + 16, j + 33, k + 4, 18, 3, 2);
        world.setBlock(i + 16, j + 33, k + 3, 18, 3, 2);
        world.setBlock(i + 17, j + 33, k + 22, 17, 3, 2);
        world.setBlock(i + 17, j + 33, k + 21, 17, 3, 2);
        world.setBlock(i + 17, j + 33, k + 20, 17, 3, 2);
        world.setBlock(i + 17, j + 33, k + 19, 17, 3, 2);
        world.setBlock(i + 17, j + 33, k + 13, 18, 3, 2);
        world.setBlock(i + 17, j + 33, k + 12, 18, 3, 2);
        world.setBlock(i + 17, j + 33, k + 11, 17, 3, 2);
        world.setBlock(i + 17, j + 33, k + 6, 17, 3, 2);
        world.setBlock(i + 17, j + 33, k + 4, 18, 3, 2);
        world.setBlock(i + 17, j + 33, k + 3, 18, 3, 2);
        world.setBlock(i + 18, j + 33, k + 21, 17, 3, 2);
        world.setBlock(i + 18, j + 33, k + 20, 17, 3, 2);
        world.setBlock(i + 18, j + 33, k + 13, 18, 3, 2);
        world.setBlock(i + 18, j + 33, k + 12, 18, 3, 2);
        world.setBlock(i + 18, j + 33, k + 11, 18, 3, 2);
        world.setBlock(i + 18, j + 33, k + 10, 17, 3, 2);
        world.setBlock(i + 18, j + 33, k + 6, 17, 3, 2);
        world.setBlock(i + 18, j + 33, k + 5, 18, 3, 2);
        world.setBlock(i + 18, j + 33, k + 4, 18, 3, 2);
        world.setBlock(i + 18, j + 33, k + 3, 18, 3, 2);
        world.setBlock(i + 19, j + 33, k + 12, 18, 3, 2);
        world.setBlock(i + 19, j + 33, k + 11, 18, 3, 2);
        world.setBlock(i + 19, j + 33, k + 10, 18, 3, 2);
        world.setBlock(i + 19, j + 33, k + 9, 17, 3, 2);
        world.setBlock(i + 19, j + 33, k + 8, 17, 3, 2);
        world.setBlock(i + 19, j + 33, k + 6, 18, 3, 2);
        world.setBlock(i + 19, j + 33, k + 5, 18, 3, 2);
        world.setBlock(i + 19, j + 33, k + 4, 18, 3, 2);
        world.setBlock(i + 20, j + 33, k + 11, 18, 3, 2);
        world.setBlock(i + 20, j + 33, k + 10, 18, 3, 2);
        world.setBlock(i + 20, j + 33, k + 9, 18, 3, 2);
        world.setBlock(i + 20, j + 33, k + 8, 18, 3, 2);
        world.setBlock(i + 20, j + 33, k + 7, 18, 3, 2);
        world.setBlock(i + 20, j + 33, k + 6, 18, 3, 2);
        world.setBlock(i + 20, j + 33, k + 5, 18, 3, 2);
        world.setBlock(i + 21, j + 33, k + 10, 18, 3, 2);
        world.setBlock(i + 21, j + 33, k + 9, 18, 3, 2);
        world.setBlock(i + 21, j + 33, k + 8, 18, 3, 2);
        world.setBlock(i + 21, j + 33, k + 7, 18, 3, 2);
        world.setBlock(i + 21, j + 33, k + 6, 18, 3, 2);
        world.setBlock(i + 12, j + 34, k + 10, 18, 3, 2);
        world.setBlock(i + 12, j + 34, k + 9, 18, 3, 2);
        world.setBlock(i + 12, j + 34, k + 8, 18, 3, 2);
        world.setBlock(i + 12, j + 34, k + 7, 18, 3, 2);
        world.setBlock(i + 12, j + 34, k + 6, 18, 3, 2);
        world.setBlock(i + 13, j + 34, k + 11, 18, 3, 2);
        world.setBlock(i + 13, j + 34, k + 10, 18, 3, 2);
        world.setBlock(i + 13, j + 34, k + 9, 18, 3, 2);
        world.setBlock(i + 13, j + 34, k + 8, 18, 3, 2);
        world.setBlock(i + 13, j + 34, k + 7, 18, 3, 2);
        world.setBlock(i + 13, j + 34, k + 6, 18, 3, 2);
        world.setBlock(i + 13, j + 34, k + 5, 18, 3, 2);
        world.setBlock(i + 14, j + 34, k + 12, 18, 3, 2);
        world.setBlock(i + 14, j + 34, k + 11, 18, 3, 2);
        world.setBlock(i + 14, j + 34, k + 10, 18, 3, 2);
        world.setBlock(i + 14, j + 34, k + 9, 18, 3, 2);
        world.setBlock(i + 14, j + 34, k + 8, 18, 3, 2);
        world.setBlock(i + 14, j + 34, k + 7, 18, 3, 2);
        world.setBlock(i + 14, j + 34, k + 6, 18, 3, 2);
        world.setBlock(i + 14, j + 34, k + 5, 18, 3, 2);
        world.setBlock(i + 14, j + 34, k + 4, 18, 3, 2);
        world.setBlock(i + 15, j + 34, k + 21, 17, 3, 2);
        world.setBlock(i + 15, j + 34, k + 20, 17, 3, 2);
        world.setBlock(i + 15, j + 34, k + 12, 18, 3, 2);
        world.setBlock(i + 15, j + 34, k + 11, 18, 3, 2);
        world.setBlock(i + 15, j + 34, k + 10, 18, 3, 2);
        world.setBlock(i + 15, j + 34, k + 9, 18, 3, 2);
        world.setBlock(i + 15, j + 34, k + 8, 18, 3, 2);
        world.setBlock(i + 15, j + 34, k + 7, 18, 3, 2);
        world.setBlock(i + 15, j + 34, k + 6, 18, 3, 2);
        world.setBlock(i + 15, j + 34, k + 5, 18, 3, 2);
        world.setBlock(i + 15, j + 34, k + 4, 18, 3, 2);
        world.setBlock(i + 16, j + 34, k + 22, 17, 3, 2);
        world.setBlock(i + 16, j + 34, k + 21, 17, 3, 2);
        world.setBlock(i + 16, j + 34, k + 20, 17, 3, 2);
        world.setBlock(i + 16, j + 34, k + 19, 17, 3, 2);
        world.setBlock(i + 16, j + 34, k + 12, 18, 3, 2);
        world.setBlock(i + 16, j + 34, k + 11, 18, 3, 2);
        world.setBlock(i + 16, j + 34, k + 10, 18, 3, 2);
        world.setBlock(i + 16, j + 34, k + 9, 18, 3, 2);
        world.setBlock(i + 16, j + 34, k + 8, 18, 3, 2);
        world.setBlock(i + 16, j + 34, k + 7, 18, 3, 2);
        world.setBlock(i + 16, j + 34, k + 6, 18, 3, 2);
        world.setBlock(i + 16, j + 34, k + 5, 18, 3, 2);
        world.setBlock(i + 16, j + 34, k + 4, 18, 3, 2);
        world.setBlock(i + 17, j + 34, k + 22, 17, 3, 2);
        world.setBlock(i + 17, j + 34, k + 21, 17, 3, 2);
        world.setBlock(i + 17, j + 34, k + 20, 17, 3, 2);
        world.setBlock(i + 17, j + 34, k + 19, 17, 3, 2);
        world.setBlock(i + 17, j + 34, k + 12, 18, 3, 2);
        world.setBlock(i + 17, j + 34, k + 11, 18, 3, 2);
        world.setBlock(i + 17, j + 34, k + 10, 18, 3, 2);
        world.setBlock(i + 17, j + 34, k + 9, 18, 3, 2);
        world.setBlock(i + 17, j + 34, k + 8, 18, 3, 2);
        world.setBlock(i + 17, j + 34, k + 7, 18, 3, 2);
        world.setBlock(i + 17, j + 34, k + 6, 18, 3, 2);
        world.setBlock(i + 17, j + 34, k + 5, 18, 3, 2);
        world.setBlock(i + 17, j + 34, k + 4, 18, 3, 2);
        world.setBlock(i + 18, j + 34, k + 21, 17, 3, 2);
        world.setBlock(i + 18, j + 34, k + 20, 17, 3, 2);
        world.setBlock(i + 18, j + 34, k + 12, 18, 3, 2);
        world.setBlock(i + 18, j + 34, k + 11, 18, 3, 2);
        world.setBlock(i + 18, j + 34, k + 10, 18, 3, 2);
        world.setBlock(i + 18, j + 34, k + 9, 18, 3, 2);
        world.setBlock(i + 18, j + 34, k + 8, 18, 3, 2);
        world.setBlock(i + 18, j + 34, k + 7, 18, 3, 2);
        world.setBlock(i + 18, j + 34, k + 6, 18, 3, 2);
        world.setBlock(i + 18, j + 34, k + 5, 18, 3, 2);
        world.setBlock(i + 18, j + 34, k + 4, 18, 3, 2);
        world.setBlock(i + 19, j + 34, k + 11, 18, 3, 2);
        world.setBlock(i + 19, j + 34, k + 10, 18, 3, 2);
        world.setBlock(i + 19, j + 34, k + 9, 18, 3, 2);
        world.setBlock(i + 19, j + 34, k + 8, 18, 3, 2);
        world.setBlock(i + 19, j + 34, k + 7, 18, 3, 2);
        world.setBlock(i + 19, j + 34, k + 6, 18, 3, 2);
        world.setBlock(i + 19, j + 34, k + 5, 18, 3, 2);
        world.setBlock(i + 20, j + 34, k + 10, 18, 3, 2);
        world.setBlock(i + 20, j + 34, k + 9, 18, 3, 2);
        world.setBlock(i + 20, j + 34, k + 8, 18, 3, 2);
        world.setBlock(i + 20, j + 34, k + 7, 18, 3, 2);
        world.setBlock(i + 20, j + 34, k + 6, 18, 3, 2);
        world.setBlock(i + 13, j + 35, k + 9, 18, 3, 2);
        world.setBlock(i + 13, j + 35, k + 8, 18, 3, 2);
        world.setBlock(i + 13, j + 35, k + 7, 18, 3, 2);
        world.setBlock(i + 14, j + 35, k + 10, 18, 3, 2);
        world.setBlock(i + 14, j + 35, k + 9, 18, 3, 2);
        world.setBlock(i + 14, j + 35, k + 8, 18, 3, 2);
        world.setBlock(i + 14, j + 35, k + 7, 18, 3, 2);
        world.setBlock(i + 14, j + 35, k + 6, 18, 3, 2);
        world.setBlock(i + 15, j + 35, k + 21, 17, 3, 2);
        world.setBlock(i + 15, j + 35, k + 20, 17, 3, 2);
        world.setBlock(i + 15, j + 35, k + 11, 18, 3, 2);
        world.setBlock(i + 15, j + 35, k + 10, 18, 3, 2);
        world.setBlock(i + 15, j + 35, k + 9, 18, 3, 2);
        world.setBlock(i + 15, j + 35, k + 8, 18, 3, 2);
        world.setBlock(i + 15, j + 35, k + 7, 18, 3, 2);
        world.setBlock(i + 15, j + 35, k + 6, 18, 3, 2);
        world.setBlock(i + 15, j + 35, k + 5, 18, 3, 2);
        world.setBlock(i + 16, j + 35, k + 22, 17, 3, 2);
        world.setBlock(i + 16, j + 35, k + 21, 17, 3, 2);
        world.setBlock(i + 16, j + 35, k + 20, 17, 3, 2);
        world.setBlock(i + 16, j + 35, k + 11, 18, 3, 2);
        world.setBlock(i + 16, j + 35, k + 10, 18, 3, 2);
        world.setBlock(i + 16, j + 35, k + 9, 18, 3, 2);
        world.setBlock(i + 16, j + 35, k + 8, 18, 3, 2);
        world.setBlock(i + 16, j + 35, k + 7, 18, 3, 2);
        world.setBlock(i + 16, j + 35, k + 6, 18, 3, 2);
        world.setBlock(i + 16, j + 35, k + 5, 18, 3, 2);
        world.setBlock(i + 17, j + 35, k + 22, 17, 3, 2);
        world.setBlock(i + 17, j + 35, k + 21, 17, 3, 2);
        world.setBlock(i + 17, j + 35, k + 20, 17, 3, 2);
        world.setBlock(i + 17, j + 35, k + 19, 17, 3, 2);
        world.setBlock(i + 17, j + 35, k + 11, 18, 3, 2);
        world.setBlock(i + 17, j + 35, k + 10, 18, 3, 2);
        world.setBlock(i + 17, j + 35, k + 9, 18, 3, 2);
        world.setBlock(i + 17, j + 35, k + 8, 18, 3, 2);
        world.setBlock(i + 17, j + 35, k + 7, 18, 3, 2);
        world.setBlock(i + 17, j + 35, k + 6, 18, 3, 2);
        world.setBlock(i + 17, j + 35, k + 5, 18, 3, 2);
        world.setBlock(i + 18, j + 35, k + 21, 17, 3, 2);
        world.setBlock(i + 18, j + 35, k + 20, 17, 3, 2);
        world.setBlock(i + 18, j + 35, k + 10, 18, 3, 2);
        world.setBlock(i + 18, j + 35, k + 9, 18, 3, 2);
        world.setBlock(i + 18, j + 35, k + 8, 18, 3, 2);
        world.setBlock(i + 18, j + 35, k + 7, 18, 3, 2);
        world.setBlock(i + 18, j + 35, k + 6, 18, 3, 2);
        world.setBlock(i + 19, j + 35, k + 9, 18, 3, 2);
        world.setBlock(i + 19, j + 35, k + 8, 18, 3, 2);
        world.setBlock(i + 19, j + 35, k + 7, 18, 3, 2);
        world.setBlock(i + 15, j + 36, k + 21, 17, 3, 2);
        world.setBlock(i + 15, j + 36, k + 20, 17, 3, 2);
        world.setBlock(i + 16, j + 36, k + 22, 17, 3, 2);
        world.setBlock(i + 16, j + 36, k + 21, 17, 3, 2);
        world.setBlock(i + 16, j + 36, k + 20, 17, 3, 2);
        world.setBlock(i + 17, j + 36, k + 22, 17, 3, 2);
        world.setBlock(i + 17, j + 36, k + 21, 17, 3, 2);
        world.setBlock(i + 17, j + 36, k + 20, 17, 3, 2);
        world.setBlock(i + 18, j + 36, k + 21, 17, 3, 2);
        world.setBlock(i + 18, j + 36, k + 20, 17, 3, 2);
        world.setBlock(i + 15, j + 37, k + 21, 17, 3, 2);
        world.setBlock(i + 15, j + 37, k + 20, 17, 3, 2);
        world.setBlock(i + 15, j + 37, k + 19, 17, 3, 2);
        world.setBlock(i + 16, j + 37, k + 22, 17, 3, 2);
        world.setBlock(i + 16, j + 37, k + 21, 17, 3, 2);
        world.setBlock(i + 16, j + 37, k + 20, 17, 3, 2);
        world.setBlock(i + 16, j + 37, k + 19, 17, 3, 2);
        world.setBlock(i + 17, j + 37, k + 22, 17, 3, 2);
        world.setBlock(i + 17, j + 37, k + 21, 17, 3, 2);
        world.setBlock(i + 17, j + 37, k + 20, 17, 3, 2);
        world.setBlock(i + 17, j + 37, k + 19, 17, 3, 2);
        world.setBlock(i + 18, j + 37, k + 21, 17, 3, 2);
        world.setBlock(i + 18, j + 37, k + 20, 17, 3, 2);
        world.setBlock(i + 14, j + 38, k + 19, 17, 3, 2);
        world.setBlock(i + 15, j + 38, k + 21, 17, 3, 2);
        world.setBlock(i + 15, j + 38, k + 20, 17, 3, 2);
        world.setBlock(i + 15, j + 38, k + 19, 17, 3, 2);
        world.setBlock(i + 16, j + 38, k + 22, 17, 3, 2);
        world.setBlock(i + 16, j + 38, k + 21, 17, 3, 2);
        world.setBlock(i + 16, j + 38, k + 20, 17, 3, 2);
        world.setBlock(i + 16, j + 38, k + 19, 17, 3, 2);
        world.setBlock(i + 16, j + 38, k + 18, 17, 3, 2);
        world.setBlock(i + 17, j + 38, k + 22, 17, 3, 2);
        world.setBlock(i + 17, j + 38, k + 21, 17, 3, 2);
        world.setBlock(i + 17, j + 38, k + 20, 17, 3, 2);
        world.setBlock(i + 17, j + 38, k + 19, 17, 3, 2);
        world.setBlock(i + 18, j + 38, k + 21, 17, 3, 2);
        world.setBlock(i + 18, j + 38, k + 20, 17, 3, 2);
        world.setBlock(i + 18, j + 38, k + 19, 17, 3, 2);
        world.setBlock(i + 14, j + 39, k + 19, 17, 3, 2);
        world.setBlock(i + 15, j + 39, k + 21, 17, 3, 2);
        world.setBlock(i + 15, j + 39, k + 20, 17, 3, 2);
        world.setBlock(i + 15, j + 39, k + 19, 17, 3, 2);
        world.setBlock(i + 15, j + 39, k + 18, 17, 3, 2);
        world.setBlock(i + 16, j + 39, k + 22, 17, 3, 2);
        world.setBlock(i + 16, j + 39, k + 21, 17, 3, 2);
        world.setBlock(i + 16, j + 39, k + 20, 17, 3, 2);
        world.setBlock(i + 16, j + 39, k + 19, 17, 3, 2);
        world.setBlock(i + 16, j + 39, k + 18, 17, 3, 2);
        world.setBlock(i + 17, j + 39, k + 22, 17, 3, 2);
        world.setBlock(i + 17, j + 39, k + 21, 17, 3, 2);
        world.setBlock(i + 17, j + 39, k + 20, 17, 3, 2);
        world.setBlock(i + 17, j + 39, k + 19, 17, 3, 2);
        world.setBlock(i + 18, j + 39, k + 22, 17, 3, 2);
        world.setBlock(i + 18, j + 39, k + 21, 17, 3, 2);
        world.setBlock(i + 18, j + 39, k + 20, 17, 3, 2);
        world.setBlock(i + 18, j + 39, k + 19, 17, 3, 2);
        world.setBlock(i + 14, j + 40, k + 20, 17, 3, 2);
        world.setBlock(i + 14, j + 40, k + 19, 17, 3, 2);
        world.setBlock(i + 15, j + 40, k + 20, 17, 3, 2);
        world.setBlock(i + 15, j + 40, k + 19, 17, 3, 2);
        world.setBlock(i + 15, j + 40, k + 18, 17, 3, 2);
        world.setBlock(i + 16, j + 40, k + 22, 17, 3, 2);
        world.setBlock(i + 16, j + 40, k + 21, 17, 3, 2);
        world.setBlock(i + 16, j + 40, k + 20, 89, 0, 2);
        world.setBlock(i + 16, j + 40, k + 19, 17, 3, 2);
        world.setBlock(i + 16, j + 40, k + 18, 17, 3, 2);
        world.setBlock(i + 17, j + 40, k + 22, 17, 3, 2);
        world.setBlock(i + 17, j + 40, k + 21, 17, 3, 2);
        world.setBlock(i + 17, j + 40, k + 20, 17, 3, 2);
        world.setBlock(i + 17, j + 40, k + 19, 17, 3, 2);
        world.setBlock(i + 18, j + 40, k + 22, 17, 3, 2);
        world.setBlock(i + 18, j + 40, k + 21, 17, 3, 2);
        world.setBlock(i + 18, j + 40, k + 20, 17, 3, 2);
        world.setBlock(i + 18, j + 40, k + 19, 17, 3, 2);
        world.setBlock(i + 14, j + 41, k + 20, 17, 3, 2);
        world.setBlock(i + 14, j + 41, k + 19, 17, 3, 2);
        world.setBlock(i + 15, j + 41, k + 20, 17, 3, 2);
        world.setBlock(i + 15, j + 41, k + 19, 17, 3, 2);
        world.setBlock(i + 16, j + 41, k + 22, 17, 3, 2);
        world.setBlock(i + 16, j + 41, k + 21, 17, 3, 2);
        world.setBlock(i + 16, j + 41, k + 17, 17, 3, 2);
        world.setBlock(i + 16, j + 41, k + 16, 17, 3, 2);
        world.setBlock(i + 17, j + 41, k + 20, 17, 3, 2);
        world.setBlock(i + 17, j + 41, k + 19, 17, 3, 2);
        world.setBlock(i + 17, j + 41, k + 18, 17, 3, 2);
        world.setBlock(i + 18, j + 41, k + 22, 17, 3, 2);
        world.setBlock(i + 18, j + 41, k + 21, 17, 3, 2);
        world.setBlock(i + 18, j + 41, k + 19, 17, 3, 2);
        world.setBlock(i + 12, j + 42, k + 19, 17, 3, 2);
        world.setBlock(i + 13, j + 42, k + 20, 17, 3, 2);
        world.setBlock(i + 13, j + 42, k + 19, 17, 3, 2);
        world.setBlock(i + 14, j + 42, k + 23, 17, 3, 2);
        world.setBlock(i + 14, j + 42, k + 20, 17, 3, 2);
        world.setBlock(i + 14, j + 42, k + 19, 17, 3, 2);
        world.setBlock(i + 15, j + 42, k + 23, 17, 3, 2);
        world.setBlock(i + 15, j + 42, k + 19, 17, 3, 2);
        world.setBlock(i + 16, j + 42, k + 23, 17, 3, 2);
        world.setBlock(i + 16, j + 42, k + 22, 17, 3, 2);
        world.setBlock(i + 16, j + 42, k + 17, 17, 3, 2);
        world.setBlock(i + 16, j + 42, k + 16, 17, 3, 2);
        world.setBlock(i + 16, j + 42, k + 15, 17, 3, 2);
        world.setBlock(i + 17, j + 42, k + 22, 17, 3, 2);
        world.setBlock(i + 17, j + 42, k + 21, 17, 3, 2);
        world.setBlock(i + 17, j + 42, k + 19, 17, 3, 2);
        world.setBlock(i + 17, j + 42, k + 18, 17, 3, 2);
        world.setBlock(i + 17, j + 42, k + 17, 17, 3, 2);
        world.setBlock(i + 17, j + 42, k + 15, 18, 3, 2);
        world.setBlock(i + 18, j + 42, k + 22, 17, 3, 2);
        world.setBlock(i + 18, j + 42, k + 21, 17, 3, 2);
        world.setBlock(i + 18, j + 42, k + 19, 17, 3, 2);
        world.setBlock(i + 18, j + 42, k + 18, 17, 3, 2);
        world.setBlock(i + 19, j + 42, k + 23, 17, 3, 2);
        world.setBlock(i + 19, j + 42, k + 22, 17, 3, 2);
        world.setBlock(i + 19, j + 42, k + 18, 17, 3, 2);
        world.setBlock(i + 20, j + 42, k + 18, 17, 3, 2);
        world.setBlock(i + 23, j + 42, k + 4, 106, 0, 2);
        world.setBlock(i + 10, j + 43, k + 19, 17, 3, 2);
        world.setBlock(i + 11, j + 43, k + 21, 17, 3, 2);
        world.setBlock(i + 11, j + 43, k + 20, 17, 3, 2);
        world.setBlock(i + 11, j + 43, k + 19, 17, 3, 2);
        world.setBlock(i + 12, j + 43, k + 20, 17, 3, 2);
        world.setBlock(i + 12, j + 43, k + 19, 17, 3, 2);
        world.setBlock(i + 13, j + 43, k + 20, 17, 3, 2);
        world.setBlock(i + 13, j + 43, k + 19, 17, 3, 2);
        world.setBlock(i + 14, j + 43, k + 25, 17, 3, 2);
        world.setBlock(i + 14, j + 43, k + 24, 17, 3, 2);
        world.setBlock(i + 14, j + 43, k + 23, 17, 3, 2);
        world.setBlock(i + 14, j + 43, k + 19, 17, 3, 2);
        world.setBlock(i + 15, j + 43, k + 3, 106, 0, 2);
        world.setBlock(i + 16, j + 43, k + 15, 17, 3, 2);
        world.setBlock(i + 16, j + 43, k + 14, 17, 3, 2);
        world.setBlock(i + 17, j + 43, k + 14, 18, 3, 2);
        world.setBlock(i + 18, j + 43, k + 23, 17, 3, 2);
        world.setBlock(i + 18, j + 43, k + 22, 17, 3, 2);
        world.setBlock(i + 19, j + 43, k + 23, 17, 3, 2);
        world.setBlock(i + 20, j + 43, k + 24, 17, 3, 2);
        world.setBlock(i + 20, j + 43, k + 23, 17, 3, 2);
        world.setBlock(i + 20, j + 43, k + 18, 17, 3, 2);
        world.setBlock(i + 20, j + 43, k + 17, 17, 3, 2);
        world.setBlock(i + 20, j + 43, k + 16, 17, 3, 2);
        world.setBlock(i + 21, j + 43, k + 16, 17, 3, 2);
        world.setBlock(i + 23, j + 43, k + 4, 106, 0, 2);
        world.setBlock(i + 4, j + 44, k + 8, 106, 0, 2);
        world.setBlock(i + 9, j + 44, k + 21, 17, 3, 2);
        world.setBlock(i + 10, j + 44, k + 21, 17, 3, 2);
        world.setBlock(i + 10, j + 44, k + 20, 17, 3, 2);
        world.setBlock(i + 10, j + 44, k + 19, 17, 3, 2);
        world.setBlock(i + 10, j + 44, k + 18, 17, 3, 2);
        world.setBlock(i + 10, j + 44, k + 17, 17, 3, 2);
        world.setBlock(i + 11, j + 44, k + 21, 17, 3, 2);
        world.setBlock(i + 11, j + 44, k + 20, 17, 3, 2);
        world.setBlock(i + 11, j + 44, k + 19, 18, 3, 2);
        world.setBlock(i + 12, j + 44, k + 20, 18, 3, 2);
        world.setBlock(i + 12, j + 44, k + 19, 18, 3, 2);
        world.setBlock(i + 12, j + 44, k + 3, 106, 0, 2);
        world.setBlock(i + 13, j + 44, k + 27, 17, 3, 2);
        world.setBlock(i + 13, j + 44, k + 26, 17, 3, 2);
        world.setBlock(i + 13, j + 44, k + 25, 17, 3, 2);
        world.setBlock(i + 13, j + 44, k + 19, 18, 3, 2);
        world.setBlock(i + 13, j + 44, k + 12, 18, 3, 2);
        world.setBlock(i + 14, j + 44, k + 25, 17, 3, 2);
        world.setBlock(i + 14, j + 44, k + 24, 18, 3, 2);
        world.setBlock(i + 14, j + 44, k + 13, 17, 3, 2);
        world.setBlock(i + 14, j + 44, k + 12, 17, 3, 2);
        world.setBlock(i + 15, j + 44, k + 25, 17, 3, 2);
        world.setBlock(i + 15, j + 44, k + 13, 17, 3, 2);
        world.setBlock(i + 15, j + 44, k + 3, 106, 0, 2);
        world.setBlock(i + 16, j + 44, k + 25, 17, 3, 2);
        world.setBlock(i + 16, j + 44, k + 14, 17, 3, 2);
        world.setBlock(i + 16, j + 44, k + 13, 17, 3, 2);
        world.setBlock(i + 17, j + 44, k + 14, 18, 3, 2);
        world.setBlock(i + 20, j + 44, k + 24, 17, 3, 2);
        world.setBlock(i + 20, j + 44, k + 23, 18, 3, 2);
        world.setBlock(i + 20, j + 44, k + 16, 18, 3, 2);
        world.setBlock(i + 21, j + 44, k + 16, 17, 3, 2);
        world.setBlock(i + 23, j + 44, k + 4, 106, 0, 2);
        world.setBlock(i + 0, j + 45, k + 26, 106, 0, 2);
        world.setBlock(i + 2, j + 45, k + 29, 106, 0, 2);
        world.setBlock(i + 4, j + 45, k + 8, 106, 0, 2);
        world.setBlock(i + 8, j + 45, k + 22, 17, 3, 2);
        world.setBlock(i + 8, j + 45, k + 21, 17, 3, 2);
        world.setBlock(i + 8, j + 45, k + 17, 17, 3, 2);
        world.setBlock(i + 9, j + 45, k + 22, 17, 3, 2);
        world.setBlock(i + 9, j + 45, k + 21, 17, 3, 2);
        world.setBlock(i + 9, j + 45, k + 17, 17, 3, 2);
        world.setBlock(i + 10, j + 45, k + 21, 18, 3, 2);
        world.setBlock(i + 10, j + 45, k + 20, 18, 3, 2);
        world.setBlock(i + 10, j + 45, k + 17, 17, 3, 2);
        world.setBlock(i + 11, j + 45, k + 20, 18, 3, 2);
        world.setBlock(i + 11, j + 45, k + 11, 18, 3, 2);
        world.setBlock(i + 12, j + 45, k + 28, 18, 3, 2);
        world.setBlock(i + 12, j + 45, k + 27, 18, 3, 2);
        world.setBlock(i + 12, j + 45, k + 12, 18, 3, 2);
        world.setBlock(i + 12, j + 45, k + 11, 17, 3, 2);
        world.setBlock(i + 12, j + 45, k + 3, 106, 0, 2);
        world.setBlock(i + 13, j + 45, k + 28, 17, 3, 2);
        world.setBlock(i + 13, j + 45, k + 27, 17, 3, 2);
        world.setBlock(i + 13, j + 45, k + 26, 18, 3, 2);
        world.setBlock(i + 13, j + 45, k + 25, 18, 3, 2);
        world.setBlock(i + 13, j + 45, k + 12, 17, 3, 2);
        world.setBlock(i + 13, j + 45, k + 11, 17, 3, 2);
        world.setBlock(i + 13, j + 45, k + 3, 106, 0, 2);
        world.setBlock(i + 14, j + 45, k + 12, 17, 3, 2);
        world.setBlock(i + 15, j + 45, k + 13, 18, 3, 2);
        world.setBlock(i + 15, j + 45, k + 12, 17, 3, 2);
        world.setBlock(i + 15, j + 45, k + 11, 17, 3, 2);
        world.setBlock(i + 15, j + 45, k + 3, 106, 0, 2);
        world.setBlock(i + 16, j + 45, k + 27, 17, 3, 2);
        world.setBlock(i + 16, j + 45, k + 26, 17, 3, 2);
        world.setBlock(i + 16, j + 45, k + 25, 17, 3, 2);
        world.setBlock(i + 20, j + 45, k + 24, 17, 3, 2);
        world.setBlock(i + 20, j + 45, k + 23, 18, 3, 2);
        world.setBlock(i + 21, j + 45, k + 26, 17, 3, 2);
        world.setBlock(i + 21, j + 45, k + 25, 17, 3, 2);
        world.setBlock(i + 21, j + 45, k + 24, 17, 3, 2);
        world.setBlock(i + 21, j + 45, k + 23, 18, 3, 2);
        world.setBlock(i + 21, j + 45, k + 16, 17, 3, 2);
        world.setBlock(i + 21, j + 45, k + 15, 18, 3, 2);
        world.setBlock(i + 22, j + 45, k + 26, 17, 3, 2);
        world.setBlock(i + 22, j + 45, k + 16, 17, 3, 2);
        world.setBlock(i + 22, j + 45, k + 15, 18, 3, 2);
        world.setBlock(i + 23, j + 45, k + 16, 17, 3, 2);
        world.setBlock(i + 23, j + 45, k + 15, 17, 3, 2);
        world.setBlock(i + 23, j + 45, k + 4, 106, 0, 2);
        world.setBlock(i + 31, j + 45, k + 12, 106, 0, 2);
        world.setBlock(i + 0, j + 46, k + 26, 106, 0, 2);
        world.setBlock(i + 2, j + 46, k + 29, 106, 0, 2);
        world.setBlock(i + 4, j + 46, k + 32, 106, 0, 2);
        world.setBlock(i + 4, j + 46, k + 8, 106, 0, 2);
        world.setBlock(i + 6, j + 46, k + 24, 17, 3, 2);
        world.setBlock(i + 7, j + 46, k + 24, 17, 3, 2);
        world.setBlock(i + 8, j + 46, k + 24, 17, 3, 2);
        world.setBlock(i + 8, j + 46, k + 23, 17, 3, 2);
        world.setBlock(i + 8, j + 46, k + 22, 17, 3, 2);
        world.setBlock(i + 8, j + 46, k + 17, 17, 3, 2);
        world.setBlock(i + 9, j + 46, k + 23, 18, 3, 2);
        world.setBlock(i + 9, j + 46, k + 22, 17, 3, 2);
        world.setBlock(i + 9, j + 46, k + 17, 18, 3, 2);
        world.setBlock(i + 9, j + 46, k + 4, 106, 0, 2);
        world.setBlock(i + 11, j + 46, k + 12, 18, 3, 2);
        world.setBlock(i + 11, j + 46, k + 11, 18, 3, 2);
        world.setBlock(i + 12, j + 46, k + 11, 17, 3, 2);
        world.setBlock(i + 12, j + 46, k + 3, 106, 0, 2);
