package morethantrees.treegen;

import java.util.Random;

import net.minecraft.block.Block;
import net.minecraft.world.World;
import net.minecraft.world.gen.feature.WorldGenerator;

public class WorldGenCalifornianRedFirLargeTree extends WorldGenerator
{
    public boolean generate(World world, Random var2, int i, int j, int k)
    {
        while ((world.isAirBlock(i + 10, j, k + 12)) && (j > 2))
        {
            j--;
        }
        
        int var6 = world.getBlockId(i + 10, j, k + 12);
        
        if (var6 != Block.grass.blockID)
        {
            return false;
        }
        
        for (int var7 = -2; var7 <= 2; var7++)
        {
            for (int var8 = -2; var8 <= 2; var8++)
            {
                if ((world.isAirBlock(i + var7 + 10, j - 1, k + var8 + 12)) && (world.isAirBlock(i + var7 + 10, j - 2, k + var8 + 12)))
                {
                    return false;
                }
            }
        }
        world.setBlock(i + 5, j + 0, k + 7, 17, 1, 2);
        world.setBlock(i + 6, j + 0, k + 8, 17, 1, 2);
        world.setBlock(i + 6, j + 0, k + 7, 17, 1, 2);
        world.setBlock(i + 6, j + 0, k + 4, 17, 1, 2);
        world.setBlock(i + 7, j + 0, k + 10, 17, 1, 2);
        world.setBlock(i + 7, j + 0, k + 7, 17, 1, 2);
        world.setBlock(i + 7, j + 0, k + 6, 17, 1, 2);
        world.setBlock(i + 7, j + 0, k + 5, 17, 1, 2);
        world.setBlock(i + 8, j + 0, k + 9, 17, 1, 2);
        world.setBlock(i + 8, j + 0, k + 8, 17, 1, 2);
        world.setBlock(i + 8, j + 0, k + 7, 17, 1, 2);
        world.setBlock(i + 8, j + 0, k + 6, 17, 1, 2);
        world.setBlock(i + 9, j + 0, k + 10, 17, 1, 2);
        world.setBlock(i + 9, j + 0, k + 8, 17, 1, 2);
        world.setBlock(i + 9, j + 0, k + 7, 17, 1, 2);
        world.setBlock(i + 9, j + 0, k + 6, 17, 1, 2);
        world.setBlock(i + 10, j + 0, k + 8, 17, 1, 2);
        world.setBlock(i + 10, j + 0, k + 6, 17, 1, 2);
        world.setBlock(i + 10, j + 0, k + 5, 17, 1, 2);
        world.setBlock(i + 6, j + 1, k + 7, 17, 1, 2);
        world.setBlock(i + 7, j + 1, k + 7, 17, 1, 2);
        world.setBlock(i + 7, j + 1, k + 6, 17, 1, 2);
        world.setBlock(i + 7, j + 1, k + 5, 17, 1, 2);
        world.setBlock(i + 8, j + 1, k + 9, 17, 1, 2);
        world.setBlock(i + 8, j + 1, k + 8, 17, 1, 2);
        world.setBlock(i + 8, j + 1, k + 7, 17, 1, 2);
        world.setBlock(i + 8, j + 1, k + 6, 17, 1, 2);
        world.setBlock(i + 9, j + 1, k + 7, 17, 1, 2);
        world.setBlock(i + 9, j + 1, k + 6, 17, 1, 2);
        world.setBlock(i + 7, j + 2, k + 7, 17, 1, 2);
        world.setBlock(i + 7, j + 2, k + 6, 17, 1, 2);
        world.setBlock(i + 8, j + 2, k + 8, 17, 1, 2);
        world.setBlock(i + 8, j + 2, k + 7, 17, 1, 2);
        world.setBlock(i + 8, j + 2, k + 6, 17, 1, 2);
        world.setBlock(i + 7, j + 3, k + 7, 17, 1, 2);
        world.setBlock(i + 7, j + 3, k + 6, 17, 1, 2);
        world.setBlock(i + 8, j + 3, k + 8, 17, 1, 2);
        world.setBlock(i + 8, j + 3, k + 7, 17, 1, 2);
        world.setBlock(i + 8, j + 3, k + 6, 17, 1, 2);
        world.setBlock(i + 7, j + 4, k + 7, 17, 1, 2);
        world.setBlock(i + 7, j + 4, k + 6, 17, 1, 2);
        world.setBlock(i + 8, j + 4, k + 7, 17, 1, 2);
        world.setBlock(i + 8, j + 4, k + 6, 17, 1, 2);
        world.setBlock(i + 7, j + 5, k + 7, 17, 1, 2);
        world.setBlock(i + 7, j + 5, k + 6, 17, 1, 2);
        world.setBlock(i + 8, j + 5, k + 7, 17, 1, 2);
        world.setBlock(i + 8, j + 5, k + 6, 17, 1, 2);
        world.setBlock(i + 7, j + 6, k + 7, 17, 1, 2);
        world.setBlock(i + 7, j + 6, k + 6, 17, 1, 2);
        world.setBlock(i + 8, j + 6, k + 7, 17, 1, 2);
        world.setBlock(i + 8, j + 6, k + 6, 17, 1, 2);
        world.setBlock(i + 7, j + 7, k + 7, 17, 1, 2);
        world.setBlock(i + 7, j + 7, k + 6, 17, 1, 2);
        world.setBlock(i + 8, j + 7, k + 7, 17, 1, 2);
        world.setBlock(i + 8, j + 7, k + 6, 17, 1, 2);
        world.setBlock(i + 7, j + 8, k + 7, 17, 1, 2);
        world.setBlock(i + 7, j + 8, k + 6, 17, 1, 2);
        world.setBlock(i + 8, j + 8, k + 7, 17, 1, 2);
        world.setBlock(i + 8, j + 8, k + 6, 17, 1, 2);
        world.setBlock(i + 7, j + 9, k + 7, 17, 1, 2);
        world.setBlock(i + 7, j + 9, k + 6, 17, 1, 2);
        world.setBlock(i + 8, j + 9, k + 7, 17, 1, 2);
        world.setBlock(i + 8, j + 9, k + 6, 17, 1, 2);
        world.setBlock(i + 7, j + 10, k + 7, 17, 1, 2);
        world.setBlock(i + 7, j + 10, k + 6, 17, 1, 2);
        world.setBlock(i + 8, j + 10, k + 7, 17, 1, 2);
        world.setBlock(i + 8, j + 10, k + 6, 17, 1, 2);
        world.setBlock(i + 7, j + 11, k + 7, 17, 1, 2);
        world.setBlock(i + 7, j + 11, k + 6, 17, 1, 2);
        world.setBlock(i + 8, j + 11, k + 7, 17, 1, 2);
        world.setBlock(i + 8, j + 11, k + 6, 17, 1, 2);
        world.setBlock(i + 7, j + 12, k + 7, 17, 1, 2);
        world.setBlock(i + 7, j + 12, k + 6, 17, 1, 2);
        world.setBlock(i + 8, j + 12, k + 7, 17, 1, 2);
        world.setBlock(i + 8, j + 12, k + 6, 17, 1, 2);
        world.setBlock(i + 7, j + 13, k + 7, 17, 1, 2);
        world.setBlock(i + 7, j + 13, k + 6, 17, 1, 2);
        world.setBlock(i + 8, j + 13, k + 7, 17, 1, 2);
        world.setBlock(i + 8, j + 13, k + 6, 17, 1, 2);
        world.setBlock(i + 7, j + 14, k + 9, 18, 1, 2);
        world.setBlock(i + 7, j + 14, k + 7, 17, 1, 2);
        world.setBlock(i + 7, j + 14, k + 6, 17, 1, 2);
        world.setBlock(i + 8, j + 14, k + 9, 18, 1, 2);
        world.setBlock(i + 8, j + 14, k + 8, 17, 1, 2);
        world.setBlock(i + 8, j + 14, k + 7, 17, 1, 2);
        world.setBlock(i + 8, j + 14, k + 6, 17, 1, 2);
        world.setBlock(i + 9, j + 14, k + 8, 18, 1, 2);
        world.setBlock(i + 9, j + 14, k + 7, 18, 1, 2);
        world.setBlock(i + 7, j + 15, k + 7, 17, 1, 2);
        world.setBlock(i + 7, j + 15, k + 6, 17, 1, 2);
        world.setBlock(i + 8, j + 15, k + 7, 17, 1, 2);
        world.setBlock(i + 8, j + 15, k + 6, 17, 1, 2);
        world.setBlock(i + 7, j + 16, k + 7, 17, 1, 2);
        world.setBlock(i + 7, j + 16, k + 6, 17, 1, 2);
        world.setBlock(i + 8, j + 16, k + 8, 18, 1, 2);
        world.setBlock(i + 8, j + 16, k + 7, 17, 1, 2);
        world.setBlock(i + 8, j + 16, k + 6, 17, 1, 2);
        world.setBlock(i + 9, j + 16, k + 8, 18, 1, 2);
        world.setBlock(i + 9, j + 16, k + 7, 17, 1, 2);
        world.setBlock(i + 9, j + 16, k + 6, 18, 1, 2);
        world.setBlock(i + 10, j + 16, k + 7, 18, 1, 2);
        world.setBlock(i + 7, j + 17, k + 7, 17, 1, 2);
        world.setBlock(i + 7, j + 17, k + 6, 17, 1, 2);
        world.setBlock(i + 8, j + 17, k + 7, 17, 1, 2);
        world.setBlock(i + 8, j + 17, k + 6, 17, 1, 2);
        world.setBlock(i + 5, j + 18, k + 8, 18, 1, 2);
        world.setBlock(i + 5, j + 18, k + 7, 18, 1, 2);
        world.setBlock(i + 5, j + 18, k + 6, 18, 1, 2);
        world.setBlock(i + 6, j + 18, k + 7, 17, 1, 2);
        world.setBlock(i + 6, j + 18, k + 6, 18, 1, 2);
        world.setBlock(i + 7, j + 18, k + 7, 17, 1, 2);
        world.setBlock(i + 7, j + 18, k + 6, 17, 1, 2);
        world.setBlock(i + 8, j + 18, k + 7, 17, 1, 2);
        world.setBlock(i + 8, j + 18, k + 6, 17, 1, 2);
        world.setBlock(i + 7, j + 19, k + 7, 17, 1, 2);
        world.setBlock(i + 7, j + 19, k + 6, 17, 1, 2);
        world.setBlock(i + 8, j + 19, k + 7, 17, 1, 2);
        world.setBlock(i + 8, j + 19, k + 6, 17, 1, 2);
        world.setBlock(i + 7, j + 20, k + 7, 17, 1, 2);
        world.setBlock(i + 7, j + 20, k + 6, 17, 1, 2);
        world.setBlock(i + 8, j + 20, k + 7, 17, 1, 2);
        world.setBlock(i + 8, j + 20, k + 6, 17, 1, 2);
        world.setBlock(i + 5, j + 21, k + 6, 18, 1, 2);
        world.setBlock(i + 5, j + 21, k + 5, 18, 1, 2);
        world.setBlock(i + 5, j + 21, k + 4, 18, 1, 2);
        world.setBlock(i + 6, j + 21, k + 6, 18, 1, 2);
        world.setBlock(i + 6, j + 21, k + 5, 17, 1, 2);
        world.setBlock(i + 6, j + 21, k + 4, 18, 1, 2);
        world.setBlock(i + 7, j + 21, k + 7, 17, 1, 2);
        world.setBlock(i + 7, j + 21, k + 6, 17, 1, 2);
        world.setBlock(i + 7, j + 21, k + 5, 18, 1, 2);
        world.setBlock(i + 7, j + 21, k + 4, 18, 1, 2);
        world.setBlock(i + 8, j + 21, k + 7, 17, 1, 2);
        world.setBlock(i + 8, j + 21, k + 6, 17, 1, 2);
        world.setBlock(i + 7, j + 22, k + 7, 17, 1, 2);
        world.setBlock(i + 7, j + 22, k + 6, 17, 1, 2);
        world.setBlock(i + 8, j + 22, k + 7, 17, 1, 2);
        world.setBlock(i + 8, j + 22, k + 6, 17, 1, 2);
        world.setBlock(i + 5, j + 23, k + 9, 18, 1, 2);
        world.setBlock(i + 5, j + 23, k + 8, 18, 1, 2);
        world.setBlock(i + 5, j + 23, k + 7, 18, 1, 2);
        world.setBlock(i + 6, j + 23, k + 9, 18, 1, 2);
        world.setBlock(i + 6, j + 23, k + 7, 18, 1, 2);
        world.setBlock(i + 7, j + 23, k + 8, 18, 1, 2);
        world.setBlock(i + 7, j + 23, k + 7, 17, 1, 2);
        world.setBlock(i + 7, j + 23, k + 6, 17, 1, 2);
        world.setBlock(i + 8, j + 23, k + 7, 17, 1, 2);
        world.setBlock(i + 8, j + 23, k + 6, 17, 1, 2);
        world.setBlock(i + 3, j + 24, k + 9, 18, 1, 2);
        world.setBlock(i + 3, j + 24, k + 8, 18, 1, 2);
        world.setBlock(i + 4, j + 24, k + 11, 18, 1, 2);
        world.setBlock(i + 4, j + 24, k + 10, 18, 1, 2);
        world.setBlock(i + 4, j + 24, k + 9, 18, 1, 2);
        world.setBlock(i + 4, j + 24, k + 8, 17, 1, 2);
        world.setBlock(i + 4, j + 24, k + 7, 18, 1, 2);
        world.setBlock(i + 5, j + 24, k + 11, 18, 1, 2);
        world.setBlock(i + 5, j + 24, k + 10, 18, 1, 2);
        world.setBlock(i + 5, j + 24, k + 9, 17, 1, 2);
        world.setBlock(i + 5, j + 24, k + 8, 18, 1, 2);
        world.setBlock(i + 6, j + 24, k + 10, 17, 1, 2);
        world.setBlock(i + 6, j + 24, k + 9, 18, 1, 2);
        world.setBlock(i + 6, j + 24, k + 8, 17, 1, 2);
        world.setBlock(i + 7, j + 24, k + 11, 18, 1, 2);
        world.setBlock(i + 7, j + 24, k + 10, 18, 1, 2);
        world.setBlock(i + 7, j + 24, k + 9, 18, 1, 2);
        world.setBlock(i + 7, j + 24, k + 7, 17, 1, 2);
        world.setBlock(i + 7, j + 24, k + 6, 17, 1, 2);
        world.setBlock(i + 8, j + 24, k + 7, 17, 1, 2);
        world.setBlock(i + 8, j + 24, k + 6, 17, 1, 2);
        world.setBlock(i + 3, j + 25, k + 11, 18, 1, 2);
        world.setBlock(i + 3, j + 25, k + 9, 18, 1, 2);
        world.setBlock(i + 4, j + 25, k + 10, 18, 1, 2);
        world.setBlock(i + 4, j + 25, k + 9, 18, 1, 2);
        world.setBlock(i + 4, j + 25, k + 8, 18, 1, 2);
        world.setBlock(i + 5, j + 25, k + 11, 18, 1, 2);
        world.setBlock(i + 5, j + 25, k + 8, 18, 1, 2);
        world.setBlock(i + 6, j + 25, k + 10, 18, 1, 2);
        world.setBlock(i + 6, j + 25, k + 9, 18, 1, 2);
        world.setBlock(i + 6, j + 25, k + 8, 18, 1, 2);
        world.setBlock(i + 7, j + 25, k + 7, 17, 1, 2);
        world.setBlock(i + 7, j + 25, k + 6, 17, 1, 2);
        world.setBlock(i + 8, j + 25, k + 7, 17, 1, 2);
        world.setBlock(i + 8, j + 25, k + 6, 17, 1, 2);
        world.setBlock(i + 7, j + 26, k + 7, 17, 1, 2);
        world.setBlock(i + 7, j + 26, k + 6, 17, 1, 2);
        world.setBlock(i + 8, j + 26, k + 7, 17, 1, 2);
        world.setBlock(i + 5, j + 27, k + 6, 18, 1, 2);
        world.setBlock(i + 6, j + 27, k + 6, 18, 1, 2);
        world.setBlock(i + 6, j + 27, k + 5, 17, 1, 2);
        world.setBlock(i + 6, j + 27, k + 4, 18, 1, 2);
        world.setBlock(i + 7, j + 27, k + 7, 17, 1, 2);
        world.setBlock(i + 7, j + 27, k + 6, 17, 1, 2);
        world.setBlock(i + 7, j + 27, k + 5, 18, 1, 2);
        world.setBlock(i + 8, j + 27, k + 8, 18, 1, 2);
        world.setBlock(i + 8, j + 27, k + 7, 17, 1, 2);
        world.setBlock(i + 9, j + 27, k + 10, 18, 1, 2);
        world.setBlock(i + 9, j + 27, k + 9, 18, 1, 2);
        world.setBlock(i + 9, j + 27, k + 8, 17, 1, 2);
        world.setBlock(i + 9, j + 27, k + 7, 18, 1, 2);
        world.setBlock(i + 10, j + 27, k + 9, 17, 1, 2);
        world.setBlock(i + 10, j + 27, k + 8, 18, 1, 2);
        world.setBlock(i + 10, j + 27, k + 7, 18, 1, 2);
        world.setBlock(i + 11, j + 27, k + 10, 18, 1, 2);
        world.setBlock(i + 11, j + 27, k + 9, 18, 1, 2);
        world.setBlock(i + 11, j + 27, k + 8, 18, 1, 2);
        world.setBlock(i + 4, j + 28, k + 4, 18, 1, 2);
        world.setBlock(i + 4, j + 28, k + 3, 18, 1, 2);
        world.setBlock(i + 5, j + 28, k + 5, 18, 1, 2);
        world.setBlock(i + 5, j + 28, k + 4, 17, 1, 2);
        world.setBlock(i + 6, j + 28, k + 5, 18, 1, 2);
        world.setBlock(i + 6, j + 28, k + 4, 18, 1, 2);
        world.setBlock(i + 6, j + 28, k + 3, 18, 1, 2);
        world.setBlock(i + 7, j + 28, k + 7, 17, 1, 2);
        world.setBlock(i + 7, j + 28, k + 6, 17, 1, 2);
        world.setBlock(i + 8, j + 28, k + 7, 17, 1, 2);
        world.setBlock(i + 1, j + 29, k + 9, 18, 1, 2);
        world.setBlock(i + 2, j + 29, k + 10, 18, 1, 2);
        world.setBlock(i + 2, j + 29, k + 9, 18, 1, 2);
        world.setBlock(i + 3, j + 29, k + 13, 18, 1, 2);
        world.setBlock(i + 3, j + 29, k + 10, 18, 1, 2);
        world.setBlock(i + 3, j + 29, k + 6, 18, 1, 2);
        world.setBlock(i + 4, j + 29, k + 13, 18, 1, 2);
        world.setBlock(i + 4, j + 29, k + 12, 18, 1, 2);
        world.setBlock(i + 4, j + 29, k + 11, 18, 1, 2);
        world.setBlock(i + 4, j + 29, k + 10, 18, 1, 2);
        world.setBlock(i + 4, j + 29, k + 9, 18, 1, 2);
        world.setBlock(i + 4, j + 29, k + 8, 18, 1, 2);
        world.setBlock(i + 4, j + 29, k + 5, 18, 1, 2);
        world.setBlock(i + 5, j + 29, k + 10, 18, 1, 2);
        world.setBlock(i + 5, j + 29, k + 9, 18, 1, 2);
        world.setBlock(i + 5, j + 29, k + 8, 18, 1, 2);
        world.setBlock(i + 5, j + 29, k + 7, 18, 1, 2);
        world.setBlock(i + 5, j + 29, k + 6, 18, 1, 2);
        world.setBlock(i + 5, j + 29, k + 5, 18, 1, 2);
        world.setBlock(i + 5, j + 29, k + 4, 18, 1, 2);
        world.setBlock(i + 6, j + 29, k + 10, 18, 1, 2);
        world.setBlock(i + 6, j + 29, k + 9, 18, 1, 2);
        world.setBlock(i + 6, j + 29, k + 8, 18, 1, 2);
        world.setBlock(i + 6, j + 29, k + 4, 18, 1, 2);
        world.setBlock(i + 6, j + 29, k + 3, 18, 1, 2);
        world.setBlock(i + 7, j + 29, k + 11, 18, 1, 2);
        world.setBlock(i + 7, j + 29, k + 10, 18, 1, 2);
        world.setBlock(i + 7, j + 29, k + 9, 18, 1, 2);
        world.setBlock(i + 7, j + 29, k + 8, 18, 1, 2);
        world.setBlock(i + 7, j + 29, k + 7, 17, 1, 2);
        world.setBlock(i + 7, j + 29, k + 6, 17, 1, 2);
        world.setBlock(i + 7, j + 29, k + 5, 18, 1, 2);
        world.setBlock(i + 7, j + 29, k + 4, 18, 1, 2);
        world.setBlock(i + 7, j + 29, k + 3, 18, 1, 2);
        world.setBlock(i + 8, j + 29, k + 7, 17, 1, 2);
        world.setBlock(i + 8, j + 29, k + 5, 18, 1, 2);
        world.setBlock(i + 8, j + 29, k + 3, 18, 1, 2);
        world.setBlock(i + 9, j + 29, k + 6, 18, 1, 2);
        world.setBlock(i + 9, j + 29, k + 5, 18, 1, 2);
        world.setBlock(i + 9, j + 29, k + 3, 18, 1, 2);
        world.setBlock(i + 10, j + 29, k + 8, 18, 1, 2);
        world.setBlock(i + 10, j + 29, k + 5, 18, 1, 2);
        world.setBlock(i + 10, j + 29, k + 4, 18, 1, 2);
        world.setBlock(i + 10, j + 29, k + 3, 18, 1, 2);
        world.setBlock(i + 10, j + 29, k + 2, 18, 1, 2);
        world.setBlock(i + 11, j + 29, k + 8, 18, 1, 2);
        world.setBlock(i + 12, j + 29, k + 7, 18, 1, 2);
        world.setBlock(i + 12, j + 29, k + 5, 18, 1, 2);
        world.setBlock(i + 12, j + 29, k + 3, 18, 1, 2);
        world.setBlock(i + 0, j + 30, k + 6, 18, 1, 2);
        world.setBlock(i + 1, j + 30, k + 6, 18, 1, 2);
        world.setBlock(i + 2, j + 30, k + 9, 18, 1, 2);
        world.setBlock(i + 2, j + 30, k + 4, 18, 1, 2);
        world.setBlock(i + 2, j + 30, k + 3, 18, 1, 2);
        world.setBlock(i + 3, j + 30, k + 7, 18, 1, 2);
        world.setBlock(i + 3, j + 30, k + 6, 18, 1, 2);
        world.setBlock(i + 3, j + 30, k + 5, 18, 1, 2);
        world.setBlock(i + 3, j + 30, k + 4, 18, 1, 2);
        world.setBlock(i + 3, j + 30, k + 3, 18, 1, 2);
        world.setBlock(i + 3, j + 30, k + 1, 18, 1, 2);
        world.setBlock(i + 4, j + 30, k + 9, 18, 1, 2);
        world.setBlock(i + 4, j + 30, k + 7, 18, 1, 2);
        world.setBlock(i + 4, j + 30, k + 6, 18, 1, 2);
        world.setBlock(i + 4, j + 30, k + 5, 18, 1, 2);
        world.setBlock(i + 4, j + 30, k + 4, 18, 1, 2);
        world.setBlock(i + 4, j + 30, k + 3, 18, 1, 2);
        world.setBlock(i + 4, j + 30, k + 2, 18, 1, 2);
        world.setBlock(i + 5, j + 30, k + 9, 18, 1, 2);
        world.setBlock(i + 5, j + 30, k + 8, 18, 1, 2);
        world.setBlock(i + 5, j + 30, k + 7, 18, 1, 2);
        world.setBlock(i + 5, j + 30, k + 6, 18, 1, 2);
        world.setBlock(i + 5, j + 30, k + 5, 18, 1, 2);
        world.setBlock(i + 5, j + 30, k + 4, 18, 1, 2);
        world.setBlock(i + 5, j + 30, k + 2, 18, 1, 2);
        world.setBlock(i + 6, j + 30, k + 9, 18, 1, 2);
        world.setBlock(i + 6, j + 30, k + 8, 18, 1, 2);
        world.setBlock(i + 6, j + 30, k + 7, 18, 1, 2);
        world.setBlock(i + 6, j + 30, k + 6, 18, 1, 2);
        world.setBlock(i + 6, j + 30, k + 5, 18, 1, 2);
        world.setBlock(i + 7, j + 30, k + 10, 18, 1, 2);
        world.setBlock(i + 7, j + 30, k + 8, 18, 1, 2);
        world.setBlock(i + 7, j + 30, k + 7, 17, 1, 2);
        world.setBlock(i + 7, j + 30, k + 6, 17, 1, 2);
        world.setBlock(i + 7, j + 30, k + 5, 18, 1, 2);
        world.setBlock(i + 7, j + 30, k + 4, 18, 1, 2);
        world.setBlock(i + 8, j + 30, k + 9, 18, 1, 2);
        world.setBlock(i + 8, j + 30, k + 7, 17, 1, 2);
        world.setBlock(i + 8, j + 30, k + 2, 18, 1, 2);
        world.setBlock(i + 9, j + 30, k + 8, 18, 1, 2);
        world.setBlock(i + 9, j + 30, k + 5, 18, 1, 2);
        world.setBlock(i + 9, j + 30, k + 4, 18, 1, 2);
        world.setBlock(i + 9, j + 30, k + 2, 18, 1, 2);
        world.setBlock(i + 10, j + 30, k + 8, 18, 1, 2);
        world.setBlock(i + 11, j + 30, k + 6, 18, 1, 2);
        world.setBlock(i + 11, j + 30, k + 5, 18, 1, 2);
        world.setBlock(i + 11, j + 30, k + 3, 18, 1, 2);
        world.setBlock(i + 12, j + 30, k + 5, 18, 1, 2);
        world.setBlock(i + 12, j + 30, k + 4, 18, 1, 2);
        world.setBlock(i + 3, j + 31, k + 10, 18, 1, 2);
        world.setBlock(i + 3, j + 31, k + 6, 18, 1, 2);
        world.setBlock(i + 3, j + 31, k + 5, 18, 1, 2);
        world.setBlock(i + 3, j + 31, k + 4, 18, 1, 2);
        world.setBlock(i + 4, j + 31, k + 9, 18, 1, 2);
        world.setBlock(i + 4, j + 31, k + 8, 18, 1, 2);
        world.setBlock(i + 4, j + 31, k + 7, 18, 1, 2);
        world.setBlock(i + 4, j + 31, k + 4, 18, 1, 2);
        world.setBlock(i + 5, j + 31, k + 12, 18, 1, 2);
        world.setBlock(i + 5, j + 31, k + 10, 18, 1, 2);
        world.setBlock(i + 5, j + 31, k + 9, 18, 1, 2);
        world.setBlock(i + 5, j + 31, k + 8, 18, 1, 2);
        world.setBlock(i + 5, j + 31, k + 7, 18, 1, 2);
        world.setBlock(i + 5, j + 31, k + 6, 18, 1, 2);
        world.setBlock(i + 5, j + 31, k + 4, 18, 1, 2);
        world.setBlock(i + 5, j + 31, k + 3, 18, 1, 2);
        world.setBlock(i + 6, j + 31, k + 12, 18, 1, 2);
        world.setBlock(i + 6, j + 31, k + 10, 18, 1, 2);
        world.setBlock(i + 6, j + 31, k + 7, 18, 1, 2);
        world.setBlock(i + 6, j + 31, k + 4, 18, 1, 2);
        world.setBlock(i + 7, j + 31, k + 13, 18, 1, 2);
        world.setBlock(i + 7, j + 31, k + 12, 18, 1, 2);
        world.setBlock(i + 7, j + 31, k + 11, 18, 1, 2);
        world.setBlock(i + 7, j + 31, k + 10, 18, 1, 2);
        world.setBlock(i + 7, j + 31, k + 9, 18, 1, 2);
        world.setBlock(i + 7, j + 31, k + 7, 17, 1, 2);
        world.setBlock(i + 7, j + 31, k + 6, 17, 1, 2);
        world.setBlock(i + 7, j + 31, k + 5, 18, 1, 2);
        world.setBlock(i + 8, j + 31, k + 12, 18, 1, 2);
        world.setBlock(i + 8, j + 31, k + 10, 18, 1, 2);
        world.setBlock(i + 8, j + 31, k + 9, 18, 1, 2);
        world.setBlock(i + 8, j + 31, k + 7, 17, 1, 2);
        world.setBlock(i + 8, j + 31, k + 6, 18, 1, 2);
        world.setBlock(i + 9, j + 31, k + 10, 18, 1, 2);
        world.setBlock(i + 9, j + 31, k + 6, 18, 1, 2);
        world.setBlock(i + 10, j + 31, k + 7, 18, 1, 2);
        world.setBlock(i + 4, j + 32, k + 8, 18, 1, 2);
        world.setBlock(i + 5, j + 32, k + 8, 17, 1, 2);
        world.setBlock(i + 5, j + 32, k + 7, 18, 1, 2);
        world.setBlock(i + 6, j + 32, k + 9, 18, 1, 2);
        world.setBlock(i + 6, j + 32, k + 8, 18, 1, 2);
        world.setBlock(i + 6, j + 32, k + 7, 17, 1, 2);
        world.setBlock(i + 6, j + 32, k + 6, 18, 1, 2);
        world.setBlock(i + 7, j + 32, k + 8, 18, 1, 2);
        world.setBlock(i + 7, j + 32, k + 7, 17, 1, 2);
        world.setBlock(i + 7, j + 32, k + 6, 17, 1, 2);
        world.setBlock(i + 8, j + 32, k + 7, 17, 1, 2);
        world.setBlock(i + 9, j + 32, k + 6, 17, 1, 2);
        world.setBlock(i + 9, j + 32, k + 5, 18, 1, 2);
        world.setBlock(i + 9, j + 32, k + 4, 18, 1, 2);
        world.setBlock(i + 10, j + 32, k + 6, 18, 1, 2);
        world.setBlock(i + 10, j + 32, k + 5, 17, 1, 2);
        world.setBlock(i + 10, j + 32, k + 4, 18, 1, 2);
        world.setBlock(i + 10, j + 32, k + 3, 18, 1, 2);
        world.setBlock(i + 11, j + 32, k + 7, 18, 1, 2);
        world.setBlock(i + 11, j + 32, k + 5, 18, 1, 2);
        world.setBlock(i + 11, j + 32, k + 4, 18, 1, 2);
        world.setBlock(i + 11, j + 32, k + 3, 18, 1, 2);
        world.setBlock(i + 11, j + 32, k + 2, 18, 1, 2);
        world.setBlock(i + 11, j + 32, k + 1, 18, 1, 2);
        world.setBlock(i + 12, j + 32, k + 6, 18, 1, 2);
        world.setBlock(i + 12, j + 32, k + 5, 18, 1, 2);
        world.setBlock(i + 12, j + 32, k + 1, 18, 1, 2);
        world.setBlock(i + 13, j + 32, k + 2, 18, 1, 2);
        world.setBlock(i + 14, j + 32, k + 4, 18, 1, 2);
        world.setBlock(i + 2, j + 33, k + 8, 18, 1, 2);
        world.setBlock(i + 3, j + 33, k + 4, 18, 1, 2);
        world.setBlock(i + 4, j + 33, k + 9, 18, 1, 2);
        world.setBlock(i + 4, j + 33, k + 7, 18, 1, 2);
        world.setBlock(i + 4, j + 33, k + 6, 18, 1, 2);
        world.setBlock(i + 4, j + 33, k + 3, 18, 1, 2);
        world.setBlock(i + 5, j + 33, k + 9, 18, 1, 2);
        world.setBlock(i + 5, j + 33, k + 8, 18, 1, 2);
        world.setBlock(i + 5, j + 33, k + 6, 18, 1, 2);
        world.setBlock(i + 5, j + 33, k + 4, 18, 1, 2);
        world.setBlock(i + 5, j + 33, k + 3, 18, 1, 2);
        world.setBlock(i + 6, j + 33, k + 11, 18, 1, 2);
        world.setBlock(i + 6, j + 33, k + 9, 18, 1, 2);
        world.setBlock(i + 6, j + 33, k + 8, 18, 1, 2);
        world.setBlock(i + 6, j + 33, k + 7, 18, 1, 2);
        world.setBlock(i + 6, j + 33, k + 6, 18, 1, 2);
        world.setBlock(i + 6, j + 33, k + 5, 18, 1, 2);
        world.setBlock(i + 6, j + 33, k + 4, 18, 1, 2);
        world.setBlock(i + 7, j + 33, k + 8, 18, 1, 2);
        world.setBlock(i + 7, j + 33, k + 7, 17, 1, 2);
        world.setBlock(i + 7, j + 33, k + 6, 17, 1, 2);
        world.setBlock(i + 7, j + 33, k + 3, 18, 1, 2);
        world.setBlock(i + 8, j + 33, k + 10, 18, 1, 2);
        world.setBlock(i + 8, j + 33, k + 7, 17, 1, 2);
        world.setBlock(i + 8, j + 33, k + 5, 18, 1, 2);
        world.setBlock(i + 8, j + 33, k + 3, 18, 1, 2);
        world.setBlock(i + 8, j + 33, k + 1, 18, 1, 2);
        world.setBlock(i + 8, j + 33, k + 0, 18, 1, 2);
        world.setBlock(i + 9, j + 33, k + 9, 18, 1, 2);
        world.setBlock(i + 9, j + 33, k + 7, 18, 1, 2);
        world.setBlock(i + 9, j + 33, k + 6, 18, 1, 2);
        world.setBlock(i + 9, j + 33, k + 4, 18, 1, 2);
        world.setBlock(i + 9, j + 33, k + 3, 18, 1, 2);
        world.setBlock(i + 9, j + 33, k + 2, 18, 1, 2);
        world.setBlock(i + 9, j + 33, k + 0, 18, 1, 2);
        world.setBlock(i + 10, j + 33, k + 9, 18, 1, 2);
        world.setBlock(i + 10, j + 33, k + 8, 18, 1, 2);
        world.setBlock(i + 10, j + 33, k + 7, 18, 1, 2);
        world.setBlock(i + 10, j + 33, k + 6, 18, 1, 2);
        world.setBlock(i + 10, j + 33, k + 5, 18, 1, 2);
        world.setBlock(i + 11, j + 33, k + 9, 18, 1, 2);
        world.setBlock(i + 11, j + 33, k + 8, 18, 1, 2);
        world.setBlock(i + 11, j + 33, k + 6, 18, 1, 2);
        world.setBlock(i + 12, j + 33, k + 8, 18, 1, 2);
        world.setBlock(i + 12, j + 33, k + 4, 18, 1, 2);
        world.setBlock(i + 4, j + 34, k + 7, 18, 1, 2);
        world.setBlock(i + 5, j + 34, k + 8, 18, 1, 2);
        world.setBlock(i + 5, j + 34, k + 6, 18, 1, 2);
        world.setBlock(i + 6, j + 34, k + 5, 18, 1, 2);
        world.setBlock(i + 7, j + 34, k + 8, 18, 1, 2);
        world.setBlock(i + 7, j + 34, k + 6, 17, 1, 2);
        world.setBlock(i + 7, j + 34, k + 5, 18, 1, 2);
        world.setBlock(i + 7, j + 34, k + 3, 18, 1, 2);
        world.setBlock(i + 8, j + 34, k + 8, 18, 1, 2);
        world.setBlock(i + 8, j + 34, k + 7, 17, 1, 2);
        world.setBlock(i + 8, j + 34, k + 6, 18, 1, 2);
        world.setBlock(i + 8, j + 34, k + 5, 18, 1, 2);
        world.setBlock(i + 8, j + 34, k + 4, 18, 1, 2);
        world.setBlock(i + 9, j + 34, k + 6, 18, 1, 2);
        world.setBlock(i + 10, j + 34, k + 9, 18, 1, 2);
        world.setBlock(i + 10, j + 34, k + 8, 18, 1, 2);
        world.setBlock(i + 10, j + 34, k + 6, 18, 1, 2);
        world.setBlock(i + 10, j + 34, k + 5, 18, 1, 2);
        world.setBlock(i + 10, j + 34, k + 4, 18, 1, 2);
        world.setBlock(i + 10, j + 34, k + 3, 18, 1, 2);
        world.setBlock(i + 11, j + 34, k + 9, 18, 1, 2);
        world.setBlock(i + 11, j + 34, k + 6, 18, 1, 2);
        world.setBlock(i + 11, j + 34, k + 3, 18, 1, 2);
        world.setBlock(i + 12, j + 34, k + 7, 18, 1, 2);
        world.setBlock(i + 13, j + 34, k + 5, 18, 1, 2);
        world.setBlock(i + 4, j + 35, k + 6, 18, 1, 2);
        world.setBlock(i + 6, j + 35, k + 8, 18, 1, 2);
        world.setBlock(i + 6, j + 35, k + 7, 18, 1, 2);
        world.setBlock(i + 6, j + 35, k + 6, 18, 1, 2);
        world.setBlock(i + 6, j + 35, k + 5, 18, 1, 2);
        world.setBlock(i + 6, j + 35, k + 3, 18, 1, 2);
        world.setBlock(i + 7, j + 35, k + 9, 18, 1, 2);
        world.setBlock(i + 7, j + 35, k + 6, 17, 1, 2);
        world.setBlock(i + 7, j + 35, k + 5, 18, 1, 2);
        world.setBlock(i + 7, j + 35, k + 4, 18, 1, 2);
        world.setBlock(i + 8, j + 35, k + 10, 18, 1, 2);
        world.setBlock(i + 8, j + 35, k + 9, 18, 1, 2);
        world.setBlock(i + 8, j + 35, k + 8, 18, 1, 2);
        world.setBlock(i + 8, j + 35, k + 7, 17, 1, 2);
        world.setBlock(i + 8, j + 35, k + 6, 18, 1, 2);
        world.setBlock(i + 9, j + 35, k + 9, 18, 1, 2);
        world.setBlock(i + 9, j + 35, k + 7, 18, 1, 2);
        world.setBlock(i + 9, j + 35, k + 6, 18, 1, 2);
        world.setBlock(i + 9, j + 35, k + 5, 18, 1, 2);
        world.setBlock(i + 9, j + 35, k + 4, 18, 1, 2);
        world.setBlock(i + 9, j + 35, k + 1, 18, 1, 2);
        world.setBlock(i + 10, j + 35, k + 9, 18, 1, 2);
        world.setBlock(i + 10, j + 35, k + 5, 18, 1, 2);
        world.setBlock(i + 10, j + 35, k + 4, 18, 1, 2);
        world.setBlock(i + 10, j + 35, k + 3, 18, 1, 2);
        world.setBlock(i + 11, j + 35, k + 7, 18, 1, 2);
        world.setBlock(i + 11, j + 35, k + 6, 18, 1, 2);
        world.setBlock(i + 11, j + 35, k + 4, 18, 1, 2);
        world.setBlock(i + 12, j + 35, k + 4, 18, 1, 2);
        world.setBlock(i + 5, j + 36, k + 11, 18, 1, 2);
        world.setBlock(i + 5, j + 36, k + 10, 18, 1, 2);
        world.setBlock(i + 6, j + 36, k + 10, 18, 1, 2);
        world.setBlock(i + 6, j + 36, k + 8, 18, 1, 2);
        world.setBlock(i + 6, j + 36, k + 6, 18, 1, 2);
        world.setBlock(i + 6, j + 36, k + 5, 18, 1, 2);
        world.setBlock(i + 7, j + 36, k + 12, 18, 1, 2);
        world.setBlock(i + 7, j + 36, k + 9, 18, 1, 2);
        world.setBlock(i + 7, j + 36, k + 8, 18, 1, 2);
        world.setBlock(i + 7, j + 36, k + 7, 18, 1, 2);
        world.setBlock(i + 7, j + 36, k + 6, 17, 1, 2);
        world.setBlock(i + 7, j + 36, k + 4, 18, 1, 2);
        world.setBlock(i + 8, j + 36, k + 13, 18, 1, 2);
        world.setBlock(i + 8, j + 36, k + 11, 18, 1, 2);
        world.setBlock(i + 8, j + 36, k + 10, 18, 1, 2);
        world.setBlock(i + 8, j + 36, k + 9, 18, 1, 2);
        world.setBlock(i + 8, j + 36, k + 8, 17, 1, 2);
        world.setBlock(i + 8, j + 36, k + 7, 17, 1, 2);
        world.setBlock(i + 8, j + 36, k + 4, 18, 1, 2);
        world.setBlock(i + 9, j + 36, k + 9, 17, 1, 2);
        world.setBlock(i + 9, j + 36, k + 8, 18, 1, 2);
        world.setBlock(i + 9, j + 36, k + 7, 18, 1, 2);
        world.setBlock(i + 10, j + 36, k + 10, 18, 1, 2);
        world.setBlock(i + 10, j + 36, k + 9, 18, 1, 2);
        world.setBlock(i + 10, j + 36, k + 8, 18, 1, 2);
        world.setBlock(i + 4, j + 37, k + 10, 18, 1, 2);
        world.setBlock(i + 4, j + 37, k + 9, 18, 1, 2);
        world.setBlock(i + 4, j + 37, k + 5, 18, 1, 2);
        world.setBlock(i + 5, j + 37, k + 11, 18, 1, 2);
        world.setBlock(i + 5, j + 37, k + 10, 18, 1, 2);
        world.setBlock(i + 5, j + 37, k + 9, 18, 1, 2);
        world.setBlock(i + 5, j + 37, k + 7, 18, 1, 2);
        world.setBlock(i + 5, j + 37, k + 6, 18, 1, 2);
        world.setBlock(i + 5, j + 37, k + 5, 18, 1, 2);
        world.setBlock(i + 6, j + 37, k + 11, 18, 1, 2);
        world.setBlock(i + 6, j + 37, k + 6, 18, 1, 2);
        world.setBlock(i + 6, j + 37, k + 5, 18, 1, 2);
        world.setBlock(i + 6, j + 37, k + 4, 18, 1, 2);
        world.setBlock(i + 7, j + 37, k + 12, 18, 1, 2);
        world.setBlock(i + 7, j + 37, k + 11, 18, 1, 2);
        world.setBlock(i + 7, j + 37, k + 10, 18, 1, 2);
        world.setBlock(i + 7, j + 37, k + 9, 18, 1, 2);
        world.setBlock(i + 7, j + 37, k + 8, 18, 1, 2);
        world.setBlock(i + 7, j + 37, k + 6, 17, 1, 2);
        world.setBlock(i + 8, j + 37, k + 12, 18, 1, 2);
        world.setBlock(i + 8, j + 37, k + 11, 18, 1, 2);
        world.setBlock(i + 8, j + 37, k + 9, 18, 1, 2);
        world.setBlock(i + 8, j + 37, k + 7, 17, 1, 2);
        world.setBlock(i + 8, j + 37, k + 6, 18, 1, 2);
        world.setBlock(i + 8, j + 37, k + 5, 18, 1, 2);
        world.setBlock(i + 9, j + 37, k + 10, 18, 1, 2);
        world.setBlock(i + 9, j + 37, k + 9, 18, 1, 2);
        world.setBlock(i + 9, j + 37, k + 5, 18, 1, 2);
        world.setBlock(i + 9, j + 37, k + 4, 18, 1, 2);
        world.setBlock(i + 10, j + 37, k + 13, 18, 1, 2);
        world.setBlock(i + 10, j + 37, k + 10, 18, 1, 2);
        world.setBlock(i + 10, j + 37, k + 8, 18, 1, 2);
        world.setBlock(i + 10, j + 37, k + 5, 18, 1, 2);
        world.setBlock(i + 11, j + 37, k + 13, 18, 1, 2);
        world.setBlock(i + 11, j + 37, k + 11, 18, 1, 2);
        world.setBlock(i + 11, j + 37, k + 8, 18, 1, 2);
        world.setBlock(i + 12, j + 37, k + 12, 18, 1, 2);
        world.setBlock(i + 6, j + 38, k + 7, 18, 1, 2);
        world.setBlock(i + 6, j + 38, k + 6, 18, 1, 2);
        world.setBlock(i + 7, j + 38, k + 9, 18, 1, 2);
        world.setBlock(i + 7, j + 38, k + 7, 18, 1, 2);
        world.setBlock(i + 7, j + 38, k + 6, 17, 1, 2);
        world.setBlock(i + 7, j + 38, k + 5, 18, 1, 2);
        world.setBlock(i + 7, j + 38, k + 4, 18, 1, 2);
        world.setBlock(i + 8, j + 38, k + 9, 18, 1, 2);
        world.setBlock(i + 8, j + 38, k + 8, 18, 1, 2);
        world.setBlock(i + 8, j + 38, k + 7, 17, 1, 2);
        world.setBlock(i + 10, j + 38, k + 7, 18, 1, 2);
        world.setBlock(i + 3, j + 39, k + 5, 18, 1, 2);
        world.setBlock(i + 4, j + 39, k + 6, 18, 1, 2);
        world.setBlock(i + 4, j + 39, k + 5, 18, 1, 2);
        world.setBlock(i + 5, j + 39, k + 7, 18, 1, 2);
        world.setBlock(i + 5, j + 39, k + 5, 18, 1, 2);
        world.setBlock(i + 5, j + 39, k + 2, 18, 1, 2);
        world.setBlock(i + 6, j + 39, k + 9, 18, 1, 2);
        world.setBlock(i + 6, j + 39, k + 8, 18, 1, 2);
        world.setBlock(i + 6, j + 39, k + 7, 18, 1, 2);
        world.setBlock(i + 6, j + 39, k + 5, 18, 1, 2);
        world.setBlock(i + 6, j + 39, k + 3, 18, 1, 2);
        world.setBlock(i + 7, j + 39, k + 8, 18, 1, 2);
        world.setBlock(i + 7, j + 39, k + 6, 17, 1, 2);
        world.setBlock(i + 7, j + 39, k + 5, 18, 1, 2);
        world.setBlock(i + 8, j + 39, k + 10, 18, 1, 2);
        world.setBlock(i + 8, j + 39, k + 8, 18, 1, 2);
        world.setBlock(i + 8, j + 39, k + 7, 17, 1, 2);
        world.setBlock(i + 9, j + 39, k + 9, 18, 1, 2);
        world.setBlock(i + 9, j + 39, k + 6, 18, 1, 2);
        world.setBlock(i + 10, j + 39, k + 6, 18, 1, 2);
        world.setBlock(i + 11, j + 39, k + 7, 18, 1, 2);
        world.setBlock(i + 5, j + 40, k + 7, 18, 1, 2);
        world.setBlock(i + 6, j + 40, k + 9, 18, 1, 2);
        world.setBlock(i + 6, j + 40, k + 7, 18, 1, 2);
        world.setBlock(i + 6, j + 40, k + 5, 18, 1, 2);
        world.setBlock(i + 7, j + 40, k + 9, 18, 1, 2);
        world.setBlock(i + 7, j + 40, k + 6, 17, 1, 2);
        world.setBlock(i + 7, j + 40, k + 4, 18, 1, 2);
        world.setBlock(i + 8, j + 40, k + 10, 18, 1, 2);
        world.setBlock(i + 8, j + 40, k + 7, 17, 1, 2);
        world.setBlock(i + 8, j + 40, k + 5, 18, 1, 2);
        world.setBlock(i + 9, j + 40, k + 10, 18, 1, 2);
        world.setBlock(i + 9, j + 40, k + 8, 18, 1, 2);
        world.setBlock(i + 10, j + 40, k + 6, 18, 1, 2);
        world.setBlock(i + 4, j + 41, k + 6, 18, 1, 2);
        world.setBlock(i + 6, j + 41, k + 8, 18, 1, 2);
        world.setBlock(i + 6, j + 41, k + 6, 18, 1, 2);
        world.setBlock(i + 6, j + 41, k + 5, 18, 1, 2);
        world.setBlock(i + 7, j + 41, k + 8, 18, 1, 2);
        world.setBlock(i + 7, j + 41, k + 7, 18, 1, 2);
        world.setBlock(i + 7, j + 41, k + 6, 17, 1, 2);
        world.setBlock(i + 7, j + 41, k + 5, 18, 1, 2);
        world.setBlock(i + 7, j + 41, k + 4, 18, 1, 2);
        world.setBlock(i + 8, j + 41, k + 7, 17, 1, 2);
        world.setBlock(i + 8, j + 41, k + 6, 18, 1, 2);
        world.setBlock(i + 8, j + 41, k + 5, 18, 1, 2);
        world.setBlock(i + 9, j + 41, k + 6, 18, 1, 2);
        world.setBlock(i + 10, j + 41, k + 6, 18, 1, 2);
        world.setBlock(i + 4, j + 42, k + 7, 18, 1, 2);
        world.setBlock(i + 5, j + 42, k + 6, 18, 1, 2);
        world.setBlock(i + 6, j + 42, k + 7, 18, 1, 2);
        world.setBlock(i + 6, j + 42, k + 6, 18, 1, 2);
        world.setBlock(i + 6, j + 42, k + 4, 18, 1, 2);
        world.setBlock(i + 7, j + 42, k + 9, 18, 1, 2);
        world.setBlock(i + 7, j + 42, k + 8, 18, 1, 2);
        world.setBlock(i + 7, j + 42, k + 7, 18, 1, 2);
        world.setBlock(i + 8, j + 42, k + 9, 18, 1, 2);
        world.setBlock(i + 8, j + 42, k + 7, 17, 1, 2);
        world.setBlock(i + 8, j + 42, k + 6, 18, 1, 2);
        world.setBlock(i + 9, j + 42, k + 9, 18, 1, 2);
        world.setBlock(i + 9, j + 42, k + 8, 18, 1, 2);
        world.setBlock(i + 9, j + 42, k + 7, 17, 1, 2);
        world.setBlock(i + 9, j + 42, k + 6, 18, 1, 2);
        world.setBlock(i + 9, j + 42, k + 5, 18, 1, 2);
        world.setBlock(i + 10, j + 42, k + 8, 18, 1, 2);
        world.setBlock(i + 10, j + 42, k + 7, 18, 1, 2);
        world.setBlock(i + 10, j + 42, k + 6, 17, 1, 2);
        world.setBlock(i + 10, j + 42, k + 5, 18, 1, 2);
        world.setBlock(i + 11, j + 42, k + 7, 18, 1, 2);
        world.setBlock(i + 11, j + 42, k + 6, 18, 1, 2);
        world.setBlock(i + 11, j + 42, k + 5, 18, 1, 2);
        world.setBlock(i + 4, j + 43, k + 6, 18, 1, 2);
        world.setBlock(i + 5, j + 43, k + 7, 18, 1, 2);
        world.setBlock(i + 5, j + 43, k + 5, 18, 1, 2);
        world.setBlock(i + 6, j + 43, k + 9, 18, 1, 2);
        world.setBlock(i + 6, j + 43, k + 8, 18, 1, 2);
        world.setBlock(i + 6, j + 43, k + 6, 18, 1, 2);
        world.setBlock(i + 7, j + 43, k + 7, 18, 1, 2);
        world.setBlock(i + 7, j + 43, k + 5, 18, 1, 2);
        world.setBlock(i + 8, j + 43, k + 7, 17, 1, 2);
        world.setBlock(i + 8, j + 43, k + 5, 18, 1, 2);
        world.setBlock(i + 8, j + 43, k + 4, 18, 1, 2);
        world.setBlock(i + 9, j + 43, k + 8, 18, 1, 2);
        world.setBlock(i + 9, j + 43, k + 5, 18, 1, 2);
        world.setBlock(i + 10, j + 43, k + 9, 18, 1, 2);
        world.setBlock(i + 10, j + 43, k + 8, 18, 1, 2);
        world.setBlock(i + 10, j + 43, k + 7, 18, 1, 2);
        world.setBlock(i + 10, j + 43, k + 6, 18, 1, 2);
        world.setBlock(i + 10, j + 43, k + 5, 18, 1, 2);
        world.setBlock(i + 11, j + 43, k + 7, 18, 1, 2);
        world.setBlock(i + 5, j + 44, k + 7, 18, 1, 2);
        world.setBlock(i + 5, j + 44, k + 6, 18, 1, 2);
        world.setBlock(i + 5, j + 44, k + 5, 18, 1, 2);
        world.setBlock(i + 6, j + 44, k + 8, 18, 1, 2);
        world.setBlock(i + 6, j + 44, k + 6, 18, 1, 2);
        world.setBlock(i + 6, j + 44, k + 5, 18, 1, 2);
        world.setBlock(i + 7, j + 44, k + 8, 18, 1, 2);
        world.setBlock(i + 7, j + 44, k + 5, 18, 1, 2);
        world.setBlock(i + 7, j + 44, k + 4, 18, 1, 2);
        world.setBlock(i + 8, j + 44, k + 9, 18, 1, 2);
        world.setBlock(i + 8, j + 44, k + 7, 17, 1, 2);
        world.setBlock(i + 8, j + 44, k + 5, 18, 1, 2);
        world.setBlock(i + 9, j + 44, k + 10, 18, 1, 2);
        world.setBlock(i + 10, j + 44, k + 9, 18, 1, 2);
        world.setBlock(i + 11, j + 44, k + 8, 18, 1, 2);
        world.setBlock(i + 5, j + 45, k + 8, 18, 1, 2);
        world.setBlock(i + 5, j + 45, k + 7, 18, 1, 2);
        world.setBlock(i + 5, j + 45, k + 6, 18, 1, 2);
        world.setBlock(i + 6, j + 45, k + 7, 18, 1, 2);
        world.setBlock(i + 6, j + 45, k + 6, 18, 1, 2);
        world.setBlock(i + 7, j + 45, k + 9, 18, 1, 2);
        world.setBlock(i + 7, j + 45, k + 7, 18, 1, 2);
        world.setBlock(i + 7, j + 45, k + 6, 18, 1, 2);
        world.setBlock(i + 7, j + 45, k + 4, 18, 1, 2);
        world.setBlock(i + 8, j + 45, k + 10, 18, 1, 2);
        world.setBlock(i + 8, j + 45, k + 9, 18, 1, 2);
        world.setBlock(i + 8, j + 45, k + 7, 17, 1, 2);
        world.setBlock(i + 8, j + 45, k + 6, 18, 1, 2);
        world.setBlock(i + 9, j + 45, k + 5, 18, 1, 2);
        world.setBlock(i + 10, j + 45, k + 8, 18, 1, 2);
        world.setBlock(i + 10, j + 45, k + 5, 18, 1, 2);
        world.setBlock(i + 11, j + 45, k + 7, 18, 1, 2);
        world.setBlock(i + 7, j + 46, k + 8, 18, 1, 2);
        world.setBlock(i + 7, j + 46, k + 7, 18, 1, 2);
        world.setBlock(i + 8, j + 46, k + 8, 18, 1, 2);
        world.setBlock(i + 8, j + 46, k + 7, 17, 1, 2);
        world.setBlock(i + 8, j + 46, k + 6, 18, 1, 2);
        world.setBlock(i + 9, j + 46, k + 8, 18, 1, 2);
        world.setBlock(i + 9, j + 46, k + 7, 18, 1, 2);
        world.setBlock(i + 9, j + 46, k + 6, 18, 1, 2);
        world.setBlock(i + 7, j + 47, k + 7, 18, 1, 2);
        world.setBlock(i + 7, j + 47, k + 6, 18, 1, 2);
        world.setBlock(i + 8, j + 47, k + 8, 18, 1, 2);
        world.setBlock(i + 8, j + 47, k + 7, 17, 1, 2);
        world.setBlock(i + 8, j + 47, k + 6, 18, 1, 2);
        world.setBlock(i + 9, j + 47, k + 7, 18, 1, 2);
        
        return true;
    }
}
