package morethantrees.treegen;

import java.util.Random;

import net.minecraft.block.Block;
import net.minecraft.world.World;
import net.minecraft.world.gen.feature.WorldGenerator;

public class WorldGenLodgepolePineLargeTree extends WorldGenerator
{
	public boolean generate(World world, Random var2, int i, int j, int k)
	  {
	    while ((world.isAirBlock(i + 10, j, k + 12)) && (j > 2))
	    {
	      j--;
	    }

	    int var6 = world.getBlockId(i + 10, j, k + 12);

	    if (var6 != Block.grass.blockID)
	    {
	      return false;
	    }

	    for (int var7 = -2; var7 <= 2; var7++)
	    {
	      for (int var8 = -2; var8 <= 2; var8++)
	      {
	        if ((world.isAirBlock(i + var7 + 10, j - 1, k + var8 + 12)) && (world.isAirBlock(i + var7 + 10, j - 2, k + var8 + 12)))
	        {
	          return false;
	        }
	      }
	    }
    	world.setBlock(i + 4, j + 0, k + 7, 17, 1, 2);
        world.setBlock(i + 5, j + 0, k + 6, 17, 1, 2);
        world.setBlock(i + 5, j + 0, k + 5, 17, 1, 2);
        world.setBlock(i + 6, j + 0, k + 6, 17, 1, 2);
        world.setBlock(i + 6, j + 0, k + 5, 17, 1, 2);
        world.setBlock(i + 6, j + 0, k + 4, 17, 1, 2);
        world.setBlock(i + 7, j + 0, k + 6, 17, 1, 2);
        world.setBlock(i + 5, j + 1, k + 6, 17, 1, 2);
        world.setBlock(i + 5, j + 1, k + 5, 17, 1, 2);
        world.setBlock(i + 6, j + 1, k + 6, 17, 1, 2);
        world.setBlock(i + 6, j + 1, k + 5, 17, 1, 2);
        world.setBlock(i + 5, j + 2, k + 6, 17, 1, 2);
        world.setBlock(i + 6, j + 2, k + 6, 17, 1, 2);
        world.setBlock(i + 6, j + 2, k + 5, 17, 1, 2);
        world.setBlock(i + 5, j + 3, k + 6, 17, 1, 2);
        world.setBlock(i + 6, j + 3, k + 6, 17, 1, 2);
        world.setBlock(i + 6, j + 3, k + 5, 17, 1, 2);
        world.setBlock(i + 5, j + 4, k + 6, 17, 1, 2);
        world.setBlock(i + 6, j + 4, k + 6, 17, 1, 2);
        world.setBlock(i + 6, j + 4, k + 5, 17, 1, 2);
        world.setBlock(i + 5, j + 5, k + 6, 17, 1, 2);
        world.setBlock(i + 6, j + 5, k + 6, 17, 1, 2);
        world.setBlock(i + 6, j + 5, k + 5, 17, 1, 2);
        world.setBlock(i + 5, j + 6, k + 6, 17, 1, 2);
        world.setBlock(i + 6, j + 6, k + 6, 17, 1, 2);
        world.setBlock(i + 6, j + 6, k + 5, 17, 1, 2);
        world.setBlock(i + 5, j + 7, k + 6, 17, 1, 2);
        world.setBlock(i + 6, j + 7, k + 6, 17, 1, 2);
        world.setBlock(i + 6, j + 7, k + 5, 17, 1, 2);
        world.setBlock(i + 5, j + 8, k + 6, 17, 1, 2);
        world.setBlock(i + 6, j + 8, k + 6, 17, 1, 2);
        world.setBlock(i + 6, j + 8, k + 5, 17, 1, 2);
        world.setBlock(i + 5, j + 9, k + 6, 17, 1, 2);
        world.setBlock(i + 6, j + 9, k + 6, 17, 1, 2);
        world.setBlock(i + 6, j + 9, k + 5, 17, 1, 2);
        world.setBlock(i + 5, j + 10, k + 6, 17, 1, 2);
        world.setBlock(i + 6, j + 10, k + 6, 17, 1, 2);
        world.setBlock(i + 6, j + 10, k + 5, 17, 1, 2);
        world.setBlock(i + 5, j + 11, k + 6, 17, 1, 2);
        world.setBlock(i + 6, j + 11, k + 6, 17, 1, 2);
        world.setBlock(i + 5, j + 12, k + 6, 17, 1, 2);
        world.setBlock(i + 6, j + 12, k + 6, 17, 1, 2);
        world.setBlock(i + 5, j + 13, k + 6, 17, 1, 2);
        world.setBlock(i + 6, j + 13, k + 6, 17, 1, 2);
        world.setBlock(i + 2, j + 14, k + 5, 18, 1, 2);
        world.setBlock(i + 3, j + 14, k + 6, 18, 1, 2);
        world.setBlock(i + 4, j + 14, k + 9, 18, 1, 2);
        world.setBlock(i + 4, j + 14, k + 6, 18, 1, 2);
        world.setBlock(i + 5, j + 14, k + 9, 18, 1, 2);
        world.setBlock(i + 5, j + 14, k + 8, 18, 1, 2);
        world.setBlock(i + 5, j + 14, k + 7, 17, 1, 2);
        world.setBlock(i + 5, j + 14, k + 6, 17, 1, 2);
        world.setBlock(i + 5, j + 14, k + 3, 18, 1, 2);
        world.setBlock(i + 6, j + 14, k + 7, 18, 1, 2);
        world.setBlock(i + 6, j + 14, k + 6, 17, 1, 2);
        world.setBlock(i + 7, j + 14, k + 6, 18, 1, 2);
        world.setBlock(i + 7, j + 14, k + 5, 18, 1, 2);
        world.setBlock(i + 8, j + 14, k + 7, 18, 1, 2);
        world.setBlock(i + 8, j + 14, k + 5, 18, 1, 2);
        world.setBlock(i + 3, j + 15, k + 9, 18, 1, 2);
        world.setBlock(i + 4, j + 15, k + 8, 17, 1, 2);
        world.setBlock(i + 4, j + 15, k + 7, 18, 1, 2);
        world.setBlock(i + 4, j + 15, k + 6, 18, 1, 2);
        world.setBlock(i + 5, j + 15, k + 7, 18, 1, 2);
        world.setBlock(i + 5, j + 15, k + 6, 17, 1, 2);
        world.setBlock(i + 5, j + 15, k + 5, 18, 1, 2);
        world.setBlock(i + 6, j + 15, k + 7, 18, 1, 2);
        world.setBlock(i + 6, j + 15, k + 6, 17, 1, 2);
        world.setBlock(i + 6, j + 15, k + 5, 18, 1, 2);
        world.setBlock(i + 7, j + 15, k + 7, 18, 1, 2);
        world.setBlock(i + 7, j + 15, k + 6, 18, 1, 2);
        world.setBlock(i + 7, j + 15, k + 5, 18, 1, 2);
        world.setBlock(i + 1, j + 16, k + 8, 18, 1, 2);
        world.setBlock(i + 2, j + 16, k + 8, 18, 1, 2);
        world.setBlock(i + 2, j + 16, k + 6, 18, 1, 2);
        world.setBlock(i + 3, j + 16, k + 8, 18, 1, 2);
        world.setBlock(i + 3, j + 16, k + 7, 18, 1, 2);
        world.setBlock(i + 3, j + 16, k + 5, 18, 1, 2);
        world.setBlock(i + 4, j + 16, k + 11, 18, 1, 2);
        world.setBlock(i + 4, j + 16, k + 10, 18, 1, 2);
        world.setBlock(i + 4, j + 16, k + 8, 17, 1, 2);
        world.setBlock(i + 4, j + 16, k + 6, 18, 1, 2);
        world.setBlock(i + 4, j + 16, k + 5, 18, 1, 2);
        world.setBlock(i + 5, j + 16, k + 6, 17, 1, 2);
        world.setBlock(i + 5, j + 16, k + 5, 18, 1, 2);
        world.setBlock(i + 6, j + 16, k + 10, 18, 1, 2);
        world.setBlock(i + 6, j + 16, k + 8, 18, 1, 2);
        world.setBlock(i + 6, j + 16, k + 6, 17, 1, 2);
        world.setBlock(i + 7, j + 16, k + 9, 18, 1, 2);
        world.setBlock(i + 7, j + 16, k + 8, 18, 1, 2);
        world.setBlock(i + 2, j + 17, k + 9, 18, 1, 2);
        world.setBlock(i + 3, j + 17, k + 9, 17, 1, 2);
        world.setBlock(i + 3, j + 17, k + 8, 18, 1, 2);
        world.setBlock(i + 4, j + 17, k + 9, 18, 1, 2);
        world.setBlock(i + 5, j + 17, k + 6, 17, 1, 2);
        world.setBlock(i + 5, j + 17, k + 5, 18, 1, 2);
        world.setBlock(i + 6, j + 17, k + 10, 18, 1, 2);
        world.setBlock(i + 6, j + 17, k + 6, 17, 1, 2);
        world.setBlock(i + 7, j + 17, k + 7, 17, 1, 2);
        world.setBlock(i + 7, j + 17, k + 4, 18, 1, 2);
        world.setBlock(i + 8, j + 17, k + 8, 18, 1, 2);
        world.setBlock(i + 8, j + 17, k + 7, 18, 1, 2);
        world.setBlock(i + 8, j + 17, k + 6, 18, 1, 2);
        world.setBlock(i + 9, j + 17, k + 9, 18, 1, 2);
        world.setBlock(i + 9, j + 17, k + 8, 18, 1, 2);
        world.setBlock(i + 9, j + 17, k + 6, 18, 1, 2);
        world.setBlock(i + 0, j + 18, k + 9, 18, 1, 2);
        world.setBlock(i + 1, j + 18, k + 11, 18, 1, 2);
        world.setBlock(i + 1, j + 18, k + 9, 18, 1, 2);
        world.setBlock(i + 1, j + 18, k + 8, 18, 1, 2);
        world.setBlock(i + 1, j + 18, k + 7, 18, 1, 2);
        world.setBlock(i + 2, j + 18, k + 9, 18, 1, 2);
        world.setBlock(i + 3, j + 18, k + 11, 18, 1, 2);
        world.setBlock(i + 3, j + 18, k + 9, 17, 1, 2);
        world.setBlock(i + 3, j + 18, k + 8, 18, 1, 2);
        world.setBlock(i + 4, j + 18, k + 9, 18, 1, 2);
        world.setBlock(i + 4, j + 18, k + 6, 18, 1, 2);
        world.setBlock(i + 5, j + 18, k + 9, 18, 1, 2);
        world.setBlock(i + 5, j + 18, k + 7, 18, 1, 2);
        world.setBlock(i + 5, j + 18, k + 6, 17, 1, 2);
        world.setBlock(i + 6, j + 18, k + 10, 18, 1, 2);
        world.setBlock(i + 6, j + 18, k + 9, 18, 1, 2);
        world.setBlock(i + 6, j + 18, k + 7, 18, 1, 2);
        world.setBlock(i + 6, j + 18, k + 6, 17, 1, 2);
        world.setBlock(i + 6, j + 18, k + 5, 18, 1, 2);
        world.setBlock(i + 7, j + 18, k + 6, 18, 1, 2);
        world.setBlock(i + 7, j + 18, k + 5, 18, 1, 2);
        world.setBlock(i + 8, j + 18, k + 7, 17, 1, 2);
        world.setBlock(i + 2, j + 19, k + 9, 18, 1, 2);
        world.setBlock(i + 3, j + 19, k + 10, 18, 1, 2);
        world.setBlock(i + 3, j + 19, k + 9, 17, 1, 2);
        world.setBlock(i + 3, j + 19, k + 6, 18, 1, 2);
        world.setBlock(i + 3, j + 19, k + 4, 18, 1, 2);
        world.setBlock(i + 4, j + 19, k + 9, 18, 1, 2);
        world.setBlock(i + 4, j + 19, k + 7, 18, 1, 2);
        world.setBlock(i + 4, j + 19, k + 5, 18, 1, 2);
        world.setBlock(i + 5, j + 19, k + 8, 18, 1, 2);
        world.setBlock(i + 5, j + 19, k + 7, 18, 1, 2);
        world.setBlock(i + 5, j + 19, k + 6, 17, 1, 2);
        world.setBlock(i + 5, j + 19, k + 5, 18, 1, 2);
        world.setBlock(i + 5, j + 19, k + 2, 18, 1, 2);
        world.setBlock(i + 6, j + 19, k + 7, 18, 1, 2);
        world.setBlock(i + 6, j + 19, k + 6, 17, 1, 2);
        world.setBlock(i + 6, j + 19, k + 5, 17, 1, 2);
        world.setBlock(i + 6, j + 19, k + 2, 18, 1, 2);
        world.setBlock(i + 7, j + 19, k + 8, 18, 1, 2);
        world.setBlock(i + 7, j + 19, k + 6, 18, 1, 2);
        world.setBlock(i + 7, j + 19, k + 5, 18, 1, 2);
        world.setBlock(i + 7, j + 19, k + 4, 18, 1, 2);
        world.setBlock(i + 8, j + 19, k + 10, 18, 1, 2);
        world.setBlock(i + 8, j + 19, k + 8, 18, 1, 2);
        world.setBlock(i + 8, j + 19, k + 7, 17, 1, 2);
        world.setBlock(i + 8, j + 19, k + 6, 18, 1, 2);
        world.setBlock(i + 8, j + 19, k + 5, 18, 1, 2);
        world.setBlock(i + 8, j + 19, k + 4, 18, 1, 2);
        world.setBlock(i + 9, j + 19, k + 7, 18, 1, 2);
        world.setBlock(i + 9, j + 19, k + 5, 18, 1, 2);
        world.setBlock(i + 10, j + 19, k + 9, 18, 1, 2);
        world.setBlock(i + 11, j + 19, k + 7, 18, 1, 2);
        world.setBlock(i + 0, j + 20, k + 8, 18, 1, 2);
        world.setBlock(i + 1, j + 20, k + 11, 18, 1, 2);
        world.setBlock(i + 1, j + 20, k + 8, 18, 1, 2);
        world.setBlock(i + 1, j + 20, k + 7, 18, 1, 2);
        world.setBlock(i + 2, j + 20, k + 10, 18, 1, 2);
        world.setBlock(i + 2, j + 20, k + 8, 18, 1, 2);
        world.setBlock(i + 3, j + 20, k + 11, 18, 1, 2);
        world.setBlock(i + 3, j + 20, k + 9, 17, 1, 2);
        world.setBlock(i + 3, j + 20, k + 8, 18, 1, 2);
        world.setBlock(i + 3, j + 20, k + 7, 18, 1, 2);
        world.setBlock(i + 4, j + 20, k + 10, 18, 1, 2);
        world.setBlock(i + 4, j + 20, k + 9, 18, 1, 2);
        world.setBlock(i + 4, j + 20, k + 8, 18, 1, 2);
        world.setBlock(i + 4, j + 20, k + 3, 18, 1, 2);
        world.setBlock(i + 5, j + 20, k + 10, 18, 1, 2);
        world.setBlock(i + 5, j + 20, k + 7, 18, 1, 2);
        world.setBlock(i + 5, j + 20, k + 6, 17, 1, 2);
        world.setBlock(i + 5, j + 20, k + 5, 18, 1, 2);
        world.setBlock(i + 6, j + 20, k + 8, 18, 1, 2);
        world.setBlock(i + 6, j + 20, k + 6, 17, 1, 2);
        world.setBlock(i + 6, j + 20, k + 5, 18, 1, 2);
        world.setBlock(i + 6, j + 20, k + 4, 18, 1, 2);
        world.setBlock(i + 7, j + 20, k + 7, 18, 1, 2);
        world.setBlock(i + 7, j + 20, k + 4, 17, 1, 2);
        world.setBlock(i + 7, j + 20, k + 3, 18, 1, 2);
        world.setBlock(i + 7, j + 20, k + 2, 18, 1, 2);
        world.setBlock(i + 8, j + 20, k + 8, 17, 1, 2);
        world.setBlock(i + 8, j + 20, k + 7, 18, 1, 2);
        world.setBlock(i + 8, j + 20, k + 4, 18, 1, 2);
        world.setBlock(i + 9, j + 20, k + 5, 18, 1, 2);
        world.setBlock(i + 9, j + 20, k + 2, 18, 1, 2);
        world.setBlock(i + 4, j + 21, k + 5, 18, 1, 2);
        world.setBlock(i + 5, j + 21, k + 8, 18, 1, 2);
        world.setBlock(i + 5, j + 21, k + 7, 18, 1, 2);
        world.setBlock(i + 5, j + 21, k + 6, 17, 1, 2);
        world.setBlock(i + 6, j + 21, k + 6, 18, 1, 2);
        world.setBlock(i + 7, j + 21, k + 7, 18, 1, 2);
        world.setBlock(i + 7, j + 21, k + 6, 18, 1, 2);
        world.setBlock(i + 7, j + 21, k + 3, 17, 1, 2);
        world.setBlock(i + 8, j + 21, k + 11, 18, 1, 2);
        world.setBlock(i + 8, j + 21, k + 10, 18, 1, 2);
        world.setBlock(i + 8, j + 21, k + 8, 17, 1, 2);
        world.setBlock(i + 8, j + 21, k + 7, 18, 1, 2);
        world.setBlock(i + 8, j + 21, k + 5, 18, 1, 2);
        world.setBlock(i + 9, j + 21, k + 10, 18, 1, 2);
        world.setBlock(i + 9, j + 21, k + 9, 18, 1, 2);
        world.setBlock(i + 9, j + 21, k + 8, 18, 1, 2);
        world.setBlock(i + 9, j + 21, k + 7, 18, 1, 2);
        world.setBlock(i + 9, j + 21, k + 6, 18, 1, 2);
        world.setBlock(i + 10, j + 21, k + 9, 18, 1, 2);
        world.setBlock(i + 10, j + 21, k + 8, 18, 1, 2);
        world.setBlock(i + 11, j + 21, k + 9, 18, 1, 2);
        world.setBlock(i + 0, j + 22, k + 6, 18, 1, 2);
        world.setBlock(i + 1, j + 22, k + 6, 18, 1, 2);
        world.setBlock(i + 1, j + 22, k + 4, 18, 1, 2);
        world.setBlock(i + 2, j + 22, k + 10, 18, 1, 2);
        world.setBlock(i + 2, j + 22, k + 9, 18, 1, 2);
        world.setBlock(i + 2, j + 22, k + 8, 18, 1, 2);
        world.setBlock(i + 2, j + 22, k + 7, 18, 1, 2);
        world.setBlock(i + 2, j + 22, k + 6, 18, 1, 2);
        world.setBlock(i + 2, j + 22, k + 2, 18, 1, 2);
        world.setBlock(i + 3, j + 22, k + 11, 18, 1, 2);
        world.setBlock(i + 3, j + 22, k + 10, 18, 1, 2);
        world.setBlock(i + 3, j + 22, k + 2, 18, 1, 2);
        world.setBlock(i + 4, j + 22, k + 9, 18, 1, 2);
        world.setBlock(i + 4, j + 22, k + 8, 18, 1, 2);
        world.setBlock(i + 4, j + 22, k + 6, 18, 1, 2);
        world.setBlock(i + 4, j + 22, k + 5, 18, 1, 2);
        world.setBlock(i + 4, j + 22, k + 4, 18, 1, 2);
        world.setBlock(i + 4, j + 22, k + 3, 18, 1, 2);
        world.setBlock(i + 4, j + 22, k + 2, 18, 1, 2);
        world.setBlock(i + 4, j + 22, k + 1, 18, 1, 2);
        world.setBlock(i + 5, j + 22, k + 10, 18, 1, 2);
        world.setBlock(i + 5, j + 22, k + 9, 18, 1, 2);
        world.setBlock(i + 5, j + 22, k + 7, 18, 1, 2);
        world.setBlock(i + 5, j + 22, k + 6, 17, 1, 2);
        world.setBlock(i + 5, j + 22, k + 4, 18, 1, 2);
        world.setBlock(i + 5, j + 22, k + 3, 18, 1, 2);
        world.setBlock(i + 5, j + 22, k + 2, 18, 1, 2);
        world.setBlock(i + 6, j + 22, k + 11, 18, 1, 2);
        world.setBlock(i + 6, j + 22, k + 7, 18, 1, 2);
        world.setBlock(i + 7, j + 22, k + 11, 18, 1, 2);
        world.setBlock(i + 7, j + 22, k + 8, 18, 1, 2);
        world.setBlock(i + 7, j + 22, k + 7, 18, 1, 2);
        world.setBlock(i + 7, j + 22, k + 6, 18, 1, 2);
        world.setBlock(i + 7, j + 22, k + 5, 18, 1, 2);
        world.setBlock(i + 7, j + 22, k + 4, 18, 1, 2);
        world.setBlock(i + 7, j + 22, k + 3, 17, 1, 2);
        world.setBlock(i + 7, j + 22, k + 2, 18, 1, 2);
        world.setBlock(i + 7, j + 22, k + 1, 18, 1, 2);
        world.setBlock(i + 8, j + 22, k + 8, 17, 1, 2);
        world.setBlock(i + 8, j + 22, k + 4, 18, 1, 2);
        world.setBlock(i + 8, j + 22, k + 2, 18, 1, 2);
        world.setBlock(i + 8, j + 22, k + 0, 18, 1, 2);
        world.setBlock(i + 9, j + 22, k + 9, 18, 1, 2);
        world.setBlock(i + 9, j + 22, k + 6, 18, 1, 2);
        world.setBlock(i + 9, j + 22, k + 3, 18, 1, 2);
        world.setBlock(i + 9, j + 22, k + 2, 18, 1, 2);
        world.setBlock(i + 10, j + 22, k + 6, 18, 1, 2);
        world.setBlock(i + 10, j + 22, k + 5, 18, 1, 2);
        world.setBlock(i + 10, j + 22, k + 2, 18, 1, 2);
        world.setBlock(i + 4, j + 23, k + 6, 18, 1, 2);
        world.setBlock(i + 4, j + 23, k + 5, 17, 1, 2);
        world.setBlock(i + 4, j + 23, k + 4, 18, 1, 2);
        world.setBlock(i + 5, j + 23, k + 6, 17, 1, 2);
        world.setBlock(i + 5, j + 23, k + 5, 18, 1, 2);
        world.setBlock(i + 5, j + 23, k + 4, 18, 1, 2);
        world.setBlock(i + 6, j + 23, k + 7, 18, 1, 2);
        world.setBlock(i + 6, j + 23, k + 6, 18, 1, 2);
        world.setBlock(i + 0, j + 24, k + 6, 18, 1, 2);
        world.setBlock(i + 0, j + 24, k + 5, 18, 1, 2);
        world.setBlock(i + 1, j + 24, k + 9, 18, 1, 2);
        world.setBlock(i + 1, j + 24, k + 7, 18, 1, 2);
        world.setBlock(i + 1, j + 24, k + 6, 18, 1, 2);
        world.setBlock(i + 2, j + 24, k + 9, 18, 1, 2);
        world.setBlock(i + 2, j + 24, k + 8, 18, 1, 2);
        world.setBlock(i + 2, j + 24, k + 6, 18, 1, 2);
        world.setBlock(i + 2, j + 24, k + 5, 18, 1, 2);
        world.setBlock(i + 2, j + 24, k + 3, 18, 1, 2);
        world.setBlock(i + 2, j + 24, k + 2, 18, 1, 2);
        world.setBlock(i + 3, j + 24, k + 7, 18, 1, 2);
        world.setBlock(i + 3, j + 24, k + 6, 18, 1, 2);
        world.setBlock(i + 3, j + 24, k + 4, 17, 1, 2);
        world.setBlock(i + 3, j + 24, k + 2, 18, 1, 2);
        world.setBlock(i + 4, j + 24, k + 10, 18, 1, 2);
        world.setBlock(i + 4, j + 24, k + 6, 18, 1, 2);
        world.setBlock(i + 4, j + 24, k + 2, 18, 1, 2);
        world.setBlock(i + 4, j + 24, k + 1, 18, 1, 2);
        world.setBlock(i + 5, j + 24, k + 11, 18, 1, 2);
        world.setBlock(i + 5, j + 24, k + 9, 18, 1, 2);
        world.setBlock(i + 5, j + 24, k + 8, 18, 1, 2);
        world.setBlock(i + 5, j + 24, k + 6, 17, 1, 2);
        world.setBlock(i + 5, j + 24, k + 4, 18, 1, 2);
        world.setBlock(i + 5, j + 24, k + 3, 18, 1, 2);
        world.setBlock(i + 5, j + 24, k + 2, 18, 1, 2);
        world.setBlock(i + 5, j + 24, k + 1, 18, 1, 2);
        world.setBlock(i + 6, j + 24, k + 4, 18, 1, 2);
        world.setBlock(i + 6, j + 24, k + 3, 18, 1, 2);
        world.setBlock(i + 6, j + 24, k + 2, 18, 1, 2);
        world.setBlock(i + 7, j + 24, k + 10, 18, 1, 2);
        world.setBlock(i + 7, j + 24, k + 6, 18, 1, 2);
        world.setBlock(i + 7, j + 24, k + 3, 18, 1, 2);
        world.setBlock(i + 8, j + 24, k + 10, 18, 1, 2);
        world.setBlock(i + 8, j + 24, k + 7, 18, 1, 2);
        world.setBlock(i + 8, j + 24, k + 6, 18, 1, 2);
        world.setBlock(i + 8, j + 24, k + 2, 18, 1, 2);
        world.setBlock(i + 9, j + 24, k + 8, 18, 1, 2);
        world.setBlock(i + 9, j + 24, k + 7, 18, 1, 2);
        world.setBlock(i + 2, j + 25, k + 5, 18, 1, 2);
        world.setBlock(i + 2, j + 25, k + 4, 18, 1, 2);
        world.setBlock(i + 2, j + 25, k + 3, 18, 1, 2);
        world.setBlock(i + 3, j + 25, k + 5, 18, 1, 2);
        world.setBlock(i + 3, j + 25, k + 4, 17, 1, 2);
        world.setBlock(i + 4, j + 25, k + 7, 18, 1, 2);
        world.setBlock(i + 4, j + 25, k + 6, 18, 1, 2);
        world.setBlock(i + 5, j + 25, k + 7, 18, 1, 2);
        world.setBlock(i + 5, j + 25, k + 6, 17, 1, 2);
        world.setBlock(i + 5, j + 25, k + 5, 18, 1, 2);
        world.setBlock(i + 0, j + 26, k + 7, 18, 1, 2);
        world.setBlock(i + 1, j + 26, k + 8, 18, 1, 2);
        world.setBlock(i + 1, j + 26, k + 4, 18, 1, 2);
        world.setBlock(i + 2, j + 26, k + 6, 18, 1, 2);
        world.setBlock(i + 3, j + 26, k + 6, 18, 1, 2);
        world.setBlock(i + 4, j + 26, k + 10, 18, 1, 2);
        world.setBlock(i + 4, j + 26, k + 9, 18, 1, 2);
        world.setBlock(i + 4, j + 26, k + 8, 18, 1, 2);
        world.setBlock(i + 4, j + 26, k + 6, 18, 1, 2);
        world.setBlock(i + 4, j + 26, k + 2, 18, 1, 2);
        world.setBlock(i + 4, j + 26, k + 1, 18, 1, 2);
        world.setBlock(i + 5, j + 26, k + 10, 18, 1, 2);
        world.setBlock(i + 5, j + 26, k + 9, 18, 1, 2);
        world.setBlock(i + 5, j + 26, k + 7, 18, 1, 2);
        world.setBlock(i + 5, j + 26, k + 6, 17, 1, 2);
        world.setBlock(i + 5, j + 26, k + 5, 18, 1, 2);
        world.setBlock(i + 5, j + 26, k + 4, 18, 1, 2);
        world.setBlock(i + 5, j + 26, k + 3, 18, 1, 2);
        world.setBlock(i + 5, j + 26, k + 2, 18, 1, 2);
        world.setBlock(i + 6, j + 26, k + 10, 18, 1, 2);
        world.setBlock(i + 6, j + 26, k + 5, 18, 1, 2);
        world.setBlock(i + 7, j + 26, k + 10, 18, 1, 2);
        world.setBlock(i + 7, j + 26, k + 8, 18, 1, 2);
        world.setBlock(i + 7, j + 26, k + 5, 18, 1, 2);
        world.setBlock(i + 7, j + 26, k + 4, 18, 1, 2);
        world.setBlock(i + 7, j + 26, k + 3, 18, 1, 2);
        world.setBlock(i + 7, j + 26, k + 1, 18, 1, 2);
        world.setBlock(i + 8, j + 26, k + 9, 18, 1, 2);
        world.setBlock(i + 8, j + 26, k + 8, 18, 1, 2);
        world.setBlock(i + 8, j + 26, k + 7, 18, 1, 2);
        world.setBlock(i + 8, j + 26, k + 6, 18, 1, 2);
        world.setBlock(i + 8, j + 26, k + 5, 18, 1, 2);
        world.setBlock(i + 8, j + 26, k + 4, 18, 1, 2);
        world.setBlock(i + 9, j + 26, k + 9, 18, 1, 2);
        world.setBlock(i + 9, j + 26, k + 3, 18, 1, 2);
        world.setBlock(i + 10, j + 26, k + 8, 18, 1, 2);
        world.setBlock(i + 10, j + 26, k + 5, 18, 1, 2);
        world.setBlock(i + 4, j + 27, k + 7, 18, 1, 2);
        world.setBlock(i + 4, j + 27, k + 6, 18, 1, 2);
        world.setBlock(i + 4, j + 27, k + 5, 18, 1, 2);
        world.setBlock(i + 5, j + 27, k + 7, 18, 1, 2);
        world.setBlock(i + 5, j + 27, k + 6, 17, 1, 2);
        world.setBlock(i + 5, j + 27, k + 5, 18, 1, 2);
        world.setBlock(i + 6, j + 27, k + 6, 18, 1, 2);
        world.setBlock(i + 6, j + 27, k + 5, 18, 1, 2);
        world.setBlock(i + 0, j + 28, k + 6, 18, 1, 2);
        world.setBlock(i + 1, j + 28, k + 8, 18, 1, 2);
        world.setBlock(i + 1, j + 28, k + 7, 18, 1, 2);
        world.setBlock(i + 1, j + 28, k + 6, 18, 1, 2);
        world.setBlock(i + 2, j + 28, k + 9, 18, 1, 2);
        world.setBlock(i + 2, j + 28, k + 5, 18, 1, 2);
        world.setBlock(i + 2, j + 28, k + 4, 18, 1, 2);
        world.setBlock(i + 3, j + 28, k + 11, 18, 1, 2);
        world.setBlock(i + 3, j + 28, k + 10, 18, 1, 2);
        world.setBlock(i + 3, j + 28, k + 8, 18, 1, 2);
        world.setBlock(i + 3, j + 28, k + 6, 18, 1, 2);
        world.setBlock(i + 3, j + 28, k + 4, 18, 1, 2);
        world.setBlock(i + 3, j + 28, k + 3, 18, 1, 2);
        world.setBlock(i + 4, j + 28, k + 11, 18, 1, 2);
        world.setBlock(i + 4, j + 28, k + 4, 18, 1, 2);
        world.setBlock(i + 5, j + 28, k + 10, 18, 1, 2);
        world.setBlock(i + 5, j + 28, k + 8, 18, 1, 2);
        world.setBlock(i + 5, j + 28, k + 7, 18, 1, 2);
        world.setBlock(i + 5, j + 28, k + 6, 17, 1, 2);
        world.setBlock(i + 5, j + 28, k + 5, 17, 1, 2);
        world.setBlock(i + 5, j + 28, k + 3, 18, 1, 2);
        world.setBlock(i + 5, j + 28, k + 2, 18, 1, 2);
        world.setBlock(i + 6, j + 28, k + 9, 18, 1, 2);
        world.setBlock(i + 6, j + 28, k + 6, 18, 1, 2);
        world.setBlock(i + 6, j + 28, k + 4, 18, 1, 2);
        world.setBlock(i + 6, j + 28, k + 2, 18, 1, 2);
        world.setBlock(i + 7, j + 28, k + 9, 18, 1, 2);
        world.setBlock(i + 7, j + 28, k + 3, 18, 1, 2);
        world.setBlock(i + 8, j + 28, k + 9, 18, 1, 2);
        world.setBlock(i + 8, j + 28, k + 7, 18, 1, 2);
        world.setBlock(i + 8, j + 28, k + 6, 18, 1, 2);
        world.setBlock(i + 8, j + 28, k + 3, 18, 1, 2);
        world.setBlock(i + 8, j + 28, k + 2, 18, 1, 2);
        world.setBlock(i + 9, j + 28, k + 7, 18, 1, 2);
        world.setBlock(i + 9, j + 28, k + 5, 18, 1, 2);
        world.setBlock(i + 9, j + 28, k + 4, 18, 1, 2);
        world.setBlock(i + 10, j + 28, k + 8, 18, 1, 2);
        world.setBlock(i + 10, j + 28, k + 4, 18, 1, 2);
        world.setBlock(i + 3, j + 29, k + 7, 18, 1, 2);
        world.setBlock(i + 3, j + 29, k + 6, 18, 1, 2);
        world.setBlock(i + 3, j + 29, k + 5, 18, 1, 2);
        world.setBlock(i + 4, j + 29, k + 6, 17, 1, 2);
        world.setBlock(i + 4, j + 29, k + 5, 18, 1, 2);
        world.setBlock(i + 5, j + 29, k + 6, 17, 1, 2);
        world.setBlock(i + 5, j + 29, k + 5, 18, 1, 2);
        world.setBlock(i + 0, j + 30, k + 8, 18, 1, 2);
        world.setBlock(i + 0, j + 30, k + 6, 18, 1, 2);
        world.setBlock(i + 0, j + 30, k + 5, 18, 1, 2);
        world.setBlock(i + 1, j + 30, k + 6, 18, 1, 2);
        world.setBlock(i + 1, j + 30, k + 3, 18, 1, 2);
        world.setBlock(i + 2, j + 30, k + 5, 18, 1, 2);
        world.setBlock(i + 2, j + 30, k + 2, 18, 1, 2);
        world.setBlock(i + 3, j + 30, k + 8, 18, 1, 2);
        world.setBlock(i + 3, j + 30, k + 6, 18, 1, 2);
        world.setBlock(i + 3, j + 30, k + 4, 18, 1, 2);
        world.setBlock(i + 3, j + 30, k + 1, 18, 1, 2);
        world.setBlock(i + 4, j + 30, k + 7, 18, 1, 2);
        world.setBlock(i + 4, j + 30, k + 6, 18, 1, 2);
        world.setBlock(i + 4, j + 30, k + 2, 18, 1, 2);
        world.setBlock(i + 5, j + 30, k + 11, 18, 1, 2);
        world.setBlock(i + 5, j + 30, k + 8, 18, 1, 2);
        world.setBlock(i + 5, j + 30, k + 7, 17, 1, 2);
        world.setBlock(i + 5, j + 30, k + 6, 17, 1, 2);
        world.setBlock(i + 5, j + 30, k + 5, 18, 1, 2);
        world.setBlock(i + 5, j + 30, k + 3, 18, 1, 2);
        world.setBlock(i + 5, j + 30, k + 2, 18, 1, 2);
        world.setBlock(i + 5, j + 30, k + 1, 18, 1, 2);
        world.setBlock(i + 6, j + 30, k + 6, 18, 1, 2);
        world.setBlock(i + 6, j + 30, k + 5, 18, 1, 2);
        world.setBlock(i + 6, j + 30, k + 2, 18, 1, 2);
        world.setBlock(i + 7, j + 30, k + 9, 18, 1, 2);
        world.setBlock(i + 7, j + 30, k + 8, 18, 1, 2);
        world.setBlock(i + 7, j + 30, k + 6, 18, 1, 2);
        world.setBlock(i + 7, j + 30, k + 5, 18, 1, 2);
        world.setBlock(i + 7, j + 30, k + 4, 18, 1, 2);
        world.setBlock(i + 7, j + 30, k + 1, 18, 1, 2);
        world.setBlock(i + 8, j + 30, k + 10, 18, 1, 2);
        world.setBlock(i + 8, j + 30, k + 9, 18, 1, 2);
        world.setBlock(i + 8, j + 30, k + 6, 18, 1, 2);
        world.setBlock(i + 9, j + 30, k + 9, 18, 1, 2);
        world.setBlock(i + 9, j + 30, k + 5, 18, 1, 2);
        world.setBlock(i + 9, j + 30, k + 4, 18, 1, 2);
        world.setBlock(i + 10, j + 30, k + 7, 18, 1, 2);
        world.setBlock(i + 10, j + 30, k + 6, 18, 1, 2);
        world.setBlock(i + 0, j + 31, k + 8, 18, 1, 2);
        world.setBlock(i + 0, j + 31, k + 5, 18, 1, 2);
        world.setBlock(i + 1, j + 31, k + 8, 18, 1, 2);
        world.setBlock(i + 1, j + 31, k + 7, 18, 1, 2);
        world.setBlock(i + 1, j + 31, k + 5, 18, 1, 2);
        world.setBlock(i + 2, j + 31, k + 8, 18, 1, 2);
        world.setBlock(i + 2, j + 31, k + 7, 18, 1, 2);
        world.setBlock(i + 2, j + 31, k + 6, 18, 1, 2);
        world.setBlock(i + 2, j + 31, k + 3, 18, 1, 2);
        world.setBlock(i + 3, j + 31, k + 10, 18, 1, 2);
        world.setBlock(i + 4, j + 31, k + 11, 18, 1, 2);
        world.setBlock(i + 4, j + 31, k + 5, 18, 1, 2);
        world.setBlock(i + 4, j + 31, k + 3, 18, 1, 2);
        world.setBlock(i + 4, j + 31, k + 1, 18, 1, 2);
        world.setBlock(i + 5, j + 31, k + 10, 18, 1, 2);
        world.setBlock(i + 5, j + 31, k + 9, 18, 1, 2);
        world.setBlock(i + 5, j + 31, k + 8, 18, 1, 2);
        world.setBlock(i + 5, j + 31, k + 7, 18, 1, 2);
        world.setBlock(i + 5, j + 31, k + 6, 17, 1, 2);
        world.setBlock(i + 5, j + 31, k + 5, 17, 1, 2);
        world.setBlock(i + 5, j + 31, k + 4, 18, 1, 2);
        world.setBlock(i + 5, j + 31, k + 2, 18, 1, 2);
        world.setBlock(i + 5, j + 31, k + 1, 18, 1, 2);
        world.setBlock(i + 6, j + 31, k + 8, 18, 1, 2);
        world.setBlock(i + 6, j + 31, k + 7, 18, 1, 2);
        world.setBlock(i + 6, j + 31, k + 3, 18, 1, 2);
        world.setBlock(i + 6, j + 31, k + 2, 18, 1, 2);
        world.setBlock(i + 7, j + 31, k + 11, 18, 1, 2);
        world.setBlock(i + 8, j + 31, k + 9, 18, 1, 2);
        world.setBlock(i + 8, j + 31, k + 5, 18, 1, 2);
        world.setBlock(i + 8, j + 31, k + 3, 18, 1, 2);
        world.setBlock(i + 9, j + 31, k + 8, 18, 1, 2);
        world.setBlock(i + 9, j + 31, k + 5, 18, 1, 2);
        world.setBlock(i + 9, j + 31, k + 4, 18, 1, 2);
        world.setBlock(i + 10, j + 31, k + 8, 18, 1, 2);
        world.setBlock(i + 10, j + 31, k + 6, 18, 1, 2);
        world.setBlock(i + 4, j + 32, k + 7, 18, 1, 2);
        world.setBlock(i + 4, j + 32, k + 6, 18, 1, 2);
        world.setBlock(i + 4, j + 32, k + 5, 18, 1, 2);
        world.setBlock(i + 5, j + 32, k + 7, 18, 1, 2);
        world.setBlock(i + 5, j + 32, k + 6, 17, 1, 2);
        world.setBlock(i + 5, j + 32, k + 5, 18, 1, 2);
        world.setBlock(i + 1, j + 33, k + 6, 18, 1, 2);
        world.setBlock(i + 2, j + 33, k + 9, 18, 1, 2);
        world.setBlock(i + 2, j + 33, k + 7, 18, 1, 2);
        world.setBlock(i + 2, j + 33, k + 4, 18, 1, 2);
        world.setBlock(i + 2, j + 33, k + 3, 18, 1, 2);
        world.setBlock(i + 3, j + 33, k + 6, 18, 1, 2);
        world.setBlock(i + 4, j + 33, k + 8, 18, 1, 2);
        world.setBlock(i + 4, j + 33, k + 6, 18, 1, 2);
        world.setBlock(i + 4, j + 33, k + 5, 18, 1, 2);
        world.setBlock(i + 4, j + 33, k + 2, 18, 1, 2);
        world.setBlock(i + 5, j + 33, k + 8, 18, 1, 2);
        world.setBlock(i + 5, j + 33, k + 7, 17, 1, 2);
        world.setBlock(i + 5, j + 33, k + 6, 17, 1, 2);
        world.setBlock(i + 5, j + 33, k + 4, 18, 1, 2);
        world.setBlock(i + 5, j + 33, k + 3, 18, 1, 2);
        world.setBlock(i + 5, j + 33, k + 2, 18, 1, 2);
        world.setBlock(i + 6, j + 33, k + 8, 18, 1, 2);
        world.setBlock(i + 6, j + 33, k + 5, 18, 1, 2);
        world.setBlock(i + 6, j + 33, k + 2, 18, 1, 2);
        world.setBlock(i + 7, j + 33, k + 8, 18, 1, 2);
        world.setBlock(i + 7, j + 33, k + 6, 18, 1, 2);
        world.setBlock(i + 7, j + 33, k + 5, 18, 1, 2);
        world.setBlock(i + 7, j + 33, k + 4, 18, 1, 2);
        world.setBlock(i + 8, j + 33, k + 8, 18, 1, 2);
        world.setBlock(i + 8, j + 33, k + 7, 18, 1, 2);
        world.setBlock(i + 8, j + 33, k + 6, 18, 1, 2);
        world.setBlock(i + 9, j + 33, k + 7, 18, 1, 2);
        world.setBlock(i + 9, j + 33, k + 6, 18, 1, 2);
        world.setBlock(i + 9, j + 33, k + 4, 18, 1, 2);
        world.setBlock(i + 3, j + 34, k + 7, 18, 1, 2);
        world.setBlock(i + 3, j + 34, k + 6, 18, 1, 2);
        world.setBlock(i + 4, j + 34, k + 6, 17, 1, 2);
        world.setBlock(i + 5, j + 34, k + 7, 18, 1, 2);
        world.setBlock(i + 5, j + 34, k + 6, 17, 1, 2);
        world.setBlock(i + 5, j + 34, k + 5, 18, 1, 2);
        world.setBlock(i + 6, j + 34, k + 7, 18, 1, 2);
        world.setBlock(i + 6, j + 34, k + 6, 17, 1, 2);
        world.setBlock(i + 6, j + 34, k + 5, 18, 1, 2);
        world.setBlock(i + 7, j + 34, k + 6, 18, 1, 2);
        world.setBlock(i + 7, j + 34, k + 5, 18, 1, 2);
        world.setBlock(i + 2, j + 35, k + 7, 18, 1, 2);
        world.setBlock(i + 2, j + 35, k + 6, 18, 1, 2);
        world.setBlock(i + 2, j + 35, k + 5, 18, 1, 2);
        world.setBlock(i + 3, j + 35, k + 8, 18, 1, 2);
        world.setBlock(i + 3, j + 35, k + 6, 18, 1, 2);
        world.setBlock(i + 3, j + 35, k + 5, 18, 1, 2);
        world.setBlock(i + 4, j + 35, k + 6, 18, 1, 2);
        world.setBlock(i + 5, j + 35, k + 6, 17, 1, 2);
        world.setBlock(i + 5, j + 35, k + 5, 18, 1, 2);
        world.setBlock(i + 6, j + 35, k + 8, 18, 1, 2);
        world.setBlock(i + 6, j + 35, k + 7, 18, 1, 2);
        world.setBlock(i + 6, j + 35, k + 6, 18, 1, 2);
        world.setBlock(i + 6, j + 35, k + 5, 18, 1, 2);
        world.setBlock(i + 7, j + 35, k + 7, 18, 1, 2);
        world.setBlock(i + 7, j + 35, k + 5, 18, 1, 2);
        world.setBlock(i + 7, j + 35, k + 4, 18, 1, 2);
        world.setBlock(i + 8, j + 35, k + 6, 18, 1, 2);
        world.setBlock(i + 8, j + 35, k + 5, 18, 1, 2);
        world.setBlock(i + 4, j + 36, k + 6, 18, 1, 2);
        world.setBlock(i + 5, j + 36, k + 7, 18, 1, 2);
        world.setBlock(i + 5, j + 36, k + 6, 17, 1, 2);
        world.setBlock(i + 6, j + 36, k + 7, 18, 1, 2);
        world.setBlock(i + 6, j + 36, k + 5, 18, 1, 2);
        world.setBlock(i + 4, j + 37, k + 5, 18, 1, 2);
        world.setBlock(i + 5, j + 37, k + 8, 18, 1, 2);
        world.setBlock(i + 5, j + 37, k + 7, 18, 1, 2);
        world.setBlock(i + 5, j + 37, k + 6, 17, 1, 2);
        world.setBlock(i + 5, j + 37, k + 5, 18, 1, 2);
        world.setBlock(i + 5, j + 37, k + 4, 18, 1, 2);
        world.setBlock(i + 6, j + 37, k + 8, 18, 1, 2);
        world.setBlock(i + 7, j + 37, k + 7, 18, 1, 2);
        world.setBlock(i + 4, j + 38, k + 7, 18, 1, 2);
        world.setBlock(i + 5, j + 38, k + 6, 17, 1, 2);
        world.setBlock(i + 5, j + 38, k + 5, 18, 1, 2);
        world.setBlock(i + 4, j + 39, k + 6, 18, 1, 2);
        world.setBlock(i + 5, j + 39, k + 7, 18, 1, 2);
        world.setBlock(i + 5, j + 39, k + 6, 17, 1, 2);
        world.setBlock(i + 5, j + 39, k + 5, 18, 1, 2);
        world.setBlock(i + 6, j + 39, k + 6, 18, 1, 2);

return true;
}
}
