package morethantrees.treegen;

import java.util.Random;

import net.minecraft.block.Block;
import net.minecraft.world.World;
import net.minecraft.world.gen.feature.WorldGenerator;

public class WorldGenGrandFirLargeTree extends WorldGenerator
{
	public boolean generate(World world, Random var2, int i, int j, int k)
	  {
	    while ((world.isAirBlock(i + 10, j, k + 12)) && (j > 2))
	    {
	      j--;
	    }

	    int var6 = world.getBlockId(i + 10, j, k + 12);

	    if (var6 != Block.grass.blockID)
	    {
	      return false;
	    }

	    for (int var7 = -2; var7 <= 2; var7++)
	    {
	      for (int var8 = -2; var8 <= 2; var8++)
	      {
	        if ((world.isAirBlock(i + var7 + 10, j - 1, k + var8 + 12)) && (world.isAirBlock(i + var7 + 10, j - 2, k + var8 + 12)))
	        {
	          return false;
	        }
	      }
	    }
    	world.setBlock(i + 3, j + 0, k + 5, 17, 1, 2);
        world.setBlock(i + 4, j + 0, k + 8, 17, 1, 2);
        world.setBlock(i + 4, j + 0, k + 6, 17, 1, 2);
        world.setBlock(i + 5, j + 0, k + 10, 17, 1, 2);
        world.setBlock(i + 5, j + 0, k + 8, 17, 1, 2);
        world.setBlock(i + 5, j + 0, k + 7, 17, 1, 2);
        world.setBlock(i + 5, j + 0, k + 5, 17, 1, 2);
        world.setBlock(i + 6, j + 0, k + 9, 17, 1, 2);
        world.setBlock(i + 6, j + 0, k + 8, 17, 1, 2);
        world.setBlock(i + 6, j + 0, k + 7, 17, 1, 2);
        world.setBlock(i + 7, j + 0, k + 8, 17, 1, 2);
        world.setBlock(i + 7, j + 0, k + 7, 17, 1, 2);
        world.setBlock(i + 8, j + 0, k + 6, 17, 1, 2);
        world.setBlock(i + 4, j + 1, k + 6, 17, 1, 2);
        world.setBlock(i + 5, j + 1, k + 8, 17, 1, 2);
        world.setBlock(i + 5, j + 1, k + 7, 17, 1, 2);
        world.setBlock(i + 6, j + 1, k + 9, 17, 1, 2);
        world.setBlock(i + 6, j + 1, k + 8, 17, 1, 2);
        world.setBlock(i + 6, j + 1, k + 7, 17, 1, 2);
        world.setBlock(i + 7, j + 1, k + 7, 17, 1, 2);
        world.setBlock(i + 5, j + 2, k + 8, 17, 1, 2);
        world.setBlock(i + 5, j + 2, k + 7, 17, 1, 2);
        world.setBlock(i + 6, j + 2, k + 8, 17, 1, 2);
        world.setBlock(i + 6, j + 2, k + 7, 17, 1, 2);
        world.setBlock(i + 5, j + 3, k + 8, 17, 1, 2);
        world.setBlock(i + 5, j + 3, k + 7, 17, 1, 2);
        world.setBlock(i + 6, j + 3, k + 8, 17, 1, 2);
        world.setBlock(i + 6, j + 3, k + 7, 17, 1, 2);
        world.setBlock(i + 5, j + 4, k + 8, 17, 1, 2);
        world.setBlock(i + 5, j + 4, k + 7, 17, 1, 2);
        world.setBlock(i + 6, j + 4, k + 8, 17, 1, 2);
        world.setBlock(i + 6, j + 4, k + 7, 17, 1, 2);
        world.setBlock(i + 5, j + 5, k + 8, 17, 1, 2);
        world.setBlock(i + 5, j + 5, k + 7, 17, 1, 2);
        world.setBlock(i + 6, j + 5, k + 8, 17, 1, 2);
        world.setBlock(i + 6, j + 5, k + 7, 17, 1, 2);
        world.setBlock(i + 5, j + 6, k + 8, 17, 1, 2);
        world.setBlock(i + 5, j + 6, k + 7, 17, 1, 2);
        world.setBlock(i + 6, j + 6, k + 8, 17, 1, 2);
        world.setBlock(i + 6, j + 6, k + 7, 17, 1, 2);
        world.setBlock(i + 5, j + 7, k + 8, 17, 1, 2);
        world.setBlock(i + 5, j + 7, k + 7, 17, 1, 2);
        world.setBlock(i + 6, j + 7, k + 8, 17, 1, 2);
        world.setBlock(i + 6, j + 7, k + 7, 17, 1, 2);
        world.setBlock(i + 5, j + 8, k + 8, 17, 1, 2);
        world.setBlock(i + 5, j + 8, k + 7, 17, 1, 2);
        world.setBlock(i + 6, j + 8, k + 8, 17, 1, 2);
        world.setBlock(i + 6, j + 8, k + 7, 17, 1, 2);
        world.setBlock(i + 5, j + 9, k + 8, 17, 1, 2);
        world.setBlock(i + 5, j + 9, k + 7, 17, 1, 2);
        world.setBlock(i + 6, j + 9, k + 8, 17, 1, 2);
        world.setBlock(i + 6, j + 9, k + 7, 17, 1, 2);
        world.setBlock(i + 5, j + 10, k + 8, 17, 1, 2);
        world.setBlock(i + 5, j + 10, k + 7, 17, 1, 2);
        world.setBlock(i + 6, j + 10, k + 8, 17, 1, 2);
        world.setBlock(i + 6, j + 10, k + 7, 17, 1, 2);
        world.setBlock(i + 5, j + 11, k + 8, 17, 1, 2);
        world.setBlock(i + 5, j + 11, k + 7, 17, 1, 2);
        world.setBlock(i + 6, j + 11, k + 8, 17, 1, 2);
        world.setBlock(i + 6, j + 11, k + 7, 17, 1, 2);
        world.setBlock(i + 5, j + 12, k + 8, 17, 1, 2);
        world.setBlock(i + 5, j + 12, k + 7, 17, 1, 2);
        world.setBlock(i + 6, j + 12, k + 8, 17, 1, 2);
        world.setBlock(i + 6, j + 12, k + 7, 17, 1, 2);
        world.setBlock(i + 5, j + 13, k + 8, 17, 1, 2);
        world.setBlock(i + 5, j + 13, k + 7, 17, 1, 2);
        world.setBlock(i + 6, j + 13, k + 8, 17, 1, 2);
        world.setBlock(i + 6, j + 13, k + 7, 17, 1, 2);
        world.setBlock(i + 5, j + 14, k + 8, 17, 1, 2);
        world.setBlock(i + 5, j + 14, k + 7, 17, 1, 2);
        world.setBlock(i + 6, j + 14, k + 8, 17, 1, 2);
        world.setBlock(i + 6, j + 14, k + 7, 17, 1, 2);
        world.setBlock(i + 5, j + 15, k + 8, 17, 1, 2);
        world.setBlock(i + 5, j + 15, k + 7, 17, 1, 2);
        world.setBlock(i + 6, j + 15, k + 8, 17, 1, 2);
        world.setBlock(i + 6, j + 15, k + 7, 17, 1, 2);
        world.setBlock(i + 3, j + 16, k + 8, 18, 1, 2);
        world.setBlock(i + 3, j + 16, k + 7, 18, 1, 2);
        world.setBlock(i + 5, j + 16, k + 10, 18, 1, 2);
        world.setBlock(i + 5, j + 16, k + 9, 18, 1, 2);
        world.setBlock(i + 5, j + 16, k + 8, 17, 1, 2);
        world.setBlock(i + 5, j + 16, k + 7, 17, 1, 2);
        world.setBlock(i + 6, j + 16, k + 10, 18, 1, 2);
        world.setBlock(i + 6, j + 16, k + 9, 18, 1, 2);
        world.setBlock(i + 6, j + 16, k + 8, 17, 1, 2);
        world.setBlock(i + 6, j + 16, k + 7, 17, 1, 2);
        world.setBlock(i + 6, j + 16, k + 6, 18, 1, 2);
        world.setBlock(i + 7, j + 16, k + 9, 18, 1, 2);
        world.setBlock(i + 4, j + 17, k + 13, 18, 1, 2);
        world.setBlock(i + 4, j + 17, k + 10, 18, 1, 2);
        world.setBlock(i + 5, j + 17, k + 13, 18, 1, 2);
        world.setBlock(i + 5, j + 17, k + 11, 17, 1, 2);
        world.setBlock(i + 5, j + 17, k + 10, 18, 1, 2);
        world.setBlock(i + 5, j + 17, k + 9, 18, 1, 2);
        world.setBlock(i + 5, j + 17, k + 8, 17, 1, 2);
        world.setBlock(i + 5, j + 17, k + 7, 17, 1, 2);
        world.setBlock(i + 6, j + 17, k + 13, 18, 1, 2);
        world.setBlock(i + 6, j + 17, k + 11, 18, 1, 2);
        world.setBlock(i + 6, j + 17, k + 10, 17, 1, 2);
        world.setBlock(i + 6, j + 17, k + 9, 17, 1, 2);
        world.setBlock(i + 6, j + 17, k + 8, 17, 1, 2);
        world.setBlock(i + 6, j + 17, k + 7, 17, 1, 2);
        world.setBlock(i + 7, j + 17, k + 12, 18, 1, 2);
        world.setBlock(i + 7, j + 17, k + 11, 18, 1, 2);
        world.setBlock(i + 4, j + 18, k + 8, 18, 1, 2);
        world.setBlock(i + 4, j + 18, k + 7, 18, 1, 2);
        world.setBlock(i + 5, j + 18, k + 8, 17, 1, 2);
        world.setBlock(i + 5, j + 18, k + 7, 17, 1, 2);
        world.setBlock(i + 5, j + 18, k + 6, 18, 1, 2);
        world.setBlock(i + 6, j + 18, k + 10, 18, 1, 2);
        world.setBlock(i + 6, j + 18, k + 9, 18, 1, 2);
        world.setBlock(i + 6, j + 18, k + 8, 17, 1, 2);
        world.setBlock(i + 6, j + 18, k + 7, 17, 1, 2);
        world.setBlock(i + 6, j + 18, k + 6, 18, 1, 2);
        world.setBlock(i + 7, j + 18, k + 8, 17, 1, 2);
        world.setBlock(i + 7, j + 18, k + 7, 18, 1, 2);
        world.setBlock(i + 8, j + 18, k + 9, 18, 1, 2);
        world.setBlock(i + 8, j + 18, k + 8, 18, 1, 2);
        world.setBlock(i + 8, j + 18, k + 7, 17, 1, 2);
        world.setBlock(i + 8, j + 18, k + 6, 18, 1, 2);
        world.setBlock(i + 9, j + 18, k + 8, 18, 1, 2);
        world.setBlock(i + 9, j + 18, k + 7, 18, 1, 2);
        world.setBlock(i + 10, j + 18, k + 7, 18, 1, 2);
        world.setBlock(i + 10, j + 18, k + 6, 18, 1, 2);
        world.setBlock(i + 2, j + 19, k + 4, 18, 1, 2);
        world.setBlock(i + 3, j + 19, k + 6, 18, 1, 2);
        world.setBlock(i + 3, j + 19, k + 4, 18, 1, 2);
        world.setBlock(i + 4, j + 19, k + 9, 18, 1, 2);
        world.setBlock(i + 4, j + 19, k + 6, 17, 1, 2);
        world.setBlock(i + 4, j + 19, k + 5, 18, 1, 2);
        world.setBlock(i + 4, j + 19, k + 4, 17, 1, 2);
        world.setBlock(i + 4, j + 19, k + 3, 18, 1, 2);
        world.setBlock(i + 5, j + 19, k + 10, 18, 1, 2);
        world.setBlock(i + 5, j + 19, k + 8, 17, 1, 2);
        world.setBlock(i + 5, j + 19, k + 7, 17, 1, 2);
        world.setBlock(i + 5, j + 19, k + 6, 18, 1, 2);
        world.setBlock(i + 5, j + 19, k + 5, 17, 1, 2);
        world.setBlock(i + 5, j + 19, k + 4, 18, 1, 2);
        world.setBlock(i + 5, j + 19, k + 2, 18, 1, 2);
        world.setBlock(i + 6, j + 19, k + 9, 18, 1, 2);
        world.setBlock(i + 6, j + 19, k + 8, 17, 1, 2);
        world.setBlock(i + 6, j + 19, k + 7, 17, 1, 2);
        world.setBlock(i + 6, j + 19, k + 6, 18, 1, 2);
        world.setBlock(i + 7, j + 19, k + 8, 18, 1, 2);
        world.setBlock(i + 7, j + 19, k + 7, 18, 1, 2);
        world.setBlock(i + 8, j + 19, k + 8, 18, 1, 2);
        world.setBlock(i + 1, j + 20, k + 10, 18, 1, 2);
        world.setBlock(i + 2, j + 20, k + 11, 18, 1, 2);
        world.setBlock(i + 2, j + 20, k + 10, 18, 1, 2);
        world.setBlock(i + 2, j + 20, k + 7, 18, 1, 2);
        world.setBlock(i + 3, j + 20, k + 11, 18, 1, 2);
        world.setBlock(i + 3, j + 20, k + 10, 18, 1, 2);
        world.setBlock(i + 3, j + 20, k + 9, 17, 1, 2);
        world.setBlock(i + 3, j + 20, k + 8, 18, 1, 2);
        world.setBlock(i + 3, j + 20, k + 7, 18, 1, 2);
        world.setBlock(i + 4, j + 20, k + 10, 18, 1, 2);
        world.setBlock(i + 4, j + 20, k + 8, 17, 1, 2);
        world.setBlock(i + 5, j + 20, k + 10, 18, 1, 2);
        world.setBlock(i + 5, j + 20, k + 9, 18, 1, 2);
        world.setBlock(i + 5, j + 20, k + 8, 17, 1, 2);
        world.setBlock(i + 5, j + 20, k + 7, 17, 1, 2);
        world.setBlock(i + 5, j + 20, k + 6, 18, 1, 2);
        world.setBlock(i + 5, j + 20, k + 5, 18, 1, 2);
        world.setBlock(i + 6, j + 20, k + 8, 17, 1, 2);
        world.setBlock(i + 6, j + 20, k + 7, 17, 1, 2);
        world.setBlock(i + 7, j + 20, k + 7, 18, 1, 2);
        world.setBlock(i + 5, j + 21, k + 8, 17, 1, 2);
        world.setBlock(i + 5, j + 21, k + 7, 17, 1, 2);
        world.setBlock(i + 6, j + 21, k + 8, 17, 1, 2);
        world.setBlock(i + 6, j + 21, k + 7, 17, 1, 2);
        world.setBlock(i + 3, j + 22, k + 7, 18, 1, 2);
        world.setBlock(i + 3, j + 22, k + 4, 18, 1, 2);
        world.setBlock(i + 4, j + 22, k + 6, 18, 1, 2);
        world.setBlock(i + 4, j + 22, k + 5, 17, 1, 2);
        world.setBlock(i + 4, j + 22, k + 4, 18, 1, 2);
        world.setBlock(i + 5, j + 22, k + 8, 17, 1, 2);
        world.setBlock(i + 5, j + 22, k + 7, 17, 1, 2);
        world.setBlock(i + 5, j + 22, k + 6, 17, 1, 2);
        world.setBlock(i + 5, j + 22, k + 5, 18, 1, 2);
        world.setBlock(i + 5, j + 22, k + 3, 18, 1, 2);
        world.setBlock(i + 6, j + 22, k + 8, 17, 1, 2);
        world.setBlock(i + 6, j + 22, k + 7, 17, 1, 2);
        world.setBlock(i + 6, j + 22, k + 6, 18, 1, 2);
        world.setBlock(i + 6, j + 22, k + 5, 17, 1, 2);
        world.setBlock(i + 6, j + 22, k + 4, 18, 1, 2);
        world.setBlock(i + 7, j + 22, k + 7, 18, 1, 2);
        world.setBlock(i + 7, j + 22, k + 5, 18, 1, 2);
        world.setBlock(i + 7, j + 22, k + 4, 18, 1, 2);
        world.setBlock(i + 7, j + 22, k + 3, 18, 1, 2);
        world.setBlock(i + 8, j + 22, k + 5, 18, 1, 2);
        world.setBlock(i + 5, j + 23, k + 8, 17, 1, 2);
        world.setBlock(i + 5, j + 23, k + 7, 17, 1, 2);
        world.setBlock(i + 6, j + 23, k + 9, 18, 1, 2);
        world.setBlock(i + 6, j + 23, k + 8, 17, 1, 2);
        world.setBlock(i + 6, j + 23, k + 7, 17, 1, 2);
        world.setBlock(i + 7, j + 23, k + 8, 18, 1, 2);
        world.setBlock(i + 7, j + 23, k + 7, 17, 1, 2);
        world.setBlock(i + 7, j + 23, k + 6, 18, 1, 2);
        world.setBlock(i + 8, j + 23, k + 8, 18, 1, 2);
        world.setBlock(i + 8, j + 23, k + 7, 17, 1, 2);
        world.setBlock(i + 9, j + 23, k + 8, 17, 1, 2);
        world.setBlock(i + 9, j + 23, k + 7, 18, 1, 2);
        world.setBlock(i + 9, j + 23, k + 6, 18, 1, 2);
        world.setBlock(i + 10, j + 23, k + 10, 18, 1, 2);
        world.setBlock(i + 10, j + 23, k + 8, 18, 1, 2);
        world.setBlock(i + 11, j + 23, k + 9, 18, 1, 2);
        world.setBlock(i + 11, j + 23, k + 8, 18, 1, 2);
        world.setBlock(i + 2, j + 24, k + 10, 18, 1, 2);
        world.setBlock(i + 2, j + 24, k + 9, 18, 1, 2);
        world.setBlock(i + 3, j + 24, k + 11, 18, 1, 2);
        world.setBlock(i + 3, j + 24, k + 10, 18, 1, 2);
        world.setBlock(i + 3, j + 24, k + 8, 17, 1, 2);
        world.setBlock(i + 3, j + 24, k + 7, 18, 1, 2);
        world.setBlock(i + 4, j + 24, k + 10, 18, 1, 2);
        world.setBlock(i + 4, j + 24, k + 9, 18, 1, 2);
        world.setBlock(i + 4, j + 24, k + 8, 18, 1, 2);
        world.setBlock(i + 4, j + 24, k + 7, 17, 1, 2);
        world.setBlock(i + 4, j + 24, k + 6, 18, 1, 2);
        world.setBlock(i + 5, j + 24, k + 12, 18, 1, 2);
        world.setBlock(i + 5, j + 24, k + 10, 17, 1, 2);
        world.setBlock(i + 5, j + 24, k + 9, 18, 1, 2);
        world.setBlock(i + 5, j + 24, k + 8, 17, 1, 2);
        world.setBlock(i + 5, j + 24, k + 7, 17, 1, 2);
        world.setBlock(i + 6, j + 24, k + 12, 18, 1, 2);
        world.setBlock(i + 6, j + 24, k + 9, 17, 1, 2);
        world.setBlock(i + 6, j + 24, k + 8, 17, 1, 2);
        world.setBlock(i + 6, j + 24, k + 7, 17, 1, 2);
        world.setBlock(i + 6, j + 24, k + 6, 18, 1, 2);
        world.setBlock(i + 6, j + 24, k + 5, 18, 1, 2);
        world.setBlock(i + 7, j + 24, k + 12, 18, 1, 2);
        world.setBlock(i + 7, j + 24, k + 11, 18, 1, 2);
        world.setBlock(i + 7, j + 24, k + 10, 17, 1, 2);
        world.setBlock(i + 7, j + 24, k + 9, 18, 1, 2);
        world.setBlock(i + 7, j + 24, k + 8, 18, 1, 2);
        world.setBlock(i + 7, j + 24, k + 7, 18, 1, 2);
        world.setBlock(i + 8, j + 24, k + 9, 18, 1, 2);
        world.setBlock(i + 8, j + 24, k + 7, 18, 1, 2);
        world.setBlock(i + 9, j + 24, k + 11, 18, 1, 2);
        world.setBlock(i + 4, j + 25, k + 9, 18, 1, 2);
        world.setBlock(i + 4, j + 25, k + 8, 18, 1, 2);
        world.setBlock(i + 5, j + 25, k + 8, 17, 1, 2);
        world.setBlock(i + 5, j + 25, k + 7, 17, 1, 2);
        world.setBlock(i + 6, j + 25, k + 9, 18, 1, 2);
        world.setBlock(i + 6, j + 25, k + 8, 17, 1, 2);
        world.setBlock(i + 6, j + 25, k + 7, 17, 1, 2);
        world.setBlock(i + 6, j + 25, k + 6, 18, 1, 2);
        world.setBlock(i + 7, j + 25, k + 8, 18, 1, 2);
        world.setBlock(i + 8, j + 25, k + 9, 18, 1, 2);
        world.setBlock(i + 8, j + 25, k + 8, 18, 1, 2);
        world.setBlock(i + 1, j + 26, k + 8, 18, 1, 2);
        world.setBlock(i + 2, j + 26, k + 9, 18, 1, 2);
        world.setBlock(i + 2, j + 26, k + 8, 18, 1, 2);
        world.setBlock(i + 2, j + 26, k + 7, 18, 1, 2);
        world.setBlock(i + 3, j + 26, k + 11, 18, 1, 2);
        world.setBlock(i + 3, j + 26, k + 10, 18, 1, 2);
        world.setBlock(i + 3, j + 26, k + 9, 17, 1, 2);
        world.setBlock(i + 3, j + 26, k + 8, 18, 1, 2);
        world.setBlock(i + 3, j + 26, k + 7, 18, 1, 2);
        world.setBlock(i + 4, j + 26, k + 11, 18, 1, 2);
        world.setBlock(i + 4, j + 26, k + 10, 18, 1, 2);
        world.setBlock(i + 4, j + 26, k + 9, 18, 1, 2);
        world.setBlock(i + 4, j + 26, k + 8, 17, 1, 2);
        world.setBlock(i + 5, j + 26, k + 8, 17, 1, 2);
        world.setBlock(i + 5, j + 26, k + 7, 17, 1, 2);
        world.setBlock(i + 6, j + 26, k + 8, 17, 1, 2);
        world.setBlock(i + 6, j + 26, k + 7, 17, 1, 2);
        world.setBlock(i + 4, j + 27, k + 8, 18, 1, 2);
        world.setBlock(i + 4, j + 27, k + 7, 18, 1, 2);
        world.setBlock(i + 5, j + 27, k + 9, 18, 1, 2);
        world.setBlock(i + 5, j + 27, k + 8, 17, 1, 2);
        world.setBlock(i + 5, j + 27, k + 7, 17, 1, 2);
        world.setBlock(i + 5, j + 27, k + 6, 18, 1, 2);
        world.setBlock(i + 5, j + 27, k + 5, 18, 1, 2);
        world.setBlock(i + 6, j + 27, k + 10, 18, 1, 2);
        world.setBlock(i + 6, j + 27, k + 9, 18, 1, 2);
        world.setBlock(i + 6, j + 27, k + 8, 17, 1, 2);
        world.setBlock(i + 6, j + 27, k + 7, 17, 1, 2);
        world.setBlock(i + 7, j + 27, k + 10, 18, 1, 2);
        world.setBlock(i + 7, j + 27, k + 6, 18, 1, 2);
        world.setBlock(i + 7, j + 27, k + 5, 18, 1, 2);
        world.setBlock(i + 8, j + 27, k + 8, 18, 1, 2);
        world.setBlock(i + 2, j + 28, k + 3, 18, 1, 2);
        world.setBlock(i + 3, j + 28, k + 3, 18, 1, 2);
        world.setBlock(i + 4, j + 28, k + 7, 18, 1, 2);
        world.setBlock(i + 4, j + 28, k + 4, 18, 1, 2);
        world.setBlock(i + 4, j + 28, k + 3, 17, 1, 2);
        world.setBlock(i + 4, j + 28, k + 2, 18, 1, 2);
        world.setBlock(i + 5, j + 28, k + 8, 17, 1, 2);
        world.setBlock(i + 5, j + 28, k + 7, 17, 1, 2);
        world.setBlock(i + 5, j + 28, k + 5, 17, 1, 2);
        world.setBlock(i + 5, j + 28, k + 4, 17, 1, 2);
        world.setBlock(i + 5, j + 28, k + 3, 18, 1, 2);
        world.setBlock(i + 5, j + 28, k + 2, 18, 1, 2);
        world.setBlock(i + 6, j + 28, k + 8, 17, 1, 2);
        world.setBlock(i + 6, j + 28, k + 7, 17, 1, 2);
        world.setBlock(i + 6, j + 28, k + 6, 17, 1, 2);
        world.setBlock(i + 6, j + 28, k + 5, 18, 1, 2);
        world.setBlock(i + 6, j + 28, k + 4, 18, 1, 2);
        world.setBlock(i + 6, j + 28, k + 3, 17, 1, 2);
        world.setBlock(i + 6, j + 28, k + 2, 18, 1, 2);
        world.setBlock(i + 6, j + 28, k + 0, 18, 1, 2);
        world.setBlock(i + 7, j + 28, k + 8, 18, 1, 2);
        world.setBlock(i + 7, j + 28, k + 5, 18, 1, 2);
        world.setBlock(i + 7, j + 28, k + 4, 18, 1, 2);
        world.setBlock(i + 7, j + 28, k + 3, 18, 1, 2);
        world.setBlock(i + 7, j + 28, k + 2, 17, 1, 2);
        world.setBlock(i + 7, j + 28, k + 1, 18, 1, 2);
        world.setBlock(i + 7, j + 28, k + 0, 18, 1, 2);
        world.setBlock(i + 8, j + 28, k + 7, 18, 1, 2);
        world.setBlock(i + 8, j + 28, k + 6, 18, 1, 2);
        world.setBlock(i + 8, j + 28, k + 4, 18, 1, 2);
        world.setBlock(i + 8, j + 28, k + 3, 18, 1, 2);
        world.setBlock(i + 8, j + 28, k + 2, 18, 1, 2);
        world.setBlock(i + 8, j + 28, k + 1, 18, 1, 2);
        world.setBlock(i + 9, j + 28, k + 2, 18, 1, 2);
        world.setBlock(i + 9, j + 28, k + 1, 18, 1, 2);
        world.setBlock(i + 3, j + 29, k + 9, 18, 1, 2);
        world.setBlock(i + 4, j + 29, k + 10, 18, 1, 2);
        world.setBlock(i + 4, j + 29, k + 6, 18, 1, 2);
        world.setBlock(i + 5, j + 29, k + 9, 18, 1, 2);
        world.setBlock(i + 5, j + 29, k + 8, 17, 1, 2);
        world.setBlock(i + 5, j + 29, k + 7, 17, 1, 2);
        world.setBlock(i + 5, j + 29, k + 6, 18, 1, 2);
        world.setBlock(i + 6, j + 29, k + 8, 17, 1, 2);
        world.setBlock(i + 6, j + 29, k + 7, 17, 1, 2);
        world.setBlock(i + 6, j + 29, k + 6, 18, 1, 2);
        world.setBlock(i + 7, j + 29, k + 9, 18, 1, 2);
        world.setBlock(i + 7, j + 29, k + 8, 18, 1, 2);
        world.setBlock(i + 7, j + 29, k + 7, 18, 1, 2);
        world.setBlock(i + 5, j + 30, k + 8, 17, 1, 2);
        world.setBlock(i + 5, j + 30, k + 7, 17, 1, 2);
        world.setBlock(i + 6, j + 30, k + 11, 18, 1, 2);
        world.setBlock(i + 6, j + 30, k + 10, 18, 1, 2);
        world.setBlock(i + 6, j + 30, k + 9, 17, 1, 2);
        world.setBlock(i + 6, j + 30, k + 8, 17, 1, 2);
        world.setBlock(i + 6, j + 30, k + 7, 17, 1, 2);
        world.setBlock(i + 7, j + 30, k + 13, 18, 1, 2);
        world.setBlock(i + 7, j + 30, k + 12, 18, 1, 2);
        world.setBlock(i + 7, j + 30, k + 11, 18, 1, 2);
        world.setBlock(i + 7, j + 30, k + 10, 17, 1, 2);
        world.setBlock(i + 7, j + 30, k + 8, 17, 1, 2);
        world.setBlock(i + 7, j + 30, k + 6, 18, 1, 2);
        world.setBlock(i + 7, j + 30, k + 5, 18, 1, 2);
        world.setBlock(i + 8, j + 30, k + 15, 18, 1, 2);
        world.setBlock(i + 8, j + 30, k + 14, 18, 1, 2);
        world.setBlock(i + 8, j + 30, k + 13, 18, 1, 2);
        world.setBlock(i + 8, j + 30, k + 12, 17, 1, 2);
        world.setBlock(i + 8, j + 30, k + 11, 17, 1, 2);
        world.setBlock(i + 8, j + 30, k + 10, 18, 1, 2);
        world.setBlock(i + 8, j + 30, k + 9, 18, 1, 2);
        world.setBlock(i + 8, j + 30, k + 7, 17, 1, 2);
        world.setBlock(i + 9, j + 30, k + 14, 18, 1, 2);
        world.setBlock(i + 9, j + 30, k + 13, 17, 1, 2);
        world.setBlock(i + 9, j + 30, k + 11, 18, 1, 2);
        world.setBlock(i + 9, j + 30, k + 9, 18, 1, 2);
        world.setBlock(i + 9, j + 30, k + 8, 18, 1, 2);
        world.setBlock(i + 9, j + 30, k + 7, 18, 1, 2);
        world.setBlock(i + 9, j + 30, k + 6, 17, 1, 2);
        world.setBlock(i + 9, j + 30, k + 5, 18, 1, 2);
        world.setBlock(i + 9, j + 30, k + 4, 18, 1, 2);
        world.setBlock(i + 9, j + 30, k + 3, 18, 1, 2);
        world.setBlock(i + 10, j + 30, k + 15, 18, 1, 2);
        world.setBlock(i + 10, j + 30, k + 8, 18, 1, 2);
        world.setBlock(i + 10, j + 30, k + 7, 18, 1, 2);
        world.setBlock(i + 10, j + 30, k + 6, 17, 1, 2);
        world.setBlock(i + 10, j + 30, k + 5, 18, 1, 2);
        world.setBlock(i + 10, j + 30, k + 2, 18, 1, 2);
        world.setBlock(i + 11, j + 30, k + 13, 18, 1, 2);
        world.setBlock(i + 11, j + 30, k + 12, 18, 1, 2);
        world.setBlock(i + 11, j + 30, k + 9, 18, 1, 2);
        world.setBlock(i + 11, j + 30, k + 8, 18, 1, 2);
        world.setBlock(i + 11, j + 30, k + 7, 17, 1, 2);
        world.setBlock(i + 11, j + 30, k + 6, 18, 1, 2);
        world.setBlock(i + 11, j + 30, k + 5, 18, 1, 2);
        world.setBlock(i + 11, j + 30, k + 4, 18, 1, 2);
        world.setBlock(i + 12, j + 30, k + 5, 18, 1, 2);
        world.setBlock(i + 13, j + 30, k + 7, 18, 1, 2);
        world.setBlock(i + 4, j + 31, k + 10, 18, 1, 2);
        world.setBlock(i + 4, j + 31, k + 8, 18, 1, 2);
        world.setBlock(i + 4, j + 31, k + 7, 18, 1, 2);
        world.setBlock(i + 5, j + 31, k + 12, 18, 1, 2);
        world.setBlock(i + 5, j + 31, k + 11, 18, 1, 2);
        world.setBlock(i + 5, j + 31, k + 9, 18, 1, 2);
        world.setBlock(i + 5, j + 31, k + 8, 17, 1, 2);
        world.setBlock(i + 5, j + 31, k + 7, 17, 1, 2);
        world.setBlock(i + 5, j + 31, k + 6, 18, 1, 2);
        world.setBlock(i + 6, j + 31, k + 12, 18, 1, 2);
        world.setBlock(i + 6, j + 31, k + 10, 18, 1, 2);
        world.setBlock(i + 6, j + 31, k + 9, 18, 1, 2);
        world.setBlock(i + 6, j + 31, k + 8, 17, 1, 2);
        world.setBlock(i + 6, j + 31, k + 7, 17, 1, 2);
        world.setBlock(i + 6, j + 31, k + 6, 18, 1, 2);
        world.setBlock(i + 7, j + 31, k + 11, 18, 1, 2);
        world.setBlock(i + 7, j + 31, k + 9, 18, 1, 2);
        world.setBlock(i + 7, j + 31, k + 8, 18, 1, 2);
        world.setBlock(i + 7, j + 31, k + 7, 18, 1, 2);
        world.setBlock(i + 7, j + 31, k + 6, 18, 1, 2);
        world.setBlock(i + 7, j + 31, k + 5, 18, 1, 2);
        world.setBlock(i + 8, j + 31, k + 12, 18, 1, 2);
        world.setBlock(i + 8, j + 31, k + 11, 18, 1, 2);
        world.setBlock(i + 8, j + 31, k + 10, 18, 1, 2);
        world.setBlock(i + 8, j + 31, k + 9, 18, 1, 2);
        world.setBlock(i + 8, j + 31, k + 8, 18, 1, 2);
        world.setBlock(i + 8, j + 31, k + 7, 18, 1, 2);
        world.setBlock(i + 8, j + 31, k + 6, 18, 1, 2);
        world.setBlock(i + 8, j + 31, k + 4, 18, 1, 2);
        world.setBlock(i + 9, j + 31, k + 8, 18, 1, 2);
        world.setBlock(i + 9, j + 31, k + 7, 18, 1, 2);
        world.setBlock(i + 9, j + 31, k + 6, 18, 1, 2);
        world.setBlock(i + 9, j + 31, k + 5, 18, 1, 2);
        world.setBlock(i + 9, j + 31, k + 4, 18, 1, 2);
        world.setBlock(i + 10, j + 31, k + 11, 18, 1, 2);
        world.setBlock(i + 10, j + 31, k + 6, 18, 1, 2);
        world.setBlock(i + 10, j + 31, k + 4, 18, 1, 2);
        world.setBlock(i + 11, j + 31, k + 6, 18, 1, 2);
        world.setBlock(i + 0, j + 32, k + 12, 18, 1, 2);
        world.setBlock(i + 1, j + 32, k + 13, 18, 1, 2);
        world.setBlock(i + 2, j + 32, k + 14, 18, 1, 2);
        world.setBlock(i + 2, j + 32, k + 12, 18, 1, 2);
        world.setBlock(i + 3, j + 32, k + 13, 18, 1, 2);
        world.setBlock(i + 3, j + 32, k + 12, 18, 1, 2);
        world.setBlock(i + 3, j + 32, k + 11, 18, 1, 2);
        world.setBlock(i + 3, j + 32, k + 10, 18, 1, 2);
        world.setBlock(i + 4, j + 32, k + 13, 18, 1, 2);
        world.setBlock(i + 4, j + 32, k + 12, 17, 1, 2);
        world.setBlock(i + 4, j + 32, k + 11, 18, 1, 2);
        world.setBlock(i + 4, j + 32, k + 10, 18, 1, 2);
        world.setBlock(i + 4, j + 32, k + 8, 18, 1, 2);
        world.setBlock(i + 5, j + 32, k + 14, 18, 1, 2);
        world.setBlock(i + 5, j + 32, k + 13, 18, 1, 2);
        world.setBlock(i + 5, j + 32, k + 12, 18, 1, 2);
        world.setBlock(i + 5, j + 32, k + 11, 17, 1, 2);
        world.setBlock(i + 5, j + 32, k + 10, 17, 1, 2);
        world.setBlock(i + 5, j + 32, k + 9, 17, 1, 2);
        world.setBlock(i + 5, j + 32, k + 8, 17, 1, 2);
        world.setBlock(i + 5, j + 32, k + 7, 17, 1, 2);
        world.setBlock(i + 6, j + 32, k + 12, 17, 1, 2);
        world.setBlock(i + 6, j + 32, k + 11, 18, 1, 2);
        world.setBlock(i + 6, j + 32, k + 9, 18, 1, 2);
        world.setBlock(i + 6, j + 32, k + 8, 17, 1, 2);
        world.setBlock(i + 6, j + 32, k + 7, 17, 1, 2);
        world.setBlock(i + 7, j + 32, k + 14, 18, 1, 2);
        world.setBlock(i + 7, j + 32, k + 13, 17, 1, 2);
        world.setBlock(i + 7, j + 32, k + 12, 18, 1, 2);
        world.setBlock(i + 7, j + 32, k + 10, 18, 1, 2);
        world.setBlock(i + 7, j + 32, k + 9, 18, 1, 2);
        world.setBlock(i + 8, j + 32, k + 11, 18, 1, 2);
        world.setBlock(i + 9, j + 32, k + 14, 18, 1, 2);
        world.setBlock(i + 9, j + 32, k + 13, 18, 1, 2);
        world.setBlock(i + 9, j + 32, k + 12, 18, 1, 2);
        world.setBlock(i + 3, j + 33, k + 10, 18, 1, 2);
        world.setBlock(i + 3, j + 33, k + 8, 18, 1, 2);
        world.setBlock(i + 4, j + 33, k + 8, 18, 1, 2);
        world.setBlock(i + 4, j + 33, k + 7, 18, 1, 2);
        world.setBlock(i + 4, j + 33, k + 5, 18, 1, 2);
        world.setBlock(i + 5, j + 33, k + 12, 18, 1, 2);
        world.setBlock(i + 5, j + 33, k + 11, 18, 1, 2);
        world.setBlock(i + 5, j + 33, k + 10, 18, 1, 2);
        world.setBlock(i + 5, j + 33, k + 9, 18, 1, 2);
        world.setBlock(i + 5, j + 33, k + 8, 17, 1, 2);
        world.setBlock(i + 5, j + 33, k + 7, 17, 1, 2);
        world.setBlock(i + 5, j + 33, k + 6, 18, 1, 2);
        world.setBlock(i + 5, j + 33, k + 5, 18, 1, 2);
        world.setBlock(i + 6, j + 33, k + 10, 18, 1, 2);
        world.setBlock(i + 6, j + 33, k + 8, 17, 1, 2);
        world.setBlock(i + 6, j + 33, k + 7, 17, 1, 2);
        world.setBlock(i + 6, j + 33, k + 6, 18, 1, 2);
        world.setBlock(i + 7, j + 33, k + 10, 18, 1, 2);
        world.setBlock(i + 7, j + 33, k + 9, 18, 1, 2);
        world.setBlock(i + 7, j + 33, k + 6, 18, 1, 2);
        world.setBlock(i + 0, j + 34, k + 3, 18, 1, 2);
        world.setBlock(i + 0, j + 34, k + 2, 18, 1, 2);
        world.setBlock(i + 1, j + 34, k + 7, 18, 1, 2);
        world.setBlock(i + 1, j + 34, k + 6, 18, 1, 2);
        world.setBlock(i + 1, j + 34, k + 5, 18, 1, 2);
        world.setBlock(i + 1, j + 34, k + 4, 18, 1, 2);
        world.setBlock(i + 1, j + 34, k + 3, 18, 1, 2);
        world.setBlock(i + 1, j + 34, k + 1, 18, 1, 2);
        world.setBlock(i + 2, j + 34, k + 9, 18, 1, 2);
        world.setBlock(i + 2, j + 34, k + 8, 18, 1, 2);
        world.setBlock(i + 2, j + 34, k + 7, 17, 1, 2);
        world.setBlock(i + 2, j + 34, k + 6, 18, 1, 2);
        world.setBlock(i + 2, j + 34, k + 5, 17, 1, 2);
        world.setBlock(i + 2, j + 34, k + 4, 18, 1, 2);
        world.setBlock(i + 2, j + 34, k + 3, 18, 1, 2);
        world.setBlock(i + 3, j + 34, k + 7, 18, 1, 2);
        world.setBlock(i + 3, j + 34, k + 6, 17, 1, 2);
        world.setBlock(i + 3, j + 34, k + 5, 18, 1, 2);
        world.setBlock(i + 3, j + 34, k + 4, 18, 1, 2);
        world.setBlock(i + 4, j + 34, k + 7, 17, 1, 2);
        world.setBlock(i + 4, j + 34, k + 6, 18, 1, 2);
        world.setBlock(i + 4, j + 34, k + 4, 18, 1, 2);
        world.setBlock(i + 5, j + 34, k + 8, 17, 1, 2);
        world.setBlock(i + 5, j + 34, k + 7, 17, 1, 2);
        world.setBlock(i + 6, j + 34, k + 8, 17, 1, 2);
        world.setBlock(i + 5, j + 35, k + 8, 17, 1, 2);
        world.setBlock(i + 5, j + 35, k + 7, 17, 1, 2);
        world.setBlock(i + 6, j + 35, k + 8, 17, 1, 2);
        world.setBlock(i + 3, j + 36, k + 7, 18, 1, 2);
        world.setBlock(i + 4, j + 36, k + 9, 18, 1, 2);
        world.setBlock(i + 4, j + 36, k + 7, 18, 1, 2);
        world.setBlock(i + 4, j + 36, k + 5, 18, 1, 2);
        world.setBlock(i + 5, j + 36, k + 8, 17, 1, 2);
        world.setBlock(i + 5, j + 36, k + 7, 17, 1, 2);
        world.setBlock(i + 6, j + 36, k + 8, 17, 1, 2);
        world.setBlock(i + 6, j + 36, k + 5, 18, 1, 2);
        world.setBlock(i + 3, j + 37, k + 6, 18, 1, 2);
        world.setBlock(i + 3, j + 37, k + 5, 18, 1, 2);
        world.setBlock(i + 4, j + 37, k + 7, 18, 1, 2);
        world.setBlock(i + 4, j + 37, k + 5, 17, 1, 2);
        world.setBlock(i + 4, j + 37, k + 4, 18, 1, 2);
        world.setBlock(i + 4, j + 37, k + 3, 18, 1, 2);
        world.setBlock(i + 5, j + 37, k + 8, 17, 1, 2);
        world.setBlock(i + 5, j + 37, k + 7, 17, 1, 2);
        world.setBlock(i + 5, j + 37, k + 6, 17, 1, 2);
        world.setBlock(i + 5, j + 37, k + 5, 18, 1, 2);
        world.setBlock(i + 5, j + 37, k + 3, 18, 1, 2);
        world.setBlock(i + 6, j + 37, k + 8, 17, 1, 2);
        world.setBlock(i + 6, j + 37, k + 6, 18, 1, 2);
        world.setBlock(i + 6, j + 37, k + 5, 18, 1, 2);
        world.setBlock(i + 7, j + 37, k + 6, 18, 1, 2);
        world.setBlock(i + 8, j + 37, k + 6, 18, 1, 2);
        world.setBlock(i + 8, j + 37, k + 5, 18, 1, 2);
        world.setBlock(i + 1, j + 38, k + 10, 18, 1, 2);
        world.setBlock(i + 1, j + 38, k + 9, 18, 1, 2);
        world.setBlock(i + 2, j + 38, k + 10, 18, 1, 2);
        world.setBlock(i + 2, j + 38, k + 9, 18, 1, 2);
        world.setBlock(i + 3, j + 38, k + 12, 18, 1, 2);
        world.setBlock(i + 3, j + 38, k + 11, 18, 1, 2);
        world.setBlock(i + 3, j + 38, k + 10, 17, 1, 2);
        world.setBlock(i + 3, j + 38, k + 8, 18, 1, 2);
        world.setBlock(i + 4, j + 38, k + 12, 18, 1, 2);
        world.setBlock(i + 4, j + 38, k + 11, 18, 1, 2);
        world.setBlock(i + 4, j + 38, k + 10, 18, 1, 2);
        world.setBlock(i + 4, j + 38, k + 9, 17, 1, 2);
        world.setBlock(i + 5, j + 38, k + 10, 18, 1, 2);
        world.setBlock(i + 5, j + 38, k + 9, 18, 1, 2);
        world.setBlock(i + 5, j + 38, k + 8, 17, 1, 2);
        world.setBlock(i + 5, j + 38, k + 7, 17, 1, 2);
        world.setBlock(i + 6, j + 38, k + 10, 18, 1, 2);
        world.setBlock(i + 6, j + 38, k + 8, 17, 1, 2);
        world.setBlock(i + 6, j + 38, k + 7, 18, 1, 2);
        world.setBlock(i + 7, j + 38, k + 7, 18, 1, 2);
        world.setBlock(i + 8, j + 38, k + 9, 18, 1, 2);
        world.setBlock(i + 3, j + 39, k + 8, 18, 1, 2);
        world.setBlock(i + 4, j + 39, k + 8, 18, 1, 2);
        world.setBlock(i + 4, j + 39, k + 7, 18, 1, 2);
        world.setBlock(i + 5, j + 39, k + 9, 18, 1, 2);
        world.setBlock(i + 5, j + 39, k + 8, 17, 1, 2);
        world.setBlock(i + 5, j + 39, k + 7, 17, 1, 2);
        world.setBlock(i + 6, j + 39, k + 11, 18, 1, 2);
        world.setBlock(i + 6, j + 39, k + 8, 17, 1, 2);
        world.setBlock(i + 6, j + 39, k + 6, 18, 1, 2);
        world.setBlock(i + 7, j + 39, k + 11, 18, 1, 2);
        world.setBlock(i + 7, j + 39, k + 10, 18, 1, 2);
        world.setBlock(i + 7, j + 39, k + 9, 17, 1, 2);
        world.setBlock(i + 7, j + 39, k + 7, 18, 1, 2);
        world.setBlock(i + 7, j + 39, k + 6, 18, 1, 2);
        world.setBlock(i + 8, j + 39, k + 12, 18, 1, 2);
        world.setBlock(i + 8, j + 39, k + 10, 17, 1, 2);
        world.setBlock(i + 8, j + 39, k + 9, 18, 1, 2);
        world.setBlock(i + 9, j + 39, k + 11, 18, 1, 2);
        world.setBlock(i + 9, j + 39, k + 10, 18, 1, 2);
        world.setBlock(i + 9, j + 39, k + 9, 18, 1, 2);
        world.setBlock(i + 10, j + 39, k + 11, 18, 1, 2);
        world.setBlock(i + 10, j + 39, k + 10, 18, 1, 2);
        world.setBlock(i + 10, j + 39, k + 9, 18, 1, 2);
        world.setBlock(i + 10, j + 39, k + 8, 18, 1, 2);
        world.setBlock(i + 1, j + 40, k + 6, 18, 1, 2);
        world.setBlock(i + 1, j + 40, k + 5, 18, 1, 2);
        world.setBlock(i + 1, j + 40, k + 4, 18, 1, 2);
        world.setBlock(i + 1, j + 40, k + 3, 18, 1, 2);
        world.setBlock(i + 2, j + 40, k + 6, 18, 1, 2);
        world.setBlock(i + 2, j + 40, k + 5, 18, 1, 2);
        world.setBlock(i + 3, j + 40, k + 7, 18, 1, 2);
        world.setBlock(i + 3, j + 40, k + 6, 17, 1, 2);
        world.setBlock(i + 3, j + 40, k + 4, 18, 1, 2);
        world.setBlock(i + 4, j + 40, k + 8, 18, 1, 2);
        world.setBlock(i + 4, j + 40, k + 7, 17, 1, 2);
        world.setBlock(i + 4, j + 40, k + 6, 18, 1, 2);
        world.setBlock(i + 4, j + 40, k + 5, 18, 1, 2);
        world.setBlock(i + 4, j + 40, k + 4, 18, 1, 2);
        world.setBlock(i + 4, j + 40, k + 2, 18, 1, 2);
        world.setBlock(i + 5, j + 40, k + 8, 17, 1, 2);
        world.setBlock(i + 5, j + 40, k + 7, 17, 1, 2);
        world.setBlock(i + 5, j + 40, k + 4, 18, 1, 2);
        world.setBlock(i + 6, j + 40, k + 8, 17, 1, 2);
        world.setBlock(i + 5, j + 41, k + 8, 17, 1, 2);
        world.setBlock(i + 5, j + 41, k + 4, 18, 1, 2);
        world.setBlock(i + 6, j + 41, k + 8, 17, 1, 2);
        world.setBlock(i + 6, j + 41, k + 6, 18, 1, 2);
        world.setBlock(i + 6, j + 41, k + 5, 18, 1, 2);
        world.setBlock(i + 7, j + 41, k + 7, 17, 1, 2);
        world.setBlock(i + 7, j + 41, k + 6, 17, 1, 2);
        world.setBlock(i + 7, j + 41, k + 5, 18, 1, 2);
        world.setBlock(i + 7, j + 41, k + 3, 18, 1, 2);
        world.setBlock(i + 8, j + 41, k + 8, 18, 1, 2);
        world.setBlock(i + 8, j + 41, k + 5, 18, 1, 2);
        world.setBlock(i + 9, j + 41, k + 7, 18, 1, 2);
        world.setBlock(i + 9, j + 41, k + 6, 18, 1, 2);
        world.setBlock(i + 9, j + 41, k + 5, 18, 1, 2);
        world.setBlock(i + 9, j + 41, k + 4, 18, 1, 2);
        world.setBlock(i + 10, j + 41, k + 6, 18, 1, 2);
        world.setBlock(i + 10, j + 41, k + 4, 18, 1, 2);
        world.setBlock(i + 11, j + 41, k + 5, 18, 1, 2);
        world.setBlock(i + 11, j + 41, k + 4, 18, 1, 2);
        world.setBlock(i + 0, j + 42, k + 10, 18, 1, 2);
        world.setBlock(i + 1, j + 42, k + 11, 18, 1, 2);
        world.setBlock(i + 1, j + 42, k + 10, 18, 1, 2);
        world.setBlock(i + 2, j + 42, k + 12, 18, 1, 2);
        world.setBlock(i + 2, j + 42, k + 11, 18, 1, 2);
        world.setBlock(i + 2, j + 42, k + 10, 18, 1, 2);
        world.setBlock(i + 2, j + 42, k + 9, 18, 1, 2);
        world.setBlock(i + 2, j + 42, k + 8, 18, 1, 2);
        world.setBlock(i + 3, j + 42, k + 11, 18, 1, 2);
        world.setBlock(i + 3, j + 42, k + 10, 17, 1, 2);
        world.setBlock(i + 3, j + 42, k + 8, 18, 1, 2);
        world.setBlock(i + 4, j + 42, k + 12, 18, 1, 2);
        world.setBlock(i + 4, j + 42, k + 10, 18, 1, 2);
        world.setBlock(i + 4, j + 42, k + 9, 17, 1, 2);
        world.setBlock(i + 5, j + 42, k + 10, 18, 1, 2);
        world.setBlock(i + 5, j + 42, k + 8, 17, 1, 2);
        world.setBlock(i + 6, j + 42, k + 8, 17, 1, 2);
        world.setBlock(i + 5, j + 43, k + 8, 17, 1, 2);
        world.setBlock(i + 6, j + 43, k + 8, 17, 1, 2);
        world.setBlock(i + 2, j + 44, k + 8, 18, 1, 2);
        world.setBlock(i + 3, j + 44, k + 9, 18, 1, 2);
        world.setBlock(i + 3, j + 44, k + 6, 18, 1, 2);
        world.setBlock(i + 4, j + 44, k + 11, 18, 1, 2);
        world.setBlock(i + 4, j + 44, k + 8, 18, 1, 2);
        world.setBlock(i + 4, j + 44, k + 7, 18, 1, 2);
        world.setBlock(i + 4, j + 44, k + 6, 18, 1, 2);
        world.setBlock(i + 5, j + 44, k + 10, 18, 1, 2);
        world.setBlock(i + 5, j + 44, k + 8, 17, 1, 2);
        world.setBlock(i + 5, j + 44, k + 6, 18, 1, 2);
        world.setBlock(i + 5, j + 44, k + 5, 18, 1, 2);
        world.setBlock(i + 5, j + 44, k + 4, 18, 1, 2);
        world.setBlock(i + 6, j + 44, k + 10, 18, 1, 2);
        world.setBlock(i + 6, j + 44, k + 8, 17, 1, 2);
        world.setBlock(i + 6, j + 44, k + 7, 18, 1, 2);
        world.setBlock(i + 6, j + 44, k + 6, 18, 1, 2);
        world.setBlock(i + 7, j + 44, k + 9, 18, 1, 2);
        world.setBlock(i + 7, j + 44, k + 7, 18, 1, 2);
        world.setBlock(i + 8, j + 44, k + 8, 18, 1, 2);
        world.setBlock(i + 5, j + 45, k + 8, 17, 1, 2);
        world.setBlock(i + 6, j + 45, k + 8, 17, 1, 2);
        world.setBlock(i + 2, j + 46, k + 7, 18, 1, 2);
        world.setBlock(i + 3, j + 46, k + 8, 18, 1, 2);
        world.setBlock(i + 4, j + 46, k + 10, 18, 1, 2);
        world.setBlock(i + 4, j + 46, k + 9, 18, 1, 2);
        world.setBlock(i + 4, j + 46, k + 6, 18, 1, 2);
        world.setBlock(i + 5, j + 46, k + 10, 18, 1, 2);
        world.setBlock(i + 5, j + 46, k + 9, 18, 1, 2);
        world.setBlock(i + 5, j + 46, k + 8, 17, 1, 2);
        world.setBlock(i + 5, j + 46, k + 7, 18, 1, 2);
        world.setBlock(i + 6, j + 46, k + 11, 18, 1, 2);
        world.setBlock(i + 6, j + 46, k + 10, 18, 1, 2);
        world.setBlock(i + 6, j + 46, k + 8, 17, 1, 2);
        world.setBlock(i + 6, j + 46, k + 7, 18, 1, 2);
        world.setBlock(i + 7, j + 46, k + 6, 18, 1, 2);
        world.setBlock(i + 8, j + 46, k + 9, 18, 1, 2);
        world.setBlock(i + 8, j + 46, k + 8, 18, 1, 2);
        world.setBlock(i + 5, j + 47, k + 8, 17, 1, 2);
        world.setBlock(i + 5, j + 47, k + 6, 18, 1, 2);
        world.setBlock(i + 6, j + 47, k + 8, 17, 1, 2);
        world.setBlock(i + 6, j + 47, k + 7, 18, 1, 2);
        world.setBlock(i + 6, j + 47, k + 6, 18, 1, 2);
        world.setBlock(i + 7, j + 47, k + 7, 18, 1, 2);
        world.setBlock(i + 4, j + 48, k + 8, 18, 1, 2);
        world.setBlock(i + 4, j + 48, k + 7, 18, 1, 2);
        world.setBlock(i + 5, j + 48, k + 9, 18, 1, 2);
        world.setBlock(i + 5, j + 48, k + 8, 18, 1, 2);
        world.setBlock(i + 5, j + 48, k + 7, 18, 1, 2);
        world.setBlock(i + 6, j + 48, k + 10, 18, 1, 2);
        world.setBlock(i + 6, j + 48, k + 9, 18, 1, 2);
        world.setBlock(i + 6, j + 48, k + 8, 17, 1, 2);
        world.setBlock(i + 6, j + 48, k + 7, 18, 1, 2);
        world.setBlock(i + 7, j + 48, k + 10, 18, 1, 2);
        world.setBlock(i + 7, j + 48, k + 9, 18, 1, 2);
        world.setBlock(i + 7, j + 48, k + 7, 18, 1, 2);
        world.setBlock(i + 8, j + 48, k + 8, 18, 1, 2);
        world.setBlock(i + 8, j + 48, k + 7, 18, 1, 2);
        world.setBlock(i + 4, j + 49, k + 9, 18, 1, 2);
        world.setBlock(i + 5, j + 49, k + 8, 18, 1, 2);
        world.setBlock(i + 6, j + 49, k + 10, 18, 1, 2);
        world.setBlock(i + 6, j + 49, k + 8, 17, 1, 2);
        world.setBlock(i + 6, j + 49, k + 6, 18, 1, 2);
        world.setBlock(i + 8, j + 49, k + 8, 18, 1, 2);
        world.setBlock(i + 5, j + 50, k + 8, 18, 1, 2);
        world.setBlock(i + 5, j + 50, k + 7, 18, 1, 2);
        world.setBlock(i + 6, j + 50, k + 8, 17, 1, 2);
        world.setBlock(i + 7, j + 50, k + 9, 18, 1, 2);
        world.setBlock(i + 5, j + 51, k + 9, 18, 1, 2);
        world.setBlock(i + 6, j + 51, k + 10, 18, 1, 2);
        world.setBlock(i + 6, j + 51, k + 9, 18, 1, 2);
        world.setBlock(i + 6, j + 51, k + 8, 17, 1, 2);
        world.setBlock(i + 6, j + 51, k + 7, 18, 1, 2);
        world.setBlock(i + 7, j + 51, k + 8, 18, 1, 2);
        world.setBlock(i + 7, j + 51, k + 7, 18, 1, 2);
        world.setBlock(i + 8, j + 51, k + 8, 18, 1, 2);
        world.setBlock(i + 4, j + 52, k + 8, 18, 1, 2);
        world.setBlock(i + 5, j + 52, k + 9, 18, 1, 2);
        world.setBlock(i + 5, j + 52, k + 8, 18, 1, 2);
        world.setBlock(i + 5, j + 52, k + 6, 18, 1, 2);
        world.setBlock(i + 6, j + 52, k + 8, 17, 1, 2);
        world.setBlock(i + 6, j + 52, k + 6, 18, 1, 2);
        world.setBlock(i + 7, j + 52, k + 10, 18, 1, 2);
        world.setBlock(i + 7, j + 52, k + 9, 18, 1, 2);
        world.setBlock(i + 7, j + 52, k + 8, 18, 1, 2);
        world.setBlock(i + 8, j + 52, k + 9, 18, 1, 2);
        world.setBlock(i + 8, j + 52, k + 8, 18, 1, 2);
        world.setBlock(i + 8, j + 52, k + 7, 18, 1, 2);
        world.setBlock(i + 5, j + 53, k + 8, 18, 1, 2);
        world.setBlock(i + 6, j + 53, k + 9, 18, 1, 2);
        world.setBlock(i + 6, j + 53, k + 8, 17, 1, 2);
        world.setBlock(i + 7, j + 53, k + 9, 18, 1, 2);
        world.setBlock(i + 8, j + 53, k + 8, 18, 1, 2);
        world.setBlock(i + 5, j + 54, k + 9, 18, 1, 2);
        world.setBlock(i + 5, j + 54, k + 8, 18, 1, 2);
        world.setBlock(i + 6, j + 54, k + 8, 17, 1, 2);
        world.setBlock(i + 7, j + 54, k + 8, 18, 1, 2);

return true;
}
}
