package morethantrees.treegen;

import java.util.Random;

import net.minecraft.block.Block;
import net.minecraft.world.World;
import net.minecraft.world.gen.feature.WorldGenerator;

public class WorldGenDouglasFirLargeTree extends WorldGenerator
{
	public boolean generate(World world, Random var2, int i, int j, int k)
	  {
	    while ((world.isAirBlock(i + 10, j, k + 12)) && (j > 2))
	    {
	      j--;
	    }

	    int var6 = world.getBlockId(i + 10, j, k + 12);

	    if (var6 != Block.grass.blockID)
	    {
	      return false;
	    }

	    for (int var7 = -2; var7 <= 2; var7++)
	    {
	      for (int var8 = -2; var8 <= 2; var8++)
	      {
	        if ((world.isAirBlock(i + var7 + 10, j - 1, k + var8 + 12)) && (world.isAirBlock(i + var7 + 10, j - 2, k + var8 + 12)))
	        {
	          return false;
	        }
	      }
	    }
    	world.setBlock(i + 7, j + 0, k + 7, 17, 1, 2);
        world.setBlock(i + 8, j + 0, k + 8, 17, 1, 2);
        world.setBlock(i + 8, j + 0, k + 7, 17, 1, 2);
        world.setBlock(i + 9, j + 0, k + 9, 17, 1, 2);
        world.setBlock(i + 9, j + 0, k + 8, 17, 1, 2);
        world.setBlock(i + 9, j + 0, k + 7, 17, 1, 2);
        world.setBlock(i + 9, j + 0, k + 6, 17, 1, 2);
        world.setBlock(i + 8, j + 1, k + 8, 17, 1, 2);
        world.setBlock(i + 8, j + 1, k + 7, 17, 1, 2);
        world.setBlock(i + 9, j + 1, k + 8, 17, 1, 2);
        world.setBlock(i + 9, j + 1, k + 7, 17, 1, 2);
        world.setBlock(i + 8, j + 2, k + 8, 17, 1, 2);
        world.setBlock(i + 8, j + 2, k + 7, 17, 1, 2);
        world.setBlock(i + 9, j + 2, k + 8, 17, 1, 2);
        world.setBlock(i + 9, j + 2, k + 7, 17, 1, 2);
        world.setBlock(i + 8, j + 3, k + 8, 17, 1, 2);
        world.setBlock(i + 9, j + 3, k + 8, 17, 1, 2);
        world.setBlock(i + 9, j + 3, k + 7, 17, 1, 2);
        world.setBlock(i + 8, j + 4, k + 8, 17, 1, 2);
        world.setBlock(i + 9, j + 4, k + 8, 17, 1, 2);
        world.setBlock(i + 9, j + 4, k + 7, 17, 1, 2);
        world.setBlock(i + 8, j + 5, k + 8, 17, 1, 2);
        world.setBlock(i + 9, j + 5, k + 8, 17, 1, 2);
        world.setBlock(i + 9, j + 5, k + 7, 17, 1, 2);
        world.setBlock(i + 8, j + 6, k + 8, 17, 1, 2);
        world.setBlock(i + 9, j + 6, k + 8, 17, 1, 2);
        world.setBlock(i + 9, j + 6, k + 7, 17, 1, 2);
        world.setBlock(i + 3, j + 7, k + 10, 18, 1, 2);
        world.setBlock(i + 3, j + 7, k + 8, 18, 1, 2);
        world.setBlock(i + 4, j + 7, k + 12, 18, 1, 2);
        world.setBlock(i + 5, j + 7, k + 11, 18, 1, 2);
        world.setBlock(i + 5, j + 7, k + 10, 18, 1, 2);
        world.setBlock(i + 5, j + 7, k + 7, 18, 1, 2);
        world.setBlock(i + 6, j + 7, k + 13, 18, 1, 2);
        world.setBlock(i + 6, j + 7, k + 11, 18, 1, 2);
        world.setBlock(i + 6, j + 7, k + 10, 17, 1, 2);
        world.setBlock(i + 6, j + 7, k + 9, 18, 1, 2);
        world.setBlock(i + 7, j + 7, k + 12, 18, 1, 2);
        world.setBlock(i + 7, j + 7, k + 11, 18, 1, 2);
        world.setBlock(i + 7, j + 7, k + 10, 18, 1, 2);
        world.setBlock(i + 7, j + 7, k + 9, 17, 1, 2);
        world.setBlock(i + 7, j + 7, k + 6, 18, 1, 2);
        world.setBlock(i + 7, j + 7, k + 5, 18, 1, 2);
        world.setBlock(i + 8, j + 7, k + 10, 18, 1, 2);
        world.setBlock(i + 8, j + 7, k + 9, 18, 1, 2);
        world.setBlock(i + 8, j + 7, k + 8, 17, 1, 2);
        world.setBlock(i + 9, j + 7, k + 11, 18, 1, 2);
        world.setBlock(i + 9, j + 7, k + 8, 17, 1, 2);
        world.setBlock(i + 9, j + 7, k + 7, 17, 1, 2);
        world.setBlock(i + 10, j + 7, k + 9, 18, 1, 2);
        world.setBlock(i + 10, j + 7, k + 8, 18, 1, 2);
        world.setBlock(i + 10, j + 7, k + 6, 18, 1, 2);
        world.setBlock(i + 11, j + 7, k + 10, 18, 1, 2);
        world.setBlock(i + 11, j + 7, k + 9, 18, 1, 2);
        world.setBlock(i + 11, j + 7, k + 8, 18, 1, 2);
        world.setBlock(i + 11, j + 7, k + 7, 18, 1, 2);
        world.setBlock(i + 4, j + 8, k + 10, 18, 1, 2);
        world.setBlock(i + 4, j + 8, k + 8, 18, 1, 2);
        world.setBlock(i + 5, j + 8, k + 9, 18, 1, 2);
        world.setBlock(i + 6, j + 8, k + 12, 18, 1, 2);
        world.setBlock(i + 6, j + 8, k + 11, 18, 1, 2);
        world.setBlock(i + 6, j + 8, k + 10, 18, 1, 2);
        world.setBlock(i + 6, j + 8, k + 9, 18, 1, 2);
        world.setBlock(i + 6, j + 8, k + 8, 18, 1, 2);
        world.setBlock(i + 7, j + 8, k + 11, 18, 1, 2);
        world.setBlock(i + 7, j + 8, k + 10, 18, 1, 2);
        world.setBlock(i + 7, j + 8, k + 9, 18, 1, 2);
        world.setBlock(i + 8, j + 8, k + 10, 18, 1, 2);
        world.setBlock(i + 8, j + 8, k + 9, 18, 1, 2);
        world.setBlock(i + 8, j + 8, k + 8, 17, 1, 2);
        world.setBlock(i + 8, j + 8, k + 7, 18, 1, 2);
        world.setBlock(i + 8, j + 8, k + 6, 18, 1, 2);
        world.setBlock(i + 9, j + 8, k + 10, 18, 1, 2);
        world.setBlock(i + 9, j + 8, k + 8, 17, 1, 2);
        world.setBlock(i + 9, j + 8, k + 7, 17, 1, 2);
        world.setBlock(i + 9, j + 8, k + 6, 18, 1, 2);
        world.setBlock(i + 10, j + 8, k + 9, 18, 1, 2);
        world.setBlock(i + 8, j + 9, k + 8, 17, 1, 2);
        world.setBlock(i + 9, j + 9, k + 8, 17, 1, 2);
        world.setBlock(i + 9, j + 9, k + 7, 17, 1, 2);
        world.setBlock(i + 4, j + 10, k + 11, 18, 1, 2);
        world.setBlock(i + 4, j + 10, k + 4, 18, 1, 2);
        world.setBlock(i + 4, j + 10, k + 3, 18, 1, 2);
        world.setBlock(i + 5, j + 10, k + 9, 18, 1, 2);
        world.setBlock(i + 5, j + 10, k + 7, 18, 1, 2);
        world.setBlock(i + 5, j + 10, k + 6, 18, 1, 2);
        world.setBlock(i + 5, j + 10, k + 5, 18, 1, 2);
        world.setBlock(i + 5, j + 10, k + 3, 18, 1, 2);
        world.setBlock(i + 5, j + 10, k + 2, 18, 1, 2);
        world.setBlock(i + 5, j + 10, k + 1, 18, 1, 2);
        world.setBlock(i + 6, j + 10, k + 8, 18, 1, 2);
        world.setBlock(i + 6, j + 10, k + 7, 18, 1, 2);
        world.setBlock(i + 6, j + 10, k + 5, 18, 1, 2);
        world.setBlock(i + 7, j + 10, k + 10, 18, 1, 2);
        world.setBlock(i + 7, j + 10, k + 9, 18, 1, 2);
        world.setBlock(i + 7, j + 10, k + 8, 17, 1, 2);
        world.setBlock(i + 7, j + 10, k + 7, 18, 1, 2);
        world.setBlock(i + 7, j + 10, k + 6, 18, 1, 2);
        world.setBlock(i + 7, j + 10, k + 5, 18, 1, 2);
        world.setBlock(i + 8, j + 10, k + 13, 18, 1, 2);
        world.setBlock(i + 8, j + 10, k + 11, 18, 1, 2);
        world.setBlock(i + 8, j + 10, k + 10, 17, 1, 2);
        world.setBlock(i + 8, j + 10, k + 9, 17, 1, 2);
        world.setBlock(i + 8, j + 10, k + 8, 17, 1, 2);
        world.setBlock(i + 8, j + 10, k + 7, 18, 1, 2);
        world.setBlock(i + 8, j + 10, k + 6, 18, 1, 2);
        world.setBlock(i + 8, j + 10, k + 5, 18, 1, 2);
        world.setBlock(i + 8, j + 10, k + 4, 17, 1, 2);
        world.setBlock(i + 8, j + 10, k + 3, 18, 1, 2);
        world.setBlock(i + 8, j + 10, k + 2, 18, 1, 2);
        world.setBlock(i + 8, j + 10, k + 1, 18, 1, 2);
        world.setBlock(i + 8, j + 10, k + 0, 18, 1, 2);
        world.setBlock(i + 9, j + 10, k + 13, 18, 1, 2);
        world.setBlock(i + 9, j + 10, k + 12, 18, 1, 2);
        world.setBlock(i + 9, j + 10, k + 10, 18, 1, 2);
        world.setBlock(i + 9, j + 10, k + 9, 18, 1, 2);
        world.setBlock(i + 9, j + 10, k + 8, 17, 1, 2);
        world.setBlock(i + 9, j + 10, k + 7, 17, 1, 2);
        world.setBlock(i + 9, j + 10, k + 6, 17, 1, 2);
        world.setBlock(i + 9, j + 10, k + 5, 17, 1, 2);
        world.setBlock(i + 9, j + 10, k + 4, 18, 1, 2);
        world.setBlock(i + 10, j + 10, k + 12, 18, 1, 2);
        world.setBlock(i + 10, j + 10, k + 11, 18, 1, 2);
        world.setBlock(i + 10, j + 10, k + 8, 17, 1, 2);
        world.setBlock(i + 10, j + 10, k + 7, 18, 1, 2);
        world.setBlock(i + 10, j + 10, k + 6, 18, 1, 2);
        world.setBlock(i + 10, j + 10, k + 5, 18, 1, 2);
        world.setBlock(i + 11, j + 10, k + 12, 18, 1, 2);
        world.setBlock(i + 11, j + 10, k + 9, 18, 1, 2);
        world.setBlock(i + 11, j + 10, k + 8, 17, 1, 2);
        world.setBlock(i + 11, j + 10, k + 7, 18, 1, 2);
        world.setBlock(i + 11, j + 10, k + 6, 18, 1, 2);
        world.setBlock(i + 11, j + 10, k + 4, 18, 1, 2);
        world.setBlock(i + 11, j + 10, k + 3, 18, 1, 2);
        world.setBlock(i + 12, j + 10, k + 9, 18, 1, 2);
        world.setBlock(i + 12, j + 10, k + 8, 18, 1, 2);
        world.setBlock(i + 12, j + 10, k + 7, 17, 1, 2);
        world.setBlock(i + 12, j + 10, k + 6, 18, 1, 2);
        world.setBlock(i + 12, j + 10, k + 5, 18, 1, 2);
        world.setBlock(i + 12, j + 10, k + 4, 18, 1, 2);
        world.setBlock(i + 13, j + 10, k + 9, 18, 1, 2);
        world.setBlock(i + 13, j + 10, k + 8, 18, 1, 2);
        world.setBlock(i + 13, j + 10, k + 7, 18, 1, 2);
        world.setBlock(i + 13, j + 10, k + 6, 17, 1, 2);
        world.setBlock(i + 13, j + 10, k + 4, 18, 1, 2);
        world.setBlock(i + 13, j + 10, k + 3, 18, 1, 2);
        world.setBlock(i + 14, j + 10, k + 10, 18, 1, 2);
        world.setBlock(i + 14, j + 10, k + 6, 18, 1, 2);
        world.setBlock(i + 14, j + 10, k + 3, 18, 1, 2);
        world.setBlock(i + 15, j + 10, k + 7, 18, 1, 2);
        world.setBlock(i + 15, j + 10, k + 4, 18, 1, 2);
        world.setBlock(i + 15, j + 10, k + 2, 18, 1, 2);
        world.setBlock(i + 16, j + 10, k + 5, 18, 1, 2);
        world.setBlock(i + 16, j + 10, k + 4, 18, 1, 2);
        world.setBlock(i + 17, j + 10, k + 7, 18, 1, 2);
        world.setBlock(i + 17, j + 10, k + 6, 18, 1, 2);
        world.setBlock(i + 17, j + 10, k + 4, 18, 1, 2);
        world.setBlock(i + 6, j + 11, k + 7, 18, 1, 2);
        world.setBlock(i + 7, j + 11, k + 8, 18, 1, 2);
        world.setBlock(i + 7, j + 11, k + 7, 18, 1, 2);
        world.setBlock(i + 7, j + 11, k + 6, 18, 1, 2);
        world.setBlock(i + 7, j + 11, k + 5, 18, 1, 2);
        world.setBlock(i + 7, j + 11, k + 4, 18, 1, 2);
        world.setBlock(i + 8, j + 11, k + 9, 18, 1, 2);
        world.setBlock(i + 8, j + 11, k + 8, 17, 1, 2);
        world.setBlock(i + 8, j + 11, k + 7, 18, 1, 2);
        world.setBlock(i + 8, j + 11, k + 6, 18, 1, 2);
        world.setBlock(i + 8, j + 11, k + 5, 18, 1, 2);
        world.setBlock(i + 8, j + 11, k + 4, 18, 1, 2);
        world.setBlock(i + 8, j + 11, k + 3, 18, 1, 2);
        world.setBlock(i + 9, j + 11, k + 8, 17, 1, 2);
        world.setBlock(i + 9, j + 11, k + 7, 18, 1, 2);
        world.setBlock(i + 9, j + 11, k + 6, 18, 1, 2);
        world.setBlock(i + 9, j + 11, k + 5, 18, 1, 2);
        world.setBlock(i + 9, j + 11, k + 4, 18, 1, 2);
        world.setBlock(i + 10, j + 11, k + 8, 18, 1, 2);
        world.setBlock(i + 10, j + 11, k + 7, 18, 1, 2);
        world.setBlock(i + 10, j + 11, k + 6, 18, 1, 2);
        world.setBlock(i + 11, j + 11, k + 10, 18, 1, 2);
        world.setBlock(i + 11, j + 11, k + 9, 18, 1, 2);
        world.setBlock(i + 11, j + 11, k + 8, 18, 1, 2);
        world.setBlock(i + 11, j + 11, k + 7, 18, 1, 2);
        world.setBlock(i + 11, j + 11, k + 6, 18, 1, 2);
        world.setBlock(i + 12, j + 11, k + 9, 18, 1, 2);
        world.setBlock(i + 12, j + 11, k + 8, 18, 1, 2);
        world.setBlock(i + 12, j + 11, k + 6, 18, 1, 2);
        world.setBlock(i + 13, j + 11, k + 8, 18, 1, 2);
        world.setBlock(i + 13, j + 11, k + 7, 18, 1, 2);
        world.setBlock(i + 13, j + 11, k + 6, 18, 1, 2);
        world.setBlock(i + 13, j + 11, k + 5, 18, 1, 2);
        world.setBlock(i + 14, j + 11, k + 7, 18, 1, 2);
        world.setBlock(i + 14, j + 11, k + 5, 18, 1, 2);
        world.setBlock(i + 15, j + 11, k + 8, 18, 1, 2);
        world.setBlock(i + 15, j + 11, k + 7, 18, 1, 2);
        world.setBlock(i + 8, j + 12, k + 8, 17, 1, 2);
        world.setBlock(i + 9, j + 12, k + 8, 17, 1, 2);
        world.setBlock(i + 0, j + 13, k + 11, 18, 1, 2);
        world.setBlock(i + 1, j + 13, k + 13, 18, 1, 2);
        world.setBlock(i + 1, j + 13, k + 12, 18, 1, 2);
        world.setBlock(i + 2, j + 13, k + 9, 18, 1, 2);
        world.setBlock(i + 3, j + 13, k + 13, 18, 1, 2);
        world.setBlock(i + 3, j + 13, k + 12, 18, 1, 2);
        world.setBlock(i + 4, j + 13, k + 13, 17, 1, 2);
        world.setBlock(i + 4, j + 13, k + 12, 18, 1, 2);
        world.setBlock(i + 4, j + 13, k + 10, 18, 1, 2);
        world.setBlock(i + 4, j + 13, k + 9, 18, 1, 2);
        world.setBlock(i + 5, j + 13, k + 12, 17, 1, 2);
        world.setBlock(i + 5, j + 13, k + 10, 18, 1, 2);
        world.setBlock(i + 6, j + 13, k + 13, 18, 1, 2);
        world.setBlock(i + 6, j + 13, k + 12, 17, 1, 2);
        world.setBlock(i + 6, j + 13, k + 9, 18, 1, 2);
        world.setBlock(i + 7, j + 13, k + 15, 18, 1, 2);
        world.setBlock(i + 7, j + 13, k + 13, 18, 1, 2);
        world.setBlock(i + 7, j + 13, k + 11, 17, 1, 2);
        world.setBlock(i + 8, j + 13, k + 14, 18, 1, 2);
        world.setBlock(i + 8, j + 13, k + 13, 18, 1, 2);
        world.setBlock(i + 8, j + 13, k + 11, 18, 1, 2);
        world.setBlock(i + 8, j + 13, k + 10, 17, 1, 2);
        world.setBlock(i + 8, j + 13, k + 9, 17, 1, 2);
        world.setBlock(i + 8, j + 13, k + 8, 17, 1, 2);
        world.setBlock(i + 9, j + 13, k + 8, 17, 1, 2);
        world.setBlock(i + 3, j + 14, k + 13, 18, 1, 2);
        world.setBlock(i + 5, j + 14, k + 13, 18, 1, 2);
        world.setBlock(i + 5, j + 14, k + 12, 18, 1, 2);
        world.setBlock(i + 5, j + 14, k + 10, 18, 1, 2);
        world.setBlock(i + 5, j + 14, k + 9, 18, 1, 2);
        world.setBlock(i + 5, j + 14, k + 8, 18, 1, 2);
        world.setBlock(i + 6, j + 14, k + 11, 18, 1, 2);
        world.setBlock(i + 6, j + 14, k + 8, 18, 1, 2);
        world.setBlock(i + 6, j + 14, k + 7, 18, 1, 2);
        world.setBlock(i + 7, j + 14, k + 12, 18, 1, 2);
        world.setBlock(i + 7, j + 14, k + 11, 18, 1, 2);
        world.setBlock(i + 7, j + 14, k + 10, 18, 1, 2);
        world.setBlock(i + 7, j + 14, k + 9, 18, 1, 2);
        world.setBlock(i + 7, j + 14, k + 8, 18, 1, 2);
        world.setBlock(i + 7, j + 14, k + 7, 18, 1, 2);
        world.setBlock(i + 8, j + 14, k + 12, 18, 1, 2);
        world.setBlock(i + 8, j + 14, k + 11, 18, 1, 2);
        world.setBlock(i + 8, j + 14, k + 10, 18, 1, 2);
        world.setBlock(i + 8, j + 14, k + 9, 18, 1, 2);
        world.setBlock(i + 8, j + 14, k + 8, 17, 1, 2);
        world.setBlock(i + 8, j + 14, k + 7, 18, 1, 2);
        world.setBlock(i + 9, j + 14, k + 10, 18, 1, 2);
        world.setBlock(i + 9, j + 14, k + 9, 18, 1, 2);
        world.setBlock(i + 9, j + 14, k + 8, 17, 1, 2);
        world.setBlock(i + 10, j + 14, k + 8, 18, 1, 2);
        world.setBlock(i + 8, j + 15, k + 8, 17, 1, 2);
        world.setBlock(i + 9, j + 15, k + 8, 17, 1, 2);
        world.setBlock(i + 8, j + 16, k + 9, 18, 1, 2);
        world.setBlock(i + 8, j + 16, k + 8, 17, 1, 2);
        world.setBlock(i + 8, j + 16, k + 7, 18, 1, 2);
        world.setBlock(i + 9, j + 16, k + 8, 17, 1, 2);
        world.setBlock(i + 9, j + 16, k + 7, 18, 1, 2);
        world.setBlock(i + 9, j + 16, k + 5, 18, 1, 2);
        world.setBlock(i + 10, j + 16, k + 9, 18, 1, 2);
        world.setBlock(i + 10, j + 16, k + 8, 17, 1, 2);
        world.setBlock(i + 10, j + 16, k + 6, 18, 1, 2);
        world.setBlock(i + 10, j + 16, k + 3, 18, 1, 2);
        world.setBlock(i + 11, j + 16, k + 10, 18, 1, 2);
        world.setBlock(i + 11, j + 16, k + 8, 17, 1, 2);
        world.setBlock(i + 11, j + 16, k + 7, 18, 1, 2);
        world.setBlock(i + 11, j + 16, k + 3, 18, 1, 2);
        world.setBlock(i + 12, j + 16, k + 11, 18, 1, 2);
        world.setBlock(i + 12, j + 16, k + 9, 18, 1, 2);
        world.setBlock(i + 12, j + 16, k + 8, 18, 1, 2);
        world.setBlock(i + 12, j + 16, k + 7, 17, 1, 2);
        world.setBlock(i + 12, j + 16, k + 5, 18, 1, 2);
        world.setBlock(i + 13, j + 16, k + 9, 18, 1, 2);
        world.setBlock(i + 13, j + 16, k + 7, 18, 1, 2);
        world.setBlock(i + 13, j + 16, k + 3, 18, 1, 2);
        world.setBlock(i + 15, j + 16, k + 7, 18, 1, 2);
        world.setBlock(i + 15, j + 16, k + 5, 18, 1, 2);
        world.setBlock(i + 16, j + 16, k + 9, 18, 1, 2);
        world.setBlock(i + 8, j + 17, k + 10, 18, 1, 2);
        world.setBlock(i + 8, j + 17, k + 9, 18, 1, 2);
        world.setBlock(i + 8, j + 17, k + 8, 17, 1, 2);
        world.setBlock(i + 8, j + 17, k + 7, 18, 1, 2);
        world.setBlock(i + 9, j + 17, k + 10, 18, 1, 2);
        world.setBlock(i + 9, j + 17, k + 8, 17, 1, 2);
        world.setBlock(i + 9, j + 17, k + 7, 18, 1, 2);
        world.setBlock(i + 9, j + 17, k + 6, 18, 1, 2);
        world.setBlock(i + 10, j + 17, k + 8, 18, 1, 2);
        world.setBlock(i + 10, j + 17, k + 7, 18, 1, 2);
        world.setBlock(i + 10, j + 17, k + 6, 18, 1, 2);
        world.setBlock(i + 11, j + 17, k + 9, 18, 1, 2);
        world.setBlock(i + 11, j + 17, k + 8, 18, 1, 2);
        world.setBlock(i + 11, j + 17, k + 7, 18, 1, 2);
        world.setBlock(i + 11, j + 17, k + 6, 18, 1, 2);
        world.setBlock(i + 11, j + 17, k + 5, 18, 1, 2);
        world.setBlock(i + 12, j + 17, k + 6, 18, 1, 2);
        world.setBlock(i + 13, j + 17, k + 6, 18, 1, 2);
        world.setBlock(i + 3, j + 18, k + 7, 18, 1, 2);
        world.setBlock(i + 4, j + 18, k + 6, 18, 1, 2);
        world.setBlock(i + 4, j + 18, k + 3, 18, 1, 2);
        world.setBlock(i + 5, j + 18, k + 7, 18, 1, 2);
        world.setBlock(i + 5, j + 18, k + 2, 18, 1, 2);
        world.setBlock(i + 5, j + 18, k + 1, 18, 1, 2);
        world.setBlock(i + 6, j + 18, k + 8, 18, 1, 2);
        world.setBlock(i + 6, j + 18, k + 7, 18, 1, 2);
        world.setBlock(i + 6, j + 18, k + 5, 18, 1, 2);
        world.setBlock(i + 6, j + 18, k + 4, 18, 1, 2);
        world.setBlock(i + 6, j + 18, k + 2, 18, 1, 2);
        world.setBlock(i + 6, j + 18, k + 1, 18, 1, 2);
        world.setBlock(i + 7, j + 18, k + 6, 18, 1, 2);
        world.setBlock(i + 7, j + 18, k + 5, 17, 1, 2);
        world.setBlock(i + 7, j + 18, k + 4, 18, 1, 2);
        world.setBlock(i + 7, j + 18, k + 3, 18, 1, 2);
        world.setBlock(i + 8, j + 18, k + 9, 18, 1, 2);
        world.setBlock(i + 8, j + 18, k + 8, 17, 1, 2);
        world.setBlock(i + 8, j + 18, k + 7, 17, 1, 2);
        world.setBlock(i + 8, j + 18, k + 6, 17, 1, 2);
        world.setBlock(i + 8, j + 18, k + 1, 18, 1, 2);
        world.setBlock(i + 9, j + 18, k + 8, 17, 1, 2);
        world.setBlock(i + 9, j + 18, k + 6, 18, 1, 2);
        world.setBlock(i + 9, j + 18, k + 4, 18, 1, 2);
        world.setBlock(i + 9, j + 18, k + 3, 18, 1, 2);
        world.setBlock(i + 10, j + 18, k + 7, 18, 1, 2);
        world.setBlock(i + 11, j + 18, k + 7, 18, 1, 2);
        world.setBlock(i + 11, j + 18, k + 4, 18, 1, 2);
        world.setBlock(i + 5, j + 19, k + 6, 18, 1, 2);
        world.setBlock(i + 5, j + 19, k + 4, 18, 1, 2);
        world.setBlock(i + 6, j + 19, k + 7, 18, 1, 2);
        world.setBlock(i + 6, j + 19, k + 5, 18, 1, 2);
        world.setBlock(i + 7, j + 19, k + 9, 18, 1, 2);
        world.setBlock(i + 7, j + 19, k + 8, 18, 1, 2);
        world.setBlock(i + 7, j + 19, k + 7, 18, 1, 2);
        world.setBlock(i + 7, j + 19, k + 6, 18, 1, 2);
        world.setBlock(i + 7, j + 19, k + 5, 18, 1, 2);
        world.setBlock(i + 7, j + 19, k + 4, 18, 1, 2);
        world.setBlock(i + 8, j + 19, k + 10, 18, 1, 2);
        world.setBlock(i + 8, j + 19, k + 8, 17, 1, 2);
        world.setBlock(i + 8, j + 19, k + 6, 18, 1, 2);
        world.setBlock(i + 8, j + 19, k + 5, 18, 1, 2);
        world.setBlock(i + 8, j + 19, k + 3, 18, 1, 2);
        world.setBlock(i + 9, j + 19, k + 10, 18, 1, 2);
        world.setBlock(i + 9, j + 19, k + 8, 17, 1, 2);
        world.setBlock(i + 9, j + 19, k + 7, 18, 1, 2);
        world.setBlock(i + 9, j + 19, k + 6, 18, 1, 2);
        world.setBlock(i + 9, j + 19, k + 5, 18, 1, 2);
        world.setBlock(i + 6, j + 20, k + 9, 18, 1, 2);
        world.setBlock(i + 6, j + 20, k + 8, 18, 1, 2);
        world.setBlock(i + 6, j + 20, k + 7, 18, 1, 2);
        world.setBlock(i + 7, j + 20, k + 10, 18, 1, 2);
        world.setBlock(i + 7, j + 20, k + 8, 18, 1, 2);
        world.setBlock(i + 7, j + 20, k + 7, 18, 1, 2);
        world.setBlock(i + 7, j + 20, k + 6, 18, 1, 2);
        world.setBlock(i + 8, j + 20, k + 10, 18, 1, 2);
        world.setBlock(i + 8, j + 20, k + 9, 18, 1, 2);
        world.setBlock(i + 8, j + 20, k + 8, 17, 1, 2);
        world.setBlock(i + 8, j + 20, k + 6, 18, 1, 2);
        world.setBlock(i + 8, j + 20, k + 5, 18, 1, 2);
        world.setBlock(i + 9, j + 20, k + 10, 18, 1, 2);
        world.setBlock(i + 9, j + 20, k + 9, 18, 1, 2);
        world.setBlock(i + 9, j + 20, k + 8, 18, 1, 2);
        world.setBlock(i + 9, j + 20, k + 7, 18, 1, 2);
        world.setBlock(i + 9, j + 20, k + 6, 18, 1, 2);
        world.setBlock(i + 10, j + 20, k + 9, 18, 1, 2);
        world.setBlock(i + 10, j + 20, k + 6, 18, 1, 2);
        world.setBlock(i + 11, j + 20, k + 4, 18, 1, 2);
        world.setBlock(i + 12, j + 20, k + 6, 18, 1, 2);
        world.setBlock(i + 8, j + 21, k + 8, 17, 1, 2);
        world.setBlock(i + 3, j + 22, k + 12, 18, 1, 2);
        world.setBlock(i + 3, j + 22, k + 10, 18, 1, 2);
        world.setBlock(i + 4, j + 22, k + 8, 18, 1, 2);
        world.setBlock(i + 5, j + 22, k + 13, 18, 1, 2);
        world.setBlock(i + 5, j + 22, k + 12, 18, 1, 2);
        world.setBlock(i + 5, j + 22, k + 11, 18, 1, 2);
        world.setBlock(i + 5, j + 22, k + 10, 18, 1, 2);
        world.setBlock(i + 5, j + 22, k + 9, 18, 1, 2);
        world.setBlock(i + 5, j + 22, k + 6, 18, 1, 2);
        world.setBlock(i + 6, j + 22, k + 12, 18, 1, 2);
        world.setBlock(i + 6, j + 22, k + 10, 17, 1, 2);
        world.setBlock(i + 6, j + 22, k + 9, 18, 1, 2);
        world.setBlock(i + 6, j + 22, k + 8, 18, 1, 2);
        world.setBlock(i + 7, j + 22, k + 13, 18, 1, 2);
        world.setBlock(i + 7, j + 22, k + 9, 17, 1, 2);
        world.setBlock(i + 7, j + 22, k + 6, 18, 1, 2);
        world.setBlock(i + 8, j + 22, k + 9, 18, 1, 2);
        world.setBlock(i + 8, j + 22, k + 8, 17, 1, 2);
        world.setBlock(i + 9, j + 22, k + 11, 18, 1, 2);
        world.setBlock(i + 10, j + 22, k + 10, 18, 1, 2);
        world.setBlock(i + 8, j + 23, k + 10, 18, 1, 2);
        world.setBlock(i + 8, j + 23, k + 8, 17, 1, 2);
        world.setBlock(i + 8, j + 23, k + 6, 18, 1, 2);
        world.setBlock(i + 9, j + 23, k + 10, 18, 1, 2);
        world.setBlock(i + 9, j + 23, k + 8, 18, 1, 2);
        world.setBlock(i + 10, j + 23, k + 9, 18, 1, 2);
        world.setBlock(i + 8, j + 24, k + 8, 17, 1, 2);
        world.setBlock(i + 5, j + 25, k + 9, 18, 1, 2);
        world.setBlock(i + 5, j + 25, k + 8, 18, 1, 2);
        world.setBlock(i + 6, j + 25, k + 11, 18, 1, 2);
        world.setBlock(i + 6, j + 25, k + 9, 18, 1, 2);
        world.setBlock(i + 6, j + 25, k + 7, 18, 1, 2);
        world.setBlock(i + 7, j + 25, k + 9, 18, 1, 2);
        world.setBlock(i + 7, j + 25, k + 7, 18, 1, 2);
        world.setBlock(i + 7, j + 25, k + 6, 18, 1, 2);
        world.setBlock(i + 8, j + 25, k + 12, 18, 1, 2);
        world.setBlock(i + 8, j + 25, k + 10, 18, 1, 2);
        world.setBlock(i + 8, j + 25, k + 9, 17, 1, 2);
        world.setBlock(i + 8, j + 25, k + 8, 17, 1, 2);
        world.setBlock(i + 9, j + 25, k + 9, 18, 1, 2);
        world.setBlock(i + 9, j + 25, k + 8, 18, 1, 2);
        world.setBlock(i + 10, j + 25, k + 8, 18, 1, 2);
        world.setBlock(i + 6, j + 26, k + 7, 18, 1, 2);
        world.setBlock(i + 8, j + 26, k + 8, 17, 1, 2);
        world.setBlock(i + 8, j + 26, k + 7, 18, 1, 2);
        world.setBlock(i + 9, j + 26, k + 6, 18, 1, 2);
        world.setBlock(i + 8, j + 27, k + 8, 17, 1, 2);
        world.setBlock(i + 6, j + 28, k + 7, 18, 1, 2);
        world.setBlock(i + 6, j + 28, k + 6, 18, 1, 2);
        world.setBlock(i + 8, j + 28, k + 10, 18, 1, 2);
        world.setBlock(i + 8, j + 28, k + 8, 17, 1, 2);
        world.setBlock(i + 8, j + 28, k + 7, 18, 1, 2);
        world.setBlock(i + 8, j + 28, k + 5, 18, 1, 2);
        world.setBlock(i + 9, j + 28, k + 8, 18, 1, 2);
        world.setBlock(i + 9, j + 28, k + 7, 17, 1, 2);
        world.setBlock(i + 10, j + 28, k + 5, 18, 1, 2);
        world.setBlock(i + 10, j + 28, k + 4, 18, 1, 2);
        world.setBlock(i + 11, j + 28, k + 8, 18, 1, 2);
        world.setBlock(i + 11, j + 28, k + 5, 18, 1, 2);
        world.setBlock(i + 8, j + 29, k + 8, 17, 1, 2);
        world.setBlock(i + 7, j + 30, k + 10, 18, 1, 2);
        world.setBlock(i + 7, j + 30, k + 8, 18, 1, 2);
        world.setBlock(i + 8, j + 30, k + 8, 17, 1, 2);
        world.setBlock(i + 9, j + 30, k + 9, 18, 1, 2);
        world.setBlock(i + 9, j + 30, k + 8, 18, 1, 2);
        world.setBlock(i + 8, j + 31, k + 8, 17, 1, 2);
        world.setBlock(i + 9, j + 31, k + 8, 18, 1, 2);
        world.setBlock(i + 9, j + 31, k + 6, 18, 1, 2);
        world.setBlock(i + 10, j + 31, k + 7, 18, 1, 2);
        world.setBlock(i + 7, j + 32, k + 9, 18, 1, 2);
        world.setBlock(i + 7, j + 32, k + 7, 18, 1, 2);
        world.setBlock(i + 8, j + 32, k + 8, 18, 1, 2);
        world.setBlock(i + 8, j + 32, k + 7, 18, 1, 2);
        world.setBlock(i + 8, j + 33, k + 8, 18, 1, 2);

return true;
}
}
