package morethantrees.treegen;

import java.util.Random;

import morethantrees.MTJT;
import net.minecraft.block.Block;
import net.minecraft.world.World;
import net.minecraft.world.gen.feature.WorldGenerator;

public class WorldGenMushroom2Shroom extends WorldGenerator
{
	public boolean generate(World world, Random var2, int i, int j, int k)
	  {
	    while ((world.isAirBlock(i + 10, j, k + 12)) && (j > 2))
	    {
	      j--;
	    }

	    int var6 = world.getBlockId(i + 10, j, k + 12);

	    if (var6 != Block.grass.blockID)
	    {
	      return false;
	    }

	    for (int var7 = -2; var7 <= 2; var7++)
	    {
	      for (int var8 = -2; var8 <= 2; var8++)
	      {
	        if ((world.isAirBlock(i + var7 + 10, j - 1, k + var8 + 12)) && (world.isAirBlock(i + var7 + 10, j - 2, k + var8 + 12)))
	        {
	          return false;
	        }
	      }
	    }
    	world.setBlock(i + 15, j + 0, k + 22, MTJT.mushroomStemmWhite.blockID, 0, 2);
        world.setBlock(i + 30, j + 0, k + 31, MTJT.mushroomStemmWhite.blockID, 0, 2);
        world.setBlock(i + 30, j + 0, k + 22, MTJT.mushroomStemmWhite.blockID, 0, 2);
        world.setBlock(i + 31, j + 0, k + 19, MTJT.mushroomStemmWhite.blockID, 0, 2);
        world.setBlock(i + 34, j + 0, k + 13, MTJT.mushroomStemmWhite.blockID, 0, 2);
        world.setBlock(i + 38, j + 0, k + 22, MTJT.mushroomStemmWhite.blockID, 0, 2);
        world.setBlock(i + 14, j + 1, k + 22, MTJT.mushroomStemmWhite.blockID, 0, 2);
        world.setBlock(i + 30, j + 1, k + 32, MTJT.mushroomStemmWhite.blockID, 0, 2);
        world.setBlock(i + 30, j + 1, k + 22, MTJT.mushroomStemmWhite.blockID, 0, 2);
        world.setBlock(i + 31, j + 1, k + 18, MTJT.mushroomStemmWhite.blockID, 0, 2);
        world.setBlock(i + 34, j + 1, k + 12, MTJT.mushroomStemmWhite.blockID, 0, 2);
        world.setBlock(i + 39, j + 1, k + 22, MTJT.mushroomStemmWhite.blockID, 0, 2);
        world.setBlock(i + 13, j + 2, k + 22, MTJT.mushroomStemmWhite.blockID, 0, 2);
        world.setBlock(i + 30, j + 2, k + 33, MTJT.mushroomStemmWhite.blockID, 0, 2);
        world.setBlock(i + 30, j + 2, k + 22, MTJT.mushroomStemmWhite.blockID, 0, 2);
        world.setBlock(i + 31, j + 2, k + 17, MTJT.mushroomStemmWhite.blockID, 0, 2);
        world.setBlock(i + 34, j + 2, k + 11, MTJT.mushroomStemmWhite.blockID, 0, 2);
        world.setBlock(i + 40, j + 2, k + 22, MTJT.mushroomStemmWhite.blockID, 0, 2);
        world.setBlock(i + 12, j + 3, k + 22, MTJT.mushroomStemmWhite.blockID, 0, 2);
        world.setBlock(i + 30, j + 3, k + 34, MTJT.mushroomStemmWhite.blockID, 0, 2);
        world.setBlock(i + 30, j + 3, k + 22, MTJT.mushroomStemmWhite.blockID, 0, 2);
        world.setBlock(i + 31, j + 3, k + 16, MTJT.mushroomStemmWhite.blockID, 0, 2);
        world.setBlock(i + 35, j + 3, k + 10, MTJT.mushroomStemmWhite.blockID, 0, 2);
        world.setBlock(i + 41, j + 3, k + 22, MTJT.mushroomStemmWhite.blockID, 0, 2);
        world.setBlock(i + 11, j + 4, k + 22, MTJT.mushroomStemmWhite.blockID, 0, 2);
        world.setBlock(i + 30, j + 4, k + 35, MTJT.mushroomStemmWhite.blockID, 0, 2);
        world.setBlock(i + 30, j + 4, k + 22, MTJT.mushroomStemmWhite.blockID, 0, 2);
        world.setBlock(i + 31, j + 4, k + 15, MTJT.mushroomStemmWhite.blockID, 0, 2);
        world.setBlock(i + 35, j + 4, k + 9, MTJT.mushroomStemmWhite.blockID, 0, 2);
        world.setBlock(i + 42, j + 4, k + 22, MTJT.mushroomStemmWhite.blockID, 0, 2);
        world.setBlock(i + 10, j + 5, k + 22, MTJT.mushroomStemmWhite.blockID, 0, 2);
        world.setBlock(i + 30, j + 5, k + 36, MTJT.mushroomStemmWhite.blockID, 0, 2);
        world.setBlock(i + 30, j + 5, k + 22, MTJT.mushroomStemmWhite.blockID, 0, 2);
        world.setBlock(i + 30, j + 5, k + 21, MTJT.mushroomStemmWhite.blockID, 0, 2);
        world.setBlock(i + 31, j + 5, k + 14, MTJT.mushroomStemmWhite.blockID, 0, 2);
        world.setBlock(i + 35, j + 5, k + 8, MTJT.mushroomStemmWhite.blockID, 0, 2);
        world.setBlock(i + 43, j + 5, k + 22, MTJT.mushroomStemmWhite.blockID, 0, 2);
        world.setBlock(i + 9, j + 6, k + 22, MTJT.mushroomStemmWhite.blockID, 0, 2);
        world.setBlock(i + 30, j + 6, k + 37, MTJT.mushroomStemmWhite.blockID, 0, 2);
        world.setBlock(i + 30, j + 6, k + 22, MTJT.mushroomStemmWhite.blockID, 0, 2);
        world.setBlock(i + 31, j + 6, k + 21, MTJT.mushroomStemmWhite.blockID, 0, 2);
        world.setBlock(i + 31, j + 6, k + 13, MTJT.mushroomStemmWhite.blockID, 0, 2);
        world.setBlock(i + 36, j + 6, k + 8, MTJT.mushroomStemmWhite.blockID, 0, 2);
        world.setBlock(i + 44, j + 6, k + 22, MTJT.mushroomStemmWhite.blockID, 0, 2);
        world.setBlock(i + 8, j + 7, k + 22, MTJT.mushroomStemmWhite.blockID, 0, 2);
        world.setBlock(i + 30, j + 7, k + 38, MTJT.mushroomStemmWhite.blockID, 0, 2);
        world.setBlock(i + 30, j + 7, k + 22, MTJT.mushroomStemmWhite.blockID, 0, 2);
        world.setBlock(i + 31, j + 7, k + 12, MTJT.mushroomStemmWhite.blockID, 0, 2);
        world.setBlock(i + 32, j + 7, k + 21, MTJT.mushroomStemmWhite.blockID, 0, 2);
        world.setBlock(i + 36, j + 7, k + 7, MTJT.mushroomStemmWhite.blockID, 0, 2);
        world.setBlock(i + 45, j + 7, k + 22, MTJT.mushroomStemmWhite.blockID, 0, 2);
        world.setBlock(i + 7, j + 8, k + 22, MTJT.mushroomStemmWhite.blockID, 0, 2);
        world.setBlock(i + 30, j + 8, k + 39, MTJT.mushroomStemmWhite.blockID, 0, 2);
        world.setBlock(i + 30, j + 8, k + 22, MTJT.mushroomStemmWhite.blockID, 0, 2);
        world.setBlock(i + 31, j + 8, k + 11, MTJT.mushroomStemmWhite.blockID, 0, 2);
        world.setBlock(i + 33, j + 8, k + 21, MTJT.mushroomStemmWhite.blockID, 0, 2);
        world.setBlock(i + 36, j + 8, k + 6, MTJT.mushroomStemmWhite.blockID, 0, 2);
        world.setBlock(i + 46, j + 8, k + 22, MTJT.mushroomStemmWhite.blockID, 0, 2);
        world.setBlock(i + 6, j + 9, k + 22, MTJT.mushroomStemmWhite.blockID, 0, 2);
        world.setBlock(i + 30, j + 9, k + 40, MTJT.mushroomStemmWhite.blockID, 0, 2);
        world.setBlock(i + 30, j + 9, k + 22, MTJT.mushroomStemmWhite.blockID, 0, 2);
        world.setBlock(i + 31, j + 9, k + 10, MTJT.mushroomStemmWhite.blockID, 0, 2);
        world.setBlock(i + 34, j + 9, k + 21, MTJT.mushroomStemmWhite.blockID, 0, 2);
        world.setBlock(i + 37, j + 9, k + 5, MTJT.mushroomStemmWhite.blockID, 0, 2);
        world.setBlock(i + 47, j + 9, k + 22, MTJT.mushroomStemmWhite.blockID, 0, 2);
        world.setBlock(i + 3, j + 10, k + 23, MTJT.mushroomTopRed.blockID, 0, 2);
        world.setBlock(i + 3, j + 10, k + 22, MTJT.mushroomTopRed.blockID, 0, 2);
        world.setBlock(i + 3, j + 10, k + 21, MTJT.mushroomTopRed.blockID, 0, 2);
        world.setBlock(i + 4, j + 10, k + 24, MTJT.mushroomTopRed.blockID, 0, 2);
        world.setBlock(i + 4, j + 10, k + 20, MTJT.mushroomTopRed.blockID, 0, 2);
        world.setBlock(i + 5, j + 10, k + 25, MTJT.mushroomTopRed.blockID, 0, 2);
        world.setBlock(i + 5, j + 10, k + 19, MTJT.mushroomTopRed.blockID, 0, 2);
        world.setBlock(i + 6, j + 10, k + 25, MTJT.mushroomTopRed.blockID, 0, 2);
        world.setBlock(i + 6, j + 10, k + 22, MTJT.mushroomStemmWhite.blockID, 0, 2);
        world.setBlock(i + 6, j + 10, k + 19, MTJT.mushroomTopRed.blockID, 0, 2);
        world.setBlock(i + 7, j + 10, k + 25, MTJT.mushroomTopRed.blockID, 0, 2);
        world.setBlock(i + 7, j + 10, k + 19, MTJT.mushroomTopRed.blockID, 0, 2);
        world.setBlock(i + 8, j + 10, k + 24, MTJT.mushroomTopRed.blockID, 0, 2);
        world.setBlock(i + 8, j + 10, k + 20, MTJT.mushroomTopRed.blockID, 0, 2);
        world.setBlock(i + 9, j + 10, k + 23, MTJT.mushroomTopRed.blockID, 0, 2);
        world.setBlock(i + 9, j + 10, k + 22, MTJT.mushroomTopRed.blockID, 0, 2);
        world.setBlock(i + 9, j + 10, k + 21, MTJT.mushroomTopRed.blockID, 0, 2);
        world.setBlock(i + 30, j + 10, k + 41, MTJT.mushroomStemmWhite.blockID, 0, 2);
        world.setBlock(i + 30, j + 10, k + 22, MTJT.mushroomStemmWhite.blockID, 0, 2);
        world.setBlock(i + 31, j + 10, k + 9, MTJT.mushroomStemmWhite.blockID, 0, 2);
        world.setBlock(i + 35, j + 10, k + 20, MTJT.mushroomStemmWhite.blockID, 0, 2);
        world.setBlock(i + 37, j + 10, k + 4, MTJT.mushroomStemmWhite.blockID, 0, 2);
        world.setBlock(i + 48, j + 10, k + 22, MTJT.mushroomStemmWhite.blockID, 0, 2);
        world.setBlock(i + 4, j + 11, k + 23, MTJT.mushroomTopRed.blockID, 0, 2);
        world.setBlock(i + 4, j + 11, k + 22, MTJT.mushroomTopRed.blockID, 0, 2);
        world.setBlock(i + 4, j + 11, k + 21, MTJT.mushroomTopRed.blockID, 0, 2);
        world.setBlock(i + 5, j + 11, k + 24, MTJT.mushroomTopRed.blockID, 0, 2);
        world.setBlock(i + 5, j + 11, k + 23, MTJT.mushroomTopRed.blockID, 0, 2);
        world.setBlock(i + 5, j + 11, k + 22, MTJT.mushroomTopRed.blockID, 0, 2);
        world.setBlock(i + 5, j + 11, k + 21, MTJT.mushroomTopRed.blockID, 0, 2);
        world.setBlock(i + 5, j + 11, k + 20, MTJT.mushroomTopRed.blockID, 0, 2);
        world.setBlock(i + 6, j + 11, k + 24, MTJT.mushroomTopRed.blockID, 0, 2);
        world.setBlock(i + 6, j + 11, k + 23, MTJT.mushroomTopRed.blockID, 0, 2);
        world.setBlock(i + 6, j + 11, k + 22, MTJT.mushroomTopRed.blockID, 0, 2);
        world.setBlock(i + 6, j + 11, k + 21, MTJT.mushroomTopRed.blockID, 0, 2);
        world.setBlock(i + 6, j + 11, k + 20, MTJT.mushroomTopRed.blockID, 0, 2);
        world.setBlock(i + 7, j + 11, k + 24, MTJT.mushroomTopRed.blockID, 0, 2);
        world.setBlock(i + 7, j + 11, k + 23, MTJT.mushroomTopRed.blockID, 0, 2);
        world.setBlock(i + 7, j + 11, k + 22, MTJT.mushroomTopRed.blockID, 0, 2);
        world.setBlock(i + 7, j + 11, k + 21, MTJT.mushroomTopRed.blockID, 0, 2);
        world.setBlock(i + 7, j + 11, k + 20, MTJT.mushroomTopRed.blockID, 0, 2);
        world.setBlock(i + 8, j + 11, k + 23, MTJT.mushroomTopRed.blockID, 0, 2);
        world.setBlock(i + 8, j + 11, k + 22, MTJT.mushroomTopRed.blockID, 0, 2);
        world.setBlock(i + 8, j + 11, k + 21, MTJT.mushroomTopRed.blockID, 0, 2);
        world.setBlock(i + 30, j + 11, k + 22, MTJT.mushroomStemmWhite.blockID, 0, 2);
        world.setBlock(i + 31, j + 11, k + 42, MTJT.mushroomStemmWhite.blockID, 0, 2);
        world.setBlock(i + 31, j + 11, k + 9, MTJT.mushroomStemmWhite.blockID, 0, 2);
        world.setBlock(i + 36, j + 11, k + 20, MTJT.mushroomStemmWhite.blockID, 0, 2);
        world.setBlock(i + 38, j + 11, k + 4, MTJT.mushroomStemmWhite.blockID, 0, 2);
        world.setBlock(i + 49, j + 11, k + 22, MTJT.mushroomStemmWhite.blockID, 0, 2);
        world.setBlock(i + 28, j + 12, k + 43, MTJT.mushroomTopRed.blockID, 0, 2);
        world.setBlock(i + 28, j + 12, k + 42, MTJT.mushroomTopRed.blockID, 0, 2);
        world.setBlock(i + 28, j + 12, k + 41, MTJT.mushroomTopRed.blockID, 0, 2);
        world.setBlock(i + 28, j + 12, k + 10, MTJT.mushroomTopRed.blockID, 0, 2);
        world.setBlock(i + 28, j + 12, k + 9, MTJT.mushroomTopRed.blockID, 0, 2);
        world.setBlock(i + 28, j + 12, k + 8, MTJT.mushroomTopRed.blockID, 0, 2);
        world.setBlock(i + 29, j + 12, k + 44, MTJT.mushroomTopRed.blockID, 0, 2);
        world.setBlock(i + 29, j + 12, k + 40, MTJT.mushroomTopRed.blockID, 0, 2);
        world.setBlock(i + 29, j + 12, k + 11, MTJT.mushroomTopRed.blockID, 0, 2);
        world.setBlock(i + 29, j + 12, k + 7, MTJT.mushroomTopRed.blockID, 0, 2);
        world.setBlock(i + 30, j + 12, k + 45, MTJT.mushroomTopRed.blockID, 0, 2);
        world.setBlock(i + 30, j + 12, k + 39, MTJT.mushroomTopRed.blockID, 0, 2);
        world.setBlock(i + 30, j + 12, k + 22, MTJT.mushroomStemmWhite.blockID, 0, 2);
        world.setBlock(i + 30, j + 12, k + 12, MTJT.mushroomTopRed.blockID, 0, 2);
        world.setBlock(i + 30, j + 12, k + 6, MTJT.mushroomTopRed.blockID, 0, 2);
        world.setBlock(i + 31, j + 12, k + 45, MTJT.mushroomTopRed.blockID, 0, 2);
        world.setBlock(i + 31, j + 12, k + 42, MTJT.mushroomStemmWhite.blockID, 0, 2);
        world.setBlock(i + 31, j + 12, k + 39, MTJT.mushroomTopRed.blockID, 0, 2);
        world.setBlock(i + 31, j + 12, k + 12, MTJT.mushroomTopRed.blockID, 0, 2);
        world.setBlock(i + 31, j + 12, k + 9, MTJT.mushroomStemmWhite.blockID, 0, 2);
        world.setBlock(i + 31, j + 12, k + 6, MTJT.mushroomTopRed.blockID, 0, 2);
        world.setBlock(i + 32, j + 12, k + 45, MTJT.mushroomTopRed.blockID, 0, 2);
        world.setBlock(i + 32, j + 12, k + 39, MTJT.mushroomTopRed.blockID, 0, 2);
        world.setBlock(i + 32, j + 12, k + 12, MTJT.mushroomTopRed.blockID, 0, 2);
        world.setBlock(i + 32, j + 12, k + 6, MTJT.mushroomTopRed.blockID, 0, 2);
        world.setBlock(i + 33, j + 12, k + 44, MTJT.mushroomTopRed.blockID, 0, 2);
        world.setBlock(i + 33, j + 12, k + 40, MTJT.mushroomTopRed.blockID, 0, 2);
        world.setBlock(i + 33, j + 12, k + 11, MTJT.mushroomTopRed.blockID, 0, 2);
        world.setBlock(i + 33, j + 12, k + 7, MTJT.mushroomTopRed.blockID, 0, 2);
        world.setBlock(i + 34, j + 12, k + 43, MTJT.mushroomTopRed.blockID, 0, 2);
        world.setBlock(i + 34, j + 12, k + 42, MTJT.mushroomTopRed.blockID, 0, 2);
        world.setBlock(i + 34, j + 12, k + 41, MTJT.mushroomTopRed.blockID, 0, 2);
        world.setBlock(i + 34, j + 12, k + 10, MTJT.mushroomTopRed.blockID, 0, 2);
        world.setBlock(i + 34, j + 12, k + 9, MTJT.mushroomTopRed.blockID, 0, 2);
        world.setBlock(i + 34, j + 12, k + 8, MTJT.mushroomTopRed.blockID, 0, 2);
        world.setBlock(i + 35, j + 12, k + 5, MTJT.mushroomTopRed.blockID, 0, 2);
        world.setBlock(i + 35, j + 12, k + 4, MTJT.mushroomTopRed.blockID, 0, 2);
        world.setBlock(i + 35, j + 12, k + 3, MTJT.mushroomTopRed.blockID, 0, 2);
        world.setBlock(i + 36, j + 12, k + 6, MTJT.mushroomTopRed.blockID, 0, 2);
        world.setBlock(i + 36, j + 12, k + 2, MTJT.mushroomTopRed.blockID, 0, 2);
        world.setBlock(i + 37, j + 12, k + 20, MTJT.mushroomStemmWhite.blockID, 0, 2);
        world.setBlock(i + 37, j + 12, k + 7, MTJT.mushroomTopRed.blockID, 0, 2);
        world.setBlock(i + 37, j + 12, k + 1, MTJT.mushroomTopRed.blockID, 0, 2);
        world.setBlock(i + 38, j + 12, k + 7, MTJT.mushroomTopRed.blockID, 0, 2);
        world.setBlock(i + 38, j + 12, k + 4, MTJT.mushroomStemmWhite.blockID, 0, 2);
        world.setBlock(i + 38, j + 12, k + 1, MTJT.mushroomTopRed.blockID, 0, 2);
        world.setBlock(i + 39, j + 12, k + 7, MTJT.mushroomTopRed.blockID, 0, 2);
        world.setBlock(i + 39, j + 12, k + 1, MTJT.mushroomTopRed.blockID, 0, 2);
        world.setBlock(i + 40, j + 12, k + 6, MTJT.mushroomTopRed.blockID, 0, 2);
        world.setBlock(i + 40, j + 12, k + 2, MTJT.mushroomTopRed.blockID, 0, 2);
        world.setBlock(i + 41, j + 12, k + 5, MTJT.mushroomTopRed.blockID, 0, 2);
        world.setBlock(i + 41, j + 12, k + 4, MTJT.mushroomTopRed.blockID, 0, 2);
        world.setBlock(i + 41, j + 12, k + 3, MTJT.mushroomTopRed.blockID, 0, 2);
        world.setBlock(i + 50, j + 12, k + 23, MTJT.mushroomStemmWhite.blockID, 0, 2);
        world.setBlock(i + 29, j + 13, k + 43, MTJT.mushroomTopRed.blockID, 0, 2);
        world.setBlock(i + 29, j + 13, k + 42, MTJT.mushroomTopRed.blockID, 0, 2);
        world.setBlock(i + 29, j + 13, k + 41, MTJT.mushroomTopRed.blockID, 0, 2);
        world.setBlock(i + 29, j + 13, k + 10, MTJT.mushroomTopRed.blockID, 0, 2);
        world.setBlock(i + 29, j + 13, k + 9, MTJT.mushroomTopRed.blockID, 0, 2);
        world.setBlock(i + 29, j + 13, k + 8, MTJT.mushroomTopRed.blockID, 0, 2);
        world.setBlock(i + 30, j + 13, k + 44, MTJT.mushroomTopRed.blockID, 0, 2);
        world.setBlock(i + 30, j + 13, k + 43, MTJT.mushroomTopRed.blockID, 0, 2);
        world.setBlock(i + 30, j + 13, k + 42, MTJT.mushroomTopRed.blockID, 0, 2);
        world.setBlock(i + 30, j + 13, k + 41, MTJT.mushroomTopRed.blockID, 0, 2);
        world.setBlock(i + 30, j + 13, k + 40, MTJT.mushroomTopRed.blockID, 0, 2);
        world.setBlock(i + 30, j + 13, k + 22, MTJT.mushroomStemmWhite.blockID, 0, 2);
        world.setBlock(i + 30, j + 13, k + 11, MTJT.mushroomTopRed.blockID, 0, 2);
        world.setBlock(i + 30, j + 13, k + 10, MTJT.mushroomTopRed.blockID, 0, 2);
        world.setBlock(i + 30, j + 13, k + 9, MTJT.mushroomTopRed.blockID, 0, 2);
        world.setBlock(i + 30, j + 13, k + 8, MTJT.mushroomTopRed.blockID, 0, 2);
        world.setBlock(i + 30, j + 13, k + 7, MTJT.mushroomTopRed.blockID, 0, 2);
        world.setBlock(i + 31, j + 13, k + 44, MTJT.mushroomTopRed.blockID, 0, 2);
        world.setBlock(i + 31, j + 13, k + 43, MTJT.mushroomTopRed.blockID, 0, 2);
        world.setBlock(i + 31, j + 13, k + 42, MTJT.mushroomTopRed.blockID, 0, 2);
        world.setBlock(i + 31, j + 13, k + 41, MTJT.mushroomTopRed.blockID, 0, 2);
        world.setBlock(i + 31, j + 13, k + 40, MTJT.mushroomTopRed.blockID, 0, 2);
        world.setBlock(i + 31, j + 13, k + 11, MTJT.mushroomTopRed.blockID, 0, 2);
        world.setBlock(i + 31, j + 13, k + 10, MTJT.mushroomTopRed.blockID, 0, 2);
        world.setBlock(i + 31, j + 13, k + 9, MTJT.mushroomTopRed.blockID, 0, 2);
        world.setBlock(i + 31, j + 13, k + 8, MTJT.mushroomTopRed.blockID, 0, 2);
        world.setBlock(i + 31, j + 13, k + 7, MTJT.mushroomTopRed.blockID, 0, 2);
        world.setBlock(i + 32, j + 13, k + 44, MTJT.mushroomTopRed.blockID, 0, 2);
        world.setBlock(i + 32, j + 13, k + 43, MTJT.mushroomTopRed.blockID, 0, 2);
        world.setBlock(i + 32, j + 13, k + 42, MTJT.mushroomTopRed.blockID, 0, 2);
        world.setBlock(i + 32, j + 13, k + 41, MTJT.mushroomTopRed.blockID, 0, 2);
        world.setBlock(i + 32, j + 13, k + 40, MTJT.mushroomTopRed.blockID, 0, 2);
        world.setBlock(i + 32, j + 13, k + 11, MTJT.mushroomTopRed.blockID, 0, 2);
        world.setBlock(i + 32, j + 13, k + 10, MTJT.mushroomTopRed.blockID, 0, 2);
        world.setBlock(i + 32, j + 13, k + 9, MTJT.mushroomTopRed.blockID, 0, 2);
        world.setBlock(i + 32, j + 13, k + 8, MTJT.mushroomTopRed.blockID, 0, 2);
        world.setBlock(i + 32, j + 13, k + 7, MTJT.mushroomTopRed.blockID, 0, 2);
        world.setBlock(i + 33, j + 13, k + 43, MTJT.mushroomTopRed.blockID, 0, 2);
        world.setBlock(i + 33, j + 13, k + 42, MTJT.mushroomTopRed.blockID, 0, 2);
        world.setBlock(i + 33, j + 13, k + 41, MTJT.mushroomTopRed.blockID, 0, 2);
        world.setBlock(i + 33, j + 13, k + 10, MTJT.mushroomTopRed.blockID, 0, 2);
        world.setBlock(i + 33, j + 13, k + 9, MTJT.mushroomTopRed.blockID, 0, 2);
        world.setBlock(i + 33, j + 13, k + 8, MTJT.mushroomTopRed.blockID, 0, 2);
        world.setBlock(i + 36, j + 13, k + 5, MTJT.mushroomTopRed.blockID, 0, 2);
        world.setBlock(i + 36, j + 13, k + 4, MTJT.mushroomTopRed.blockID, 0, 2);
        world.setBlock(i + 36, j + 13, k + 3, MTJT.mushroomTopRed.blockID, 0, 2);
        world.setBlock(i + 37, j + 13, k + 6, MTJT.mushroomTopRed.blockID, 0, 2);
        world.setBlock(i + 37, j + 13, k + 5, MTJT.mushroomTopRed.blockID, 0, 2);
        world.setBlock(i + 37, j + 13, k + 4, MTJT.mushroomTopRed.blockID, 0, 2);
        world.setBlock(i + 37, j + 13, k + 3, MTJT.mushroomTopRed.blockID, 0, 2);
        world.setBlock(i + 37, j + 13, k + 2, MTJT.mushroomTopRed.blockID, 0, 2);
        world.setBlock(i + 38, j + 13, k + 20, MTJT.mushroomStemmWhite.blockID, 0, 2);
        world.setBlock(i + 38, j + 13, k + 6, MTJT.mushroomTopRed.blockID, 0, 2);
        world.setBlock(i + 38, j + 13, k + 5, MTJT.mushroomTopRed.blockID, 0, 2);
        world.setBlock(i + 38, j + 13, k + 4, MTJT.mushroomTopRed.blockID, 0, 2);
        world.setBlock(i + 38, j + 13, k + 3, MTJT.mushroomTopRed.blockID, 0, 2);
        world.setBlock(i + 38, j + 13, k + 2, MTJT.mushroomTopRed.blockID, 0, 2);
        world.setBlock(i + 39, j + 13, k + 6, MTJT.mushroomTopRed.blockID, 0, 2);
        world.setBlock(i + 39, j + 13, k + 5, MTJT.mushroomTopRed.blockID, 0, 2);
        world.setBlock(i + 39, j + 13, k + 4, MTJT.mushroomTopRed.blockID, 0, 2);
        world.setBlock(i + 39, j + 13, k + 3, MTJT.mushroomTopRed.blockID, 0, 2);
        world.setBlock(i + 39, j + 13, k + 2, MTJT.mushroomTopRed.blockID, 0, 2);
        world.setBlock(i + 40, j + 13, k + 5, MTJT.mushroomTopRed.blockID, 0, 2);
        world.setBlock(i + 40, j + 13, k + 4, MTJT.mushroomTopRed.blockID, 0, 2);
        world.setBlock(i + 40, j + 13, k + 3, MTJT.mushroomTopRed.blockID, 0, 2);
        world.setBlock(i + 47, j + 13, k + 24, MTJT.mushroomTopRed.blockID, 0, 2);
        world.setBlock(i + 47, j + 13, k + 23, MTJT.mushroomTopRed.blockID, 0, 2);
        world.setBlock(i + 47, j + 13, k + 22, MTJT.mushroomTopRed.blockID, 0, 2);
        world.setBlock(i + 48, j + 13, k + 25, MTJT.mushroomTopRed.blockID, 0, 2);
        world.setBlock(i + 48, j + 13, k + 21, MTJT.mushroomTopRed.blockID, 0, 2);
        world.setBlock(i + 49, j + 13, k + 26, MTJT.mushroomTopRed.blockID, 0, 2);
        world.setBlock(i + 49, j + 13, k + 20, MTJT.mushroomTopRed.blockID, 0, 2);
        world.setBlock(i + 50, j + 13, k + 26, MTJT.mushroomTopRed.blockID, 0, 2);
        world.setBlock(i + 50, j + 13, k + 23, MTJT.mushroomStemmWhite.blockID, 0, 2);
        world.setBlock(i + 50, j + 13, k + 20, MTJT.mushroomTopRed.blockID, 0, 2);
        world.setBlock(i + 51, j + 13, k + 26, MTJT.mushroomTopRed.blockID, 0, 2);
        world.setBlock(i + 51, j + 13, k + 20, MTJT.mushroomTopRed.blockID, 0, 2);
        world.setBlock(i + 52, j + 13, k + 25, MTJT.mushroomTopRed.blockID, 0, 2);
        world.setBlock(i + 52, j + 13, k + 21, MTJT.mushroomTopRed.blockID, 0, 2);
        world.setBlock(i + 53, j + 13, k + 24, MTJT.mushroomTopRed.blockID, 0, 2);
        world.setBlock(i + 53, j + 13, k + 23, MTJT.mushroomTopRed.blockID, 0, 2);
        world.setBlock(i + 53, j + 13, k + 22, MTJT.mushroomTopRed.blockID, 0, 2);
        world.setBlock(i + 29, j + 14, k + 22, MTJT.mushroomStemmWhite.blockID, 0, 2);
        world.setBlock(i + 39, j + 14, k + 20, MTJT.mushroomStemmWhite.blockID, 0, 2);
        world.setBlock(i + 48, j + 14, k + 24, MTJT.mushroomTopRed.blockID, 0, 2);
        world.setBlock(i + 48, j + 14, k + 23, MTJT.mushroomTopRed.blockID, 0, 2);
        world.setBlock(i + 48, j + 14, k + 22, MTJT.mushroomTopRed.blockID, 0, 2);
        world.setBlock(i + 49, j + 14, k + 25, MTJT.mushroomTopRed.blockID, 0, 2);
        world.setBlock(i + 49, j + 14, k + 24, MTJT.mushroomTopRed.blockID, 0, 2);
        world.setBlock(i + 49, j + 14, k + 23, MTJT.mushroomTopRed.blockID, 0, 2);
        world.setBlock(i + 49, j + 14, k + 22, MTJT.mushroomTopRed.blockID, 0, 2);
        world.setBlock(i + 49, j + 14, k + 21, MTJT.mushroomTopRed.blockID, 0, 2);
        world.setBlock(i + 50, j + 14, k + 25, MTJT.mushroomTopRed.blockID, 0, 2);
        world.setBlock(i + 50, j + 14, k + 24, MTJT.mushroomTopRed.blockID, 0, 2);
        world.setBlock(i + 50, j + 14, k + 23, MTJT.mushroomTopRed.blockID, 0, 2);
        world.setBlock(i + 50, j + 14, k + 22, MTJT.mushroomTopRed.blockID, 0, 2);
        world.setBlock(i + 50, j + 14, k + 21, MTJT.mushroomTopRed.blockID, 0, 2);
        world.setBlock(i + 51, j + 14, k + 25, MTJT.mushroomTopRed.blockID, 0, 2);
        world.setBlock(i + 51, j + 14, k + 24, MTJT.mushroomTopRed.blockID, 0, 2);
        world.setBlock(i + 51, j + 14, k + 23, MTJT.mushroomTopRed.blockID, 0, 2);
        world.setBlock(i + 51, j + 14, k + 22, MTJT.mushroomTopRed.blockID, 0, 2);
        world.setBlock(i + 51, j + 14, k + 21, MTJT.mushroomTopRed.blockID, 0, 2);
        world.setBlock(i + 52, j + 14, k + 24, MTJT.mushroomTopRed.blockID, 0, 2);
        world.setBlock(i + 52, j + 14, k + 23, MTJT.mushroomTopRed.blockID, 0, 2);
        world.setBlock(i + 52, j + 14, k + 22, MTJT.mushroomTopRed.blockID, 0, 2);
        world.setBlock(i + 29, j + 15, k + 23, MTJT.mushroomStemmWhite.blockID, 0, 2);
        world.setBlock(i + 40, j + 15, k + 20, MTJT.mushroomStemmWhite.blockID, 0, 2);
        world.setBlock(i + 29, j + 16, k + 23, MTJT.mushroomStemmWhite.blockID, 0, 2);
        world.setBlock(i + 37, j + 16, k + 21, MTJT.mushroomTopRed.blockID, 0, 2);
        world.setBlock(i + 37, j + 16, k + 20, MTJT.mushroomTopRed.blockID, 0, 2);
        world.setBlock(i + 37, j + 16, k + 19, MTJT.mushroomTopRed.blockID, 0, 2);
        world.setBlock(i + 38, j + 16, k + 22, MTJT.mushroomTopRed.blockID, 0, 2);
        world.setBlock(i + 38, j + 16, k + 18, MTJT.mushroomTopRed.blockID, 0, 2);
        world.setBlock(i + 39, j + 16, k + 23, MTJT.mushroomTopRed.blockID, 0, 2);
        world.setBlock(i + 39, j + 16, k + 17, MTJT.mushroomTopRed.blockID, 0, 2);
        world.setBlock(i + 40, j + 16, k + 23, MTJT.mushroomTopRed.blockID, 0, 2);
        world.setBlock(i + 40, j + 16, k + 20, MTJT.mushroomStemmWhite.blockID, 0, 2);
        world.setBlock(i + 40, j + 16, k + 17, MTJT.mushroomTopRed.blockID, 0, 2);
        world.setBlock(i + 41, j + 16, k + 23, MTJT.mushroomTopRed.blockID, 0, 2);
        world.setBlock(i + 41, j + 16, k + 17, MTJT.mushroomTopRed.blockID, 0, 2);
        world.setBlock(i + 42, j + 16, k + 22, MTJT.mushroomTopRed.blockID, 0, 2);
        world.setBlock(i + 42, j + 16, k + 18, MTJT.mushroomTopRed.blockID, 0, 2);
        world.setBlock(i + 43, j + 16, k + 21, MTJT.mushroomTopRed.blockID, 0, 2);
        world.setBlock(i + 43, j + 16, k + 20, MTJT.mushroomTopRed.blockID, 0, 2);
        world.setBlock(i + 43, j + 16, k + 19, MTJT.mushroomTopRed.blockID, 0, 2);
        world.setBlock(i + 29, j + 17, k + 24, MTJT.mushroomStemmWhite.blockID, 0, 2);
        world.setBlock(i + 38, j + 17, k + 21, MTJT.mushroomTopRed.blockID, 0, 2);
        world.setBlock(i + 38, j + 17, k + 20, MTJT.mushroomTopRed.blockID, 0, 2);
        world.setBlock(i + 38, j + 17, k + 19, MTJT.mushroomTopRed.blockID, 0, 2);
        world.setBlock(i + 39, j + 17, k + 22, MTJT.mushroomTopRed.blockID, 0, 2);
        world.setBlock(i + 39, j + 17, k + 21, MTJT.mushroomTopRed.blockID, 0, 2);
        world.setBlock(i + 39, j + 17, k + 20, MTJT.mushroomTopRed.blockID, 0, 2);
        world.setBlock(i + 39, j + 17, k + 19, MTJT.mushroomTopRed.blockID, 0, 2);
        world.setBlock(i + 39, j + 17, k + 18, MTJT.mushroomTopRed.blockID, 0, 2);
        world.setBlock(i + 40, j + 17, k + 22, MTJT.mushroomTopRed.blockID, 0, 2);
        world.setBlock(i + 40, j + 17, k + 21, MTJT.mushroomTopRed.blockID, 0, 2);
        world.setBlock(i + 40, j + 17, k + 20, MTJT.mushroomTopRed.blockID, 0, 2);
        world.setBlock(i + 40, j + 17, k + 19, MTJT.mushroomTopRed.blockID, 0, 2);
        world.setBlock(i + 40, j + 17, k + 18, MTJT.mushroomTopRed.blockID, 0, 2);
        world.setBlock(i + 41, j + 17, k + 22, MTJT.mushroomTopRed.blockID, 0, 2);
        world.setBlock(i + 41, j + 17, k + 21, MTJT.mushroomTopRed.blockID, 0, 2);
        world.setBlock(i + 41, j + 17, k + 20, MTJT.mushroomTopRed.blockID, 0, 2);
        world.setBlock(i + 41, j + 17, k + 19, MTJT.mushroomTopRed.blockID, 0, 2);
        world.setBlock(i + 41, j + 17, k + 18, MTJT.mushroomTopRed.blockID, 0, 2);
        world.setBlock(i + 42, j + 17, k + 21, MTJT.mushroomTopRed.blockID, 0, 2);
        world.setBlock(i + 42, j + 17, k + 20, MTJT.mushroomTopRed.blockID, 0, 2);
        world.setBlock(i + 42, j + 17, k + 19, MTJT.mushroomTopRed.blockID, 0, 2);
        world.setBlock(i + 29, j + 18, k + 24, MTJT.mushroomStemmWhite.blockID, 0, 2);
        world.setBlock(i + 29, j + 19, k + 25, MTJT.mushroomStemmWhite.blockID, 0, 2);
        world.setBlock(i + 29, j + 20, k + 25, MTJT.mushroomStemmWhite.blockID, 0, 2);
        world.setBlock(i + 29, j + 21, k + 26, MTJT.mushroomStemmWhite.blockID, 0, 2);
        world.setBlock(i + 26, j + 22, k + 27, MTJT.mushroomTopRed.blockID, 0, 2);
        world.setBlock(i + 26, j + 22, k + 26, MTJT.mushroomTopRed.blockID, 0, 2);
        world.setBlock(i + 26, j + 22, k + 25, MTJT.mushroomTopRed.blockID, 0, 2);
        world.setBlock(i + 27, j + 22, k + 28, MTJT.mushroomTopRed.blockID, 0, 2);
        world.setBlock(i + 27, j + 22, k + 24, MTJT.mushroomTopRed.blockID, 0, 2);
        world.setBlock(i + 28, j + 22, k + 29, MTJT.mushroomTopRed.blockID, 0, 2);
        world.setBlock(i + 28, j + 22, k + 23, MTJT.mushroomTopRed.blockID, 0, 2);
        world.setBlock(i + 29, j + 22, k + 29, MTJT.mushroomTopRed.blockID, 0, 2);
        world.setBlock(i + 29, j + 22, k + 26, MTJT.mushroomStemmWhite.blockID, 0, 2);
        world.setBlock(i + 29, j + 22, k + 23, MTJT.mushroomTopRed.blockID, 0, 2);
        world.setBlock(i + 30, j + 22, k + 29, MTJT.mushroomTopRed.blockID, 0, 2);
        world.setBlock(i + 30, j + 22, k + 23, MTJT.mushroomTopRed.blockID, 0, 2);
        world.setBlock(i + 31, j + 22, k + 28, MTJT.mushroomTopRed.blockID, 0, 2);
        world.setBlock(i + 31, j + 22, k + 24, MTJT.mushroomTopRed.blockID, 0, 2);
        world.setBlock(i + 32, j + 22, k + 27, MTJT.mushroomTopRed.blockID, 0, 2);
        world.setBlock(i + 32, j + 22, k + 26, MTJT.mushroomTopRed.blockID, 0, 2);
        world.setBlock(i + 32, j + 22, k + 25, MTJT.mushroomTopRed.blockID, 0, 2);
        world.setBlock(i + 27, j + 23, k + 27, MTJT.mushroomTopRed.blockID, 0, 2);
        world.setBlock(i + 27, j + 23, k + 26, MTJT.mushroomTopRed.blockID, 0, 2);
        world.setBlock(i + 27, j + 23, k + 25, MTJT.mushroomTopRed.blockID, 0, 2);
        world.setBlock(i + 28, j + 23, k + 28, MTJT.mushroomTopRed.blockID, 0, 2);
        world.setBlock(i + 28, j + 23, k + 27, MTJT.mushroomTopRed.blockID, 0, 2);
        world.setBlock(i + 28, j + 23, k + 26, MTJT.mushroomTopRed.blockID, 0, 2);
        world.setBlock(i + 28, j + 23, k + 25, MTJT.mushroomTopRed.blockID, 0, 2);
        world.setBlock(i + 28, j + 23, k + 24, MTJT.mushroomTopRed.blockID, 0, 2);
        world.setBlock(i + 29, j + 23, k + 28, MTJT.mushroomTopRed.blockID, 0, 2);
        world.setBlock(i + 29, j + 23, k + 27, MTJT.mushroomTopRed.blockID, 0, 2);
        world.setBlock(i + 29, j + 23, k + 26, MTJT.mushroomTopRed.blockID, 0, 2);
        world.setBlock(i + 29, j + 23, k + 25, MTJT.mushroomTopRed.blockID, 0, 2);
        world.setBlock(i + 29, j + 23, k + 24, MTJT.mushroomTopRed.blockID, 0, 2);
        world.setBlock(i + 30, j + 23, k + 28, MTJT.mushroomTopRed.blockID, 0, 2);
        world.setBlock(i + 30, j + 23, k + 27, MTJT.mushroomTopRed.blockID, 0, 2);
        world.setBlock(i + 30, j + 23, k + 26, MTJT.mushroomTopRed.blockID, 0, 2);
        world.setBlock(i + 30, j + 23, k + 25, MTJT.mushroomTopRed.blockID, 0, 2);
        world.setBlock(i + 30, j + 23, k + 24, MTJT.mushroomTopRed.blockID, 0, 2);
        world.setBlock(i + 31, j + 23, k + 27, MTJT.mushroomTopRed.blockID, 0, 2);
        world.setBlock(i + 31, j + 23, k + 26, MTJT.mushroomTopRed.blockID, 0, 2);
        world.setBlock(i + 31, j + 23, k + 25, MTJT.mushroomTopRed.blockID, 0, 2);

return true;
}
}