package morethantrees.treegen;

import java.util.Random;

import morethantrees.MTJT;
import net.minecraft.block.Block;
import net.minecraft.world.World;
import net.minecraft.world.gen.feature.WorldGenerator;

public class WorldGenBlackTrees extends WorldGenerator
{
	
	public boolean generate(World world, Random var2, int i, int j, int k)
	  {
	    while ((world.isAirBlock(i + 10, j, k + 12)) && (j > 2))
	    {
	      j--;
	    }

	    int var6 = world.getBlockId(i + 10, j, k + 12);

	    if (var6 != Block.grass.blockID && var6 != Block.dirt.blockID && var6 != Block.stone.blockID)
	    {
	      return false;
	    }

	    for (int var7 = -2; var7 <= 2; var7++)
	    {
	      for (int var8 = -2; var8 <= 2; var8++)
	      {
	        if ((world.isAirBlock(i + var7 + 10, j - 1, k + var8 + 12)) && (world.isAirBlock(i + var7 + 10, j - 2, k + var8 + 12)))
	        {
	          return false;
	        }
	      }
	    }
    	world.setBlock(i + 5, j + 0, k + 13, MTJT.blackLog.blockID, 0, 2);
        world.setBlock(i + 6, j + 0, k + 12, MTJT.blackLog.blockID, 0, 2);
        world.setBlock(i + 7, j + 0, k + 13, MTJT.blackLog.blockID, 0, 2);
        world.setBlock(i + 7, j + 0, k + 12, MTJT.blackLog.blockID, 0, 2);
        world.setBlock(i + 7, j + 0, k + 11, MTJT.blackLog.blockID, 0, 2);
        world.setBlock(i + 8, j + 0, k + 12, MTJT.blackLog.blockID, 0, 2);
        world.setBlock(i + 6, j + 1, k + 12, MTJT.blackLog.blockID, 0, 2);
        world.setBlock(i + 7, j + 1, k + 12, MTJT.blackLog.blockID, 0, 2);
        world.setBlock(i + 7, j + 2, k + 12, MTJT.blackLog.blockID, 0, 2);
        world.setBlock(i + 7, j + 3, k + 12, MTJT.blackLog.blockID, 0, 2);
        world.setBlock(i + 7, j + 4, k + 11, MTJT.blackLog.blockID, 0, 2);
        world.setBlock(i + 7, j + 5, k + 11, MTJT.blackLog.blockID, 0, 2);
        world.setBlock(i + 7, j + 6, k + 11, MTJT.blackLog.blockID, 0, 2);
        world.setBlock(i + 6, j + 7, k + 10, MTJT.blackLog.blockID, 0, 2);
        world.setBlock(i + 5, j + 8, k + 11, MTJT.blackLog.blockID, 0, 2);
        world.setBlock(i + 5, j + 8, k + 4, MTJT.blackLeaves.blockID, 0, 2);
        world.setBlock(i + 6, j + 8, k + 10, MTJT.blackLog.blockID, 0, 2);
        world.setBlock(i + 6, j + 8, k + 9, MTJT.blackLog.blockID, 0, 2);
        world.setBlock(i + 6, j + 8, k + 5, MTJT.blackLeaves.blockID, 0, 2);
        world.setBlock(i + 4, j + 9, k + 12, MTJT.blackLog.blockID, 0, 2);
        world.setBlock(i + 4, j + 9, k + 4, MTJT.blackLeaves.blockID, 0, 2);
        world.setBlock(i + 6, j + 9, k + 10, MTJT.blackLog.blockID, 0, 2);
        world.setBlock(i + 7, j + 9, k + 8, MTJT.blackLog.blockID, 0, 2);
        world.setBlock(i + 8, j + 9, k + 5, MTJT.blackLeaves.blockID, 0, 2);
        world.setBlock(i + 9, j + 9, k + 2, MTJT.blackLeaves.blockID, 0, 2);
        world.setBlock(i + 4, j + 10, k + 12, MTJT.blackLog.blockID, 0, 2);
        world.setBlock(i + 4, j + 10, k + 7, MTJT.blackLeaves.blockID, 0, 2);
        world.setBlock(i + 5, j + 10, k + 9, MTJT.blackLog.blockID, 0, 2);
        world.setBlock(i + 6, j + 10, k + 2, MTJT.blackLeaves.blockID, 0, 2);
        world.setBlock(i + 7, j + 10, k + 7, MTJT.blackLog.blockID, 0, 2);
        world.setBlock(i + 7, j + 10, k + 6, MTJT.blackLog.blockID, 0, 2);
        world.setBlock(i + 8, j + 10, k + 5, MTJT.blackLeaves.blockID, 0, 2);
        world.setBlock(i + 8, j + 10, k + 3, MTJT.blackLeaves.blockID, 0, 2);
        world.setBlock(i + 9, j + 10, k + 3, MTJT.blackLeaves.blockID, 0, 2);
        world.setBlock(i + 11, j + 10, k + 4, MTJT.blackLeaves.blockID, 0, 2);
        world.setBlock(i + 3, j + 11, k + 12, MTJT.blackLog.blockID, 0, 2);
        world.setBlock(i + 4, j + 11, k + 6, MTJT.blackLeaves.blockID, 0, 2);
        world.setBlock(i + 4, j + 11, k + 4, MTJT.blackLeaves.blockID, 0, 2);
        world.setBlock(i + 5, j + 11, k + 13, MTJT.blackLog.blockID, 0, 2);
        world.setBlock(i + 5, j + 11, k + 9, MTJT.blackLog.blockID, 0, 2);
        world.setBlock(i + 5, j + 11, k + 5, MTJT.blackLeaves.blockID, 0, 2);
        world.setBlock(i + 5, j + 11, k + 4, MTJT.blackLeaves.blockID, 0, 2);
        world.setBlock(i + 6, j + 11, k + 6, MTJT.blackLeaves.blockID, 0, 2);
        world.setBlock(i + 6, j + 11, k + 5, MTJT.blackLog.blockID, 0, 2);
        world.setBlock(i + 6, j + 11, k + 4, MTJT.blackLeaves.blockID, 0, 2);
        world.setBlock(i + 6, j + 11, k + 3, MTJT.blackLeaves.blockID, 0, 2);
        world.setBlock(i + 6, j + 11, k + 2, MTJT.blackLeaves.blockID, 0, 2);
        world.setBlock(i + 7, j + 11, k + 4, MTJT.blackLeaves.blockID, 0, 2);
        world.setBlock(i + 8, j + 11, k + 5, MTJT.blackLog.blockID, 0, 2);
        world.setBlock(i + 8, j + 11, k + 4, MTJT.blackLog.blockID, 0, 2);
        world.setBlock(i + 8, j + 11, k + 0, MTJT.blackLeaves.blockID, 0, 2);
        world.setBlock(i + 9, j + 11, k + 5, MTJT.blackLeaves.blockID, 0, 2);
        world.setBlock(i + 11, j + 11, k + 3, MTJT.blackLeaves.blockID, 0, 2);
        world.setBlock(i + 3, j + 12, k + 12, MTJT.blackLog.blockID, 0, 2);
        world.setBlock(i + 3, j + 12, k + 6, MTJT.blackLeaves.blockID, 0, 2);
        world.setBlock(i + 3, j + 12, k + 4, MTJT.blackLeaves.blockID, 0, 2);
        world.setBlock(i + 4, j + 12, k + 8, MTJT.blackLog.blockID, 0, 2);
        world.setBlock(i + 5, j + 12, k + 13, MTJT.blackLog.blockID, 0, 2);
        world.setBlock(i + 5, j + 12, k + 10, MTJT.blackLog.blockID, 0, 2);
        world.setBlock(i + 5, j + 12, k + 4, MTJT.blackLeaves.blockID, 0, 2);
        world.setBlock(i + 6, j + 12, k + 9, MTJT.blackLog.blockID, 0, 2);
        world.setBlock(i + 6, j + 12, k + 6, MTJT.blackLeaves.blockID, 0, 2);
        world.setBlock(i + 6, j + 12, k + 5, MTJT.blackLeaves.blockID, 0, 2);
        world.setBlock(i + 6, j + 12, k + 3, MTJT.blackLeaves.blockID, 0, 2);
        world.setBlock(i + 6, j + 12, k + 2, MTJT.blackLeaves.blockID, 0, 2);
        world.setBlock(i + 7, j + 12, k + 7, MTJT.blackLeaves.blockID, 0, 2);
        world.setBlock(i + 7, j + 12, k + 3, MTJT.blackLeaves.blockID, 0, 2);
        world.setBlock(i + 8, j + 12, k + 5, MTJT.blackLeaves.blockID, 0, 2);
        world.setBlock(i + 9, j + 12, k + 5, MTJT.blackLeaves.blockID, 0, 2);
        world.setBlock(i + 9, j + 12, k + 3, MTJT.blackLog.blockID, 0, 2);
        world.setBlock(i + 9, j + 12, k + 1, MTJT.blackLeaves.blockID, 0, 2);
        world.setBlock(i + 9, j + 12, k + 0, MTJT.blackLeaves.blockID, 0, 2);
        world.setBlock(i + 10, j + 12, k + 6, MTJT.blackLeaves.blockID, 0, 2);
        world.setBlock(i + 10, j + 12, k + 5, MTJT.blackLeaves.blockID, 0, 2);
        world.setBlock(i + 11, j + 12, k + 1, MTJT.blackLeaves.blockID, 0, 2);
        world.setBlock(i + 1, j + 13, k + 9, MTJT.blackLeaves.blockID, 0, 2);
        world.setBlock(i + 1, j + 13, k + 7, MTJT.blackLeaves.blockID, 0, 2);
        world.setBlock(i + 2, j + 13, k + 11, MTJT.blackLog.blockID, 0, 2);
        world.setBlock(i + 3, j + 13, k + 9, MTJT.blackLeaves.blockID, 0, 2);
        world.setBlock(i + 3, j + 13, k + 6, MTJT.blackLeaves.blockID, 0, 2);
        world.setBlock(i + 4, j + 13, k + 10, MTJT.blackLeaves.blockID, 0, 2);
        world.setBlock(i + 4, j + 13, k + 8, MTJT.blackLog.blockID, 0, 2);
        world.setBlock(i + 4, j + 13, k + 6, MTJT.blackLeaves.blockID, 0, 2);
        world.setBlock(i + 4, j + 13, k + 3, MTJT.blackLeaves.blockID, 0, 2);
        world.setBlock(i + 5, j + 13, k + 14, MTJT.blackLog.blockID, 0, 2);
        world.setBlock(i + 6, j + 13, k + 19, MTJT.blackLeaves.blockID, 0, 2);
        world.setBlock(i + 6, j + 13, k + 18, MTJT.blackLeaves.blockID, 0, 2);
        world.setBlock(i + 6, j + 13, k + 16, MTJT.blackLeaves.blockID, 0, 2);
        world.setBlock(i + 6, j + 13, k + 14, MTJT.blackLeaves.blockID, 0, 2);
        world.setBlock(i + 6, j + 13, k + 11, MTJT.blackLog.blockID, 0, 2);
        world.setBlock(i + 6, j + 13, k + 3, MTJT.blackLeaves.blockID, 0, 2);
        world.setBlock(i + 7, j + 13, k + 8, MTJT.blackLog.blockID, 0, 2);
        world.setBlock(i + 7, j + 13, k + 5, MTJT.blackLeaves.blockID, 0, 2);
        world.setBlock(i + 9, j + 13, k + 3, MTJT.blackLeaves.blockID, 0, 2);
        world.setBlock(i + 9, j + 13, k + 2, MTJT.blackLeaves.blockID, 0, 2);
        world.setBlock(i + 10, j + 13, k + 5, MTJT.blackLeaves.blockID, 0, 2);
        world.setBlock(i + 10, j + 13, k + 3, MTJT.blackLeaves.blockID, 0, 2);
        world.setBlock(i + 11, j + 13, k + 2, MTJT.blackLeaves.blockID, 0, 2);
        world.setBlock(i + 0, j + 14, k + 9, MTJT.blackLeaves.blockID, 0, 2);
        world.setBlock(i + 1, j + 14, k + 11, MTJT.blackLog.blockID, 0, 2);
        world.setBlock(i + 1, j + 14, k + 9, MTJT.blackLeaves.blockID, 0, 2);
        world.setBlock(i + 1, j + 14, k + 7, MTJT.blackLeaves.blockID, 0, 2);
        world.setBlock(i + 1, j + 14, k + 6, MTJT.blackLeaves.blockID, 0, 2);
        world.setBlock(i + 1, j + 14, k + 4, MTJT.blackLeaves.blockID, 0, 2);
        world.setBlock(i + 2, j + 14, k + 9, MTJT.blackLeaves.blockID, 0, 2);
        world.setBlock(i + 2, j + 14, k + 7, MTJT.blackLeaves.blockID, 0, 2);
        world.setBlock(i + 3, j + 14, k + 12, MTJT.blackLeaves.blockID, 0, 2);
        world.setBlock(i + 3, j + 14, k + 9, MTJT.blackLog.blockID, 0, 2);
        world.setBlock(i + 3, j + 14, k + 6, MTJT.blackLeaves.blockID, 0, 2);
        world.setBlock(i + 3, j + 14, k + 4, MTJT.blackLeaves.blockID, 0, 2);
        world.setBlock(i + 4, j + 14, k + 15, MTJT.blackLog.blockID, 0, 2);
        world.setBlock(i + 4, j + 14, k + 13, MTJT.blackLeaves.blockID, 0, 2);
        world.setBlock(i + 4, j + 14, k + 7, MTJT.blackLog.blockID, 0, 2);
        world.setBlock(i + 5, j + 14, k + 18, MTJT.blackLeaves.blockID, 0, 2);
        world.setBlock(i + 5, j + 14, k + 16, MTJT.blackLeaves.blockID, 0, 2);
        world.setBlock(i + 5, j + 14, k + 7, MTJT.blackLeaves.blockID, 0, 2);
        world.setBlock(i + 6, j + 14, k + 18, MTJT.blackLeaves.blockID, 0, 2);
        world.setBlock(i + 6, j + 14, k + 17, MTJT.blackLeaves.blockID, 0, 2);
        world.setBlock(i + 6, j + 14, k + 16, MTJT.blackLeaves.blockID, 0, 2);
        world.setBlock(i + 6, j + 14, k + 12, MTJT.blackLog.blockID, 0, 2);
        world.setBlock(i + 6, j + 14, k + 5, MTJT.blackLeaves.blockID, 0, 2);
        world.setBlock(i + 7, j + 14, k + 20, MTJT.blackLeaves.blockID, 0, 2);
        world.setBlock(i + 7, j + 14, k + 18, MTJT.blackLeaves.blockID, 0, 2);
        world.setBlock(i + 7, j + 14, k + 11, MTJT.blackLeaves.blockID, 0, 2);
        world.setBlock(i + 7, j + 14, k + 9, MTJT.blackLeaves.blockID, 0, 2);
        world.setBlock(i + 7, j + 14, k + 8, MTJT.blackLog.blockID, 0, 2);
        world.setBlock(i + 7, j + 14, k + 6, MTJT.blackLeaves.blockID, 0, 2);
        world.setBlock(i + 8, j + 14, k + 19, MTJT.blackLeaves.blockID, 0, 2);
        world.setBlock(i + 8, j + 14, k + 1, MTJT.blackLeaves.blockID, 0, 2);
        world.setBlock(i + 9, j + 14, k + 9, MTJT.blackLeaves.blockID, 0, 2);
        world.setBlock(i + 10, j + 14, k + 3, MTJT.blackLeaves.blockID, 0, 2);
        world.setBlock(i + 11, j + 14, k + 2, MTJT.blackLeaves.blockID, 0, 2);
        world.setBlock(i + 1, j + 15, k + 11, MTJT.blackLeaves.blockID, 0, 2);
        world.setBlock(i + 2, j + 15, k + 9, MTJT.blackLeaves.blockID, 0, 2);
        world.setBlock(i + 2, j + 15, k + 4, MTJT.blackLeaves.blockID, 0, 2);
        world.setBlock(i + 3, j + 15, k + 14, MTJT.blackLeaves.blockID, 0, 2);
        world.setBlock(i + 3, j + 15, k + 13, MTJT.blackLeaves.blockID, 0, 2);
        world.setBlock(i + 3, j + 15, k + 12, MTJT.blackLeaves.blockID, 0, 2);
        world.setBlock(i + 3, j + 15, k + 9, MTJT.blackLog.blockID, 0, 2);
        world.setBlock(i + 3, j + 15, k + 8, MTJT.blackLeaves.blockID, 0, 2);
        world.setBlock(i + 3, j + 15, k + 6, MTJT.blackLog.blockID, 0, 2);
        world.setBlock(i + 3, j + 15, k + 4, MTJT.blackLeaves.blockID, 0, 2);
        world.setBlock(i + 4, j + 15, k + 12, MTJT.blackLeaves.blockID, 0, 2);
        world.setBlock(i + 4, j + 15, k + 10, MTJT.blackLeaves.blockID, 0, 2);
        world.setBlock(i + 5, j + 15, k + 20, MTJT.blackLeaves.blockID, 0, 2);
        world.setBlock(i + 5, j + 15, k + 14, MTJT.blackLeaves.blockID, 0, 2);
        world.setBlock(i + 5, j + 15, k + 7, MTJT.blackLeaves.blockID, 0, 2);
        world.setBlock(i + 5, j + 15, k + 6, MTJT.blackLog.blockID, 0, 2);
        world.setBlock(i + 6, j + 15, k + 17, MTJT.blackLeaves.blockID, 0, 2);
        world.setBlock(i + 6, j + 15, k + 15, MTJT.blackLeaves.blockID, 0, 2);
        world.setBlock(i + 6, j + 15, k + 14, MTJT.blackLog.blockID, 0, 2);
        world.setBlock(i + 6, j + 15, k + 13, MTJT.blackLog.blockID, 0, 2);
        world.setBlock(i + 6, j + 15, k + 5, MTJT.blackLeaves.blockID, 0, 2);
        world.setBlock(i + 7, j + 15, k + 18, MTJT.blackLeaves.blockID, 0, 2);
        world.setBlock(i + 7, j + 15, k + 16, MTJT.blackLeaves.blockID, 0, 2);
        world.setBlock(i + 7, j + 15, k + 14, MTJT.blackLeaves.blockID, 0, 2);
        world.setBlock(i + 7, j + 15, k + 11, MTJT.blackLeaves.blockID, 0, 2);
        world.setBlock(i + 7, j + 15, k + 9, MTJT.blackLeaves.blockID, 0, 2);
        world.setBlock(i + 7, j + 15, k + 7, MTJT.blackLog.blockID, 0, 2);
        world.setBlock(i + 7, j + 15, k + 5, MTJT.blackLeaves.blockID, 0, 2);
        world.setBlock(i + 8, j + 15, k + 18, MTJT.blackLeaves.blockID, 0, 2);
        world.setBlock(i + 8, j + 15, k + 9, MTJT.blackLog.blockID, 0, 2);
        world.setBlock(i + 9, j + 15, k + 17, MTJT.blackLeaves.blockID, 0, 2);
        world.setBlock(i + 9, j + 15, k + 13, MTJT.blackLeaves.blockID, 0, 2);
        world.setBlock(i + 9, j + 15, k + 11, MTJT.blackLeaves.blockID, 0, 2);
        world.setBlock(i + 9, j + 15, k + 7, MTJT.blackLeaves.blockID, 0, 2);
        world.setBlock(i + 9, j + 15, k + 3, MTJT.blackLeaves.blockID, 0, 2);
        world.setBlock(i + 10, j + 15, k + 2, MTJT.blackLeaves.blockID, 0, 2);
        world.setBlock(i + 0, j + 16, k + 8, MTJT.blackLeaves.blockID, 0, 2);
        world.setBlock(i + 0, j + 16, k + 6, MTJT.blackLeaves.blockID, 0, 2);
        world.setBlock(i + 1, j + 16, k + 11, MTJT.blackLeaves.blockID, 0, 2);
        world.setBlock(i + 1, j + 16, k + 8, MTJT.blackLeaves.blockID, 0, 2);
        world.setBlock(i + 2, j + 16, k + 8, MTJT.blackLeaves.blockID, 0, 2);
        world.setBlock(i + 2, j + 16, k + 4, MTJT.blackLeaves.blockID, 0, 2);
        world.setBlock(i + 3, j + 16, k + 9, MTJT.blackLeaves.blockID, 0, 2);
        world.setBlock(i + 3, j + 16, k + 7, MTJT.blackLeaves.blockID, 0, 2);
        world.setBlock(i + 3, j + 16, k + 6, MTJT.blackLog.blockID, 0, 2);
        world.setBlock(i + 3, j + 16, k + 5, MTJT.blackLeaves.blockID, 0, 2);
        world.setBlock(i + 4, j + 16, k + 19, MTJT.blackLeaves.blockID, 0, 2);
        world.setBlock(i + 4, j + 16, k + 16, MTJT.blackLeaves.blockID, 0, 2);
        world.setBlock(i + 4, j + 16, k + 14, MTJT.blackLeaves.blockID, 0, 2);
        world.setBlock(i + 4, j + 16, k + 13, MTJT.blackLeaves.blockID, 0, 2);
        world.setBlock(i + 4, j + 16, k + 8, MTJT.blackLeaves.blockID, 0, 2);
        world.setBlock(i + 5, j + 16, k + 17, MTJT.blackLeaves.blockID, 0, 2);
        world.setBlock(i + 5, j + 16, k + 15, MTJT.blackLeaves.blockID, 0, 2);
        world.setBlock(i + 5, j + 16, k + 7, MTJT.blackLeaves.blockID, 0, 2);
        world.setBlock(i + 5, j + 16, k + 5, MTJT.blackLog.blockID, 0, 2);
        world.setBlock(i + 5, j + 16, k + 4, MTJT.blackLeaves.blockID, 0, 2);
        world.setBlock(i + 6, j + 16, k + 21, MTJT.blackLeaves.blockID, 0, 2);
        world.setBlock(i + 6, j + 16, k + 18, MTJT.blackLog.blockID, 0, 2);
        world.setBlock(i + 6, j + 16, k + 15, MTJT.blackLeaves.blockID, 0, 2);
        world.setBlock(i + 6, j + 16, k + 12, MTJT.blackLeaves.blockID, 0, 2);
        world.setBlock(i + 6, j + 16, k + 11, MTJT.blackLeaves.blockID, 0, 2);
        world.setBlock(i + 6, j + 16, k + 10, MTJT.blackLeaves.blockID, 0, 2);
        world.setBlock(i + 6, j + 16, k + 2, MTJT.blackLeaves.blockID, 0, 2);
        world.setBlock(i + 7, j + 16, k + 21, MTJT.blackLeaves.blockID, 0, 2);
        world.setBlock(i + 7, j + 16, k + 15, MTJT.blackLog.blockID, 0, 2);
        world.setBlock(i + 7, j + 16, k + 13, MTJT.blackLeaves.blockID, 0, 2);
        world.setBlock(i + 7, j + 16, k + 12, MTJT.blackLeaves.blockID, 0, 2);
        world.setBlock(i + 7, j + 16, k + 9, MTJT.blackLeaves.blockID, 0, 2);
        world.setBlock(i + 7, j + 16, k + 8, MTJT.blackLeaves.blockID, 0, 2);
        world.setBlock(i + 7, j + 16, k + 5, MTJT.blackLeaves.blockID, 0, 2);
        world.setBlock(i + 8, j + 16, k + 18, MTJT.blackLeaves.blockID, 0, 2);
        world.setBlock(i + 8, j + 16, k + 15, MTJT.blackLeaves.blockID, 0, 2);
        world.setBlock(i + 8, j + 16, k + 13, MTJT.blackLeaves.blockID, 0, 2);
        world.setBlock(i + 8, j + 16, k + 11, MTJT.blackLeaves.blockID, 0, 2);
        world.setBlock(i + 9, j + 16, k + 18, MTJT.blackLeaves.blockID, 0, 2);
        world.setBlock(i + 9, j + 16, k + 16, MTJT.blackLeaves.blockID, 0, 2);
        world.setBlock(i + 9, j + 16, k + 15, MTJT.blackLeaves.blockID, 0, 2);
        world.setBlock(i + 9, j + 16, k + 12, MTJT.blackLeaves.blockID, 0, 2);
        world.setBlock(i + 9, j + 16, k + 10, MTJT.blackLog.blockID, 0, 2);
        world.setBlock(i + 10, j + 16, k + 9, MTJT.blackLeaves.blockID, 0, 2);
        world.setBlock(i + 11, j + 16, k + 8, MTJT.blackLeaves.blockID, 0, 2);
        world.setBlock(i + 12, j + 16, k + 9, MTJT.blackLeaves.blockID, 0, 2);
        world.setBlock(i + 0, j + 17, k + 5, MTJT.blackLeaves.blockID, 0, 2);
        world.setBlock(i + 1, j + 17, k + 4, MTJT.blackLeaves.blockID, 0, 2);
        world.setBlock(i + 2, j + 17, k + 10, MTJT.blackLeaves.blockID, 0, 2);
        world.setBlock(i + 2, j + 17, k + 9, MTJT.blackLeaves.blockID, 0, 2);
        world.setBlock(i + 3, j + 17, k + 17, MTJT.blackLeaves.blockID, 0, 2);
        world.setBlock(i + 3, j + 17, k + 9, MTJT.blackLeaves.blockID, 0, 2);
        world.setBlock(i + 4, j + 17, k + 17, MTJT.blackLeaves.blockID, 0, 2);
        world.setBlock(i + 4, j + 17, k + 14, MTJT.blackLeaves.blockID, 0, 2);
        world.setBlock(i + 4, j + 17, k + 9, MTJT.blackLeaves.blockID, 0, 2);
        world.setBlock(i + 4, j + 17, k + 7, MTJT.blackLeaves.blockID, 0, 2);
        world.setBlock(i + 4, j + 17, k + 5, MTJT.blackLeaves.blockID, 0, 2);
        world.setBlock(i + 4, j + 17, k + 4, MTJT.blackLeaves.blockID, 0, 2);
        world.setBlock(i + 5, j + 17, k + 18, MTJT.blackLeaves.blockID, 0, 2);
        world.setBlock(i + 5, j + 17, k + 17, MTJT.blackLeaves.blockID, 0, 2);
        world.setBlock(i + 5, j + 17, k + 16, MTJT.blackLeaves.blockID, 0, 2);
        world.setBlock(i + 5, j + 17, k + 12, MTJT.blackLeaves.blockID, 0, 2);
        world.setBlock(i + 5, j + 17, k + 10, MTJT.blackLeaves.blockID, 0, 2);
        world.setBlock(i + 5, j + 17, k + 9, MTJT.blackLeaves.blockID, 0, 2);
        world.setBlock(i + 5, j + 17, k + 7, MTJT.blackLeaves.blockID, 0, 2);
        world.setBlock(i + 5, j + 17, k + 6, MTJT.blackLeaves.blockID, 0, 2);
        world.setBlock(i + 5, j + 17, k + 5, MTJT.blackLeaves.blockID, 0, 2);
        world.setBlock(i + 5, j + 17, k + 4, MTJT.blackLeaves.blockID, 0, 2);
        world.setBlock(i + 6, j + 17, k + 18, MTJT.blackLeaves.blockID, 0, 2);
        world.setBlock(i + 6, j + 17, k + 17, MTJT.blackLeaves.blockID, 0, 2);
        world.setBlock(i + 6, j + 17, k + 14, MTJT.blackLeaves.blockID, 0, 2);
        world.setBlock(i + 6, j + 17, k + 13, MTJT.blackLeaves.blockID, 0, 2);
        world.setBlock(i + 6, j + 17, k + 3, MTJT.blackLeaves.blockID, 0, 2);
        world.setBlock(i + 6, j + 17, k + 2, MTJT.blackLeaves.blockID, 0, 2);
        world.setBlock(i + 7, j + 17, k + 18, MTJT.blackLeaves.blockID, 0, 2);
        world.setBlock(i + 7, j + 17, k + 17, MTJT.blackLog.blockID, 0, 2);
        world.setBlock(i + 7, j + 17, k + 16, MTJT.blackLog.blockID, 0, 2);
        world.setBlock(i + 7, j + 17, k + 15, MTJT.blackLeaves.blockID, 0, 2);
        world.setBlock(i + 7, j + 17, k + 12, MTJT.blackLeaves.blockID, 0, 2);
        world.setBlock(i + 7, j + 17, k + 5, MTJT.blackLeaves.blockID, 0, 2);
        world.setBlock(i + 8, j + 17, k + 20, MTJT.blackLeaves.blockID, 0, 2);
        world.setBlock(i + 8, j + 17, k + 18, MTJT.blackLog.blockID, 0, 2);
        world.setBlock(i + 8, j + 17, k + 17, MTJT.blackLeaves.blockID, 0, 2);
        world.setBlock(i + 8, j + 17, k + 12, MTJT.blackLeaves.blockID, 0, 2);
        world.setBlock(i + 9, j + 17, k + 18, MTJT.blackLeaves.blockID, 0, 2);
        world.setBlock(i + 9, j + 17, k + 9, MTJT.blackLeaves.blockID, 0, 2);
        world.setBlock(i + 9, j + 17, k + 8, MTJT.blackLeaves.blockID, 0, 2);
        world.setBlock(i + 10, j + 17, k + 11, MTJT.blackLeaves.blockID, 0, 2);
        world.setBlock(i + 10, j + 17, k + 8, MTJT.blackLeaves.blockID, 0, 2);
        world.setBlock(i + 11, j + 17, k + 19, MTJT.blackLeaves.blockID, 0, 2);
        world.setBlock(i + 11, j + 17, k + 11, MTJT.blackLeaves.blockID, 0, 2);
        world.setBlock(i + 11, j + 17, k + 10, MTJT.blackLeaves.blockID, 0, 2);
        world.setBlock(i + 1, j + 18, k + 4, MTJT.blackLeaves.blockID, 0, 2);
        world.setBlock(i + 3, j + 18, k + 10, MTJT.blackLeaves.blockID, 0, 2);
        world.setBlock(i + 3, j + 18, k + 8, MTJT.blackLeaves.blockID, 0, 2);
        world.setBlock(i + 3, j + 18, k + 6, MTJT.blackLeaves.blockID, 0, 2);
        world.setBlock(i + 3, j + 18, k + 5, MTJT.blackLeaves.blockID, 0, 2);
        world.setBlock(i + 4, j + 18, k + 18, MTJT.blackLeaves.blockID, 0, 2);
        world.setBlock(i + 5, j + 18, k + 17, MTJT.blackLeaves.blockID, 0, 2);
        world.setBlock(i + 5, j + 18, k + 14, MTJT.blackLeaves.blockID, 0, 2);
        world.setBlock(i + 5, j + 18, k + 12, MTJT.blackLeaves.blockID, 0, 2);
        world.setBlock(i + 5, j + 18, k + 6, MTJT.blackLeaves.blockID, 0, 2);
        world.setBlock(i + 6, j + 18, k + 17, MTJT.blackLeaves.blockID, 0, 2);
        world.setBlock(i + 6, j + 18, k + 15, MTJT.blackLeaves.blockID, 0, 2);
        world.setBlock(i + 6, j + 18, k + 10, MTJT.blackLeaves.blockID, 0, 2);
        world.setBlock(i + 7, j + 18, k + 12, MTJT.blackLeaves.blockID, 0, 2);
        world.setBlock(i + 7, j + 18, k + 11, MTJT.blackLeaves.blockID, 0, 2);
        world.setBlock(i + 7, j + 18, k + 10, MTJT.blackLeaves.blockID, 0, 2);
        world.setBlock(i + 8, j + 18, k + 17, MTJT.blackLeaves.blockID, 0, 2);
        world.setBlock(i + 8, j + 18, k + 15, MTJT.blackLeaves.blockID, 0, 2);
        world.setBlock(i + 8, j + 18, k + 8, MTJT.blackLeaves.blockID, 0, 2);
        world.setBlock(i + 9, j + 18, k + 12, MTJT.blackLeaves.blockID, 0, 2);
        world.setBlock(i + 9, j + 18, k + 10, MTJT.blackLeaves.blockID, 0, 2);
        world.setBlock(i + 9, j + 18, k + 8, MTJT.blackLeaves.blockID, 0, 2);
        world.setBlock(i + 10, j + 18, k + 19, MTJT.blackLeaves.blockID, 0, 2);
        world.setBlock(i + 10, j + 18, k + 11, MTJT.blackLeaves.blockID, 0, 2);
        world.setBlock(i + 11, j + 18, k + 19, MTJT.blackLeaves.blockID, 0, 2);
        world.setBlock(i + 2, j + 19, k + 6, MTJT.blackLeaves.blockID, 0, 2);
        world.setBlock(i + 4, j + 19, k + 13, MTJT.blackLeaves.blockID, 0, 2);
        world.setBlock(i + 4, j + 19, k + 11, MTJT.blackLeaves.blockID, 0, 2);
        world.setBlock(i + 4, j + 19, k + 6, MTJT.blackLeaves.blockID, 0, 2);
        world.setBlock(i + 5, j + 19, k + 5, MTJT.blackLeaves.blockID, 0, 2);
        world.setBlock(i + 5, j + 19, k + 4, MTJT.blackLeaves.blockID, 0, 2);
        world.setBlock(i + 6, j + 19, k + 19, MTJT.blackLeaves.blockID, 0, 2);
        world.setBlock(i + 7, j + 19, k + 14, MTJT.blackLeaves.blockID, 0, 2);
        world.setBlock(i + 7, j + 19, k + 10, MTJT.blackLeaves.blockID, 0, 2);
        world.setBlock(i + 7, j + 19, k + 9, MTJT.blackLeaves.blockID, 0, 2);
        world.setBlock(i + 8, j + 19, k + 18, MTJT.blackLeaves.blockID, 0, 2);
        world.setBlock(i + 8, j + 19, k + 14, MTJT.blackLeaves.blockID, 0, 2);
        world.setBlock(i + 8, j + 19, k + 12, MTJT.blackLeaves.blockID, 0, 2);
        world.setBlock(i + 8, j + 19, k + 9, MTJT.blackLeaves.blockID, 0, 2);
        world.setBlock(i + 9, j + 19, k + 20, MTJT.blackLeaves.blockID, 0, 2);
        world.setBlock(i + 9, j + 19, k + 17, MTJT.blackLeaves.blockID, 0, 2);
        world.setBlock(i + 9, j + 19, k + 13, MTJT.blackLeaves.blockID, 0, 2);
        world.setBlock(i + 5, j + 20, k + 10, MTJT.blackLeaves.blockID, 0, 2);
        world.setBlock(i + 6, j + 20, k + 9, MTJT.blackLeaves.blockID, 0, 2);
        world.setBlock(i + 7, j + 20, k + 19, MTJT.blackLeaves.blockID, 0, 2);
        world.setBlock(i + 8, j + 20, k + 18, MTJT.blackLeaves.blockID, 0, 2);
        world.setBlock(i + 8, j + 20, k + 12, MTJT.blackLeaves.blockID, 0, 2);
        world.setBlock(i + 6, j + 21, k + 10, MTJT.blackLeaves.blockID, 0, 2);
        world.setBlock(i + 7, j + 21, k + 12, MTJT.blackLeaves.blockID, 0, 2);
        world.setBlock(i + 7, j + 21, k + 10, MTJT.blackLeaves.blockID, 0, 2);
        world.setBlock(i + 9, j + 21, k + 14, MTJT.blackLeaves.blockID, 0, 2);
        world.setBlock(i + 6, j + 22, k + 13, MTJT.blackLeaves.blockID, 0, 2);
        world.setBlock(i + 6, j + 22, k + 11, MTJT.blackLeaves.blockID, 0, 2);
        world.setBlock(i + 8, j + 22, k + 12, MTJT.blackLeaves.blockID, 0, 2);
    	return true;
    }
}