package morethantrees.treegen;

import java.util.Random;

import morethantrees.MTJT;
import net.minecraft.block.Block;
import net.minecraft.world.World;
import net.minecraft.world.gen.feature.WorldGenerator;

public class WorldGenTallBrownMushroomShroom extends WorldGenerator
{
	public boolean generate(World world, Random var2, int i, int j, int k)
	  {
	    while ((world.isAirBlock(i + 10, j, k + 12)) && (j > 2))
	    {
	      j--;
	    }

	    int var6 = world.getBlockId(i + 10, j, k + 12);

	    if (var6 != Block.grass.blockID)
	    {
	      return false;
	    }

	    for (int var7 = -2; var7 <= 2; var7++)
	    {
	      for (int var8 = -2; var8 <= 2; var8++)
	      {
	        if ((world.isAirBlock(i + var7 + 10, j - 1, k + var8 + 12)) && (world.isAirBlock(i + var7 + 10, j - 2, k + var8 + 12)))
	        {
	          return false;
	        }
	      }
	    }
    	world.setBlock(i + 8, j + 0, k + 10, MTJT.mushroomStemmBrown.blockID, 0, 2);
        world.setBlock(i + 8, j + 0, k + 9, MTJT.mushroomStemmBrown.blockID, 0, 2);
        world.setBlock(i + 8, j + 0, k + 8, MTJT.mushroomStemmBrown.blockID, 0, 2);
        world.setBlock(i + 9, j + 0, k + 10, MTJT.mushroomStemmBrown.blockID, 0, 2);
        world.setBlock(i + 9, j + 0, k + 9, MTJT.mushroomStemmBrown.blockID, 0, 2);
        world.setBlock(i + 9, j + 0, k + 8, MTJT.mushroomStemmBrown.blockID, 0, 2);
        world.setBlock(i + 10, j + 0, k + 10, MTJT.mushroomStemmBrown.blockID, 0, 2);
        world.setBlock(i + 10, j + 0, k + 9, MTJT.mushroomStemmBrown.blockID, 0, 2);
        world.setBlock(i + 10, j + 0, k + 8, MTJT.mushroomStemmBrown.blockID, 0, 2);
        world.setBlock(i + 8, j + 1, k + 10, MTJT.mushroomStemmBrown.blockID, 0, 2);
        world.setBlock(i + 8, j + 1, k + 9, MTJT.mushroomStemmBrown.blockID, 0, 2);
        world.setBlock(i + 8, j + 1, k + 8, MTJT.mushroomStemmBrown.blockID, 0, 2);
        world.setBlock(i + 9, j + 1, k + 10, MTJT.mushroomStemmBrown.blockID, 0, 2);
        world.setBlock(i + 9, j + 1, k + 9, MTJT.mushroomStemmBrown.blockID, 0, 2);
        world.setBlock(i + 9, j + 1, k + 8, MTJT.mushroomStemmBrown.blockID, 0, 2);
        world.setBlock(i + 10, j + 1, k + 10, MTJT.mushroomStemmBrown.blockID, 0, 2);
        world.setBlock(i + 10, j + 1, k + 9, MTJT.mushroomStemmBrown.blockID, 0, 2);
        world.setBlock(i + 10, j + 1, k + 8, MTJT.mushroomStemmBrown.blockID, 0, 2);
        world.setBlock(i + 8, j + 2, k + 10, MTJT.mushroomStemmBrown.blockID, 0, 2);
        world.setBlock(i + 8, j + 2, k + 9, MTJT.mushroomStemmBrown.blockID, 0, 2);
        world.setBlock(i + 8, j + 2, k + 8, MTJT.mushroomStemmBrown.blockID, 0, 2);
        world.setBlock(i + 9, j + 2, k + 10, MTJT.mushroomStemmBrown.blockID, 0, 2);
        world.setBlock(i + 9, j + 2, k + 9, MTJT.mushroomStemmBrown.blockID, 0, 2);
        world.setBlock(i + 9, j + 2, k + 8, MTJT.mushroomStemmBrown.blockID, 0, 2);
        world.setBlock(i + 10, j + 2, k + 10, MTJT.mushroomStemmBrown.blockID, 0, 2);
        world.setBlock(i + 10, j + 2, k + 9, MTJT.mushroomStemmBrown.blockID, 0, 2);
        world.setBlock(i + 10, j + 2, k + 8, MTJT.mushroomStemmBrown.blockID, 0, 2);
        world.setBlock(i + 8, j + 3, k + 10, MTJT.mushroomStemmBrown.blockID, 0, 2);
        world.setBlock(i + 8, j + 3, k + 9, MTJT.mushroomStemmBrown.blockID, 0, 2);
        world.setBlock(i + 8, j + 3, k + 8, MTJT.mushroomStemmBrown.blockID, 0, 2);
        world.setBlock(i + 9, j + 3, k + 10, MTJT.mushroomStemmBrown.blockID, 0, 2);
        world.setBlock(i + 9, j + 3, k + 9, MTJT.mushroomStemmBrown.blockID, 0, 2);
        world.setBlock(i + 9, j + 3, k + 8, MTJT.mushroomStemmBrown.blockID, 0, 2);
        world.setBlock(i + 10, j + 3, k + 10, MTJT.mushroomStemmBrown.blockID, 0, 2);
        world.setBlock(i + 10, j + 3, k + 9, MTJT.mushroomStemmBrown.blockID, 0, 2);
        world.setBlock(i + 10, j + 3, k + 8, MTJT.mushroomStemmBrown.blockID, 0, 2);
        world.setBlock(i + 8, j + 4, k + 10, MTJT.mushroomStemmBrown.blockID, 0, 2);
        world.setBlock(i + 8, j + 4, k + 9, MTJT.mushroomStemmBrown.blockID, 0, 2);
        world.setBlock(i + 8, j + 4, k + 8, MTJT.mushroomStemmBrown.blockID, 0, 2);
        world.setBlock(i + 9, j + 4, k + 10, MTJT.mushroomStemmBrown.blockID, 0, 2);
        world.setBlock(i + 9, j + 4, k + 9, MTJT.mushroomStemmBrown.blockID, 0, 2);
        world.setBlock(i + 9, j + 4, k + 8, MTJT.mushroomStemmBrown.blockID, 0, 2);
        world.setBlock(i + 10, j + 4, k + 10, MTJT.mushroomStemmBrown.blockID, 0, 2);
        world.setBlock(i + 10, j + 4, k + 9, MTJT.mushroomStemmBrown.blockID, 0, 2);
        world.setBlock(i + 10, j + 4, k + 8, MTJT.mushroomStemmBrown.blockID, 0, 2);
        world.setBlock(i + 8, j + 5, k + 10, MTJT.mushroomStemmBrown.blockID, 0, 2);
        world.setBlock(i + 8, j + 5, k + 9, MTJT.mushroomStemmBrown.blockID, 0, 2);
        world.setBlock(i + 8, j + 5, k + 8, MTJT.mushroomStemmBrown.blockID, 0, 2);
        world.setBlock(i + 9, j + 5, k + 10, MTJT.mushroomStemmBrown.blockID, 0, 2);
        world.setBlock(i + 9, j + 5, k + 9, MTJT.mushroomStemmBrown.blockID, 0, 2);
        world.setBlock(i + 9, j + 5, k + 8, MTJT.mushroomStemmBrown.blockID, 0, 2);
        world.setBlock(i + 10, j + 5, k + 10, MTJT.mushroomStemmBrown.blockID, 0, 2);
        world.setBlock(i + 10, j + 5, k + 9, MTJT.mushroomStemmBrown.blockID, 0, 2);
        world.setBlock(i + 10, j + 5, k + 8, MTJT.mushroomStemmBrown.blockID, 0, 2);
        world.setBlock(i + 8, j + 6, k + 10, MTJT.mushroomStemmBrown.blockID, 0, 2);
        world.setBlock(i + 8, j + 6, k + 9, MTJT.mushroomStemmBrown.blockID, 0, 2);
        world.setBlock(i + 8, j + 6, k + 8, MTJT.mushroomStemmBrown.blockID, 0, 2);
        world.setBlock(i + 9, j + 6, k + 10, MTJT.mushroomStemmBrown.blockID, 0, 2);
        world.setBlock(i + 9, j + 6, k + 9, MTJT.mushroomStemmBrown.blockID, 0, 2);
        world.setBlock(i + 9, j + 6, k + 8, MTJT.mushroomStemmBrown.blockID, 0, 2);
        world.setBlock(i + 10, j + 6, k + 10, MTJT.mushroomStemmBrown.blockID, 0, 2);
        world.setBlock(i + 10, j + 6, k + 9, MTJT.mushroomStemmBrown.blockID, 0, 2);
        world.setBlock(i + 10, j + 6, k + 8, MTJT.mushroomStemmBrown.blockID, 0, 2);
        world.setBlock(i + 8, j + 7, k + 10, MTJT.mushroomStemmBrown.blockID, 0, 2);
        world.setBlock(i + 8, j + 7, k + 9, MTJT.mushroomStemmBrown.blockID, 0, 2);
        world.setBlock(i + 8, j + 7, k + 8, MTJT.mushroomStemmBrown.blockID, 0, 2);
        world.setBlock(i + 9, j + 7, k + 10, MTJT.mushroomStemmBrown.blockID, 0, 2);
        world.setBlock(i + 9, j + 7, k + 9, MTJT.mushroomStemmBrown.blockID, 0, 2);
        world.setBlock(i + 9, j + 7, k + 8, MTJT.mushroomStemmBrown.blockID, 0, 2);
        world.setBlock(i + 10, j + 7, k + 10, MTJT.mushroomStemmBrown.blockID, 0, 2);
        world.setBlock(i + 10, j + 7, k + 9, MTJT.mushroomStemmBrown.blockID, 0, 2);
        world.setBlock(i + 10, j + 7, k + 8, MTJT.mushroomStemmBrown.blockID, 0, 2);
        world.setBlock(i + 8, j + 8, k + 10, MTJT.mushroomStemmBrown.blockID, 0, 2);
        world.setBlock(i + 8, j + 8, k + 9, MTJT.mushroomStemmBrown.blockID, 0, 2);
        world.setBlock(i + 8, j + 8, k + 8, MTJT.mushroomStemmBrown.blockID, 0, 2);
        world.setBlock(i + 9, j + 8, k + 10, MTJT.mushroomStemmBrown.blockID, 0, 2);
        world.setBlock(i + 9, j + 8, k + 9, MTJT.mushroomStemmBrown.blockID, 0, 2);
        world.setBlock(i + 9, j + 8, k + 8, MTJT.mushroomStemmBrown.blockID, 0, 2);
        world.setBlock(i + 10, j + 8, k + 10, MTJT.mushroomStemmBrown.blockID, 0, 2);
        world.setBlock(i + 10, j + 8, k + 9, MTJT.mushroomStemmBrown.blockID, 0, 2);
        world.setBlock(i + 10, j + 8, k + 8, MTJT.mushroomStemmBrown.blockID, 0, 2);
        world.setBlock(i + 8, j + 9, k + 10, MTJT.mushroomStemmBrown.blockID, 0, 2);
        world.setBlock(i + 8, j + 9, k + 9, MTJT.mushroomStemmBrown.blockID, 0, 2);
        world.setBlock(i + 8, j + 9, k + 8, MTJT.mushroomStemmBrown.blockID, 0, 2);
        world.setBlock(i + 9, j + 9, k + 10, MTJT.mushroomStemmBrown.blockID, 0, 2);
        world.setBlock(i + 9, j + 9, k + 9, MTJT.mushroomStemmBrown.blockID, 0, 2);
        world.setBlock(i + 9, j + 9, k + 8, MTJT.mushroomStemmBrown.blockID, 0, 2);
        world.setBlock(i + 10, j + 9, k + 10, MTJT.mushroomStemmBrown.blockID, 0, 2);
        world.setBlock(i + 10, j + 9, k + 9, MTJT.mushroomStemmBrown.blockID, 0, 2);
        world.setBlock(i + 10, j + 9, k + 8, MTJT.mushroomStemmBrown.blockID, 0, 2);
        world.setBlock(i + 8, j + 10, k + 10, MTJT.mushroomStemmBrown.blockID, 0, 2);
        world.setBlock(i + 8, j + 10, k + 9, MTJT.mushroomStemmBrown.blockID, 0, 2);
        world.setBlock(i + 8, j + 10, k + 8, MTJT.mushroomStemmBrown.blockID, 0, 2);
        world.setBlock(i + 9, j + 10, k + 10, MTJT.mushroomStemmBrown.blockID, 0, 2);
        world.setBlock(i + 9, j + 10, k + 9, MTJT.mushroomStemmBrown.blockID, 0, 2);
        world.setBlock(i + 9, j + 10, k + 8, MTJT.mushroomStemmBrown.blockID, 0, 2);
        world.setBlock(i + 10, j + 10, k + 10, MTJT.mushroomStemmBrown.blockID, 0, 2);
        world.setBlock(i + 10, j + 10, k + 9, MTJT.mushroomStemmBrown.blockID, 0, 2);
        world.setBlock(i + 10, j + 10, k + 8, MTJT.mushroomStemmBrown.blockID, 0, 2);
        world.setBlock(i + 8, j + 11, k + 10, MTJT.mushroomStemmBrown.blockID, 0, 2);
        world.setBlock(i + 8, j + 11, k + 9, MTJT.mushroomStemmBrown.blockID, 0, 2);
        world.setBlock(i + 8, j + 11, k + 8, MTJT.mushroomStemmBrown.blockID, 0, 2);
        world.setBlock(i + 9, j + 11, k + 10, MTJT.mushroomStemmBrown.blockID, 0, 2);
        world.setBlock(i + 9, j + 11, k + 9, MTJT.mushroomStemmBrown.blockID, 0, 2);
        world.setBlock(i + 9, j + 11, k + 8, MTJT.mushroomStemmBrown.blockID, 0, 2);
        world.setBlock(i + 10, j + 11, k + 10, MTJT.mushroomStemmBrown.blockID, 0, 2);
        world.setBlock(i + 10, j + 11, k + 9, MTJT.mushroomStemmBrown.blockID, 0, 2);
        world.setBlock(i + 10, j + 11, k + 8, MTJT.mushroomStemmBrown.blockID, 0, 2);
        world.setBlock(i + 8, j + 12, k + 10, MTJT.mushroomStemmBrown.blockID, 0, 2);
        world.setBlock(i + 8, j + 12, k + 9, MTJT.mushroomStemmBrown.blockID, 0, 2);
        world.setBlock(i + 8, j + 12, k + 8, MTJT.mushroomStemmBrown.blockID, 0, 2);
        world.setBlock(i + 9, j + 12, k + 10, MTJT.mushroomStemmBrown.blockID, 0, 2);
        world.setBlock(i + 9, j + 12, k + 9, MTJT.mushroomStemmBrown.blockID, 0, 2);
        world.setBlock(i + 9, j + 12, k + 8, MTJT.mushroomStemmBrown.blockID, 0, 2);
        world.setBlock(i + 10, j + 12, k + 10, MTJT.mushroomStemmBrown.blockID, 0, 2);
        world.setBlock(i + 10, j + 12, k + 9, MTJT.mushroomStemmBrown.blockID, 0, 2);
        world.setBlock(i + 10, j + 12, k + 8, MTJT.mushroomStemmBrown.blockID, 0, 2);
        world.setBlock(i + 8, j + 13, k + 10, MTJT.mushroomStemmBrown.blockID, 0, 2);
        world.setBlock(i + 8, j + 13, k + 9, MTJT.mushroomStemmBrown.blockID, 0, 2);
        world.setBlock(i + 8, j + 13, k + 8, MTJT.mushroomStemmBrown.blockID, 0, 2);
        world.setBlock(i + 9, j + 13, k + 10, MTJT.mushroomStemmBrown.blockID, 0, 2);
        world.setBlock(i + 9, j + 13, k + 9, MTJT.mushroomStemmBrown.blockID, 0, 2);
        world.setBlock(i + 9, j + 13, k + 8, MTJT.mushroomStemmBrown.blockID, 0, 2);
        world.setBlock(i + 10, j + 13, k + 10, MTJT.mushroomStemmBrown.blockID, 0, 2);
        world.setBlock(i + 10, j + 13, k + 9, MTJT.mushroomStemmBrown.blockID, 0, 2);
        world.setBlock(i + 10, j + 13, k + 8, MTJT.mushroomStemmBrown.blockID, 0, 2);
        world.setBlock(i + 8, j + 14, k + 10, MTJT.mushroomStemmBrown.blockID, 0, 2);
        world.setBlock(i + 8, j + 14, k + 9, MTJT.mushroomStemmBrown.blockID, 0, 2);
        world.setBlock(i + 8, j + 14, k + 8, MTJT.mushroomStemmBrown.blockID, 0, 2);
        world.setBlock(i + 9, j + 14, k + 10, MTJT.mushroomStemmBrown.blockID, 0, 2);
        world.setBlock(i + 9, j + 14, k + 9, MTJT.mushroomStemmBrown.blockID, 0, 2);
        world.setBlock(i + 9, j + 14, k + 8, MTJT.mushroomStemmBrown.blockID, 0, 2);
        world.setBlock(i + 10, j + 14, k + 10, MTJT.mushroomStemmBrown.blockID, 0, 2);
        world.setBlock(i + 10, j + 14, k + 9, MTJT.mushroomStemmBrown.blockID, 0, 2);
        world.setBlock(i + 10, j + 14, k + 8, MTJT.mushroomStemmBrown.blockID, 0, 2);
        world.setBlock(i + 8, j + 15, k + 10, MTJT.mushroomStemmBrown.blockID, 0, 2);
        world.setBlock(i + 8, j + 15, k + 9, MTJT.mushroomStemmBrown.blockID, 0, 2);
        world.setBlock(i + 8, j + 15, k + 8, MTJT.mushroomStemmBrown.blockID, 0, 2);
        world.setBlock(i + 9, j + 15, k + 10, MTJT.mushroomStemmBrown.blockID, 0, 2);
        world.setBlock(i + 9, j + 15, k + 9, MTJT.mushroomStemmBrown.blockID, 0, 2);
        world.setBlock(i + 9, j + 15, k + 8, MTJT.mushroomStemmBrown.blockID, 0, 2);
        world.setBlock(i + 10, j + 15, k + 10, MTJT.mushroomStemmBrown.blockID, 0, 2);
        world.setBlock(i + 10, j + 15, k + 9, MTJT.mushroomStemmBrown.blockID, 0, 2);
        world.setBlock(i + 10, j + 15, k + 8, MTJT.mushroomStemmBrown.blockID, 0, 2);
        world.setBlock(i + 8, j + 16, k + 10, MTJT.mushroomStemmBrown.blockID, 0, 2);
        world.setBlock(i + 8, j + 16, k + 9, MTJT.mushroomStemmBrown.blockID, 0, 2);
        world.setBlock(i + 8, j + 16, k + 8, MTJT.mushroomStemmBrown.blockID, 0, 2);
        world.setBlock(i + 9, j + 16, k + 10, MTJT.mushroomStemmBrown.blockID, 0, 2);
        world.setBlock(i + 9, j + 16, k + 9, MTJT.mushroomStemmBrown.blockID, 0, 2);
        world.setBlock(i + 9, j + 16, k + 8, MTJT.mushroomStemmBrown.blockID, 0, 2);
        world.setBlock(i + 10, j + 16, k + 10, MTJT.mushroomStemmBrown.blockID, 0, 2);
        world.setBlock(i + 10, j + 16, k + 9, MTJT.mushroomStemmBrown.blockID, 0, 2);
        world.setBlock(i + 10, j + 16, k + 8, MTJT.mushroomStemmBrown.blockID, 0, 2);
        world.setBlock(i + 8, j + 17, k + 10, MTJT.mushroomStemmBrown.blockID, 0, 2);
        world.setBlock(i + 8, j + 17, k + 9, MTJT.mushroomStemmBrown.blockID, 0, 2);
        world.setBlock(i + 8, j + 17, k + 8, MTJT.mushroomStemmBrown.blockID, 0, 2);
        world.setBlock(i + 9, j + 17, k + 10, MTJT.mushroomStemmBrown.blockID, 0, 2);
        world.setBlock(i + 9, j + 17, k + 9, MTJT.mushroomStemmBrown.blockID, 0, 2);
        world.setBlock(i + 9, j + 17, k + 8, MTJT.mushroomStemmBrown.blockID, 0, 2);
        world.setBlock(i + 10, j + 17, k + 10, MTJT.mushroomStemmBrown.blockID, 0, 2);
        world.setBlock(i + 10, j + 17, k + 9, MTJT.mushroomStemmBrown.blockID, 0, 2);
        world.setBlock(i + 10, j + 17, k + 8, MTJT.mushroomStemmBrown.blockID, 0, 2);
        world.setBlock(i + 8, j + 18, k + 10, MTJT.mushroomStemmBrown.blockID, 0, 2);
        world.setBlock(i + 8, j + 18, k + 9, MTJT.mushroomStemmBrown.blockID, 0, 2);
        world.setBlock(i + 8, j + 18, k + 8, MTJT.mushroomStemmBrown.blockID, 0, 2);
        world.setBlock(i + 9, j + 18, k + 10, MTJT.mushroomStemmBrown.blockID, 0, 2);
        world.setBlock(i + 9, j + 18, k + 9, MTJT.mushroomStemmBrown.blockID, 0, 2);
        world.setBlock(i + 9, j + 18, k + 8, MTJT.mushroomStemmBrown.blockID, 0, 2);
        world.setBlock(i + 10, j + 18, k + 10, MTJT.mushroomStemmBrown.blockID, 0, 2);
        world.setBlock(i + 10, j + 18, k + 9, MTJT.mushroomStemmBrown.blockID, 0, 2);
        world.setBlock(i + 10, j + 18, k + 8, MTJT.mushroomStemmBrown.blockID, 0, 2);
        world.setBlock(i + 8, j + 19, k + 10, MTJT.mushroomStemmBrown.blockID, 0, 2);
        world.setBlock(i + 8, j + 19, k + 9, MTJT.mushroomStemmBrown.blockID, 0, 2);
        world.setBlock(i + 8, j + 19, k + 8, MTJT.mushroomStemmBrown.blockID, 0, 2);
        world.setBlock(i + 9, j + 19, k + 10, MTJT.mushroomStemmBrown.blockID, 0, 2);
        world.setBlock(i + 9, j + 19, k + 9, MTJT.mushroomStemmBrown.blockID, 0, 2);
        world.setBlock(i + 9, j + 19, k + 8, MTJT.mushroomStemmBrown.blockID, 0, 2);
        world.setBlock(i + 10, j + 19, k + 10, MTJT.mushroomStemmBrown.blockID, 0, 2);
        world.setBlock(i + 10, j + 19, k + 9, MTJT.mushroomStemmBrown.blockID, 0, 2);
        world.setBlock(i + 10, j + 19, k + 8, MTJT.mushroomStemmBrown.blockID, 0, 2);
        world.setBlock(i + 8, j + 20, k + 10, MTJT.mushroomStemmBrown.blockID, 0, 2);
        world.setBlock(i + 8, j + 20, k + 9, MTJT.mushroomStemmBrown.blockID, 0, 2);
        world.setBlock(i + 8, j + 20, k + 8, MTJT.mushroomStemmBrown.blockID, 0, 2);
        world.setBlock(i + 9, j + 20, k + 10, MTJT.mushroomStemmBrown.blockID, 0, 2);
        world.setBlock(i + 9, j + 20, k + 9, MTJT.mushroomStemmBrown.blockID, 0, 2);
        world.setBlock(i + 9, j + 20, k + 8, MTJT.mushroomStemmBrown.blockID, 0, 2);
        world.setBlock(i + 10, j + 20, k + 10, MTJT.mushroomStemmBrown.blockID, 0, 2);
        world.setBlock(i + 10, j + 20, k + 9, MTJT.mushroomStemmBrown.blockID, 0, 2);
        world.setBlock(i + 10, j + 20, k + 8, MTJT.mushroomStemmBrown.blockID, 0, 2);
        world.setBlock(i + 8, j + 21, k + 10, MTJT.mushroomStemmBrown.blockID, 0, 2);
        world.setBlock(i + 8, j + 21, k + 9, MTJT.mushroomStemmBrown.blockID, 0, 2);
        world.setBlock(i + 8, j + 21, k + 8, MTJT.mushroomStemmBrown.blockID, 0, 2);
        world.setBlock(i + 9, j + 21, k + 10, MTJT.mushroomStemmBrown.blockID, 0, 2);
        world.setBlock(i + 9, j + 21, k + 9, MTJT.mushroomStemmBrown.blockID, 0, 2);
        world.setBlock(i + 9, j + 21, k + 8, MTJT.mushroomStemmBrown.blockID, 0, 2);
        world.setBlock(i + 10, j + 21, k + 10, MTJT.mushroomStemmBrown.blockID, 0, 2);
        world.setBlock(i + 10, j + 21, k + 9, MTJT.mushroomStemmBrown.blockID, 0, 2);
        world.setBlock(i + 10, j + 21, k + 8, MTJT.mushroomStemmBrown.blockID, 0, 2);
        world.setBlock(i + 0, j + 22, k + 11, MTJT.mushroomTopBrown.blockID, 0, 2);
        world.setBlock(i + 0, j + 22, k + 10, MTJT.mushroomTopBrown.blockID, 0, 2);
        world.setBlock(i + 0, j + 22, k + 9, MTJT.mushroomTopBrown.blockID, 0, 2);
        world.setBlock(i + 0, j + 22, k + 8, MTJT.mushroomTopBrown.blockID, 0, 2);
        world.setBlock(i + 0, j + 22, k + 7, MTJT.mushroomTopBrown.blockID, 0, 2);
        world.setBlock(i + 1, j + 22, k + 15, MTJT.mushroomTopBrown.blockID, 0, 2);
        world.setBlock(i + 1, j + 22, k + 14, MTJT.mushroomTopBrown.blockID, 0, 2);
        world.setBlock(i + 1, j + 22, k + 13, MTJT.mushroomTopBrown.blockID, 0, 2);
        world.setBlock(i + 1, j + 22, k + 12, MTJT.mushroomTopBrown.blockID, 0, 2);
        world.setBlock(i + 1, j + 22, k + 6, MTJT.mushroomTopBrown.blockID, 0, 2);
        world.setBlock(i + 1, j + 22, k + 5, MTJT.mushroomTopBrown.blockID, 0, 2);
        world.setBlock(i + 1, j + 22, k + 4, MTJT.mushroomTopBrown.blockID, 0, 2);
        world.setBlock(i + 1, j + 22, k + 3, MTJT.mushroomTopBrown.blockID, 0, 2);
        world.setBlock(i + 2, j + 22, k + 16, MTJT.mushroomTopBrown.blockID, 0, 2);
        world.setBlock(i + 2, j + 22, k + 15, MTJT.mushroomTopBrown.blockID, 0, 2);
        world.setBlock(i + 2, j + 22, k + 3, MTJT.mushroomTopBrown.blockID, 0, 2);
        world.setBlock(i + 2, j + 22, k + 2, MTJT.mushroomTopBrown.blockID, 0, 2);
        world.setBlock(i + 3, j + 22, k + 17, MTJT.mushroomTopBrown.blockID, 0, 2);
        world.setBlock(i + 3, j + 22, k + 16, MTJT.mushroomTopBrown.blockID, 0, 2);
        world.setBlock(i + 3, j + 22, k + 2, MTJT.mushroomTopBrown.blockID, 0, 2);
        world.setBlock(i + 3, j + 22, k + 1, MTJT.mushroomTopBrown.blockID, 0, 2);
        world.setBlock(i + 4, j + 22, k + 17, MTJT.mushroomTopBrown.blockID, 0, 2);
        world.setBlock(i + 4, j + 22, k + 1, MTJT.mushroomTopBrown.blockID, 0, 2);
        world.setBlock(i + 5, j + 22, k + 17, MTJT.mushroomTopBrown.blockID, 0, 2);
        world.setBlock(i + 5, j + 22, k + 1, MTJT.mushroomTopBrown.blockID, 0, 2);
        world.setBlock(i + 6, j + 22, k + 17, MTJT.mushroomTopBrown.blockID, 0, 2);
        world.setBlock(i + 6, j + 22, k + 1, MTJT.mushroomTopBrown.blockID, 0, 2);
        world.setBlock(i + 7, j + 22, k + 18, MTJT.mushroomTopBrown.blockID, 0, 2);
        world.setBlock(i + 7, j + 22, k + 0, MTJT.mushroomTopBrown.blockID, 0, 2);
        world.setBlock(i + 8, j + 22, k + 18, MTJT.mushroomTopBrown.blockID, 0, 2);
        world.setBlock(i + 8, j + 22, k + 10, MTJT.mushroomTopBrown.blockID, 0, 2);
        world.setBlock(i + 8, j + 22, k + 9, MTJT.mushroomTopBrown.blockID, 0, 2);
        world.setBlock(i + 8, j + 22, k + 8, MTJT.mushroomTopBrown.blockID, 0, 2);
        world.setBlock(i + 8, j + 22, k + 0, MTJT.mushroomTopBrown.blockID, 0, 2);
        world.setBlock(i + 9, j + 22, k + 18, MTJT.mushroomTopBrown.blockID, 0, 2);
        world.setBlock(i + 9, j + 22, k + 10, MTJT.mushroomTopBrown.blockID, 0, 2);
        world.setBlock(i + 9, j + 22, k + 9, MTJT.mushroomTopBrown.blockID, 0, 2);
        world.setBlock(i + 9, j + 22, k + 8, MTJT.mushroomTopBrown.blockID, 0, 2);
        world.setBlock(i + 9, j + 22, k + 0, MTJT.mushroomTopBrown.blockID, 0, 2);
        world.setBlock(i + 10, j + 22, k + 18, MTJT.mushroomTopBrown.blockID, 0, 2);
        world.setBlock(i + 10, j + 22, k + 10, MTJT.mushroomTopBrown.blockID, 0, 2);
        world.setBlock(i + 10, j + 22, k + 9, MTJT.mushroomTopBrown.blockID, 0, 2);
        world.setBlock(i + 10, j + 22, k + 8, MTJT.mushroomTopBrown.blockID, 0, 2);
        world.setBlock(i + 10, j + 22, k + 0, MTJT.mushroomTopBrown.blockID, 0, 2);
        world.setBlock(i + 11, j + 22, k + 18, MTJT.mushroomTopBrown.blockID, 0, 2);
        world.setBlock(i + 11, j + 22, k + 0, MTJT.mushroomTopBrown.blockID, 0, 2);
        world.setBlock(i + 12, j + 22, k + 17, MTJT.mushroomTopBrown.blockID, 0, 2);
        world.setBlock(i + 12, j + 22, k + 1, MTJT.mushroomTopBrown.blockID, 0, 2);
        world.setBlock(i + 13, j + 22, k + 17, MTJT.mushroomTopBrown.blockID, 0, 2);
        world.setBlock(i + 13, j + 22, k + 1, MTJT.mushroomTopBrown.blockID, 0, 2);
        world.setBlock(i + 14, j + 22, k + 17, MTJT.mushroomTopBrown.blockID, 0, 2);
        world.setBlock(i + 14, j + 22, k + 1, MTJT.mushroomTopBrown.blockID, 0, 2);
        world.setBlock(i + 15, j + 22, k + 17, MTJT.mushroomTopBrown.blockID, 0, 2);
        world.setBlock(i + 15, j + 22, k + 16, MTJT.mushroomTopBrown.blockID, 0, 2);
        world.setBlock(i + 15, j + 22, k + 2, MTJT.mushroomTopBrown.blockID, 0, 2);
        world.setBlock(i + 15, j + 22, k + 1, MTJT.mushroomTopBrown.blockID, 0, 2);
        world.setBlock(i + 16, j + 22, k + 16, MTJT.mushroomTopBrown.blockID, 0, 2);
        world.setBlock(i + 16, j + 22, k + 15, MTJT.mushroomTopBrown.blockID, 0, 2);
        world.setBlock(i + 16, j + 22, k + 3, MTJT.mushroomTopBrown.blockID, 0, 2);
        world.setBlock(i + 16, j + 22, k + 2, MTJT.mushroomTopBrown.blockID, 0, 2);
        world.setBlock(i + 17, j + 22, k + 15, MTJT.mushroomTopBrown.blockID, 0, 2);
        world.setBlock(i + 17, j + 22, k + 14, MTJT.mushroomTopBrown.blockID, 0, 2);
        world.setBlock(i + 17, j + 22, k + 13, MTJT.mushroomTopBrown.blockID, 0, 2);
        world.setBlock(i + 17, j + 22, k + 12, MTJT.mushroomTopBrown.blockID, 0, 2);
        world.setBlock(i + 17, j + 22, k + 6, MTJT.mushroomTopBrown.blockID, 0, 2);
        world.setBlock(i + 17, j + 22, k + 5, MTJT.mushroomTopBrown.blockID, 0, 2);
        world.setBlock(i + 17, j + 22, k + 4, MTJT.mushroomTopBrown.blockID, 0, 2);
        world.setBlock(i + 17, j + 22, k + 3, MTJT.mushroomTopBrown.blockID, 0, 2);
        world.setBlock(i + 18, j + 22, k + 11, MTJT.mushroomTopBrown.blockID, 0, 2);
        world.setBlock(i + 18, j + 22, k + 10, MTJT.mushroomTopBrown.blockID, 0, 2);
        world.setBlock(i + 18, j + 22, k + 9, MTJT.mushroomTopBrown.blockID, 0, 2);
        world.setBlock(i + 18, j + 22, k + 8, MTJT.mushroomTopBrown.blockID, 0, 2);
        world.setBlock(i + 18, j + 22, k + 7, MTJT.mushroomTopBrown.blockID, 0, 2);
        world.setBlock(i + 1, j + 23, k + 11, MTJT.mushroomTopBrown.blockID, 0, 2);
        world.setBlock(i + 1, j + 23, k + 10, MTJT.mushroomTopBrown.blockID, 0, 2);
        world.setBlock(i + 1, j + 23, k + 9, MTJT.mushroomTopBrown.blockID, 0, 2);
        world.setBlock(i + 1, j + 23, k + 8, MTJT.mushroomTopBrown.blockID, 0, 2);
        world.setBlock(i + 1, j + 23, k + 7, MTJT.mushroomTopBrown.blockID, 0, 2);
        world.setBlock(i + 2, j + 23, k + 14, MTJT.mushroomTopBrown.blockID, 0, 2);
        world.setBlock(i + 2, j + 23, k + 13, MTJT.mushroomTopBrown.blockID, 0, 2);
        world.setBlock(i + 2, j + 23, k + 12, MTJT.mushroomTopBrown.blockID, 0, 2);
        world.setBlock(i + 2, j + 23, k + 6, MTJT.mushroomTopBrown.blockID, 0, 2);
        world.setBlock(i + 2, j + 23, k + 5, MTJT.mushroomTopBrown.blockID, 0, 2);
        world.setBlock(i + 2, j + 23, k + 4, MTJT.mushroomTopBrown.blockID, 0, 2);
        world.setBlock(i + 3, j + 23, k + 15, MTJT.mushroomTopBrown.blockID, 0, 2);
        world.setBlock(i + 3, j + 23, k + 14, MTJT.mushroomTopBrown.blockID, 0, 2);
        world.setBlock(i + 3, j + 23, k + 4, MTJT.mushroomTopBrown.blockID, 0, 2);
        world.setBlock(i + 3, j + 23, k + 3, MTJT.mushroomTopBrown.blockID, 0, 2);
        world.setBlock(i + 4, j + 23, k + 16, MTJT.mushroomTopBrown.blockID, 0, 2);
        world.setBlock(i + 4, j + 23, k + 15, MTJT.mushroomTopBrown.blockID, 0, 2);
        world.setBlock(i + 4, j + 23, k + 3, MTJT.mushroomTopBrown.blockID, 0, 2);
        world.setBlock(i + 4, j + 23, k + 2, MTJT.mushroomTopBrown.blockID, 0, 2);
        world.setBlock(i + 5, j + 23, k + 16, MTJT.mushroomTopBrown.blockID, 0, 2);
        world.setBlock(i + 5, j + 23, k + 2, MTJT.mushroomTopBrown.blockID, 0, 2);
        world.setBlock(i + 6, j + 23, k + 16, MTJT.mushroomTopBrown.blockID, 0, 2);
        world.setBlock(i + 6, j + 23, k + 2, MTJT.mushroomTopBrown.blockID, 0, 2);
        world.setBlock(i + 7, j + 23, k + 17, MTJT.mushroomTopBrown.blockID, 0, 2);
        world.setBlock(i + 7, j + 23, k + 1, MTJT.mushroomTopBrown.blockID, 0, 2);
        world.setBlock(i + 8, j + 23, k + 17, MTJT.mushroomTopBrown.blockID, 0, 2);
        world.setBlock(i + 8, j + 23, k + 10, MTJT.mushroomTopBrown.blockID, 0, 2);
        world.setBlock(i + 8, j + 23, k + 9, MTJT.mushroomTopBrown.blockID, 0, 2);
        world.setBlock(i + 8, j + 23, k + 8, MTJT.mushroomTopBrown.blockID, 0, 2);
        world.setBlock(i + 8, j + 23, k + 1, MTJT.mushroomTopBrown.blockID, 0, 2);
        world.setBlock(i + 9, j + 23, k + 17, MTJT.mushroomTopBrown.blockID, 0, 2);
        world.setBlock(i + 9, j + 23, k + 10, MTJT.mushroomTopBrown.blockID, 0, 2);
        world.setBlock(i + 9, j + 23, k + 9, MTJT.mushroomTopBrown.blockID, 0, 2);
        world.setBlock(i + 9, j + 23, k + 8, MTJT.mushroomTopBrown.blockID, 0, 2);
        world.setBlock(i + 9, j + 23, k + 1, MTJT.mushroomTopBrown.blockID, 0, 2);
        world.setBlock(i + 10, j + 23, k + 17, MTJT.mushroomTopBrown.blockID, 0, 2);
        world.setBlock(i + 10, j + 23, k + 10, MTJT.mushroomTopBrown.blockID, 0, 2);
        world.setBlock(i + 10, j + 23, k + 9, MTJT.mushroomTopBrown.blockID, 0, 2);
        world.setBlock(i + 10, j + 23, k + 8, MTJT.mushroomTopBrown.blockID, 0, 2);
        world.setBlock(i + 10, j + 23, k + 1, MTJT.mushroomTopBrown.blockID, 0, 2);
        world.setBlock(i + 11, j + 23, k + 17, MTJT.mushroomTopBrown.blockID, 0, 2);
        world.setBlock(i + 11, j + 23, k + 1, MTJT.mushroomTopBrown.blockID, 0, 2);
        world.setBlock(i + 12, j + 23, k + 16, MTJT.mushroomTopBrown.blockID, 0, 2);
        world.setBlock(i + 12, j + 23, k + 2, MTJT.mushroomTopBrown.blockID, 0, 2);
        world.setBlock(i + 13, j + 23, k + 16, MTJT.mushroomTopBrown.blockID, 0, 2);
        world.setBlock(i + 13, j + 23, k + 2, MTJT.mushroomTopBrown.blockID, 0, 2);
        world.setBlock(i + 14, j + 23, k + 16, MTJT.mushroomTopBrown.blockID, 0, 2);
        world.setBlock(i + 14, j + 23, k + 15, MTJT.mushroomTopBrown.blockID, 0, 2);
        world.setBlock(i + 14, j + 23, k + 3, MTJT.mushroomTopBrown.blockID, 0, 2);
        world.setBlock(i + 14, j + 23, k + 2, MTJT.mushroomTopBrown.blockID, 0, 2);
        world.setBlock(i + 15, j + 23, k + 15, MTJT.mushroomTopBrown.blockID, 0, 2);
        world.setBlock(i + 15, j + 23, k + 14, MTJT.mushroomTopBrown.blockID, 0, 2);
        world.setBlock(i + 15, j + 23, k + 4, MTJT.mushroomTopBrown.blockID, 0, 2);
        world.setBlock(i + 15, j + 23, k + 3, MTJT.mushroomTopBrown.blockID, 0, 2);
        world.setBlock(i + 16, j + 23, k + 14, MTJT.mushroomTopBrown.blockID, 0, 2);
        world.setBlock(i + 16, j + 23, k + 13, MTJT.mushroomTopBrown.blockID, 0, 2);
        world.setBlock(i + 16, j + 23, k + 12, MTJT.mushroomTopBrown.blockID, 0, 2);
        world.setBlock(i + 16, j + 23, k + 6, MTJT.mushroomTopBrown.blockID, 0, 2);
        world.setBlock(i + 16, j + 23, k + 5, MTJT.mushroomTopBrown.blockID, 0, 2);
        world.setBlock(i + 16, j + 23, k + 4, MTJT.mushroomTopBrown.blockID, 0, 2);
        world.setBlock(i + 17, j + 23, k + 11, MTJT.mushroomTopBrown.blockID, 0, 2);
        world.setBlock(i + 17, j + 23, k + 10, MTJT.mushroomTopBrown.blockID, 0, 2);
        world.setBlock(i + 17, j + 23, k + 9, MTJT.mushroomTopBrown.blockID, 0, 2);
        world.setBlock(i + 17, j + 23, k + 8, MTJT.mushroomTopBrown.blockID, 0, 2);
        world.setBlock(i + 17, j + 23, k + 7, MTJT.mushroomTopBrown.blockID, 0, 2);
        world.setBlock(i + 2, j + 24, k + 11, MTJT.mushroomTopBrown.blockID, 0, 2);
        world.setBlock(i + 2, j + 24, k + 10, MTJT.mushroomTopBrown.blockID, 0, 2);
        world.setBlock(i + 2, j + 24, k + 9, MTJT.mushroomTopBrown.blockID, 0, 2);
        world.setBlock(i + 2, j + 24, k + 8, MTJT.mushroomTopBrown.blockID, 0, 2);
        world.setBlock(i + 2, j + 24, k + 7, MTJT.mushroomTopBrown.blockID, 0, 2);
        world.setBlock(i + 3, j + 24, k + 13, MTJT.mushroomTopBrown.blockID, 0, 2);
        world.setBlock(i + 3, j + 24, k + 12, MTJT.mushroomTopBrown.blockID, 0, 2);
        world.setBlock(i + 3, j + 24, k + 6, MTJT.mushroomTopBrown.blockID, 0, 2);
        world.setBlock(i + 3, j + 24, k + 5, MTJT.mushroomTopBrown.blockID, 0, 2);
        world.setBlock(i + 4, j + 24, k + 14, MTJT.mushroomTopBrown.blockID, 0, 2);
        world.setBlock(i + 4, j + 24, k + 13, MTJT.mushroomTopBrown.blockID, 0, 2);
        world.setBlock(i + 4, j + 24, k + 5, MTJT.mushroomTopBrown.blockID, 0, 2);
        world.setBlock(i + 4, j + 24, k + 4, MTJT.mushroomTopBrown.blockID, 0, 2);
        world.setBlock(i + 5, j + 24, k + 15, MTJT.mushroomTopBrown.blockID, 0, 2);
        world.setBlock(i + 5, j + 24, k + 14, MTJT.mushroomTopBrown.blockID, 0, 2);
        world.setBlock(i + 5, j + 24, k + 4, MTJT.mushroomTopBrown.blockID, 0, 2);
        world.setBlock(i + 5, j + 24, k + 3, MTJT.mushroomTopBrown.blockID, 0, 2);
        world.setBlock(i + 6, j + 24, k + 15, MTJT.mushroomTopBrown.blockID, 0, 2);
        world.setBlock(i + 6, j + 24, k + 3, MTJT.mushroomTopBrown.blockID, 0, 2);
        world.setBlock(i + 7, j + 24, k + 16, MTJT.mushroomTopBrown.blockID, 0, 2);
        world.setBlock(i + 7, j + 24, k + 2, MTJT.mushroomTopBrown.blockID, 0, 2);
        world.setBlock(i + 8, j + 24, k + 16, MTJT.mushroomTopBrown.blockID, 0, 2);
        world.setBlock(i + 8, j + 24, k + 10, MTJT.mushroomTopBrown.blockID, 0, 2);
        world.setBlock(i + 8, j + 24, k + 9, MTJT.mushroomTopBrown.blockID, 0, 2);
        world.setBlock(i + 8, j + 24, k + 8, MTJT.mushroomTopBrown.blockID, 0, 2);
        world.setBlock(i + 8, j + 24, k + 2, MTJT.mushroomTopBrown.blockID, 0, 2);
        world.setBlock(i + 9, j + 24, k + 16, MTJT.mushroomTopBrown.blockID, 0, 2);
        world.setBlock(i + 9, j + 24, k + 10, MTJT.mushroomTopBrown.blockID, 0, 2);
        world.setBlock(i + 9, j + 24, k + 9, MTJT.mushroomTopBrown.blockID, 0, 2);
        world.setBlock(i + 9, j + 24, k + 8, MTJT.mushroomTopBrown.blockID, 0, 2);
        world.setBlock(i + 9, j + 24, k + 2, MTJT.mushroomTopBrown.blockID, 0, 2);
        world.setBlock(i + 10, j + 24, k + 16, MTJT.mushroomTopBrown.blockID, 0, 2);
        world.setBlock(i + 10, j + 24, k + 10, MTJT.mushroomTopBrown.blockID, 0, 2);
        world.setBlock(i + 10, j + 24, k + 9, MTJT.mushroomTopBrown.blockID, 0, 2);
        world.setBlock(i + 10, j + 24, k + 8, MTJT.mushroomTopBrown.blockID, 0, 2);
        world.setBlock(i + 10, j + 24, k + 2, MTJT.mushroomTopBrown.blockID, 0, 2);
        world.setBlock(i + 11, j + 24, k + 16, MTJT.mushroomTopBrown.blockID, 0, 2);
        world.setBlock(i + 11, j + 24, k + 2, MTJT.mushroomTopBrown.blockID, 0, 2);
        world.setBlock(i + 12, j + 24, k + 15, MTJT.mushroomTopBrown.blockID, 0, 2);
        world.setBlock(i + 12, j + 24, k + 3, MTJT.mushroomTopBrown.blockID, 0, 2);
        world.setBlock(i + 13, j + 24, k + 15, MTJT.mushroomTopBrown.blockID, 0, 2);
        world.setBlock(i + 13, j + 24, k + 14, MTJT.mushroomTopBrown.blockID, 0, 2);
        world.setBlock(i + 13, j + 24, k + 4, MTJT.mushroomTopBrown.blockID, 0, 2);
        world.setBlock(i + 13, j + 24, k + 3, MTJT.mushroomTopBrown.blockID, 0, 2);
        world.setBlock(i + 14, j + 24, k + 14, MTJT.mushroomTopBrown.blockID, 0, 2);
        world.setBlock(i + 14, j + 24, k + 13, MTJT.mushroomTopBrown.blockID, 0, 2);
        world.setBlock(i + 14, j + 24, k + 5, MTJT.mushroomTopBrown.blockID, 0, 2);
        world.setBlock(i + 14, j + 24, k + 4, MTJT.mushroomTopBrown.blockID, 0, 2);
        world.setBlock(i + 15, j + 24, k + 13, MTJT.mushroomTopBrown.blockID, 0, 2);
        world.setBlock(i + 15, j + 24, k + 12, MTJT.mushroomTopBrown.blockID, 0, 2);
        world.setBlock(i + 15, j + 24, k + 6, MTJT.mushroomTopBrown.blockID, 0, 2);
        world.setBlock(i + 15, j + 24, k + 5, MTJT.mushroomTopBrown.blockID, 0, 2);
        world.setBlock(i + 16, j + 24, k + 11, MTJT.mushroomTopBrown.blockID, 0, 2);
        world.setBlock(i + 16, j + 24, k + 10, MTJT.mushroomTopBrown.blockID, 0, 2);
        world.setBlock(i + 16, j + 24, k + 9, MTJT.mushroomTopBrown.blockID, 0, 2);
        world.setBlock(i + 16, j + 24, k + 8, MTJT.mushroomTopBrown.blockID, 0, 2);
        world.setBlock(i + 16, j + 24, k + 7, MTJT.mushroomTopBrown.blockID, 0, 2);
        world.setBlock(i + 3, j + 25, k + 11, MTJT.mushroomTopBrown.blockID, 0, 2);
        world.setBlock(i + 3, j + 25, k + 10, MTJT.mushroomTopBrown.blockID, 0, 2);
        world.setBlock(i + 3, j + 25, k + 9, MTJT.mushroomTopBrown.blockID, 0, 2);
        world.setBlock(i + 3, j + 25, k + 8, MTJT.mushroomTopBrown.blockID, 0, 2);
        world.setBlock(i + 3, j + 25, k + 7, MTJT.mushroomTopBrown.blockID, 0, 2);
        world.setBlock(i + 4, j + 25, k + 12, MTJT.mushroomTopBrown.blockID, 0, 2);
        world.setBlock(i + 4, j + 25, k + 11, MTJT.mushroomTopBrown.blockID, 0, 2);
        world.setBlock(i + 4, j + 25, k + 10, MTJT.mushroomTopBrown.blockID, 0, 2);
        world.setBlock(i + 4, j + 25, k + 9, MTJT.mushroomTopBrown.blockID, 0, 2);
        world.setBlock(i + 4, j + 25, k + 8, MTJT.mushroomTopBrown.blockID, 0, 2);
        world.setBlock(i + 4, j + 25, k + 7, MTJT.mushroomTopBrown.blockID, 0, 2);
        world.setBlock(i + 4, j + 25, k + 6, MTJT.mushroomTopBrown.blockID, 0, 2);
        world.setBlock(i + 5, j + 25, k + 13, MTJT.mushroomTopBrown.blockID, 0, 2);
        world.setBlock(i + 5, j + 25, k + 12, MTJT.mushroomTopBrown.blockID, 0, 2);
        world.setBlock(i + 5, j + 25, k + 11, MTJT.mushroomTopBrown.blockID, 0, 2);
        world.setBlock(i + 5, j + 25, k + 10, MTJT.mushroomTopBrown.blockID, 0, 2);
        world.setBlock(i + 5, j + 25, k + 9, MTJT.mushroomTopBrown.blockID, 0, 2);
        world.setBlock(i + 5, j + 25, k + 8, MTJT.mushroomTopBrown.blockID, 0, 2);
        world.setBlock(i + 5, j + 25, k + 7, MTJT.mushroomTopBrown.blockID, 0, 2);
        world.setBlock(i + 5, j + 25, k + 6, MTJT.mushroomTopBrown.blockID, 0, 2);
        world.setBlock(i + 5, j + 25, k + 5, MTJT.mushroomTopBrown.blockID, 0, 2);
        world.setBlock(i + 6, j + 25, k + 14, MTJT.mushroomTopBrown.blockID, 0, 2);
        world.setBlock(i + 6, j + 25, k + 13, MTJT.mushroomTopBrown.blockID, 0, 2);
        world.setBlock(i + 6, j + 25, k + 12, MTJT.mushroomTopBrown.blockID, 0, 2);
        world.setBlock(i + 6, j + 25, k + 11, MTJT.mushroomTopBrown.blockID, 0, 2);
        world.setBlock(i + 6, j + 25, k + 10, MTJT.mushroomTopBrown.blockID, 0, 2);
        world.setBlock(i + 6, j + 25, k + 9, MTJT.mushroomTopBrown.blockID, 0, 2);
        world.setBlock(i + 6, j + 25, k + 8, MTJT.mushroomTopBrown.blockID, 0, 2);
        world.setBlock(i + 6, j + 25, k + 7, MTJT.mushroomTopBrown.blockID, 0, 2);
        world.setBlock(i + 6, j + 25, k + 6, MTJT.mushroomTopBrown.blockID, 0, 2);
        world.setBlock(i + 6, j + 25, k + 5, MTJT.mushroomTopBrown.blockID, 0, 2);
        world.setBlock(i + 6, j + 25, k + 4, MTJT.mushroomTopBrown.blockID, 0, 2);
        world.setBlock(i + 7, j + 25, k + 15, MTJT.mushroomTopBrown.blockID, 0, 2);
        world.setBlock(i + 7, j + 25, k + 14, MTJT.mushroomTopBrown.blockID, 0, 2);
        world.setBlock(i + 7, j + 25, k + 13, MTJT.mushroomTopBrown.blockID, 0, 2);
        world.setBlock(i + 7, j + 25, k + 12, MTJT.mushroomTopBrown.blockID, 0, 2);
        world.setBlock(i + 7, j + 25, k + 11, MTJT.mushroomTopBrown.blockID, 0, 2);
        world.setBlock(i + 7, j + 25, k + 10, MTJT.mushroomTopBrown.blockID, 0, 2);
        world.setBlock(i + 7, j + 25, k + 9, MTJT.mushroomTopBrown.blockID, 0, 2);
        world.setBlock(i + 7, j + 25, k + 8, MTJT.mushroomTopBrown.blockID, 0, 2);
        world.setBlock(i + 7, j + 25, k + 7, MTJT.mushroomTopBrown.blockID, 0, 2);
        world.setBlock(i + 7, j + 25, k + 6, MTJT.mushroomTopBrown.blockID, 0, 2);
        world.setBlock(i + 7, j + 25, k + 5, MTJT.mushroomTopBrown.blockID, 0, 2);
        world.setBlock(i + 7, j + 25, k + 4, MTJT.mushroomTopBrown.blockID, 0, 2);
        world.setBlock(i + 7, j + 25, k + 3, MTJT.mushroomTopBrown.blockID, 0, 2);
        world.setBlock(i + 8, j + 25, k + 15, MTJT.mushroomTopBrown.blockID, 0, 2);
        world.setBlock(i + 8, j + 25, k + 14, MTJT.mushroomTopBrown.blockID, 0, 2);
        world.setBlock(i + 8, j + 25, k + 13, MTJT.mushroomTopBrown.blockID, 0, 2);
        world.setBlock(i + 8, j + 25, k + 12, MTJT.mushroomTopBrown.blockID, 0, 2);
        world.setBlock(i + 8, j + 25, k + 11, MTJT.mushroomTopBrown.blockID, 0, 2);
        world.setBlock(i + 8, j + 25, k + 10, MTJT.mushroomTopBrown.blockID, 0, 2);
        world.setBlock(i + 8, j + 25, k + 9, MTJT.mushroomTopBrown.blockID, 0, 2);
        world.setBlock(i + 8, j + 25, k + 8, MTJT.mushroomTopBrown.blockID, 0, 2);
        world.setBlock(i + 8, j + 25, k + 7, MTJT.mushroomTopBrown.blockID, 0, 2);
        world.setBlock(i + 8, j + 25, k + 6, MTJT.mushroomTopBrown.blockID, 0, 2);
        world.setBlock(i + 8, j + 25, k + 5, MTJT.mushroomTopBrown.blockID, 0, 2);
        world.setBlock(i + 8, j + 25, k + 4, MTJT.mushroomTopBrown.blockID, 0, 2);
        world.setBlock(i + 8, j + 25, k + 3, MTJT.mushroomTopBrown.blockID, 0, 2);
        world.setBlock(i + 9, j + 25, k + 15, MTJT.mushroomTopBrown.blockID, 0, 2);
        world.setBlock(i + 9, j + 25, k + 14, MTJT.mushroomTopBrown.blockID, 0, 2);
        world.setBlock(i + 9, j + 25, k + 13, MTJT.mushroomTopBrown.blockID, 0, 2);
        world.setBlock(i + 9, j + 25, k + 12, MTJT.mushroomTopBrown.blockID, 0, 2);
        world.setBlock(i + 9, j + 25, k + 11, MTJT.mushroomTopBrown.blockID, 0, 2);
        world.setBlock(i + 9, j + 25, k + 10, MTJT.mushroomTopBrown.blockID, 0, 2);
        world.setBlock(i + 9, j + 25, k + 9, MTJT.mushroomTopBrown.blockID, 0, 2);
        world.setBlock(i + 9, j + 25, k + 8, MTJT.mushroomTopBrown.blockID, 0, 2);
        world.setBlock(i + 9, j + 25, k + 7, MTJT.mushroomTopBrown.blockID, 0, 2);
        world.setBlock(i + 9, j + 25, k + 6, MTJT.mushroomTopBrown.blockID, 0, 2);
        world.setBlock(i + 9, j + 25, k + 5, MTJT.mushroomTopBrown.blockID, 0, 2);
        world.setBlock(i + 9, j + 25, k + 4, MTJT.mushroomTopBrown.blockID, 0, 2);
        world.setBlock(i + 9, j + 25, k + 3, MTJT.mushroomTopBrown.blockID, 0, 2);
        world.setBlock(i + 10, j + 25, k + 15, MTJT.mushroomTopBrown.blockID, 0, 2);
        world.setBlock(i + 10, j + 25, k + 14, MTJT.mushroomTopBrown.blockID, 0, 2);
        world.setBlock(i + 10, j + 25, k + 13, MTJT.mushroomTopBrown.blockID, 0, 2);
        world.setBlock(i + 10, j + 25, k + 12, MTJT.mushroomTopBrown.blockID, 0, 2);
        world.setBlock(i + 10, j + 25, k + 11, MTJT.mushroomTopBrown.blockID, 0, 2);
        world.setBlock(i + 10, j + 25, k + 10, MTJT.mushroomTopBrown.blockID, 0, 2);
        world.setBlock(i + 10, j + 25, k + 9, MTJT.mushroomTopBrown.blockID, 0, 2);
        world.setBlock(i + 10, j + 25, k + 8, MTJT.mushroomTopBrown.blockID, 0, 2);
        world.setBlock(i + 10, j + 25, k + 7, MTJT.mushroomTopBrown.blockID, 0, 2);
        world.setBlock(i + 10, j + 25, k + 6, MTJT.mushroomTopBrown.blockID, 0, 2);
        world.setBlock(i + 10, j + 25, k + 5, MTJT.mushroomTopBrown.blockID, 0, 2);
        world.setBlock(i + 10, j + 25, k + 4, MTJT.mushroomTopBrown.blockID, 0, 2);
        world.setBlock(i + 10, j + 25, k + 3, MTJT.mushroomTopBrown.blockID, 0, 2);
        world.setBlock(i + 11, j + 25, k + 15, MTJT.mushroomTopBrown.blockID, 0, 2);
        world.setBlock(i + 11, j + 25, k + 14, MTJT.mushroomTopBrown.blockID, 0, 2);
        world.setBlock(i + 11, j + 25, k + 13, MTJT.mushroomTopBrown.blockID, 0, 2);
        world.setBlock(i + 11, j + 25, k + 12, MTJT.mushroomTopBrown.blockID, 0, 2);
        world.setBlock(i + 11, j + 25, k + 11, MTJT.mushroomTopBrown.blockID, 0, 2);
        world.setBlock(i + 11, j + 25, k + 10, MTJT.mushroomTopBrown.blockID, 0, 2);
        world.setBlock(i + 11, j + 25, k + 9, MTJT.mushroomTopBrown.blockID, 0, 2);
        world.setBlock(i + 11, j + 25, k + 8, MTJT.mushroomTopBrown.blockID, 0, 2);
        world.setBlock(i + 11, j + 25, k + 7, MTJT.mushroomTopBrown.blockID, 0, 2);
        world.setBlock(i + 11, j + 25, k + 6, MTJT.mushroomTopBrown.blockID, 0, 2);
        world.setBlock(i + 11, j + 25, k + 5, MTJT.mushroomTopBrown.blockID, 0, 2);
        world.setBlock(i + 11, j + 25, k + 4, MTJT.mushroomTopBrown.blockID, 0, 2);
        world.setBlock(i + 11, j + 25, k + 3, MTJT.mushroomTopBrown.blockID, 0, 2);
        world.setBlock(i + 12, j + 25, k + 14, MTJT.mushroomTopBrown.blockID, 0, 2);
        world.setBlock(i + 12, j + 25, k + 13, MTJT.mushroomTopBrown.blockID, 0, 2);
        world.setBlock(i + 12, j + 25, k + 12, MTJT.mushroomTopBrown.blockID, 0, 2);
        world.setBlock(i + 12, j + 25, k + 11, MTJT.mushroomTopBrown.blockID, 0, 2);
        world.setBlock(i + 12, j + 25, k + 10, MTJT.mushroomTopBrown.blockID, 0, 2);
        world.setBlock(i + 12, j + 25, k + 9, MTJT.mushroomTopBrown.blockID, 0, 2);
        world.setBlock(i + 12, j + 25, k + 8, MTJT.mushroomTopBrown.blockID, 0, 2);
        world.setBlock(i + 12, j + 25, k + 7, MTJT.mushroomTopBrown.blockID, 0, 2);
        world.setBlock(i + 12, j + 25, k + 6, MTJT.mushroomTopBrown.blockID, 0, 2);
        world.setBlock(i + 12, j + 25, k + 5, MTJT.mushroomTopBrown.blockID, 0, 2);
        world.setBlock(i + 12, j + 25, k + 4, MTJT.mushroomTopBrown.blockID, 0, 2);
        world.setBlock(i + 13, j + 25, k + 13, MTJT.mushroomTopBrown.blockID, 0, 2);
        world.setBlock(i + 13, j + 25, k + 12, MTJT.mushroomTopBrown.blockID, 0, 2);
        world.setBlock(i + 13, j + 25, k + 11, MTJT.mushroomTopBrown.blockID, 0, 2);
        world.setBlock(i + 13, j + 25, k + 10, MTJT.mushroomTopBrown.blockID, 0, 2);
        world.setBlock(i + 13, j + 25, k + 9, MTJT.mushroomTopBrown.blockID, 0, 2);
        world.setBlock(i + 13, j + 25, k + 8, MTJT.mushroomTopBrown.blockID, 0, 2);
        world.setBlock(i + 13, j + 25, k + 7, MTJT.mushroomTopBrown.blockID, 0, 2);
        world.setBlock(i + 13, j + 25, k + 6, MTJT.mushroomTopBrown.blockID, 0, 2);
        world.setBlock(i + 13, j + 25, k + 5, MTJT.mushroomTopBrown.blockID, 0, 2);
        world.setBlock(i + 14, j + 25, k + 12, MTJT.mushroomTopBrown.blockID, 0, 2);
        world.setBlock(i + 14, j + 25, k + 11, MTJT.mushroomTopBrown.blockID, 0, 2);
        world.setBlock(i + 14, j + 25, k + 10, MTJT.mushroomTopBrown.blockID, 0, 2);
        world.setBlock(i + 14, j + 25, k + 9, MTJT.mushroomTopBrown.blockID, 0, 2);
        world.setBlock(i + 14, j + 25, k + 8, MTJT.mushroomTopBrown.blockID, 0, 2);
        world.setBlock(i + 14, j + 25, k + 7, MTJT.mushroomTopBrown.blockID, 0, 2);
        world.setBlock(i + 14, j + 25, k + 6, MTJT.mushroomTopBrown.blockID, 0, 2);
        world.setBlock(i + 15, j + 25, k + 11, MTJT.mushroomTopBrown.blockID, 0, 2);
        world.setBlock(i + 15, j + 25, k + 10, MTJT.mushroomTopBrown.blockID, 0, 2);
        world.setBlock(i + 15, j + 25, k + 9, MTJT.mushroomTopBrown.blockID, 0, 2);
        world.setBlock(i + 15, j + 25, k + 8, MTJT.mushroomTopBrown.blockID, 0, 2);
        world.setBlock(i + 15, j + 25, k + 7, MTJT.mushroomTopBrown.blockID, 0, 2);

return true;
}
}
