package morethantrees.treegen;

import java.util.Random;

import morethantrees.MTJT;
import net.minecraft.block.Block;
import net.minecraft.world.World;
import net.minecraft.world.gen.feature.WorldGenerator;

public class WorldGenSunflowerTrees extends WorldGenerator
{
	public boolean generate(World world, Random var2, int i, int j, int k)
	  {
	    while ((world.isAirBlock(i + 10, j, k + 12)) && (j > 2))
	    {
	      j--;
	    }

	    int var6 = world.getBlockId(i + 10, j, k + 12);

	    if (var6 != Block.grass.blockID)
	    {
	      return false;
	    }

	    for (int var7 = -2; var7 <= 2; var7++)
	    {
	      for (int var8 = -2; var8 <= 2; var8++)
	      {
	        if ((world.isAirBlock(i + var7 + 10, j - 1, k + var8 + 12)) && (world.isAirBlock(i + var7 + 10, j - 2, k + var8 + 12)))
	        {
	          return false;
	        }
	      }
	    }
	    world.setBlock(i + 6, j + 0, k + 12, MTJT.sunflowerLog.blockID, 0, 2);
        world.setBlock(i + 7, j + 0, k + 13, MTJT.sunflowerLog.blockID, 0, 2);
        world.setBlock(i + 7, j + 0, k + 12, MTJT.sunflowerLog.blockID, 0, 2);
        world.setBlock(i + 7, j + 0, k + 11, MTJT.sunflowerLog.blockID, 0, 2);
        world.setBlock(i + 8, j + 0, k + 12, MTJT.sunflowerLog.blockID, 0, 2);
        world.setBlock(i + 7, j + 1, k + 12, MTJT.sunflowerLog.blockID, 0, 2);
        world.setBlock(i + 7, j + 1, k + 11, MTJT.sunflowerLog.blockID, 0, 2);
        world.setBlock(i + 7, j + 2, k + 12, MTJT.sunflowerLog.blockID, 0, 2);
        world.setBlock(i + 7, j + 3, k + 12, MTJT.sunflowerLog.blockID, 0, 2);
        world.setBlock(i + 7, j + 4, k + 12, MTJT.sunflowerLog.blockID, 0, 2);
        world.setBlock(i + 7, j + 5, k + 12, MTJT.sunflowerLog.blockID, 0, 2);
        world.setBlock(i + 7, j + 6, k + 12, MTJT.sunflowerLog.blockID, 0, 2);
        world.setBlock(i + 7, j + 7, k + 12, MTJT.sunflowerLog.blockID, 0, 2);
        world.setBlock(i + 7, j + 8, k + 12, MTJT.sunflowerLog.blockID, 0, 2);
        world.setBlock(i + 7, j + 9, k + 12, MTJT.sunflowerLog.blockID, 0, 2);
        world.setBlock(i + 7, j + 10, k + 11, MTJT.sunflowerLog.blockID, 0, 2);
        world.setBlock(i + 8, j + 10, k + 13, MTJT.sunflowerLog.blockID, 0, 2);
        world.setBlock(i + 6, j + 11, k + 11, MTJT.sunflowerLog.blockID, 0, 2);
        world.setBlock(i + 8, j + 11, k + 13, MTJT.sunflowerLog.blockID, 0, 2);
        world.setBlock(i + 6, j + 12, k + 11, MTJT.sunflowerLog.blockID, 0, 2);
        world.setBlock(i + 8, j + 12, k + 13, MTJT.sunflowerLog.blockID, 0, 2);
        world.setBlock(i + 6, j + 13, k + 10, MTJT.sunflowerLog.blockID, 0, 2);
        world.setBlock(i + 9, j + 13, k + 14, MTJT.sunflowerLog.blockID, 0, 2);
        world.setBlock(i + 4, j + 14, k + 18, MTJT.sunflowerLeaves.blockID, 0, 2);
        world.setBlock(i + 6, j + 14, k + 10, MTJT.sunflowerLog.blockID, 0, 2);
        world.setBlock(i + 9, j + 14, k + 14, MTJT.sunflowerLog.blockID, 0, 2);
        world.setBlock(i + 3, j + 15, k + 15, MTJT.sunflowerLeaves.blockID, 0, 2);
        world.setBlock(i + 4, j + 15, k + 16, MTJT.sunflowerLeaves.blockID, 0, 2);
        world.setBlock(i + 4, j + 15, k + 12, MTJT.sunflowerLeaves.blockID, 0, 2);
        world.setBlock(i + 5, j + 15, k + 17, MTJT.sunflowerLeaves.blockID, 0, 2);
        world.setBlock(i + 6, j + 15, k + 18, MTJT.sunflowerLeaves.blockID, 0, 2);
        world.setBlock(i + 6, j + 15, k + 10, MTJT.sunflowerLog.blockID, 0, 2);
        world.setBlock(i + 7, j + 15, k + 18, MTJT.sunflowerLeaves.blockID, 0, 2);
        world.setBlock(i + 7, j + 15, k + 16, MTJT.sunflowerLeaves.blockID, 0, 2);
        world.setBlock(i + 8, j + 15, k + 15, MTJT.sunflowerLog.blockID, 0, 2);
        world.setBlock(i + 9, j + 15, k + 14, MTJT.sunflowerLog.blockID, 0, 2);
        world.setBlock(i + 2, j + 16, k + 17, MTJT.sunflowerLeaves.blockID, 0, 2);
        world.setBlock(i + 2, j + 16, k + 11, MTJT.sunflowerLeaves.blockID, 0, 2);
        world.setBlock(i + 3, j + 16, k + 19, MTJT.sunflowerLeaves.blockID, 0, 2);
        world.setBlock(i + 3, j + 16, k + 18, MTJT.sunflowerLeaves.blockID, 0, 2);
        world.setBlock(i + 3, j + 16, k + 17, MTJT.sunflowerLeaves.blockID, 0, 2);
        world.setBlock(i + 3, j + 16, k + 12, MTJT.sunflowerLeaves.blockID, 0, 2);
        world.setBlock(i + 4, j + 16, k + 16, MTJT.sunflowerLeaves.blockID, 0, 2);
        world.setBlock(i + 4, j + 16, k + 11, MTJT.sunflowerLeaves.blockID, 0, 2);
        world.setBlock(i + 4, j + 16, k + 9, MTJT.sunflowerLeaves.blockID, 0, 2);
        world.setBlock(i + 5, j + 16, k + 15, MTJT.sunflowerLeaves.blockID, 0, 2);
        world.setBlock(i + 5, j + 16, k + 11, MTJT.sunflowerLog.blockID, 0, 2);
        world.setBlock(i + 6, j + 16, k + 17, MTJT.sunflowerLog.blockID, 0, 2);
        world.setBlock(i + 6, j + 16, k + 9, MTJT.sunflowerLog.blockID, 0, 2);
        world.setBlock(i + 7, j + 16, k + 17, MTJT.sunflowerLeaves.blockID, 0, 2);
        world.setBlock(i + 7, j + 16, k + 16, MTJT.sunflowerLog.blockID, 0, 2);
        world.setBlock(i + 9, j + 16, k + 14, MTJT.sunflowerLog.blockID, 0, 2);
        world.setBlock(i + 1, j + 17, k + 19, MTJT.sunflowerLeaves.blockID, 0, 2);
        world.setBlock(i + 2, j + 17, k + 18, MTJT.sunflowerLeaves.blockID, 0, 2);
        world.setBlock(i + 3, j + 17, k + 19, MTJT.sunflowerLeaves.blockID, 0, 2);
        world.setBlock(i + 3, j + 17, k + 18, MTJT.sunflowerLeaves.blockID, 0, 2);
        world.setBlock(i + 3, j + 17, k + 17, MTJT.sunflowerLeaves.blockID, 0, 2);
        world.setBlock(i + 4, j + 17, k + 19, MTJT.sunflowerLeaves.blockID, 0, 2);
        world.setBlock(i + 4, j + 17, k + 17, MTJT.sunflowerLeaves.blockID, 0, 2);
        world.setBlock(i + 4, j + 17, k + 16, MTJT.sunflowerLeaves.blockID, 0, 2);
        world.setBlock(i + 4, j + 17, k + 13, MTJT.sunflowerLeaves.blockID, 0, 2);
        world.setBlock(i + 5, j + 17, k + 20, MTJT.sunflowerLeaves.blockID, 0, 2);
        world.setBlock(i + 5, j + 17, k + 17, MTJT.sunflowerLog.blockID, 0, 2);
        world.setBlock(i + 5, j + 17, k + 11, MTJT.sunflowerLog.blockID, 0, 2);
        world.setBlock(i + 6, j + 17, k + 20, MTJT.sunflowerLeaves.blockID, 0, 2);
        world.setBlock(i + 6, j + 17, k + 18, MTJT.sunflowerLeaves.blockID, 0, 2);
        world.setBlock(i + 6, j + 17, k + 17, MTJT.sunflowerLeaves.blockID, 0, 2);
        world.setBlock(i + 6, j + 17, k + 15, MTJT.sunflowerLeaves.blockID, 0, 2);
        world.setBlock(i + 6, j + 17, k + 14, MTJT.sunflowerLeaves.blockID, 0, 2);
        world.setBlock(i + 6, j + 17, k + 9, MTJT.sunflowerLog.blockID, 0, 2);
        world.setBlock(i + 7, j + 17, k + 19, MTJT.sunflowerLeaves.blockID, 0, 2);
        world.setBlock(i + 7, j + 17, k + 18, MTJT.sunflowerLeaves.blockID, 0, 2);
        world.setBlock(i + 9, j + 17, k + 15, MTJT.sunflowerLog.blockID, 0, 2);
        world.setBlock(i + 0, j + 18, k + 19, MTJT.sunflowerLeaves.blockID, 0, 2);
        world.setBlock(i + 0, j + 18, k + 18, MTJT.sunflowerLeaves.blockID, 0, 2);
        world.setBlock(i + 1, j + 18, k + 18, MTJT.sunflowerLeaves.blockID, 0, 2);
        world.setBlock(i + 2, j + 18, k + 12, MTJT.sunflowerLeaves.blockID, 0, 2);
        world.setBlock(i + 3, j + 18, k + 17, MTJT.sunflowerLeaves.blockID, 0, 2);
        world.setBlock(i + 3, j + 18, k + 13, MTJT.sunflowerLeaves.blockID, 0, 2);
        world.setBlock(i + 3, j + 18, k + 11, MTJT.sunflowerLeaves.blockID, 0, 2);
        world.setBlock(i + 3, j + 18, k + 9, MTJT.sunflowerLeaves.blockID, 0, 2);
        world.setBlock(i + 4, j + 18, k + 18, MTJT.sunflowerLeaves.blockID, 0, 2);
        world.setBlock(i + 4, j + 18, k + 16, MTJT.sunflowerLeaves.blockID, 0, 2);
        world.setBlock(i + 4, j + 18, k + 12, MTJT.sunflowerLeaves.blockID, 0, 2);
        world.setBlock(i + 4, j + 18, k + 11, MTJT.sunflowerLog.blockID, 0, 2);
        world.setBlock(i + 5, j + 18, k + 16, MTJT.sunflowerLeaves.blockID, 0, 2);
        world.setBlock(i + 5, j + 18, k + 14, MTJT.sunflowerLeaves.blockID, 0, 2);
        world.setBlock(i + 6, j + 18, k + 12, MTJT.sunflowerLog.blockID, 0, 2);
        world.setBlock(i + 6, j + 18, k + 9, MTJT.sunflowerLog.blockID, 0, 2);
        world.setBlock(i + 7, j + 18, k + 10, MTJT.sunflowerLeaves.blockID, 0, 2);
        world.setBlock(i + 8, j + 18, k + 16, MTJT.sunflowerLog.blockID, 0, 2);
        world.setBlock(i + 9, j + 18, k + 15, MTJT.sunflowerLog.blockID, 0, 2);
        world.setBlock(i + 1, j + 19, k + 12, MTJT.sunflowerLeaves.blockID, 0, 2);
        world.setBlock(i + 2, j + 19, k + 20, MTJT.sunflowerLeaves.blockID, 0, 2);
        world.setBlock(i + 2, j + 19, k + 15, MTJT.sunflowerLeaves.blockID, 0, 2);
        world.setBlock(i + 3, j + 19, k + 20, MTJT.sunflowerLeaves.blockID, 0, 2);
        world.setBlock(i + 3, j + 19, k + 18, MTJT.sunflowerLeaves.blockID, 0, 2);
        world.setBlock(i + 3, j + 19, k + 16, MTJT.sunflowerLeaves.blockID, 0, 2);
        world.setBlock(i + 4, j + 19, k + 21, MTJT.sunflowerLeaves.blockID, 0, 2);
        world.setBlock(i + 4, j + 19, k + 19, MTJT.sunflowerLeaves.blockID, 0, 2);
        world.setBlock(i + 4, j + 19, k + 17, MTJT.sunflowerLeaves.blockID, 0, 2);
        world.setBlock(i + 4, j + 19, k + 13, MTJT.sunflowerLeaves.blockID, 0, 2);
        world.setBlock(i + 4, j + 19, k + 12, MTJT.sunflowerLeaves.blockID, 0, 2);
        world.setBlock(i + 4, j + 19, k + 11, MTJT.sunflowerLeaves.blockID, 0, 2);
        world.setBlock(i + 5, j + 19, k + 19, MTJT.sunflowerLeaves.blockID, 0, 2);
        world.setBlock(i + 5, j + 19, k + 17, MTJT.sunflowerLeaves.blockID, 0, 2);
        world.setBlock(i + 5, j + 19, k + 16, MTJT.sunflowerLeaves.blockID, 0, 2);
        world.setBlock(i + 6, j + 19, k + 19, MTJT.sunflowerLeaves.blockID, 0, 2);
        world.setBlock(i + 6, j + 19, k + 18, MTJT.sunflowerLeaves.blockID, 0, 2);
        world.setBlock(i + 6, j + 19, k + 17, MTJT.sunflowerLeaves.blockID, 0, 2);
        world.setBlock(i + 6, j + 19, k + 16, MTJT.sunflowerLeaves.blockID, 0, 2);
        world.setBlock(i + 6, j + 19, k + 9, MTJT.sunflowerLog.blockID, 0, 2);
        world.setBlock(i + 7, j + 19, k + 18, MTJT.sunflowerLog.blockID, 0, 2);
        world.setBlock(i + 7, j + 19, k + 17, MTJT.sunflowerLog.blockID, 0, 2);
        world.setBlock(i + 9, j + 19, k + 15, MTJT.sunflowerLog.blockID, 0, 2);
        world.setBlock(i + 0, j + 20, k + 17, MTJT.sunflowerLeaves.blockID, 0, 2);
        world.setBlock(i + 1, j + 20, k + 16, MTJT.sunflowerLeaves.blockID, 0, 2);
        world.setBlock(i + 2, j + 20, k + 10, MTJT.sunflowerLeaves.blockID, 0, 2);
        world.setBlock(i + 3, j + 20, k + 21, MTJT.sunflowerLeaves.blockID, 0, 2);
        world.setBlock(i + 3, j + 20, k + 19, MTJT.sunflowerLeaves.blockID, 0, 2);
        world.setBlock(i + 3, j + 20, k + 18, MTJT.sunflowerLeaves.blockID, 0, 2);
        world.setBlock(i + 3, j + 20, k + 17, MTJT.sunflowerLeaves.blockID, 0, 2);
        world.setBlock(i + 3, j + 20, k + 16, MTJT.sunflowerLeaves.blockID, 0, 2);
        world.setBlock(i + 3, j + 20, k + 13, MTJT.sunflowerLeaves.blockID, 0, 2);
        world.setBlock(i + 3, j + 20, k + 9, MTJT.sunflowerLeaves.blockID, 0, 2);
        world.setBlock(i + 4, j + 20, k + 20, MTJT.sunflowerLeaves.blockID, 0, 2);
        world.setBlock(i + 4, j + 20, k + 17, MTJT.sunflowerLeaves.blockID, 0, 2);
        world.setBlock(i + 4, j + 20, k + 10, MTJT.sunflowerLeaves.blockID, 0, 2);
        world.setBlock(i + 5, j + 20, k + 20, MTJT.sunflowerLeaves.blockID, 0, 2);
        world.setBlock(i + 5, j + 20, k + 19, MTJT.sunflowerLeaves.blockID, 0, 2);
        world.setBlock(i + 6, j + 20, k + 19, MTJT.sunflowerLog.blockID, 0, 2);
        world.setBlock(i + 6, j + 20, k + 16, MTJT.sunflowerLeaves.blockID, 0, 2);
        world.setBlock(i + 6, j + 20, k + 8, MTJT.sunflowerLog.blockID, 0, 2);
        world.setBlock(i + 7, j + 20, k + 21, MTJT.sunflowerLeaves.blockID, 0, 2);
        world.setBlock(i + 7, j + 20, k + 20, MTJT.sunflowerLeaves.blockID, 0, 2);
        world.setBlock(i + 7, j + 20, k + 16, MTJT.sunflowerLeaves.blockID, 0, 2);
        world.setBlock(i + 8, j + 20, k + 20, MTJT.sunflowerLeaves.blockID, 0, 2);
        world.setBlock(i + 8, j + 20, k + 18, MTJT.sunflowerLeaves.blockID, 0, 2);
        world.setBlock(i + 9, j + 20, k + 15, MTJT.sunflowerLog.blockID, 0, 2);
        world.setBlock(i + 1, j + 21, k + 18, MTJT.sunflowerLeaves.blockID, 0, 2);
        world.setBlock(i + 2, j + 21, k + 19, MTJT.sunflowerLeaves.blockID, 0, 2);
        world.setBlock(i + 2, j + 21, k + 17, MTJT.sunflowerLeaves.blockID, 0, 2);
        world.setBlock(i + 2, j + 21, k + 16, MTJT.sunflowerLeaves.blockID, 0, 2);
        world.setBlock(i + 4, j + 21, k + 12, MTJT.sunflowerLeaves.blockID, 0, 2);
        world.setBlock(i + 5, j + 21, k + 16, MTJT.sunflowerLeaves.blockID, 0, 2);
        world.setBlock(i + 5, j + 21, k + 7, MTJT.sunflowerLog.blockID, 0, 2);
        world.setBlock(i + 5, j + 21, k + 6, MTJT.sunflowerLog.blockID, 0, 2);
        world.setBlock(i + 6, j + 21, k + 22, MTJT.sunflowerLeaves.blockID, 0, 2);
        world.setBlock(i + 6, j + 21, k + 19, MTJT.sunflowerLeaves.blockID, 0, 2);
        world.setBlock(i + 6, j + 21, k + 18, MTJT.sunflowerLeaves.blockID, 0, 2);
        world.setBlock(i + 7, j + 21, k + 20, MTJT.sunflowerLeaves.blockID, 0, 2);
        world.setBlock(i + 7, j + 21, k + 16, MTJT.sunflowerLeaves.blockID, 0, 2);
        world.setBlock(i + 7, j + 21, k + 8, MTJT.sunflowerLog.blockID, 0, 2);
        world.setBlock(i + 8, j + 21, k + 19, MTJT.sunflowerLeaves.blockID, 0, 2);
        world.setBlock(i + 8, j + 21, k + 16, MTJT.sunflowerLog.blockID, 0, 2);
        world.setBlock(i + 9, j + 21, k + 18, MTJT.sunflowerLeaves.blockID, 0, 2);
        world.setBlock(i + 10, j + 21, k + 15, MTJT.sunflowerLog.blockID, 0, 2);
        world.setBlock(i + 4, j + 22, k + 19, MTJT.sunflowerLeaves.blockID, 0, 2);
        world.setBlock(i + 4, j + 22, k + 5, MTJT.sunflowerLog.blockID, 0, 2);
        world.setBlock(i + 6, j + 22, k + 17, MTJT.sunflowerLeaves.blockID, 0, 2);
        world.setBlock(i + 7, j + 22, k + 17, MTJT.sunflowerLeaves.blockID, 0, 2);
        world.setBlock(i + 7, j + 22, k + 13, MTJT.sunflowerLeaves.blockID, 0, 2);
        world.setBlock(i + 7, j + 22, k + 8, MTJT.sunflowerLog.blockID, 0, 2);
        world.setBlock(i + 8, j + 22, k + 19, MTJT.sunflowerLeaves.blockID, 0, 2);
        world.setBlock(i + 8, j + 22, k + 16, MTJT.sunflowerLog.blockID, 0, 2);
        world.setBlock(i + 8, j + 22, k + 14, MTJT.sunflowerLeaves.blockID, 0, 2);
        world.setBlock(i + 11, j + 22, k + 15, MTJT.sunflowerLeaves.blockID, 0, 2);
        world.setBlock(i + 11, j + 22, k + 14, MTJT.sunflowerLog.blockID, 0, 2);
        world.setBlock(i + 13, j + 22, k + 15, MTJT.sunflowerLeaves.blockID, 0, 2);
        world.setBlock(i + 2, j + 23, k + 4, MTJT.sunflowerLeaves.blockID, 0, 2);
        world.setBlock(i + 3, j + 23, k + 6, MTJT.sunflowerLeaves.blockID, 0, 2);
        world.setBlock(i + 3, j + 23, k + 4, MTJT.sunflowerLog.blockID, 0, 2);
        world.setBlock(i + 3, j + 23, k + 3, MTJT.sunflowerLeaves.blockID, 0, 2);
        world.setBlock(i + 4, j + 23, k + 17, MTJT.sunflowerLeaves.blockID, 0, 2);
        world.setBlock(i + 5, j + 23, k + 20, MTJT.sunflowerLeaves.blockID, 0, 2);
        world.setBlock(i + 5, j + 23, k + 18, MTJT.sunflowerLeaves.blockID, 0, 2);
        world.setBlock(i + 5, j + 23, k + 17, MTJT.sunflowerLeaves.blockID, 0, 2);
        world.setBlock(i + 5, j + 23, k + 14, MTJT.sunflowerLeaves.blockID, 0, 2);
        world.setBlock(i + 5, j + 23, k + 6, MTJT.sunflowerLeaves.blockID, 0, 2);
        world.setBlock(i + 5, j + 23, k + 4, MTJT.sunflowerLeaves.blockID, 0, 2);
        world.setBlock(i + 6, j + 23, k + 13, MTJT.sunflowerLeaves.blockID, 0, 2);
        world.setBlock(i + 7, j + 23, k + 18, MTJT.sunflowerLeaves.blockID, 0, 2);
        world.setBlock(i + 7, j + 23, k + 17, MTJT.sunflowerLog.blockID, 0, 2);
        world.setBlock(i + 7, j + 23, k + 16, MTJT.sunflowerLeaves.blockID, 0, 2);
        world.setBlock(i + 8, j + 23, k + 16, MTJT.sunflowerLeaves.blockID, 0, 2);
        world.setBlock(i + 8, j + 23, k + 15, MTJT.sunflowerLog.blockID, 0, 2);
        world.setBlock(i + 8, j + 23, k + 8, MTJT.sunflowerLog.blockID, 0, 2);
        world.setBlock(i + 9, j + 23, k + 18, MTJT.sunflowerLeaves.blockID, 0, 2);
        world.setBlock(i + 9, j + 23, k + 14, MTJT.sunflowerLeaves.blockID, 0, 2);
        world.setBlock(i + 9, j + 23, k + 13, MTJT.sunflowerLeaves.blockID, 0, 2);
        world.setBlock(i + 9, j + 23, k + 8, MTJT.sunflowerLeaves.blockID, 0, 2);
        world.setBlock(i + 10, j + 23, k + 9, MTJT.sunflowerLeaves.blockID, 0, 2);
        world.setBlock(i + 11, j + 23, k + 14, MTJT.sunflowerLog.blockID, 0, 2);
        world.setBlock(i + 11, j + 23, k + 7, MTJT.sunflowerLeaves.blockID, 0, 2);
        world.setBlock(i + 2, j + 24, k + 7, MTJT.sunflowerLeaves.blockID, 0, 2);
        world.setBlock(i + 2, j + 24, k + 5, MTJT.sunflowerLeaves.blockID, 0, 2);
        world.setBlock(i + 2, j + 24, k + 4, MTJT.sunflowerLeaves.blockID, 0, 2);
        world.setBlock(i + 3, j + 24, k + 4, MTJT.sunflowerLog.blockID, 0, 2);
        world.setBlock(i + 3, j + 24, k + 3, MTJT.sunflowerLeaves.blockID, 0, 2);
        world.setBlock(i + 4, j + 24, k + 17, MTJT.sunflowerLeaves.blockID, 0, 2);
        world.setBlock(i + 4, j + 24, k + 15, MTJT.sunflowerLeaves.blockID, 0, 2);
        world.setBlock(i + 4, j + 24, k + 5, MTJT.sunflowerLeaves.blockID, 0, 2);
        world.setBlock(i + 4, j + 24, k + 4, MTJT.sunflowerLeaves.blockID, 0, 2);
        world.setBlock(i + 4, j + 24, k + 2, MTJT.sunflowerLeaves.blockID, 0, 2);
        world.setBlock(i + 5, j + 24, k + 18, MTJT.sunflowerLeaves.blockID, 0, 2);
        world.setBlock(i + 5, j + 24, k + 17, MTJT.sunflowerLeaves.blockID, 0, 2);
        world.setBlock(i + 5, j + 24, k + 7, MTJT.sunflowerLeaves.blockID, 0, 2);
        world.setBlock(i + 6, j + 24, k + 16, MTJT.sunflowerLeaves.blockID, 0, 2);
        world.setBlock(i + 6, j + 24, k + 12, MTJT.sunflowerLeaves.blockID, 0, 2);
        world.setBlock(i + 6, j + 24, k + 6, MTJT.sunflowerLeaves.blockID, 0, 2);
        world.setBlock(i + 7, j + 24, k + 20, MTJT.sunflowerLeaves.blockID, 0, 2);
        world.setBlock(i + 7, j + 24, k + 19, MTJT.sunflowerLeaves.blockID, 0, 2);
        world.setBlock(i + 7, j + 24, k + 17, MTJT.sunflowerLog.blockID, 0, 2);
        world.setBlock(i + 7, j + 24, k + 16, MTJT.sunflowerLeaves.blockID, 0, 2);
        world.setBlock(i + 7, j + 24, k + 14, MTJT.sunflowerLog.blockID, 0, 2);
        world.setBlock(i + 7, j + 24, k + 12, MTJT.sunflowerLeaves.blockID, 0, 2);
        world.setBlock(i + 7, j + 24, k + 5, MTJT.sunflowerLeaves.blockID, 0, 2);
        world.setBlock(i + 8, j + 24, k + 18, MTJT.sunflowerLeaves.blockID, 0, 2);
        world.setBlock(i + 8, j + 24, k + 17, MTJT.sunflowerLeaves.blockID, 0, 2);
        world.setBlock(i + 8, j + 24, k + 14, MTJT.sunflowerLeaves.blockID, 0, 2);
        world.setBlock(i + 8, j + 24, k + 8, MTJT.sunflowerLog.blockID, 0, 2);
        world.setBlock(i + 9, j + 24, k + 19, MTJT.sunflowerLeaves.blockID, 0, 2);
        world.setBlock(i + 9, j + 24, k + 11, MTJT.sunflowerLeaves.blockID, 0, 2);
        world.setBlock(i + 9, j + 24, k + 9, MTJT.sunflowerLog.blockID, 0, 2);
        world.setBlock(i + 10, j + 24, k + 15, MTJT.sunflowerLeaves.blockID, 0, 2);
        world.setBlock(i + 10, j + 24, k + 12, MTJT.sunflowerLeaves.blockID, 0, 2);
        world.setBlock(i + 10, j + 24, k + 10, MTJT.sunflowerLeaves.blockID, 0, 2);
        world.setBlock(i + 11, j + 24, k + 5, MTJT.sunflowerLeaves.blockID, 0, 2);
        world.setBlock(i + 12, j + 24, k + 17, MTJT.sunflowerLeaves.blockID, 0, 2);
        world.setBlock(i + 12, j + 24, k + 15, MTJT.sunflowerLog.blockID, 0, 2);
        world.setBlock(i + 12, j + 24, k + 13, MTJT.sunflowerLog.blockID, 0, 2);
        world.setBlock(i + 12, j + 24, k + 12, MTJT.sunflowerLeaves.blockID, 0, 2);
        world.setBlock(i + 15, j + 24, k + 16, MTJT.sunflowerLeaves.blockID, 0, 2);
        world.setBlock(i + 0, j + 25, k + 3, MTJT.sunflowerLeaves.blockID, 0, 2);
        world.setBlock(i + 1, j + 25, k + 5, MTJT.sunflowerLeaves.blockID, 0, 2);
        world.setBlock(i + 2, j + 25, k + 6, MTJT.sunflowerLeaves.blockID, 0, 2);
        world.setBlock(i + 2, j + 25, k + 3, MTJT.sunflowerLeaves.blockID, 0, 2);
        world.setBlock(i + 2, j + 25, k + 1, MTJT.sunflowerLeaves.blockID, 0, 2);
        world.setBlock(i + 2, j + 25, k + 0, MTJT.sunflowerLeaves.blockID, 0, 2);
        world.setBlock(i + 3, j + 25, k + 6, MTJT.sunflowerLeaves.blockID, 0, 2);
        world.setBlock(i + 3, j + 25, k + 3, MTJT.sunflowerLog.blockID, 0, 2);
        world.setBlock(i + 4, j + 25, k + 14, MTJT.sunflowerLeaves.blockID, 0, 2);
        world.setBlock(i + 4, j + 25, k + 13, MTJT.sunflowerLeaves.blockID, 0, 2);
        world.setBlock(i + 4, j + 25, k + 8, MTJT.sunflowerLeaves.blockID, 0, 2);
        world.setBlock(i + 4, j + 25, k + 6, MTJT.sunflowerLeaves.blockID, 0, 2);
        world.setBlock(i + 4, j + 25, k + 5, MTJT.sunflowerLog.blockID, 0, 2);
        world.setBlock(i + 4, j + 25, k + 2, MTJT.sunflowerLeaves.blockID, 0, 2);
        world.setBlock(i + 5, j + 25, k + 15, MTJT.sunflowerLeaves.blockID, 0, 2);
        world.setBlock(i + 5, j + 25, k + 13, MTJT.sunflowerLeaves.blockID, 0, 2);
        world.setBlock(i + 5, j + 25, k + 5, MTJT.sunflowerLeaves.blockID, 0, 2);
        world.setBlock(i + 6, j + 25, k + 16, MTJT.sunflowerLeaves.blockID, 0, 2);
        world.setBlock(i + 6, j + 25, k + 12, MTJT.sunflowerLeaves.blockID, 0, 2);
        world.setBlock(i + 6, j + 25, k + 6, MTJT.sunflowerLeaves.blockID, 0, 2);
        world.setBlock(i + 6, j + 25, k + 5, MTJT.sunflowerLeaves.blockID, 0, 2);
        world.setBlock(i + 6, j + 25, k + 4, MTJT.sunflowerLeaves.blockID, 0, 2);
        world.setBlock(i + 7, j + 25, k + 20, MTJT.sunflowerLeaves.blockID, 0, 2);
        world.setBlock(i + 7, j + 25, k + 17, MTJT.sunflowerLeaves.blockID, 0, 2);
        world.setBlock(i + 7, j + 25, k + 15, MTJT.sunflowerLeaves.blockID, 0, 2);
        world.setBlock(i + 7, j + 25, k + 14, MTJT.sunflowerLog.blockID, 0, 2);
        world.setBlock(i + 7, j + 25, k + 7, MTJT.sunflowerLeaves.blockID, 0, 2);
        world.setBlock(i + 7, j + 25, k + 5, MTJT.sunflowerLeaves.blockID, 0, 2);
        world.setBlock(i + 8, j + 25, k + 17, MTJT.sunflowerLeaves.blockID, 0, 2);
        world.setBlock(i + 8, j + 25, k + 16, MTJT.sunflowerLeaves.blockID, 0, 2);
        world.setBlock(i + 8, j + 25, k + 13, MTJT.sunflowerLeaves.blockID, 0, 2);
        world.setBlock(i + 8, j + 25, k + 8, MTJT.sunflowerLeaves.blockID, 0, 2);
        world.setBlock(i + 9, j + 25, k + 14, MTJT.sunflowerLeaves.blockID, 0, 2);
        world.setBlock(i + 9, j + 25, k + 12, MTJT.sunflowerLeaves.blockID, 0, 2);
        world.setBlock(i + 9, j + 25, k + 7, MTJT.sunflowerLog.blockID, 0, 2);
        world.setBlock(i + 9, j + 25, k + 5, MTJT.sunflowerLeaves.blockID, 0, 2);
        world.setBlock(i + 9, j + 25, k + 4, MTJT.sunflowerLeaves.blockID, 0, 2);
        world.setBlock(i + 10, j + 25, k + 14, MTJT.sunflowerLeaves.blockID, 0, 2);
        world.setBlock(i + 10, j + 25, k + 13, MTJT.sunflowerLeaves.blockID, 0, 2);
        world.setBlock(i + 10, j + 25, k + 10, MTJT.sunflowerLog.blockID, 0, 2);
        world.setBlock(i + 10, j + 25, k + 9, MTJT.sunflowerLeaves.blockID, 0, 2);
        world.setBlock(i + 10, j + 25, k + 7, MTJT.sunflowerLeaves.blockID, 0, 2);
        world.setBlock(i + 10, j + 25, k + 6, MTJT.sunflowerLeaves.blockID, 0, 2);
        world.setBlock(i + 11, j + 25, k + 12, MTJT.sunflowerLeaves.blockID, 0, 2);
        world.setBlock(i + 11, j + 25, k + 5, MTJT.sunflowerLeaves.blockID, 0, 2);
        world.setBlock(i + 12, j + 25, k + 16, MTJT.sunflowerLeaves.blockID, 0, 2);
        world.setBlock(i + 12, j + 25, k + 15, MTJT.sunflowerLog.blockID, 0, 2);
        world.setBlock(i + 12, j + 25, k + 13, MTJT.sunflowerLeaves.blockID, 0, 2);
        world.setBlock(i + 13, j + 25, k + 18, MTJT.sunflowerLeaves.blockID, 0, 2);
        world.setBlock(i + 15, j + 25, k + 15, MTJT.sunflowerLeaves.blockID, 0, 2);
        world.setBlock(i + 0, j + 26, k + 3, MTJT.sunflowerLeaves.blockID, 0, 2);
        world.setBlock(i + 1, j + 26, k + 4, MTJT.sunflowerLeaves.blockID, 0, 2);
        world.setBlock(i + 1, j + 26, k + 0, MTJT.sunflowerLeaves.blockID, 0, 2);
        world.setBlock(i + 2, j + 26, k + 3, MTJT.sunflowerLog.blockID, 0, 2);
        world.setBlock(i + 2, j + 26, k + 2, MTJT.sunflowerLeaves.blockID, 0, 2);
        world.setBlock(i + 2, j + 26, k + 1, MTJT.sunflowerLeaves.blockID, 0, 2);
        world.setBlock(i + 3, j + 26, k + 3, MTJT.sunflowerLeaves.blockID, 0, 2);
        world.setBlock(i + 4, j + 26, k + 14, MTJT.sunflowerLeaves.blockID, 0, 2);
        world.setBlock(i + 4, j + 26, k + 13, MTJT.sunflowerLeaves.blockID, 0, 2);
        world.setBlock(i + 4, j + 26, k + 8, MTJT.sunflowerLeaves.blockID, 0, 2);
        world.setBlock(i + 4, j + 26, k + 7, MTJT.sunflowerLeaves.blockID, 0, 2);
        world.setBlock(i + 4, j + 26, k + 6, MTJT.sunflowerLeaves.blockID, 0, 2);
        world.setBlock(i + 4, j + 26, k + 5, MTJT.sunflowerLog.blockID, 0, 2);
        world.setBlock(i + 5, j + 26, k + 15, MTJT.sunflowerLeaves.blockID, 0, 2);
        world.setBlock(i + 5, j + 26, k + 14, MTJT.sunflowerLeaves.blockID, 0, 2);
        world.setBlock(i + 5, j + 26, k + 5, MTJT.sunflowerLeaves.blockID, 0, 2);
        world.setBlock(i + 5, j + 26, k + 2, MTJT.sunflowerLeaves.blockID, 0, 2);
        world.setBlock(i + 6, j + 26, k + 14, MTJT.sunflowerLeaves.blockID, 0, 2);
        world.setBlock(i + 7, j + 26, k + 17, MTJT.sunflowerLeaves.blockID, 0, 2);
        world.setBlock(i + 7, j + 26, k + 13, MTJT.sunflowerLeaves.blockID, 0, 2);
        world.setBlock(i + 7, j + 26, k + 11, MTJT.sunflowerLeaves.blockID, 0, 2);
        world.setBlock(i + 7, j + 26, k + 9, MTJT.sunflowerLeaves.blockID, 0, 2);
        world.setBlock(i + 8, j + 26, k + 19, MTJT.sunflowerLeaves.blockID, 0, 2);
        world.setBlock(i + 8, j + 26, k + 17, MTJT.sunflowerLeaves.blockID, 0, 2);
        world.setBlock(i + 8, j + 26, k + 16, MTJT.sunflowerLeaves.blockID, 0, 2);
        world.setBlock(i + 8, j + 26, k + 13, MTJT.sunflowerLeaves.blockID, 0, 2);
        world.setBlock(i + 8, j + 26, k + 11, MTJT.sunflowerLeaves.blockID, 0, 2);
        world.setBlock(i + 8, j + 26, k + 10, MTJT.sunflowerLeaves.blockID, 0, 2);
        world.setBlock(i + 8, j + 26, k + 8, MTJT.sunflowerLeaves.blockID, 0, 2);
        world.setBlock(i + 9, j + 26, k + 17, MTJT.sunflowerLeaves.blockID, 0, 2);
        world.setBlock(i + 9, j + 26, k + 15, MTJT.sunflowerLeaves.blockID, 0, 2);
        world.setBlock(i + 9, j + 26, k + 14, MTJT.sunflowerLeaves.blockID, 0, 2);
        world.setBlock(i + 9, j + 26, k + 12, MTJT.sunflowerLeaves.blockID, 0, 2);
        world.setBlock(i + 9, j + 26, k + 10, MTJT.sunflowerLeaves.blockID, 0, 2);
        world.setBlock(i + 9, j + 26, k + 9, MTJT.sunflowerLeaves.blockID, 0, 2);
        world.setBlock(i + 9, j + 26, k + 5, MTJT.sunflowerLeaves.blockID, 0, 2);
        world.setBlock(i + 10, j + 26, k + 15, MTJT.sunflowerLeaves.blockID, 0, 2);
        world.setBlock(i + 10, j + 26, k + 10, MTJT.sunflowerLog.blockID, 0, 2);
        world.setBlock(i + 11, j + 26, k + 13, MTJT.sunflowerLeaves.blockID, 0, 2);
        world.setBlock(i + 11, j + 26, k + 10, MTJT.sunflowerLeaves.blockID, 0, 2);
        world.setBlock(i + 11, j + 26, k + 8, MTJT.sunflowerLeaves.blockID, 0, 2);
        world.setBlock(i + 11, j + 26, k + 7, MTJT.sunflowerLeaves.blockID, 0, 2);
        world.setBlock(i + 12, j + 26, k + 15, MTJT.sunflowerLeaves.blockID, 0, 2);
        world.setBlock(i + 12, j + 26, k + 12, MTJT.sunflowerLeaves.blockID, 0, 2);
        world.setBlock(i + 13, j + 26, k + 13, MTJT.sunflowerLeaves.blockID, 0, 2);
        world.setBlock(i + 15, j + 26, k + 15, MTJT.sunflowerLeaves.blockID, 0, 2);
        world.setBlock(i + 0, j + 27, k + 3, MTJT.sunflowerLeaves.blockID, 0, 2);
        world.setBlock(i + 1, j + 27, k + 6, MTJT.sunflowerLeaves.blockID, 0, 2);
        world.setBlock(i + 1, j + 27, k + 5, MTJT.sunflowerLeaves.blockID, 0, 2);
        world.setBlock(i + 1, j + 27, k + 3, MTJT.sunflowerLeaves.blockID, 0, 2);
        world.setBlock(i + 6, j + 27, k + 12, MTJT.sunflowerLeaves.blockID, 0, 2);
        world.setBlock(i + 6, j + 27, k + 6, MTJT.sunflowerLeaves.blockID, 0, 2);
        world.setBlock(i + 7, j + 27, k + 17, MTJT.sunflowerLeaves.blockID, 0, 2);
        world.setBlock(i + 7, j + 27, k + 15, MTJT.sunflowerLeaves.blockID, 0, 2);
        world.setBlock(i + 7, j + 27, k + 14, MTJT.sunflowerLeaves.blockID, 0, 2);
        world.setBlock(i + 8, j + 27, k + 13, MTJT.sunflowerLeaves.blockID, 0, 2);
        world.setBlock(i + 8, j + 27, k + 9, MTJT.sunflowerLeaves.blockID, 0, 2);
        world.setBlock(i + 8, j + 27, k + 7, MTJT.sunflowerLeaves.blockID, 0, 2);
        world.setBlock(i + 9, j + 27, k + 14, MTJT.sunflowerLeaves.blockID, 0, 2);
        world.setBlock(i + 9, j + 27, k + 7, MTJT.sunflowerLeaves.blockID, 0, 2);
        world.setBlock(i + 9, j + 27, k + 5, MTJT.sunflowerLeaves.blockID, 0, 2);
        world.setBlock(i + 10, j + 27, k + 13, MTJT.sunflowerLeaves.blockID, 0, 2);
        world.setBlock(i + 10, j + 27, k + 10, MTJT.sunflowerLeaves.blockID, 0, 2);
        world.setBlock(i + 10, j + 27, k + 7, MTJT.sunflowerLeaves.blockID, 0, 2);
        world.setBlock(i + 10, j + 27, k + 5, MTJT.sunflowerLeaves.blockID, 0, 2);
        world.setBlock(i + 11, j + 27, k + 9, MTJT.sunflowerLeaves.blockID, 0, 2);
        world.setBlock(i + 12, j + 27, k + 16, MTJT.sunflowerLeaves.blockID, 0, 2);
        world.setBlock(i + 12, j + 27, k + 15, MTJT.sunflowerLeaves.blockID, 0, 2);
        world.setBlock(i + 12, j + 27, k + 13, MTJT.sunflowerLeaves.blockID, 0, 2);
        world.setBlock(i + 12, j + 27, k + 10, MTJT.sunflowerLeaves.blockID, 0, 2);
        world.setBlock(i + 13, j + 27, k + 17, MTJT.sunflowerLeaves.blockID, 0, 2);
        world.setBlock(i + 14, j + 27, k + 14, MTJT.sunflowerLeaves.blockID, 0, 2);
        world.setBlock(i + 2, j + 28, k + 3, MTJT.sunflowerLeaves.blockID, 0, 2);
        world.setBlock(i + 3, j + 28, k + 5, MTJT.sunflowerLeaves.blockID, 0, 2);
        world.setBlock(i + 3, j + 28, k + 4, MTJT.sunflowerLeaves.blockID, 0, 2);
        world.setBlock(i + 3, j + 28, k + 1, MTJT.sunflowerLeaves.blockID, 0, 2);
        world.setBlock(i + 4, j + 28, k + 5, MTJT.sunflowerLeaves.blockID, 0, 2);
        world.setBlock(i + 6, j + 28, k + 5, MTJT.sunflowerLeaves.blockID, 0, 2);
        world.setBlock(i + 7, j + 28, k + 13, MTJT.sunflowerLeaves.blockID, 0, 2);
        world.setBlock(i + 8, j + 28, k + 15, MTJT.sunflowerLeaves.blockID, 0, 2);
        world.setBlock(i + 8, j + 28, k + 10, MTJT.sunflowerLeaves.blockID, 0, 2);
        world.setBlock(i + 9, j + 28, k + 8, MTJT.sunflowerLeaves.blockID, 0, 2);
        world.setBlock(i + 12, j + 28, k + 15, MTJT.sunflowerLeaves.blockID, 0, 2);
        world.setBlock(i + 12, j + 28, k + 14, MTJT.sunflowerLeaves.blockID, 0, 2);
        world.setBlock(i + 12, j + 28, k + 9, MTJT.sunflowerLeaves.blockID, 0, 2);
        world.setBlock(i + 13, j + 28, k + 16, MTJT.sunflowerLeaves.blockID, 0, 2);
        world.setBlock(i + 3, j + 29, k + 6, MTJT.sunflowerLeaves.blockID, 0, 2);
        world.setBlock(i + 5, j + 29, k + 5, MTJT.sunflowerLeaves.blockID, 0, 2);
        world.setBlock(i + 5, j + 29, k + 4, MTJT.sunflowerLeaves.blockID, 0, 2);
        world.setBlock(i + 10, j + 29, k + 10, MTJT.sunflowerLeaves.blockID, 0, 2);
        world.setBlock(i + 10, j + 29, k + 9, MTJT.sunflowerLeaves.blockID, 0, 2);

return true;
}
}
